Workbook

Sheet ES
A1: EOSY Causes of Dropout in ELEMENTARY LEVEL (ALL SECTOR)
A2: SY 2019-2020
A3: Based on LIS, as of November 28, 2020 | N3: Had to Take Care Siblings | AG3: Early Marriage/Pregnancy | AZ3: Parents Attitude Toward Schooling | BS3: Family problems/Feuds | CL3: Illness | DE3: Overage | DX3: Death | EQ3: Drug Abuse | FJ3: Poor Academic Performance | GC3: Lack of interest/Distractions | GV3: Hunger/Malnutrition | HO3: Teacher Factors | IH3: Physical Conditions of Classrooms | JA3: Peer Influences | JT3: Distance between Home and School | KM3: Armed Conflict | LF3: Calamities/Disasters | LY3: Child Labor, Work | MR3: GRAND TOTAL (Dropout ES)
N4: Kindergarten | P4: Grade 1 | R4: Grade 2 | T4: Grade 3 | V4: Grade 4 | X4: Grade 5 | Z4: Grade 6 | AB4: Non-Graded | AD4: Grand Total | AG4: Kindergarten | AI4: Grade 1 | AK4: Grade 2 | AM4: Grade 3 | AO4: Grade 4 | AQ4: Grade 5 | AS4: Grade 6 | AU4: Non-Graded | AW4: Grand Total | AZ4: Kindergarten | BB4: Grade 1 | BD4: Grade 2 | BF4: Grade 3 | BH4: Grade 4 | BJ4: Grade 5 | BL4: Grade 6 | BN4: Non-Graded | BP4: Grand Total | BS4: Kindergarten | BU4: Grade 1 | BW4: Grade 2 | BY4: Grade 3 | CA4: Grade 4 | CC4: Grade 5 | CE4: Grade 6 | CG4: Non-Graded | CI4: Grand Total | CL4: Kindergarten | CN4: Grade 1 | CP4: Grade 2 | CR4: Grade 3 | CT4: Grade 4 | CV4: Grade 5 | CX4: Grade 6 | CZ4: Non-Graded | DB4: Grand Total | DE4: Kindergarten | DG4: Grade 1 | DI4: Grade 2 | DK4: Grade 3 | DM4: Grade 4 | DO4: Grade 5 | DQ4: Grade 6 | DS4: Non-Graded | DU4: Grand Total | DX4: Kindergarten | DZ4: Grade 1 | EB4: Grade 2 | ED4: Grade 3 | EF4: Grade 4 | EH4: Grade 5 | EJ4: Grade 6 | EL4: Non-Graded | EN4: Grand Total | EQ4: Kindergarten | ES4: Grade 1 | EU4: Grade 2 | EW4: Grade 3 | EY4: Grade 4 | FA4: Grade 5 | FC4: Grade 6 | FE4: Non-Graded | FG4: Grand Total | FJ4: Kindergarten | FL4: Grade 1 | FN4: Grade 2 | FP4: Grade 3 | FR4: Grade 4 | FT4: Grade 5 | FV4: Grade 6 | FX4: Non-Graded | FZ4: Grand Total | GC4: Kindergarten | GE4: Grade 1 | GG4: Grade 2 | GI4: Grade 3 | GK4: Grade 4 | GM4: Grade 5 | GO4: Grade 6 | GQ4: Non-Graded | GS4: Grand Total | GV4: Kindergarten | GX4: Grade 1 | GZ4: Grade 2 | HB4: Grade 3 | HD4: Grade 4 | HF4: Grade 5 | HH4: Grade 6 | HJ4: Non-Graded | HL4: Grand Total | HO4: Kindergarten | HQ4: Grade 1 | HS4: Grade 2 | HU4: Grade 3 | HW4: Grade 4 | HY4: Grade 5 | IA4: Grade 6 | IC4: Non-Graded | IE4: Grand Total | IH4: Kindergarten | IJ4: Grade 1 | IL4: Grade 2 | IN4: Grade 3 | IP4: Grade 4 | IR4: Grade 5 | IT4: Grade 6 | IV4: Non-Graded | IX4: Grand Total | JA4: Kindergarten | JC4: Grade 1 | JE4: Grade 2 | JG4: Grade 3 | JI4: Grade 4 | JK4: Grade 5 | JM4: Grade 6 | JO4: Non-Graded | JQ4: Grand Total | JT4: Kindergarten | JV4: Grade 1 | JX4: Grade 2 | JZ4: Grade 3 | KB4: Grade 4 | KD4: Grade 5 | KF4: Grade 6 | KH4: Non-Graded | KJ4: Grand Total | KM4: Kindergarten | KO4: Grade 1 | KQ4: Grade 2 | KS4: Grade 3 | KU4: Grade 4 | KW4: Grade 5 | KY4: Grade 6 | LA4: Non-Graded | LC4: Grand Total | LF4: Kindergarten | LH4: Grade 1 | LJ4: Grade 2 | LL4: Grade 3 | LN4: Grade 4 | LP4: Grade 5 | LR4: Grade 6 | LT4: Non-Graded | LV4: Grand Total | LY4: Kindergarten | MA4: Grade 1 | MC4: Grade 2 | ME4: Grade 3 | MG4: Grade 4 | MI4: Grade 5 | MK4: Grade 6 | MM4: Non-Graded | MO4: Grand Total | MR4: Kindergarten | MT4: Grade 1 | MV4: Grade 2 | MX4: Grade 3 | MZ4: Grade 4 | NB4: Grade 5 | ND4: Grade 6 | NF4: Non-Graded | NH4: Grand Total
M5: 1977 | N5: Male | O5: Female | P5: Male | Q5: Female | R5: Male | S5: Female | T5: Male | U5: Female | V5: Male | W5: Female | X5: Male | Y5: Female | Z5: Male | AA5: Female | AB5: Male | AC5: Female | AD5: Male | AE5: Female | AF5: Total | AG5: Male | AH5: Female | AI5: Male | AJ5: Female | AK5: Male | AL5: Female | AM5: Male | AN5: Female | AO5: Male | AP5: Female | AQ5: Male | AR5: Female | AS5: Male | AT5: Female | AU5: Male | AV5: Female | AW5: Male | AX5: Female | AY5: Total | AZ5: Male | BA5: Female | BB5: Male | BC5: Female | BD5: Male | BE5: Female | BF5: Male | BG5: Female | BH5: Male | BI5: Female | BJ5: Male | BK5: Female | BL5: Male | BM5: Female | BN5: Male | BO5: Female | BP5: Male | BQ5: Female | BR5: Total | BS5: Male | BT5: Female | BU5: Male | BV5: Female | BW5: Male | BX5: Female | BY5: Male | BZ5: Female | CA5: Male | CB5: Female | CC5: Male | CD5: Female | CE5: Male | CF5: Female | CG5: Male | CH5: Female | CI5: Male | CJ5: Female | CK5: Total | CL5: Male | CM5: Female | CN5: Male | CO5: Female | CP5: Male | CQ5: Female | CR5: Male | CS5: Female | CT5: Male | CU5: Female | CV5: Male | CW5: Female | CX5: Male | CY5: Female | CZ5: Male | DA5: Female | DB5: Male | DC5: Female | DD5: Total | DE5: Male | DF5: Female | DG5: Male | DH5: Female | DI5: Male | DJ5: Female | DK5: Male | DL5: Female | DM5: Male | DN5: Female | DO5: Male | DP5: Female | DQ5: Male | DR5: Female | DS5: Male | DT5: Female | DU5: Male | DV5: Female | DW5: Total | DX5: Male | DY5: Female | DZ5: Male | EA5: Female | EB5: Male | EC5: Female | ED5: Male | EE5: Female | EF5: Male | EG5: Female | EH5: Male | EI5: Female | EJ5: Male | EK5: Female | EL5: Male | EM5: Female | EN5: Male | EO5: Female | EP5: Total | EQ5: Male | ER5: Female | ES5: Male | ET5: Female | EU5: Male | EV5: Female | EW5: Male | EX5: Female | EY5: Male | EZ5: Female | FA5: Male | FB5: Female | FC5: Male | FD5: Female | FE5: Male | FF5: Female | FG5: Male | FH5: Female | FI5: Total | FJ5: Male | FK5: Female | FL5: Male | FM5: Female | FN5: Male | FO5: Female | FP5: Male | FQ5: Female | FR5: Male | FS5: Female | FT5: Male | FU5: Female | FV5: Male | FW5: Female | FX5: Male | FY5: Female | FZ5: Male | GA5: Female | GB5: Total | GC5: Male | GD5: Female | GE5: Male | GF5: Female | GG5: Male | GH5: Female | GI5: Male | GJ5: Female | GK5: Male | GL5: Female | GM5: Male | GN5: Female | GO5: Male | GP5: Female | GQ5: Male | GR5: Female | GS5: Male | GT5: Female | GU5: Total | GV5: Male | GW5: Female | GX5: Male | GY5: Female | GZ5: Male | HA5: Female | HB5: Male | HC5: Female | HD5: Male | HE5: Female | HF5: Male | HG5: Female | HH5: Male | HI5: Female | HJ5: Male | HK5: Female | HL5: Male | HM5: Female | HN5: Total | HO5: Male | HP5: Female | HQ5: Male | HR5: Female | HS5: Male | HT5: Female | HU5: Male | HV5: Female | HW5: Male | HX5: Female | HY5: Male | HZ5: Female | IA5: Male | IB5: Female | IC5: Male | ID5: Female | IE5: Male | IF5: Female | IG5: Total | IH5: Male | II5: Female | IJ5: Male | IK5: Female | IL5: Male | IM5: Female | IN5: Male | IO5: Female | IP5: Male | IQ5: Female | IR5: Male | IS5: Female | IT5: Male | IU5: Female | IV5: Male | IW5: Female | IX5: Male | IY5: Female | IZ5: Total | JA5: Male | JB5: Female | JC5: Male | JD5: Female | JE5: Male | JF5: Female | JG5: Male | JH5: Female | JI5: Male | JJ5: Female | JK5: Male | JL5: Female | JM5: Male | JN5: Female | JO5: Male | JP5: Female | JQ5: Male | JR5: Female | JS5: Total | JT5: Male | JU5: Female | JV5: Male | JW5: Female | JX5: Male | JY5: Female | JZ5: Male | KA5: Female | KB5: Male | KC5: Female | KD5: Male | KE5: Female | KF5: Male | KG5: Female | KH5: Male | KI5: Female | KJ5: Male | KK5: Female | KL5: Total | KM5: Male | KN5: Female | KO5: Male | KP5: Female | KQ5: Male | KR5: Female | KS5: Male | KT5: Female | KU5: Male | KV5: Female | KW5: Male | KX5: Female | KY5: Male | KZ5: Female | LA5: Male | LB5: Female | LC5: Male | LD5: Female | LE5: Total | LF5: Male | LG5: Female | LH5: Male | LI5: Female | LJ5: Male | LK5: Female | LL5: Male | LM5: Female | LN5: Male | LO5: Female | LP5: Male | LQ5: Female | LR5: Male | LS5: Female | LT5: Male | LU5: Female | LV5: Male | LW5: Female | LX5: Total | LY5: Male | LZ5: Female | MA5: Male | MB5: Female | MC5: Male | MD5: Female | ME5: Male | MF5: Female | MG5: Male | MH5: Female | MI5: Male | MJ5: Female | MK5: Male | ML5: Female | MM5: Male | MN5: Female | MO5: Male | MP5: Female | MQ5: Total | MR5: Male | MS5: Female | MT5: Male | MU5: Female | MV5: Male | MW5: Female | MX5: Male | MY5: Female | MZ5: Male | NA5: Female | NB5: Male | NC5: Female | ND5: Male | NE5: Female | NF5: Male | NG5: Female | NH5: Male | NI5: Female | NJ5: Total
M6: 155604 | N6: =SUM(N8:N74) -> 0 | O6: =SUM(O8:O74) -> 0 | P6: =SUM(P8:P74) -> 0 | Q6: =SUM(Q8:Q74) -> 0 | R6: =SUM(R8:R74) -> 0 | S6: =SUM(S8:S74) -> 0 | T6: =SUM(T8:T74) -> 0 | U6: =SUM(U8:U74) -> 0 | ... NJ6: =SUM(NJ8:NJ74) -> 417
A7: region | B7: division | C7: beis_school_id | D7: school_name | E7: province | F7: municipality | G7: legislative_district | H7: barangay | I7: school_type | J7: sector | K7: school_subclassification | L7: curricular_offering | M7: Modified Curricular Offering | N7: take_care_siblings_k_male | O7: take_care_siblings_k_female | P7: take_care_siblings_g1_male | Q7: take_care_siblings_g1_female | R7: take_care_siblings_g2_male | S7: take_care_siblings_g2_female | T7: take_care_siblings_g3_male | U7: take_care_siblings_g3_female | V7: take_care_siblings_g4_male | W7: take_care_siblings_g4_female | X7: take_care_siblings_g5_male | Y7: take_care_siblings_g5_female | Z7: take_care_siblings_g6_male | AA7: take_care_siblings_g6_female | AB7: take_care_siblings_ng_male | AC7: take_care_siblings_ng_female | AD7: take_care_siblings_male | AE7: take_care_siblings_female | AF7: take_care_siblings_Total | AG7: marr_preg_k_male | AH7: marr_preg_k_female | AI7: marr_preg_g1_male | AJ7: marr_preg_g1_female | AK7: marr_preg_g2_male | AL7: marr_preg_g2_female | AM7: marr_preg_g3_male | AN7: marr_preg_g3_female | AO7: marr_preg_g4_male | AP7: marr_preg_g4_female | AQ7: marr_preg_g5_male | AR7: marr_preg_g5_female | AS7: marr_preg_g6_male | AT7: marr_preg_g6_female | AU7: marr_preg_ng_male | AV7: marr_preg_ng_female | AW7: marr_preg_male | AX7: marr_preg_female | AY7: marr_preg_total | AZ7: parents_toward_school_k_male | BA7: parents_toward_school_k_female | BB7: parents_toward_school_g1_male | BC7: parents_toward_school_g1_female | BD7: parents_toward_school_g2_male | BE7: parents_toward_school_g2_female | BF7: parents_toward_school_g3_male | BG7: parents_toward_school_g3_female | BH7: parents_toward_school_g4_male | BI7: parents_toward_school_g4_female | BJ7: parents_toward_school_g5_male | BK7: parents_toward_school_g5_female | BL7: parents_toward_school_g6_male | BM7: parents_toward_school_g6_female | BN7: parents_toward_school_ng_male | BO7: parents_toward_school_ng_female | BP7: parents_toward_school_male | BQ7: parents_toward_school_female | BR7: parents_toward_school_total | BS7: fam_prob_feuds_k_male | BT7: fam_prob_feuds_k_female | BU7: fam_prob_feuds_g1_male | BV7: fam_prob_feuds_g1_female | BW7: fam_prob_feuds_g2_male | BX7: fam_prob_feuds_g2_female | BY7: fam_prob_feuds_g3_male | BZ7: fam_prob_feuds_g3_female | CA7: fam_prob_feuds_g4_male | CB7: fam_prob_feuds_g4_female | CC7: fam_prob_feuds_g5_male | CD7: fam_prob_feuds_g5_female | CE7: fam_prob_feuds_g6_male | CF7: fam_prob_feuds_g6_female | CG7: fam_prob_feuds_ng_male | CH7: fam_prob_feuds_ng_female | CI7: fam_prob_feuds_male | CJ7: fam_prob_feuds_female | CK7: fam_prob_feuds_total | CL7: illness_k_male | CM7: illness_k_female | CN7: illness_g1_male | CO7: illness_g1_female | CP7: illness_g2_male | CQ7: illness_g2_female | CR7: illness_g3_male | CS7: illness_g3_female | CT7: illness_g4_male | CU7: illness_g4_female | CV7: illness_g5_male | CW7: illness_g5_female | CX7: illness_g6_male | CY7: illness_g6_female | CZ7: illness_ng_male | DA7: illness_ng_female | DB7: illness_male | DC7: illness_female | DD7: illness_total | DE7: overage_k_male | DF7: overage_k_female | DG7: overage_g1_male | DH7: overage_g1_female | DI7: overage_g2_male | DJ7: overage_g2_female | DK7: overage_g3_male | DL7: overage_g3_female | DM7: overage_g4_male | DN7: overage_g4_female | DO7: overage_g5_male | DP7: overage_g5_female | DQ7: overage_g6_male | DR7: overage_g6_female | DS7: overage_ng_male | DT7: overage_ng_female | DU7: overage_male | DV7: overage_female | DW7: overage_total | DX7: death_k_male | DY7: death_k_female | DZ7: death_g1_male | EA7: death_g1_female | EB7: death_g2_male | EC7: death_g2_female | ED7: death_g3_male | EE7: death_g3_female | EF7: death_g4_male | EG7: death_g4_female | EH7: death_g5_male | EI7: death_g5_female | EJ7: death_g6_male | EK7: death_g6_female | EL7: death_ng_male | EM7: death_ng_female | EN7: death_male | EO7: death_female | EP7: death_total | EQ7: drug_abuse_k_male | ER7: drug_abuse_k_female | ES7: drug_abuse_g1_male | ET7: drug_abuse_g1_female | EU7: drug_abuse_g2_male | EV7: drug_abuse_g2_female | EW7: drug_abuse_g3_male | EX7: drug_abuse_g3_female | EY7: drug_abuse_g4_male | EZ7: drug_abuse_g4_female | FA7: drug_abuse_g5_male | FB7: drug_abuse_g5_female | FC7: drug_abuse_g6_male | FD7: drug_abuse_g6_female | FE7: drug_abuse_ng_male | FF7: drug_abuse_ng_female | FG7: drug_abuse_male | FH7: drug_abuse_female | FI7: drug_abuse_total | FJ7: poor_acad_perf_k_male | FK7: poor_acad_perf_k_female | FL7: poor_acad_perf_g1_male | FM7: poor_acad_perf_g1_female | FN7: poor_acad_perf_g2_male | FO7: poor_acad_perf_g2_female | FP7: poor_acad_perf_g3_male | FQ7: poor_acad_perf_g3_female | FR7: poor_acad_perf_g4_male | FS7: poor_acad_perf_g4_female | FT7: poor_acad_perf_g5_male | FU7: poor_acad_perf_g5_female | FV7: poor_acad_perf_g6_male | FW7: poor_acad_perf_g6_female | FX7: poor_acad_perf_ng_male | FY7: poor_acad_perf_ng_female | FZ7: poor_acad_perf_male | GA7: poor_acad_perf_female | GB7: poor_acad_perf_total | GC7: lack_of_interest_k_male | GD7: lack_of_interest_k_female | GE7: lack_of_interest_g1_male | GF7: lack_of_interest_g1_female | GG7: lack_of_interest_g2_male | GH7: lack_of_interest_g2_female | GI7: lack_of_interest_g3_male | GJ7: lack_of_interest_g3_female | GK7: lack_of_interest_g4_male | GL7: lack_of_interest_g4_female | GM7: lack_of_interest_g5_male | GN7: lack_of_interest_g5_female | GO7: lack_of_interest_g6_male | GP7: lack_of_interest_g6_female | GQ7: lack_of_interest_ng_male | GR7: lack_of_interest_ng_female | GS7: lack_of_interest_male | GT7: lack_of_interest_female | GU7: lack_of_interest_total | GV7: hunger_malnu_k_male | GW7: hunger_malnu_k_female | GX7: hunger_malnu_g1_male | GY7: hunger_malnu_g1_female | GZ7: hunger_malnu_g2_male | HA7: hunger_malnu_g2_female | HB7: hunger_malnu_g3_male | HC7: hunger_malnu_g3_female | HD7: hunger_malnu_g4_male | HE7: hunger_malnu_g4_female | HF7: hunger_malnu_g5_male | HG7: hunger_malnu_g5_female | HH7: hunger_malnu_g6_male | HI7: hunger_malnu_g6_female | HJ7: hunger_malnu_ng_male | HK7: hunger_malnu_ng_female | HL7: hunger_malnu_male | HM7: hunger_malnu_female | HN7: hunger_malnu_total | HO7: teacher_factor_k_male | HP7: teacher_factor_k_female | HQ7: teacher_factor_g1_male | HR7: teacher_factor_g1_female | HS7: teacher_factor_g2_male | HT7: teacher_factor_g2_female | HU7: teacher_factor_g3_male | HV7: teacher_factor_g3_female | HW7: teacher_factor_g4_male | HX7: teacher_factor_g4_female | HY7: teacher_factor_g5_male | HZ7: teacher_factor_g5_female | IA7: teacher_factor_g6_male | IB7: teacher_factor_g6_female | IC7: teacher_factor_ng_male | ID7: teacher_factor_ng_female | IE7: teacher_factor_male | IF7: teacher_factor_female | IG7: teacher_factor_total | IH7: physical_cond_classroom_k_male | II7: physical_cond_classroom_k_female | IJ7: physical_cond_classroom_g1_male | IK7: physical_cond_classroom_g1_female | IL7: physical_cond_classroom_g2_male | IM7: physical_cond_classroom_g2_female | IN7: physical_cond_classroom_g3_male | IO7: physical_cond_classroom_g3_female | IP7: physical_cond_classroom_g4_male | IQ7: physical_cond_classroom_g4_female | IR7: physical_cond_classroom_g5_male | IS7: physical_cond_classroom_g5_female | IT7: physical_cond_classroom_g6_male | IU7: physical_cond_classroom_g6_female | IV7: physical_cond_classroom_ng_male | IW7: physical_cond_classroom_ng_female | IX7: physical_cond_classroom_male | IY7: physical_cond_classroom_female | IZ7: physical_cond_classroom_total | JA7: peer_influ_k_male | JB7: peer_influ_k_female | JC7: peer_influ_g1_male | JD7: peer_influ_g1_female | JE7: peer_influ_g2_male | JF7: peer_influ_g2_female | JG7: peer_influ_g3_male | JH7: peer_influ_g3_female | JI7: peer_influ_g4_male | JJ7: peer_influ_g4_female | JK7: peer_influ_g5_male | JL7: peer_influ_g5_female | JM7: peer_influ_g6_male | JN7: peer_influ_g6_female | JO7: peer_influ_ng_male | JP7: peer_influ_ng_female | JQ7: peer_influ_male | JR7: peer_influ_female | JS7: peer_influ_total | JT7: distance_home_school_k_male | JU7: distance_home_school_k_female | JV7: distance_home_school_g1_male | JW7: distance_home_school_g1_female | JX7: distance_home_school_g2_male | JY7: distance_home_school_g2_female | JZ7: distance_home_school_g3_male | KA7: distance_home_school_g3_female | KB7: distance_home_school_g4_male | KC7: distance_home_school_g4_female | KD7: distance_home_school_g5_male | KE7: distance_home_school_g5_female | KF7: distance_home_school_g6_male | KG7: distance_home_school_g6_female | KH7: distance_home_school_ng_male | KI7: distance_home_school_ng_female | KJ7: distance_home_school_male | KK7: distance_home_school_female | KL7: distance_home_school_total | KM7: armed_conflict_k_male | KN7: armed_conflict_k_female | KO7: armed_conflict_g1_male | KP7: armed_conflict_g1_female | KQ7: armed_conflict_g2_male | KR7: armed_conflict_g2_female | KS7: armed_conflict_g3_male | KT7: armed_conflict_g3_female | KU7: armed_conflict_g4_male | KV7: armed_conflict_g4_female | KW7: armed_conflict_g5_male | KX7: armed_conflict_g5_female | KY7: armed_conflict_g6_male | KZ7: armed_conflict_g6_female | LA7: armed_conflict_ng_male | LB7: armed_conflict_ng_female | LC7: armed_conflict_male | LD7: armed_conflict_female | LE7: armed_conflict_total | LF7: calamities_k_male | LG7: calamities_k_female | LH7: calamities_g1_male | LI7: calamities_g1_female | LJ7: calamities_g2_male | LK7: calamities_g2_female | LL7: calamities_g3_male | LM7: calamities_g3_female | LN7: calamities_g4_male | LO7: calamities_g4_female | LP7: calamities_g5_male | LQ7: calamities_g5_female | LR7: calamities_g6_male | LS7: calamities_g6_female | LT7: calamities_ng_male | LU7: calamities_ng_female | LV7: calamities_male | LW7: calamities_female | LX7: calamities_total | LY7: child_labor_k_male | LZ7: child_labor_k_female | MA7: child_labor_g1_male | MB7: child_labor_g1_female | MC7: child_labor_g2_male | MD7: child_labor_g2_female | ME7: child_labor_g3_male | MF7: child_labor_g3_female | MG7: child_labor_g4_male | MH7: child_labor_g4_female | MI7: child_labor_g5_male | MJ7: child_labor_g5_female | MK7: child_labor_g6_male | ML7: child_labor_g6_female | MM7: child_labor_ng_male | MN7: child_labor_ng_female | MO7: child_labor_male | MP7: child_labor_female | MQ7: child_labor_total | MR7: k_male | MS7: k_female | MT7: g1_male | MU7: g1_female | MV7: g2_male | MW7: g2_female | MX7: g3_male | MY7: g3_female | MZ7: g4_male | NA7: g4_female | NB7: g5_male | NC7: g5_female | ND7: g6_male | NE7: g6_female | NF7: ng_male | NG7: ng_female | NH7: Male | NI7: Female | NJ7: Total
A8: Region XI | B8: Mati City | C8: 101813 | D8: Bugakan Elementary School | E8: DAVAO ORIENTAL | F8: CITY OF MATI (Capital) | G8: 2nd District | H8: TAGABAKID | I8: School with no Annexes | J8: Public | K8: DepED Managed | L8: Kinder & Grade 1-6 | M8: Purely ES | N8: 0 | O8: 0 | P8: 0 | Q8: 0 | R8: 0 | S8: 0 | T8: 0 | U8: 0 | V8: 0 | W8: 0 | X8: 0 | Y8: 0 | Z8: 0 | AA8: 0 | AB8: 0 | AC8: 0 | AD8: 0 | AE8: 0 | AF8: 0 | AG8: 0 | AH8: 0 | AI8: 0 | AJ8: 0 | AK8: 0 | AL8: 0 | AM8: 0 | AN8: 0 | AO8: 0 | AP8: 0 | AQ8: 0 | AR8: 0 | AS8: 0 | AT8: 0 | AU8: 0 | AV8: 0 | AW8: 0 | AX8: 0 | AY8: 0 | AZ8: 0 | BA8: 0 | BB8: 0 | BC8: 0 | BD8: 0 | BE8: 0 | BF8: 0 | BG8: 0 | BH8: 0 | BI8: 0 | BJ8: 0 | BK8: 0 | BL8: 0 | BM8: 0 | BN8: 0 | BO8: 0 | BP8: 0 | BQ8: 0 | BR8: 0 | BS8: 0 | BT8: 0 | BU8: 0 | BV8: 0 | BW8: 0 | BX8: 0 | BY8: 0 | BZ8: 0 | CA8: 0 | CB8: 0 | CC8: 0 | CD8: 0 | CE8: 0 | CF8: 0 | CG8: 0 | CH8: 0 | CI8: 0 | CJ8: 0 | CK8: 0 | CL8: 1 | CM8: 0 | CN8: 0 | CO8: 0 | CP8: 0 | CQ8: 0 | CR8: 0 | CS8: 0 | CT8: 0 | CU8: 0 | CV8: 0 | CW8: 0 | CX8: 0 | CY8: 0 | CZ8: 0 | DA8: 0 | DB8: 1 | DC8: 0 | DD8: 1 | DE8: 0 | DF8: 0 | DG8: 0 | DH8: 0 | DI8: 0 | DJ8: 0 | DK8: 0 | DL8: 0 | DM8: 0 | DN8: 0 | DO8: 0 | DP8: 0 | DQ8: 0 | DR8: 0 | DS8: 0 | DT8: 0 | DU8: 0 | DV8: 0 | DW8: 0 | DX8: 0 | DY8: 0 | DZ8: 0 | EA8: 0 | EB8: 0 | EC8: 0 | ED8: 0 | EE8: 0 | EF8: 0 | EG8: 0 | EH8: 0 | EI8: 0 | EJ8: 0 | EK8: 0 | EL8: 0 | EM8: 0 | EN8: 0 | EO8: 0 | EP8: 0 | EQ8: 0 | ER8: 0 | ES8: 0 | ET8: 0 | EU8: 0 | EV8: 0 | EW8: 0 | EX8: 0 | EY8: 0 | EZ8: 0 | FA8: 0 | FB8: 0 | FC8: 0 | FD8: 0 | FE8: 0 | FF8: 0 | FG8: 0 | FH8: 0 | FI8: 0 | FJ8: 0 | FK8: 0 | FL8: 0 | FM8: 0 | FN8: 0 | FO8: 0 | FP8: 0 | FQ8: 0 | FR8: 0 | FS8: 0 | FT8: 0 | FU8: 0 | FV8: 0 | FW8: 0 | FX8: 0 | FY8: 0 | FZ8: 0 | GA8: 0 | GB8: 0 | GC8: 0 | GD8: 0 | GE8: 0 | GF8: 0 | GG8: 0 | GH8: 0 | GI8: 0 | GJ8: 0 | GK8: 0 | GL8: 0 | GM8: 0 | GN8: 0 | GO8: 0 | GP8: 0 | GQ8: 0 | GR8: 0 | GS8: 0 | GT8: 0 | GU8: 0 | GV8: 0 | GW8: 0 | GX8: 0 | GY8: 0 | GZ8: 0 | HA8: 0 | HB8: 0 | HC8: 0 | HD8: 0 | HE8: 0 | HF8: 0 | HG8: 0 | HH8: 0 | HI8: 0 | HJ8: 0 | HK8: 0 | HL8: 0 | HM8: 0 | HN8: 0 | HO8: 0 | HP8: 0 | HQ8: 0 | HR8: 0 | HS8: 0 | HT8: 0 | HU8: 0 | HV8: 0 | HW8: 0 | HX8: 0 | HY8: 0 | HZ8: 0 | IA8: 0 | IB8: 0 | IC8: 0 | ID8: 0 | IE8: 0 | IF8: 0 | IG8: 0 | IH8: 0 | II8: 0 | IJ8: 0 | IK8: 0 | IL8: 0 | IM8: 0 | IN8: 0 | IO8: 0 | IP8: 0 | IQ8: 0 | IR8: 0 | IS8: 0 | IT8: 0 | IU8: 0 | IV8: 0 | IW8: 0 | IX8: 0 | IY8: 0 | IZ8: 0 | JA8: 0 | JB8: 0 | JC8: 0 | JD8: 0 | JE8: 0 | JF8: 0 | JG8: 0 | JH8: 0 | JI8: 0 | JJ8: 0 | JK8: 0 | JL8: 0 | JM8: 0 | JN8: 0 | JO8: 0 | JP8: 0 | JQ8: 0 | JR8: 0 | JS8: 0 | JT8: 0 | JU8: 0 | JV8: 0 | JW8: 0 | JX8: 0 | JY8: 0 | JZ8: 0 | KA8: 0 | KB8: 0 | KC8: 0 | KD8: 0 | KE8: 0 | KF8: 0 | KG8: 0 | KH8: 0 | KI8: 0 | KJ8: 0 | KK8: 0 | KL8: 0 | KM8: 0 | KN8: 0 | KO8: 0 | KP8: 0 | KQ8: 0 | KR8: 0 | KS8: 0 | KT8: 0 | KU8: 0 | KV8: 0 | KW8: 0 | KX8: 0 | KY8: 0 | KZ8: 0 | LA8: 0 | LB8: 0 | LC8: 0 | LD8: 0 | LE8: 0 | LF8: 0 | LG8: 0 | LH8: 0 | LI8: 0 | LJ8: 0 | LK8: 0 | LL8: 0 | LM8: 0 | LN8: 0 | LO8: 0 | LP8: 0 | LQ8: 0 | LR8: 0 | LS8: 0 | LT8: 0 | LU8: 0 | LV8: 0 | LW8: 0 | LX8: 0 | LY8: 0 | LZ8: 0 | MA8: 0 | MB8: 0 | MC8: 0 | MD8: 0 | ME8: 0 | MF8: 0 | MG8: 0 | MH8: 0 | MI8: 0 | MJ8: 0 | MK8: 0 | ML8: 0 | MM8: 0 | MN8: 0 | MO8: 0 | MP8: 0 | MQ8: 0 | MR8: =SUMIF($N$7:$MQ$7,"*"&MR$7&"*",$N8:$MQ8) -> 1 | MS8: =SUMIF($N$7:$MQ$7,"*"&MS$7&"*",$N8:$MQ8) -> 0 | MT8: =SUMIF($N$7:$MQ$7,"*"&MT$7&"*",$N8:$MQ8) -> 0 | MU8: =SUMIF($N$7:$MQ$7,"*"&MU$7&"*",$N8:$MQ8) -> 0 | MV8: =SUMIF($N$7:$MQ$7,"*"&MV$7&"*",$N8:$MQ8) -> 0 | MW8: =SUMIF($N$7:$MQ$7,"*"&MW$7&"*",$N8:$MQ8) -> 0 | MX8: =SUMIF($N$7:$MQ$7,"*"&MX$7&"*",$N8:$MQ8) -> 0 | MY8: =SUMIF($N$7:$MQ$7,"*"&MY$7&"*",$N8:$MQ8) -> 0 | ... NG8: =SUMIF($N$7:$MQ$7,"*"&NG$7&"*",$N8:$MQ8) -> 0 | NH8: =SUMIF($MR$5:$NG$5,NH$7,$MR8:$NG8) -> 1 | NI8: =SUMIF($MR$5:$NG$5,NI$7,$MR8:$NG8) -> 0 | NJ8: =SUM(NH8:NI8) -> 1
A9: Region XI | B9: Mati City | C9: 102157 | D9: Catmonan Elementary School | E9: DAVAO ORIENTAL | F9: CITY OF MATI (Capital) | G9: 2nd District | H9: MACAMBOL | I9: School with no Annexes | J9: Public | K9: DepED Managed | L9: Kinder & Grade 1-6 | M9: Purely ES | N9: 0 | O9: 0 | P9: 0 | Q9: 0 | R9: 0 | S9: 0 | T9: 0 | U9: 0 | V9: 0 | W9: 0 | X9: 0 | Y9: 0 | Z9: 0 | AA9: 0 | AB9: 0 | AC9: 0 | AD9: 0 | AE9: 0 | AF9: 0 | AG9: 0 | AH9: 0 | AI9: 0 | AJ9: 0 | AK9: 0 | AL9: 0 | AM9: 0 | AN9: 0 | AO9: 0 | AP9: 0 | AQ9: 0 | AR9: 0 | AS9: 0 | AT9: 0 | AU9: 0 | AV9: 0 | AW9: 0 | AX9: 0 | AY9: 0 | AZ9: 0 | BA9: 0 | BB9: 0 | BC9: 0 | BD9: 0 | BE9: 0 | BF9: 0 | BG9: 0 | BH9: 0 | BI9: 0 | BJ9: 0 | BK9: 0 | BL9: 0 | BM9: 0 | BN9: 0 | BO9: 0 | BP9: 0 | BQ9: 0 | BR9: 0 | BS9: 0 | BT9: 0 | BU9: 0 | BV9: 0 | BW9: 0 | BX9: 0 | BY9: 1 | BZ9: 0 | CA9: 0 | CB9: 0 | CC9: 0 | CD9: 0 | CE9: 1 | CF9: 0 | CG9: 0 | CH9: 0 | CI9: 2 | CJ9: 0 | CK9: 2 | CL9: 1 | CM9: 0 | CN9: 0 | CO9: 0 | CP9: 0 | CQ9: 0 | CR9: 0 | CS9: 0 | CT9: 0 | CU9: 0 | CV9: 0 | CW9: 0 | CX9: 0 | CY9: 0 | CZ9: 0 | DA9: 0 | DB9: 1 | DC9: 0 | DD9: 1 | DE9: 0 | DF9: 0 | DG9: 0 | DH9: 0 | DI9: 0 | DJ9: 0 | DK9: 0 | DL9: 0 | DM9: 0 | DN9: 0 | DO9: 0 | DP9: 0 | DQ9: 0 | DR9: 0 | DS9: 0 | DT9: 0 | DU9: 0 | DV9: 0 | DW9: 0 | DX9: 0 | DY9: 0 | DZ9: 0 | EA9: 0 | EB9: 0 | EC9: 0 | ED9: 0 | EE9: 0 | EF9: 0 | EG9: 0 | EH9: 0 | EI9: 0 | EJ9: 0 | EK9: 0 | EL9: 0 | EM9: 0 | EN9: 0 | EO9: 0 | EP9: 0 | EQ9: 0 | ER9: 0 | ES9: 0 | ET9: 0 | EU9: 0 | EV9: 0 | EW9: 0 | EX9: 0 | EY9: 0 | EZ9: 0 | FA9: 0 | FB9: 0 | FC9: 0 | FD9: 0 | FE9: 0 | FF9: 0 | FG9: 0 | FH9: 0 | FI9: 0 | FJ9: 0 | FK9: 0 | FL9: 0 | FM9: 0 | FN9: 0 | FO9: 0 | FP9: 0 | FQ9: 0 | FR9: 0 | FS9: 0 | FT9: 0 | FU9: 0 | FV9: 0 | FW9: 0 | FX9: 0 | FY9: 0 | FZ9: 0 | GA9: 0 | GB9: 0 | GC9: 3 | GD9: 0 | GE9: 0 | GF9: 0 | GG9: 0 | GH9: 0 | GI9: 0 | GJ9: 0 | GK9: 0 | GL9: 0 | GM9: 0 | GN9: 0 | GO9: 1 | GP9: 0 | GQ9: 0 | GR9: 0 | GS9: 4 | GT9: 0 | GU9: 4 | GV9: 0 | GW9: 0 | GX9: 0 | GY9: 0 | GZ9: 0 | HA9: 0 | HB9: 0 | HC9: 0 | HD9: 0 | HE9: 0 | HF9: 0 | HG9: 0 | HH9: 0 | HI9: 0 | HJ9: 0 | HK9: 0 | HL9: 0 | HM9: 0 | HN9: 0 | HO9: 0 | HP9: 0 | HQ9: 0 | HR9: 0 | HS9: 0 | HT9: 0 | HU9: 0 | HV9: 0 | HW9: 0 | HX9: 0 | HY9: 0 | HZ9: 0 | IA9: 0 | IB9: 0 | IC9: 0 | ID9: 0 | IE9: 0 | IF9: 0 | IG9: 0 | IH9: 0 | II9: 0 | IJ9: 0 | IK9: 0 | IL9: 0 | IM9: 0 | IN9: 0 | IO9: 0 | IP9: 0 | IQ9: 0 | IR9: 0 | IS9: 0 | IT9: 0 | IU9: 0 | IV9: 0 | IW9: 0 | IX9: 0 | IY9: 0 | IZ9: 0 | JA9: 0 | JB9: 0 | JC9: 0 | JD9: 0 | JE9: 0 | JF9: 0 | JG9: 0 | JH9: 0 | JI9: 0 | JJ9: 0 | JK9: 0 | JL9: 0 | JM9: 0 | JN9: 0 | JO9: 0 | JP9: 0 | JQ9: 0 | JR9: 0 | JS9: 0 | JT9: 1 | JU9: 0 | JV9: 0 | JW9: 0 | JX9: 0 | JY9: 0 | JZ9: 0 | KA9: 0 | KB9: 0 | KC9: 0 | KD9: 0 | KE9: 0 | KF9: 0 | KG9: 0 | KH9: 0 | KI9: 0 | KJ9: 1 | KK9: 0 | KL9: 1 | KM9: 0 | KN9: 0 | KO9: 0 | KP9: 0 | KQ9: 0 | KR9: 0 | KS9: 0 | KT9: 0 | KU9: 0 | KV9: 0 | KW9: 0 | KX9: 0 | KY9: 0 | KZ9: 0 | LA9: 0 | LB9: 0 | LC9: 0 | LD9: 0 | LE9: 0 | LF9: 0 | LG9: 0 | LH9: 0 | LI9: 0 | LJ9: 0 | LK9: 0 | LL9: 0 | LM9: 0 | LN9: 0 | LO9: 0 | LP9: 0 | LQ9: 0 | LR9: 0 | LS9: 0 | LT9: 0 | LU9: 0 | LV9: 0 | LW9: 0 | LX9: 0 | LY9: 0 | LZ9: 0 | MA9: 0 | MB9: 0 | MC9: 0 | MD9: 0 | ME9: 0 | MF9: 0 | MG9: 0 | MH9: 0 | MI9: 0 | MJ9: 0 | MK9: 0 | ML9: 0 | MM9: 0 | MN9: 0 | MO9: 0 | MP9: 0 | MQ9: 0 | MR9: =SUMIF($N$7:$MQ$7,"*"&MR$7&"*",$N9:$MQ9) -> 5 | MS9: =SUMIF($N$7:$MQ$7,"*"&MS$7&"*",$N9:$MQ9) -> 0 | MT9: =SUMIF($N$7:$MQ$7,"*"&MT$7&"*",$N9:$MQ9) -> 0 | MU9: =SUMIF($N$7:$MQ$7,"*"&MU$7&"*",$N9:$MQ9) -> 0 | MV9: =SUMIF($N$7:$MQ$7,"*"&MV$7&"*",$N9:$MQ9) -> 0 | MW9: =SUMIF($N$7:$MQ$7,"*"&MW$7&"*",$N9:$MQ9) -> 0 | MX9: =SUMIF($N$7:$MQ$7,"*"&MX$7&"*",$N9:$MQ9) -> 1 | MY9: =SUMIF($N$7:$MQ$7,"*"&MY$7&"*",$N9:$MQ9) -> 0 | ... NG9: =SUMIF($N$7:$MQ$7,"*"&NG$7&"*",$N9:$MQ9) -> 0 | NH9: =SUMIF($MR$5:$NG$5,NH$7,$MR9:$NG9) -> 8 | NI9: =SUMIF($MR$5:$NG$5,NI$7,$MR9:$NG9) -> 0 | NJ9: =SUM(NH9:NI9) -> 8
A10: Region XI | B10: Mati City | C10: 102164 | D10: Talucanga Elementary School | E10: DAVAO ORIENTAL | F10: CITY OF MATI (Capital) | G10: 2nd District | H10: LUBAN | I10: School with no Annexes | J10: Public | K10: DepED Managed | L10: Kinder & Grade 1-6 | M10: Purely ES | N10: 0 | O10: 0 | P10: 0 | Q10: 0 | R10: 0 | S10: 0 | T10: 0 | U10: 0 | V10: 0 | W10: 0 | X10: 0 | Y10: 0 | Z10: 0 | AA10: 0 | AB10: 0 | AC10: 0 | AD10: 0 | AE10: 0 | AF10: 0 | AG10: 0 | AH10: 0 | AI10: 0 | AJ10: 0 | AK10: 0 | AL10: 0 | AM10: 0 | AN10: 0 | AO10: 0 | AP10: 0 | AQ10: 0 | AR10: 0 | AS10: 0 | AT10: 0 | AU10: 0 | AV10: 0 | AW10: 0 | AX10: 0 | AY10: 0 | AZ10: 0 | BA10: 0 | BB10: 0 | BC10: 0 | BD10: 0 | BE10: 0 | BF10: 0 | BG10: 0 | BH10: 0 | BI10: 0 | BJ10: 0 | BK10: 0 | BL10: 0 | BM10: 0 | BN10: 0 | BO10: 0 | BP10: 0 | BQ10: 0 | BR10: 0 | BS10: 0 | BT10: 0 | BU10: 0 | BV10: 0 | BW10: 0 | BX10: 0 | BY10: 0 | BZ10: 0 | CA10: 0 | CB10: 0 | CC10: 0 | CD10: 0 | CE10: 0 | CF10: 0 | CG10: 0 | CH10: 0 | CI10: 0 | CJ10: 0 | CK10: 0 | CL10: 0 | CM10: 1 | CN10: 0 | CO10: 0 | CP10: 0 | CQ10: 0 | CR10: 0 | CS10: 0 | CT10: 0 | CU10: 0 | CV10: 0 | CW10: 0 | CX10: 0 | CY10: 0 | CZ10: 0 | DA10: 0 | DB10: 0 | DC10: 1 | DD10: 1 | DE10: 0 | DF10: 0 | DG10: 0 | DH10: 0 | DI10: 0 | DJ10: 0 | DK10: 0 | DL10: 0 | DM10: 0 | DN10: 0 | DO10: 0 | DP10: 0 | DQ10: 0 | DR10: 0 | DS10: 0 | DT10: 0 | DU10: 0 | DV10: 0 | DW10: 0 | DX10: 0 | DY10: 0 | DZ10: 0 | EA10: 0 | EB10: 0 | EC10: 0 | ED10: 0 | EE10: 0 | EF10: 0 | EG10: 0 | EH10: 0 | EI10: 0 | EJ10: 0 | EK10: 0 | EL10: 0 | EM10: 0 | EN10: 0 | EO10: 0 | EP10: 0 | EQ10: 0 | ER10: 0 | ES10: 0 | ET10: 0 | EU10: 0 | EV10: 0 | EW10: 0 | EX10: 0 | EY10: 0 | EZ10: 0 | FA10: 0 | FB10: 0 | FC10: 0 | FD10: 0 | FE10: 0 | FF10: 0 | FG10: 0 | FH10: 0 | FI10: 0 | FJ10: 0 | FK10: 0 | FL10: 0 | FM10: 0 | FN10: 0 | FO10: 0 | FP10: 0 | FQ10: 0 | FR10: 0 | FS10: 0 | FT10: 0 | FU10: 0 | FV10: 0 | FW10: 0 | FX10: 0 | FY10: 0 | FZ10: 0 | GA10: 0 | GB10: 0 | GC10: 0 | GD10: 0 | GE10: 0 | GF10: 0 | GG10: 0 | GH10: 0 | GI10: 0 | GJ10: 0 | GK10: 0 | GL10: 0 | GM10: 0 | GN10: 0 | GO10: 0 | GP10: 0 | GQ10: 0 | GR10: 0 | GS10: 0 | GT10: 0 | GU10: 0 | GV10: 0 | GW10: 0 | GX10: 0 | GY10: 0 | GZ10: 0 | HA10: 0 | HB10: 0 | HC10: 0 | HD10: 0 | HE10: 0 | HF10: 0 | HG10: 0 | HH10: 0 | HI10: 0 | HJ10: 0 | HK10: 0 | HL10: 0 | HM10: 0 | HN10: 0 | HO10: 0 | HP10: 0 | HQ10: 0 | HR10: 0 | HS10: 0 | HT10: 0 | HU10: 0 | HV10: 0 | HW10: 0 | HX10: 0 | HY10: 0 | HZ10: 0 | IA10: 0 | IB10: 0 | IC10: 0 | ID10: 0 | IE10: 0 | IF10: 0 | IG10: 0 | IH10: 0 | II10: 0 | IJ10: 0 | IK10: 0 | IL10: 0 | IM10: 0 | IN10: 0 | IO10: 0 | IP10: 0 | IQ10: 0 | IR10: 0 | IS10: 0 | IT10: 0 | IU10: 0 | IV10: 0 | IW10: 0 | IX10: 0 | IY10: 0 | IZ10: 0 | JA10: 0 | JB10: 0 | JC10: 0 | JD10: 0 | JE10: 0 | JF10: 0 | JG10: 0 | JH10: 0 | JI10: 0 | JJ10: 0 | JK10: 0 | JL10: 0 | JM10: 0 | JN10: 0 | JO10: 0 | JP10: 0 | JQ10: 0 | JR10: 0 | JS10: 0 | JT10: 0 | JU10: 0 | JV10: 0 | JW10: 0 | JX10: 0 | JY10: 0 | JZ10: 0 | KA10: 0 | KB10: 0 | KC10: 0 | KD10: 0 | KE10: 0 | KF10: 0 | KG10: 0 | KH10: 0 | KI10: 0 | KJ10: 0 | KK10: 0 | KL10: 0 | KM10: 0 | KN10: 0 | KO10: 0 | KP10: 0 | KQ10: 0 | KR10: 0 | KS10: 0 | KT10: 0 | KU10: 0 | KV10: 0 | KW10: 0 | KX10: 0 | KY10: 0 | KZ10: 0 | LA10: 0 | LB10: 0 | LC10: 0 | LD10: 0 | LE10: 0 | LF10: 0 | LG10: 0 | LH10: 0 | LI10: 0 | LJ10: 0 | LK10: 0 | LL10: 0 | LM10: 0 | LN10: 0 | LO10: 0 | LP10: 0 | LQ10: 0 | LR10: 0 | LS10: 0 | LT10: 0 | LU10: 0 | LV10: 0 | LW10: 0 | LX10: 0 | LY10: 0 | LZ10: 0 | MA10: 0 | MB10: 0 | MC10: 0 | MD10: 0 | ME10: 0 | MF10: 0 | MG10: 0 | MH10: 0 | MI10: 0 | MJ10: 0 | MK10: 0 | ML10: 0 | MM10: 0 | MN10: 0 | MO10: 0 | MP10: 0 | MQ10: 0 | MR10: =SUMIF($N$7:$MQ$7,"*"&MR$7&"*",$N10:$MQ10) -> 0 | MS10: =SUMIF($N$7:$MQ$7,"*"&MS$7&"*",$N10:$MQ10) -> 1 | MT10: =SUMIF($N$7:$MQ$7,"*"&MT$7&"*",$N10:$MQ10) -> 0 | MU10: =SUMIF($N$7:$MQ$7,"*"&MU$7&"*",$N10:$MQ10) -> 0 | MV10: =SUMIF($N$7:$MQ$7,"*"&MV$7&"*",$N10:$MQ10) -> 0 | MW10: =SUMIF($N$7:$MQ$7,"*"&MW$7&"*",$N10:$MQ10) -> 0 | MX10: =SUMIF($N$7:$MQ$7,"*"&MX$7&"*",$N10:$MQ10) -> 0 | MY10: =SUMIF($N$7:$MQ$7,"*"&MY$7&"*",$N10:$MQ10) -> 0 | ... NG10: =SUMIF($N$7:$MQ$7,"*"&NG$7&"*",$N10:$MQ10) -> 0 | NH10: =SUMIF($MR$5:$NG$5,NH$7,$MR10:$NG10) -> 0 | NI10: =SUMIF($MR$5:$NG$5,NI$7,$MR10:$NG10) -> 1 | NJ10: =SUM(NH10:NI10) -> 1
A11: Region XI | B11: Mati City | C11: 129374 | D11: Badas ES | E11: DAVAO ORIENTAL | F11: CITY OF MATI (Capital) | G11: 2nd District | H11: BADAS | I11: School with no Annexes | J11: Public | K11: DepED Managed | L11: Kinder & Grade 1-6 | M11: Purely ES | N11: 0 | O11: 0 | P11: 0 | Q11: 0 | R11: 0 | S11: 0 | T11: 0 | U11: 0 | V11: 0 | W11: 0 | X11: 0 | Y11: 0 | Z11: 0 | AA11: 0 | AB11: 0 | AC11: 0 | AD11: 0 | AE11: 0 | AF11: 0 | AG11: 0 | AH11: 0 | AI11: 0 | AJ11: 0 | AK11: 0 | AL11: 0 | AM11: 0 | AN11: 0 | AO11: 0 | AP11: 0 | AQ11: 0 | AR11: 0 | AS11: 0 | AT11: 0 | AU11: 0 | AV11: 0 | AW11: 0 | AX11: 0 | AY11: 0 | AZ11: 3 | BA11: 1 | BB11: 0 | BC11: 0 | BD11: 0 | BE11: 0 | BF11: 0 | BG11: 0 | BH11: 0 | BI11: 0 | BJ11: 0 | BK11: 0 | BL11: 0 | BM11: 0 | BN11: 0 | BO11: 0 | BP11: 3 | BQ11: 1 | BR11: 4 | BS11: 0 | BT11: 0 | BU11: 0 | BV11: 0 | BW11: 0 | BX11: 0 | BY11: 0 | BZ11: 0 | CA11: 0 | CB11: 0 | CC11: 0 | CD11: 0 | CE11: 0 | CF11: 0 | CG11: 0 | CH11: 0 | CI11: 0 | CJ11: 0 | CK11: 0 | CL11: 0 | CM11: 0 | CN11: 0 | CO11: 0 | CP11: 0 | CQ11: 0 | CR11: 0 | CS11: 0 | CT11: 0 | CU11: 0 | CV11: 0 | CW11: 0 | CX11: 0 | CY11: 0 | CZ11: 0 | DA11: 0 | DB11: 0 | DC11: 0 | DD11: 0 | DE11: 0 | DF11: 0 | DG11: 0 | DH11: 0 | DI11: 0 | DJ11: 0 | DK11: 0 | DL11: 0 | DM11: 0 | DN11: 0 | DO11: 0 | DP11: 0 | DQ11: 0 | DR11: 0 | DS11: 0 | DT11: 0 | DU11: 0 | DV11: 0 | DW11: 0 | DX11: 0 | DY11: 0 | DZ11: 0 | EA11: 0 | EB11: 0 | EC11: 0 | ED11: 0 | EE11: 0 | EF11: 0 | EG11: 0 | EH11: 0 | EI11: 0 | EJ11: 0 | EK11: 0 | EL11: 0 | EM11: 0 | EN11: 0 | EO11: 0 | EP11: 0 | EQ11: 0 | ER11: 0 | ES11: 0 | ET11: 0 | EU11: 0 | EV11: 0 | EW11: 0 | EX11: 0 | EY11: 0 | EZ11: 0 | FA11: 0 | FB11: 0 | FC11: 0 | FD11: 0 | FE11: 0 | FF11: 0 | FG11: 0 | FH11: 0 | FI11: 0 | FJ11: 0 | FK11: 0 | FL11: 0 | FM11: 0 | FN11: 0 | FO11: 0 | FP11: 0 | FQ11: 0 | FR11: 0 | FS11: 0 | FT11: 0 | FU11: 0 | FV11: 0 | FW11: 0 | FX11: 0 | FY11: 0 | FZ11: 0 | GA11: 0 | GB11: 0 | GC11: 0 | GD11: 0 | GE11: 0 | GF11: 0 | GG11: 0 | GH11: 0 | GI11: 0 | GJ11: 0 | GK11: 0 | GL11: 0 | GM11: 0 | GN11: 0 | GO11: 0 | GP11: 0 | GQ11: 0 | GR11: 0 | GS11: 0 | GT11: 0 | GU11: 0 | GV11: 0 | GW11: 0 | GX11: 0 | GY11: 0 | GZ11: 0 | HA11: 0 | HB11: 0 | HC11: 0 | HD11: 0 | HE11: 0 | HF11: 0 | HG11: 0 | HH11: 0 | HI11: 0 | HJ11: 0 | HK11: 0 | HL11: 0 | HM11: 0 | HN11: 0 | HO11: 0 | HP11: 0 | HQ11: 0 | HR11: 0 | HS11: 0 | HT11: 0 | HU11: 0 | HV11: 0 | HW11: 0 | HX11: 0 | HY11: 0 | HZ11: 0 | IA11: 0 | IB11: 0 | IC11: 0 | ID11: 0 | IE11: 0 | IF11: 0 | IG11: 0 | IH11: 0 | II11: 0 | IJ11: 0 | IK11: 0 | IL11: 0 | IM11: 0 | IN11: 0 | IO11: 0 | IP11: 0 | IQ11: 0 | IR11: 0 | IS11: 0 | IT11: 0 | IU11: 0 | IV11: 0 | IW11: 0 | IX11: 0 | IY11: 0 | IZ11: 0 | JA11: 0 | JB11: 0 | JC11: 0 | JD11: 0 | JE11: 0 | JF11: 0 | JG11: 0 | JH11: 0 | JI11: 0 | JJ11: 0 | JK11: 0 | JL11: 0 | JM11: 0 | JN11: 0 | JO11: 0 | JP11: 0 | JQ11: 0 | JR11: 0 | JS11: 0 | JT11: 0 | JU11: 0 | JV11: 0 | JW11: 0 | JX11: 0 | JY11: 0 | JZ11: 0 | KA11: 0 | KB11: 0 | KC11: 0 | KD11: 0 | KE11: 0 | KF11: 0 | KG11: 0 | KH11: 0 | KI11: 0 | KJ11: 0 | KK11: 0 | KL11: 0 | KM11: 0 | KN11: 0 | KO11: 0 | KP11: 0 | KQ11: 0 | KR11: 0 | KS11: 0 | KT11: 0 | KU11: 0 | KV11: 0 | KW11: 0 | KX11: 0 | KY11: 0 | KZ11: 0 | LA11: 0 | LB11: 0 | LC11: 0 | LD11: 0 | LE11: 0 | LF11: 0 | LG11: 0 | LH11: 0 | LI11: 0 | LJ11: 0 | LK11: 0 | LL11: 0 | LM11: 0 | LN11: 0 | LO11: 0 | LP11: 0 | LQ11: 0 | LR11: 0 | LS11: 0 | LT11: 0 | LU11: 0 | LV11: 0 | LW11: 0 | LX11: 0 | LY11: 0 | LZ11: 0 | MA11: 0 | MB11: 0 | MC11: 0 | MD11: 0 | ME11: 0 | MF11: 0 | MG11: 0 | MH11: 0 | MI11: 0 | MJ11: 0 | MK11: 0 | ML11: 0 | MM11: 0 | MN11: 0 | MO11: 0 | MP11: 0 | MQ11: 0 | MR11: =SUMIF($N$7:$MQ$7,"*"&MR$7&"*",$N11:$MQ11) -> 3 | MS11: =SUMIF($N$7:$MQ$7,"*"&MS$7&"*",$N11:$MQ11) -> 1 | MT11: =SUMIF($N$7:$MQ$7,"*"&MT$7&"*",$N11:$MQ11) -> 0 | MU11: =SUMIF($N$7:$MQ$7,"*"&MU$7&"*",$N11:$MQ11) -> 0 | MV11: =SUMIF($N$7:$MQ$7,"*"&MV$7&"*",$N11:$MQ11) -> 0 | MW11: =SUMIF($N$7:$MQ$7,"*"&MW$7&"*",$N11:$MQ11) -> 0 | MX11: =SUMIF($N$7:$MQ$7,"*"&MX$7&"*",$N11:$MQ11) -> 0 | MY11: =SUMIF($N$7:$MQ$7,"*"&MY$7&"*",$N11:$MQ11) -> 0 | ... NG11: =SUMIF($N$7:$MQ$7,"*"&NG$7&"*",$N11:$MQ11) -> 0 | NH11: =SUMIF($MR$5:$NG$5,NH$7,$MR11:$NG11) -> 3 | NI11: =SUMIF($MR$5:$NG$5,NI$7,$MR11:$NG11) -> 1 | NJ11: =SUM(NH11:NI11) -> 4
A12: Region XI | B12: Mati City | C12: 129375 | D12: Baso ES | E12: DAVAO ORIENTAL | F12: CITY OF MATI (Capital) | G12: 2nd District | H12: BADAS | I12: School with no Annexes | J12: Public | K12: DepED Managed | L12: Kinder & Grade 1-6 | M12: Purely ES | N12: 0 | O12: 0 | P12: 0 | Q12: 0 | R12: 0 | S12: 0 | T12: 0 | U12: 0 | V12: 0 | W12: 0 | X12: 0 | Y12: 0 | Z12: 0 | AA12: 0 | AB12: 0 | AC12: 0 | AD12: 0 | AE12: 0 | AF12: 0 | AG12: 0 | AH12: 0 | AI12: 0 | AJ12: 0 | AK12: 0 | AL12: 0 | AM12: 0 | AN12: 0 | AO12: 0 | AP12: 0 | AQ12: 0 | AR12: 0 | AS12: 0 | AT12: 0 | AU12: 0 | AV12: 0 | AW12: 0 | AX12: 0 | AY12: 0 | AZ12: 0 | BA12: 0 | BB12: 0 | BC12: 0 | BD12: 0 | BE12: 0 | BF12: 0 | BG12: 0 | BH12: 0 | BI12: 0 | BJ12: 0 | BK12: 0 | BL12: 0 | BM12: 0 | BN12: 0 | BO12: 0 | BP12: 0 | BQ12: 0 | BR12: 0 | BS12: 0 | BT12: 0 | BU12: 0 | BV12: 0 | BW12: 0 | BX12: 0 | BY12: 0 | BZ12: 0 | CA12: 0 | CB12: 0 | CC12: 0 | CD12: 0 | CE12: 0 | CF12: 0 | CG12: 0 | CH12: 0 | CI12: 0 | CJ12: 0 | CK12: 0 | CL12: 0 | CM12: 0 | CN12: 0 | CO12: 0 | CP12: 0 | CQ12: 0 | CR12: 0 | CS12: 0 | CT12: 0 | CU12: 0 | CV12: 0 | CW12: 0 | CX12: 0 | CY12: 0 | CZ12: 0 | DA12: 0 | DB12: 0 | DC12: 0 | DD12: 0 | DE12: 0 | DF12: 0 | DG12: 0 | DH12: 0 | DI12: 0 | DJ12: 0 | DK12: 0 | DL12: 0 | DM12: 0 | DN12: 0 | DO12: 0 | DP12: 0 | DQ12: 0 | DR12: 0 | DS12: 0 | DT12: 0 | DU12: 0 | DV12: 0 | DW12: 0 | DX12: 0 | DY12: 0 | DZ12: 0 | EA12: 0 | EB12: 0 | EC12: 0 | ED12: 0 | EE12: 0 | EF12: 0 | EG12: 0 | EH12: 0 | EI12: 0 | EJ12: 0 | EK12: 0 | EL12: 0 | EM12: 0 | EN12: 0 | EO12: 0 | EP12: 0 | EQ12: 0 | ER12: 0 | ES12: 0 | ET12: 0 | EU12: 0 | EV12: 0 | EW12: 0 | EX12: 0 | EY12: 0 | EZ12: 0 | FA12: 0 | FB12: 0 | FC12: 0 | FD12: 0 | FE12: 0 | FF12: 0 | FG12: 0 | FH12: 0 | FI12: 0 | FJ12: 0 | FK12: 0 | FL12: 0 | FM12: 0 | FN12: 0 | FO12: 0 | FP12: 0 | FQ12: 0 | FR12: 0 | FS12: 0 | FT12: 0 | FU12: 0 | FV12: 0 | FW12: 0 | FX12: 0 | FY12: 0 | FZ12: 0 | GA12: 0 | GB12: 0 | GC12: 0 | GD12: 0 | GE12: 0 | GF12: 0 | GG12: 0 | GH12: 0 | GI12: 0 | GJ12: 0 | GK12: 0 | GL12: 0 | GM12: 0 | GN12: 0 | GO12: 0 | GP12: 0 | GQ12: 0 | GR12: 0 | GS12: 0 | GT12: 0 | GU12: 0 | GV12: 0 | GW12: 0 | GX12: 0 | GY12: 0 | GZ12: 0 | HA12: 0 | HB12: 0 | HC12: 0 | HD12: 0 | HE12: 0 | HF12: 0 | HG12: 0 | HH12: 0 | HI12: 0 | HJ12: 0 | HK12: 0 | HL12: 0 | HM12: 0 | HN12: 0 | HO12: 0 | HP12: 0 | HQ12: 0 | HR12: 0 | HS12: 0 | HT12: 0 | HU12: 0 | HV12: 0 | HW12: 0 | HX12: 0 | HY12: 0 | HZ12: 0 | IA12: 0 | IB12: 0 | IC12: 0 | ID12: 0 | IE12: 0 | IF12: 0 | IG12: 0 | IH12: 0 | II12: 0 | IJ12: 0 | IK12: 0 | IL12: 0 | IM12: 0 | IN12: 0 | IO12: 0 | IP12: 0 | IQ12: 0 | IR12: 0 | IS12: 0 | IT12: 0 | IU12: 0 | IV12: 0 | IW12: 0 | IX12: 0 | IY12: 0 | IZ12: 0 | JA12: 0 | JB12: 0 | JC12: 0 | JD12: 0 | JE12: 0 | JF12: 0 | JG12: 0 | JH12: 0 | JI12: 0 | JJ12: 0 | JK12: 0 | JL12: 0 | JM12: 0 | JN12: 0 | JO12: 0 | JP12: 0 | JQ12: 0 | JR12: 0 | JS12: 0 | JT12: 0 | JU12: 0 | JV12: 0 | JW12: 0 | JX12: 0 | JY12: 0 | JZ12: 0 | KA12: 0 | KB12: 0 | KC12: 0 | KD12: 0 | KE12: 0 | KF12: 0 | KG12: 0 | KH12: 0 | KI12: 0 | KJ12: 0 | KK12: 0 | KL12: 0 | KM12: 0 | KN12: 0 | KO12: 0 | KP12: 0 | KQ12: 0 | KR12: 0 | KS12: 0 | KT12: 0 | KU12: 0 | KV12: 0 | KW12: 0 | KX12: 0 | KY12: 0 | KZ12: 0 | LA12: 0 | LB12: 0 | LC12: 0 | LD12: 0 | LE12: 0 | LF12: 0 | LG12: 0 | LH12: 0 | LI12: 0 | LJ12: 0 | LK12: 0 | LL12: 0 | LM12: 0 | LN12: 0 | LO12: 0 | LP12: 0 | LQ12: 0 | LR12: 0 | LS12: 0 | LT12: 0 | LU12: 0 | LV12: 0 | LW12: 0 | LX12: 0 | LY12: 0 | LZ12: 0 | MA12: 0 | MB12: 0 | MC12: 0 | MD12: 0 | ME12: 0 | MF12: 0 | MG12: 0 | MH12: 0 | MI12: 0 | MJ12: 0 | MK12: 0 | ML12: 0 | MM12: 0 | MN12: 0 | MO12: 0 | MP12: 0 | MQ12: 0 | MR12: =SUMIF($N$7:$MQ$7,"*"&MR$7&"*",$N12:$MQ12) -> 0 | MS12: =SUMIF($N$7:$MQ$7,"*"&MS$7&"*",$N12:$MQ12) -> 0 | MT12: =SUMIF($N$7:$MQ$7,"*"&MT$7&"*",$N12:$MQ12) -> 0 | MU12: =SUMIF($N$7:$MQ$7,"*"&MU$7&"*",$N12:$MQ12) -> 0 | MV12: =SUMIF($N$7:$MQ$7,"*"&MV$7&"*",$N12:$MQ12) -> 0 | MW12: =SUMIF($N$7:$MQ$7,"*"&MW$7&"*",$N12:$MQ12) -> 0 | MX12: =SUMIF($N$7:$MQ$7,"*"&MX$7&"*",$N12:$MQ12) -> 0 | MY12: =SUMIF($N$7:$MQ$7,"*"&MY$7&"*",$N12:$MQ12) -> 0 | ... NG12: =SUMIF($N$7:$MQ$7,"*"&NG$7&"*",$N12:$MQ12) -> 0 | NH12: =SUMIF($MR$5:$NG$5,NH$7,$MR12:$NG12) -> 0 | NI12: =SUMIF($MR$5:$NG$5,NI$7,$MR12:$NG12) -> 0 | NJ12: =SUM(NH12:NI12) -> 0
A13: Region XI | B13: Mati City | C13: 129376 | D13: Belsonda ES | E13: DAVAO ORIENTAL | F13: CITY OF MATI (Capital) | G13: 2nd District | H13: CENTRAL (POB.) | I13: School with no Annexes | J13: Public | K13: DepED Managed | L13: Kinder & Grade 1-6 | M13: Purely ES | N13: 0 | O13: 0 | P13: 0 | Q13: 0 | R13: 0 | S13: 0 | T13: 0 | U13: 0 | V13: 0 | W13: 0 | X13: 0 | Y13: 0 | Z13: 0 | AA13: 0 | AB13: 0 | AC13: 0 | AD13: 0 | AE13: 0 | AF13: 0 | AG13: 0 | AH13: 0 | AI13: 0 | AJ13: 0 | AK13: 0 | AL13: 0 | AM13: 0 | AN13: 0 | AO13: 0 | AP13: 0 | AQ13: 0 | AR13: 0 | AS13: 0 | AT13: 0 | AU13: 0 | AV13: 0 | AW13: 0 | AX13: 0 | AY13: 0 | AZ13: 0 | BA13: 0 | BB13: 0 | BC13: 0 | BD13: 0 | BE13: 0 | BF13: 0 | BG13: 0 | BH13: 0 | BI13: 0 | BJ13: 0 | BK13: 0 | BL13: 0 | BM13: 0 | BN13: 0 | BO13: 0 | BP13: 0 | BQ13: 0 | BR13: 0 | BS13: 0 | BT13: 0 | BU13: 0 | BV13: 0 | BW13: 0 | BX13: 0 | BY13: 0 | BZ13: 0 | CA13: 0 | CB13: 0 | CC13: 0 | CD13: 0 | CE13: 0 | CF13: 0 | CG13: 0 | CH13: 0 | CI13: 0 | CJ13: 0 | CK13: 0 | CL13: 0 | CM13: 0 | CN13: 0 | CO13: 0 | CP13: 0 | CQ13: 0 | CR13: 0 | CS13: 0 | CT13: 0 | CU13: 0 | CV13: 0 | CW13: 0 | CX13: 0 | CY13: 0 | CZ13: 0 | DA13: 0 | DB13: 0 | DC13: 0 | DD13: 0 | DE13: 0 | DF13: 0 | DG13: 0 | DH13: 0 | DI13: 0 | DJ13: 0 | DK13: 0 | DL13: 0 | DM13: 0 | DN13: 0 | DO13: 0 | DP13: 0 | DQ13: 0 | DR13: 0 | DS13: 0 | DT13: 0 | DU13: 0 | DV13: 0 | DW13: 0 | DX13: 0 | DY13: 0 | DZ13: 0 | EA13: 0 | EB13: 0 | EC13: 0 | ED13: 0 | EE13: 0 | EF13: 0 | EG13: 0 | EH13: 0 | EI13: 0 | EJ13: 0 | EK13: 0 | EL13: 0 | EM13: 0 | EN13: 0 | EO13: 0 | EP13: 0 | EQ13: 0 | ER13: 0 | ES13: 0 | ET13: 0 | EU13: 0 | EV13: 0 | EW13: 0 | EX13: 0 | EY13: 0 | EZ13: 0 | FA13: 0 | FB13: 0 | FC13: 0 | FD13: 0 | FE13: 0 | FF13: 0 | FG13: 0 | FH13: 0 | FI13: 0 | FJ13: 0 | FK13: 0 | FL13: 0 | FM13: 0 | FN13: 0 | FO13: 0 | FP13: 0 | FQ13: 0 | FR13: 0 | FS13: 0 | FT13: 0 | FU13: 0 | FV13: 0 | FW13: 0 | FX13: 0 | FY13: 0 | FZ13: 0 | GA13: 0 | GB13: 0 | GC13: 0 | GD13: 0 | GE13: 0 | GF13: 0 | GG13: 0 | GH13: 0 | GI13: 0 | GJ13: 0 | GK13: 0 | GL13: 0 | GM13: 0 | GN13: 0 | GO13: 0 | GP13: 0 | GQ13: 0 | GR13: 0 | GS13: 0 | GT13: 0 | GU13: 0 | GV13: 0 | GW13: 0 | GX13: 0 | GY13: 0 | GZ13: 0 | HA13: 0 | HB13: 0 | HC13: 0 | HD13: 0 | HE13: 0 | HF13: 0 | HG13: 0 | HH13: 0 | HI13: 0 | HJ13: 0 | HK13: 0 | HL13: 0 | HM13: 0 | HN13: 0 | HO13: 0 | HP13: 0 | HQ13: 0 | HR13: 0 | HS13: 0 | HT13: 0 | HU13: 0 | HV13: 0 | HW13: 0 | HX13: 0 | HY13: 0 | HZ13: 0 | IA13: 0 | IB13: 0 | IC13: 0 | ID13: 0 | IE13: 0 | IF13: 0 | IG13: 0 | IH13: 0 | II13: 0 | IJ13: 0 | IK13: 0 | IL13: 0 | IM13: 0 | IN13: 0 | IO13: 0 | IP13: 0 | IQ13: 0 | IR13: 0 | IS13: 0 | IT13: 0 | IU13: 0 | IV13: 0 | IW13: 0 | IX13: 0 | IY13: 0 | IZ13: 0 | JA13: 0 | JB13: 0 | JC13: 0 | JD13: 0 | JE13: 0 | JF13: 0 | JG13: 0 | JH13: 0 | JI13: 0 | JJ13: 0 | JK13: 0 | JL13: 0 | JM13: 0 | JN13: 0 | JO13: 0 | JP13: 0 | JQ13: 0 | JR13: 0 | JS13: 0 | JT13: 0 | JU13: 0 | JV13: 0 | JW13: 0 | JX13: 0 | JY13: 0 | JZ13: 0 | KA13: 0 | KB13: 0 | KC13: 0 | KD13: 0 | KE13: 0 | KF13: 0 | KG13: 0 | KH13: 0 | KI13: 0 | KJ13: 0 | KK13: 0 | KL13: 0 | KM13: 0 | KN13: 0 | KO13: 0 | KP13: 0 | KQ13: 0 | KR13: 0 | KS13: 0 | KT13: 0 | KU13: 0 | KV13: 0 | KW13: 0 | KX13: 0 | KY13: 0 | KZ13: 0 | LA13: 0 | LB13: 0 | LC13: 0 | LD13: 0 | LE13: 0 | LF13: 0 | LG13: 0 | LH13: 0 | LI13: 0 | LJ13: 0 | LK13: 0 | LL13: 0 | LM13: 0 | LN13: 0 | LO13: 0 | LP13: 0 | LQ13: 0 | LR13: 0 | LS13: 0 | LT13: 0 | LU13: 0 | LV13: 0 | LW13: 0 | LX13: 0 | LY13: 0 | LZ13: 0 | MA13: 0 | MB13: 0 | MC13: 0 | MD13: 0 | ME13: 0 | MF13: 0 | MG13: 0 | MH13: 0 | MI13: 0 | MJ13: 0 | MK13: 0 | ML13: 0 | MM13: 0 | MN13: 0 | MO13: 0 | MP13: 0 | MQ13: 0 | MR13: =SUMIF($N$7:$MQ$7,"*"&MR$7&"*",$N13:$MQ13) -> 0 | MS13: =SUMIF($N$7:$MQ$7,"*"&MS$7&"*",$N13:$MQ13) -> 0 | MT13: =SUMIF($N$7:$MQ$7,"*"&MT$7&"*",$N13:$MQ13) -> 0 | MU13: =SUMIF($N$7:$MQ$7,"*"&MU$7&"*",$N13:$MQ13) -> 0 | MV13: =SUMIF($N$7:$MQ$7,"*"&MV$7&"*",$N13:$MQ13) -> 0 | MW13: =SUMIF($N$7:$MQ$7,"*"&MW$7&"*",$N13:$MQ13) -> 0 | MX13: =SUMIF($N$7:$MQ$7,"*"&MX$7&"*",$N13:$MQ13) -> 0 | MY13: =SUMIF($N$7:$MQ$7,"*"&MY$7&"*",$N13:$MQ13) -> 0 | ... NG13: =SUMIF($N$7:$MQ$7,"*"&NG$7&"*",$N13:$MQ13) -> 0 | NH13: =SUMIF($MR$5:$NG$5,NH$7,$MR13:$NG13) -> 0 | NI13: =SUMIF($MR$5:$NG$5,NI$7,$MR13:$NG13) -> 0 | NJ13: =SUM(NH13:NI13) -> 0
A14: Region XI | B14: Mati City | C14: 129377 | D14: Bagong Lipunan Improvement Site and Services Elementary School | E14: DAVAO ORIENTAL | F14: CITY OF MATI (Capital) | G14: 2nd District | H14: SAINZ | I14: School with no Annexes | J14: Public | K14: DepED Managed | L14: Kinder & Grade 1-6 | M14: Purely ES | N14: 0 | O14: 0 | P14: 0 | Q14: 0 | R14: 0 | S14: 0 | T14: 0 | U14: 0 | V14: 0 | W14: 0 | X14: 0 | Y14: 0 | Z14: 0 | AA14: 0 | AB14: 0 | AC14: 0 | AD14: 0 | AE14: 0 | AF14: 0 | AG14: 0 | AH14: 0 | AI14: 0 | AJ14: 0 | AK14: 0 | AL14: 0 | AM14: 0 | AN14: 0 | AO14: 0 | AP14: 0 | AQ14: 0 | AR14: 0 | AS14: 0 | AT14: 0 | AU14: 0 | AV14: 0 | AW14: 0 | AX14: 0 | AY14: 0 | AZ14: 0 | BA14: 1 | BB14: 1 | BC14: 0 | BD14: 0 | BE14: 0 | BF14: 0 | BG14: 0 | BH14: 0 | BI14: 0 | BJ14: 0 | BK14: 0 | BL14: 0 | BM14: 0 | BN14: 0 | BO14: 0 | BP14: 1 | BQ14: 1 | BR14: 2 | BS14: 0 | BT14: 1 | BU14: 0 | BV14: 0 | BW14: 0 | BX14: 0 | BY14: 0 | BZ14: 0 | CA14: 0 | CB14: 0 | CC14: 0 | CD14: 0 | CE14: 1 | CF14: 0 | CG14: 0 | CH14: 0 | CI14: 1 | CJ14: 1 | CK14: 2 | CL14: 0 | CM14: 0 | CN14: 0 | CO14: 0 | CP14: 0 | CQ14: 0 | CR14: 0 | CS14: 0 | CT14: 0 | CU14: 0 | CV14: 0 | CW14: 0 | CX14: 0 | CY14: 0 | CZ14: 0 | DA14: 0 | DB14: 0 | DC14: 0 | DD14: 0 | DE14: 0 | DF14: 0 | DG14: 0 | DH14: 0 | DI14: 0 | DJ14: 0 | DK14: 0 | DL14: 0 | DM14: 0 | DN14: 0 | DO14: 0 | DP14: 0 | DQ14: 0 | DR14: 0 | DS14: 0 | DT14: 0 | DU14: 0 | DV14: 0 | DW14: 0 | DX14: 0 | DY14: 0 | DZ14: 0 | EA14: 0 | EB14: 0 | EC14: 0 | ED14: 0 | EE14: 0 | EF14: 0 | EG14: 0 | EH14: 0 | EI14: 0 | EJ14: 0 | EK14: 0 | EL14: 0 | EM14: 0 | EN14: 0 | EO14: 0 | EP14: 0 | EQ14: 0 | ER14: 0 | ES14: 0 | ET14: 0 | EU14: 0 | EV14: 0 | EW14: 0 | EX14: 0 | EY14: 0 | EZ14: 0 | FA14: 0 | FB14: 0 | FC14: 0 | FD14: 0 | FE14: 0 | FF14: 0 | FG14: 0 | FH14: 0 | FI14: 0 | FJ14: 0 | FK14: 0 | FL14: 0 | FM14: 0 | FN14: 0 | FO14: 0 | FP14: 0 | FQ14: 0 | FR14: 0 | FS14: 0 | FT14: 0 | FU14: 0 | FV14: 1 | FW14: 0 | FX14: 0 | FY14: 0 | FZ14: 1 | GA14: 0 | GB14: 1 | GC14: 0 | GD14: 0 | GE14: 0 | GF14: 0 | GG14: 0 | GH14: 0 | GI14: 0 | GJ14: 0 | GK14: 0 | GL14: 0 | GM14: 0 | GN14: 0 | GO14: 2 | GP14: 1 | GQ14: 0 | GR14: 0 | GS14: 2 | GT14: 1 | GU14: 3 | GV14: 0 | GW14: 0 | GX14: 0 | GY14: 0 | GZ14: 0 | HA14: 0 | HB14: 0 | HC14: 0 | HD14: 0 | HE14: 0 | HF14: 0 | HG14: 0 | HH14: 0 | HI14: 0 | HJ14: 0 | HK14: 0 | HL14: 0 | HM14: 0 | HN14: 0 | HO14: 0 | HP14: 0 | HQ14: 0 | HR14: 0 | HS14: 0 | HT14: 0 | HU14: 0 | HV14: 0 | HW14: 0 | HX14: 0 | HY14: 0 | HZ14: 0 | IA14: 0 | IB14: 0 | IC14: 0 | ID14: 0 | IE14: 0 | IF14: 0 | IG14: 0 | IH14: 0 | II14: 0 | IJ14: 0 | IK14: 0 | IL14: 0 | IM14: 0 | IN14: 0 | IO14: 0 | IP14: 0 | IQ14: 0 | IR14: 0 | IS14: 0 | IT14: 0 | IU14: 0 | IV14: 0 | IW14: 0 | IX14: 0 | IY14: 0 | IZ14: 0 | JA14: 0 | JB14: 0 | JC14: 0 | JD14: 0 | JE14: 0 | JF14: 0 | JG14: 0 | JH14: 0 | JI14: 0 | JJ14: 0 | JK14: 0 | JL14: 0 | JM14: 0 | JN14: 0 | JO14: 0 | JP14: 0 | JQ14: 0 | JR14: 0 | JS14: 0 | JT14: 0 | JU14: 0 | JV14: 0 | JW14: 2 | JX14: 0 | JY14: 0 | JZ14: 0 | KA14: 0 | KB14: 0 | KC14: 0 | KD14: 0 | KE14: 0 | KF14: 0 | KG14: 0 | KH14: 0 | KI14: 0 | KJ14: 0 | KK14: 2 | KL14: 2 | KM14: 0 | KN14: 0 | KO14: 0 | KP14: 0 | KQ14: 0 | KR14: 0 | KS14: 0 | KT14: 0 | KU14: 0 | KV14: 0 | KW14: 0 | KX14: 0 | KY14: 0 | KZ14: 0 | LA14: 0 | LB14: 0 | LC14: 0 | LD14: 0 | LE14: 0 | LF14: 0 | LG14: 0 | LH14: 0 | LI14: 0 | LJ14: 0 | LK14: 0 | LL14: 0 | LM14: 0 | LN14: 0 | LO14: 0 | LP14: 0 | LQ14: 0 | LR14: 0 | LS14: 0 | LT14: 0 | LU14: 0 | LV14: 0 | LW14: 0 | LX14: 0 | LY14: 0 | LZ14: 0 | MA14: 0 | MB14: 0 | MC14: 0 | MD14: 0 | ME14: 0 | MF14: 0 | MG14: 0 | MH14: 0 | MI14: 2 | MJ14: 0 | MK14: 0 | ML14: 0 | MM14: 0 | MN14: 0 | MO14: 2 | MP14: 0 | MQ14: 2 | MR14: =SUMIF($N$7:$MQ$7,"*"&MR$7&"*",$N14:$MQ14) -> 0 | MS14: =SUMIF($N$7:$MQ$7,"*"&MS$7&"*",$N14:$MQ14) -> 2 | MT14: =SUMIF($N$7:$MQ$7,"*"&MT$7&"*",$N14:$MQ14) -> 1 | MU14: =SUMIF($N$7:$MQ$7,"*"&MU$7&"*",$N14:$MQ14) -> 2 | MV14: =SUMIF($N$7:$MQ$7,"*"&MV$7&"*",$N14:$MQ14) -> 0 | MW14: =SUMIF($N$7:$MQ$7,"*"&MW$7&"*",$N14:$MQ14) -> 0 | MX14: =SUMIF($N$7:$MQ$7,"*"&MX$7&"*",$N14:$MQ14) -> 0 | MY14: =SUMIF($N$7:$MQ$7,"*"&MY$7&"*",$N14:$MQ14) -> 0 | ... NG14: =SUMIF($N$7:$MQ$7,"*"&NG$7&"*",$N14:$MQ14) -> 0 | NH14: =SUMIF($MR$5:$NG$5,NH$7,$MR14:$NG14) -> 7 | NI14: =SUMIF($MR$5:$NG$5,NI$7,$MR14:$NG14) -> 5 | NJ14: =SUM(NH14:NI14) -> 12
A15: Region XI | B15: Mati City | C15: 129380 | D15: Rabat-Rocamora Mati CES I | E15: DAVAO ORIENTAL | F15: CITY OF MATI (Capital) | G15: 2nd District | H15: CENTRAL (POB.) | I15: School with no Annexes | J15: Public | K15: DepED Managed | L15: Kinder & Grade 1-6 | M15: Purely ES | N15: 0 | O15: 0 | P15: 0 | Q15: 0 | R15: 0 | S15: 0 | T15: 0 | U15: 0 | V15: 0 | W15: 0 | X15: 0 | Y15: 0 | Z15: 0 | AA15: 0 | AB15: 0 | AC15: 0 | AD15: 0 | AE15: 0 | AF15: 0 | AG15: 0 | AH15: 0 | AI15: 0 | AJ15: 0 | AK15: 0 | AL15: 0 | AM15: 0 | AN15: 0 | AO15: 0 | AP15: 0 | AQ15: 0 | AR15: 0 | AS15: 0 | AT15: 0 | AU15: 0 | AV15: 0 | AW15: 0 | AX15: 0 | AY15: 0 | AZ15: 0 | BA15: 0 | BB15: 0 | BC15: 0 | BD15: 0 | BE15: 0 | BF15: 1 | BG15: 1 | BH15: 0 | BI15: 0 | BJ15: 0 | BK15: 0 | BL15: 0 | BM15: 0 | BN15: 0 | BO15: 0 | BP15: 1 | BQ15: 1 | BR15: 2 | BS15: 0 | BT15: 1 | BU15: 1 | BV15: 2 | BW15: 0 | BX15: 0 | BY15: 3 | BZ15: 0 | CA15: 1 | CB15: 0 | CC15: 1 | CD15: 0 | CE15: 0 | CF15: 0 | CG15: 0 | CH15: 0 | CI15: 6 | CJ15: 3 | CK15: 9 | CL15: 0 | CM15: 0 | CN15: 0 | CO15: 0 | CP15: 1 | CQ15: 0 | CR15: 1 | CS15: 0 | CT15: 0 | CU15: 0 | CV15: 0 | CW15: 0 | CX15: 1 | CY15: 0 | CZ15: 0 | DA15: 0 | DB15: 3 | DC15: 0 | DD15: 3 | DE15: 0 | DF15: 0 | DG15: 0 | DH15: 0 | DI15: 0 | DJ15: 0 | DK15: 0 | DL15: 0 | DM15: 0 | DN15: 0 | DO15: 0 | DP15: 0 | DQ15: 0 | DR15: 0 | DS15: 0 | DT15: 0 | DU15: 0 | DV15: 0 | DW15: 0 | DX15: 0 | DY15: 0 | DZ15: 0 | EA15: 0 | EB15: 0 | EC15: 0 | ED15: 0 | EE15: 0 | EF15: 0 | EG15: 0 | EH15: 0 | EI15: 0 | EJ15: 0 | EK15: 0 | EL15: 0 | EM15: 0 | EN15: 0 | EO15: 0 | EP15: 0 | EQ15: 0 | ER15: 0 | ES15: 0 | ET15: 0 | EU15: 0 | EV15: 0 | EW15: 0 | EX15: 0 | EY15: 0 | EZ15: 0 | FA15: 0 | FB15: 0 | FC15: 0 | FD15: 0 | FE15: 0 | FF15: 0 | FG15: 0 | FH15: 0 | FI15: 0 | FJ15: 0 | FK15: 2 | FL15: 0 | FM15: 0 | FN15: 0 | FO15: 0 | FP15: 0 | FQ15: 0 | FR15: 0 | FS15: 0 | FT15: 0 | FU15: 0 | FV15: 0 | FW15: 0 | FX15: 0 | FY15: 0 | FZ15: 0 | GA15: 2 | GB15: 2 | GC15: 1 | GD15: 2 | GE15: 3 | GF15: 0 | GG15: 0 | GH15: 1 | GI15: 1 | GJ15: 1 | GK15: 0 | GL15: 0 | GM15: 0 | GN15: 0 | GO15: 2 | GP15: 0 | GQ15: 0 | GR15: 0 | GS15: 7 | GT15: 4 | GU15: 11 | GV15: 0 | GW15: 0 | GX15: 0 | GY15: 0 | GZ15: 0 | HA15: 0 | HB15: 0 | HC15: 0 | HD15: 0 | HE15: 0 | HF15: 0 | HG15: 0 | HH15: 0 | HI15: 0 | HJ15: 0 | HK15: 0 | HL15: 0 | HM15: 0 | HN15: 0 | HO15: 0 | HP15: 0 | HQ15: 0 | HR15: 0 | HS15: 0 | HT15: 0 | HU15: 0 | HV15: 0 | HW15: 0 | HX15: 0 | HY15: 0 | HZ15: 0 | IA15: 0 | IB15: 0 | IC15: 0 | ID15: 0 | IE15: 0 | IF15: 0 | IG15: 0 | IH15: 0 | II15: 0 | IJ15: 0 | IK15: 0 | IL15: 0 | IM15: 0 | IN15: 0 | IO15: 0 | IP15: 0 | IQ15: 0 | IR15: 0 | IS15: 0 | IT15: 0 | IU15: 0 | IV15: 0 | IW15: 0 | IX15: 0 | IY15: 0 | IZ15: 0 | JA15: 0 | JB15: 0 | JC15: 0 | JD15: 0 | JE15: 0 | JF15: 0 | JG15: 0 | JH15: 0 | JI15: 0 | JJ15: 0 | JK15: 0 | JL15: 0 | JM15: 0 | JN15: 0 | JO15: 0 | JP15: 0 | JQ15: 0 | JR15: 0 | JS15: 0 | JT15: 1 | JU15: 0 | JV15: 0 | JW15: 0 | JX15: 0 | JY15: 0 | JZ15: 0 | KA15: 1 | KB15: 0 | KC15: 0 | KD15: 0 | KE15: 0 | KF15: 0 | KG15: 1 | KH15: 0 | KI15: 0 | KJ15: 1 | KK15: 2 | KL15: 3 | KM15: 0 | KN15: 0 | KO15: 0 | KP15: 0 | KQ15: 0 | KR15: 0 | KS15: 0 | KT15: 0 | KU15: 0 | KV15: 0 | KW15: 0 | KX15: 0 | KY15: 0 | KZ15: 0 | LA15: 0 | LB15: 0 | LC15: 0 | LD15: 0 | LE15: 0 | LF15: 0 | LG15: 0 | LH15: 0 | LI15: 0 | LJ15: 0 | LK15: 0 | LL15: 0 | LM15: 0 | LN15: 0 | LO15: 0 | LP15: 0 | LQ15: 0 | LR15: 0 | LS15: 0 | LT15: 0 | LU15: 0 | LV15: 0 | LW15: 0 | LX15: 0 | LY15: 0 | LZ15: 0 | MA15: 0 | MB15: 0 | MC15: 0 | MD15: 0 | ME15: 0 | MF15: 0 | MG15: 0 | MH15: 0 | MI15: 0 | MJ15: 0 | MK15: 0 | ML15: 0 | MM15: 0 | MN15: 0 | MO15: 0 | MP15: 0 | MQ15: 0 | MR15: =SUMIF($N$7:$MQ$7,"*"&MR$7&"*",$N15:$MQ15) -> 2 | MS15: =SUMIF($N$7:$MQ$7,"*"&MS$7&"*",$N15:$MQ15) -> 5 | MT15: =SUMIF($N$7:$MQ$7,"*"&MT$7&"*",$N15:$MQ15) -> 4 | MU15: =SUMIF($N$7:$MQ$7,"*"&MU$7&"*",$N15:$MQ15) -> 2 | MV15: =SUMIF($N$7:$MQ$7,"*"&MV$7&"*",$N15:$MQ15) -> 1 | MW15: =SUMIF($N$7:$MQ$7,"*"&MW$7&"*",$N15:$MQ15) -> 1 | MX15: =SUMIF($N$7:$MQ$7,"*"&MX$7&"*",$N15:$MQ15) -> 6 | MY15: =SUMIF($N$7:$MQ$7,"*"&MY$7&"*",$N15:$MQ15) -> 3 | ... NG15: =SUMIF($N$7:$MQ$7,"*"&NG$7&"*",$N15:$MQ15) -> 0 | NH15: =SUMIF($MR$5:$NG$5,NH$7,$MR15:$NG15) -> 18 | NI15: =SUMIF($MR$5:$NG$5,NI$7,$MR15:$NG15) -> 12 | NJ15: =SUM(NH15:NI15) -> 30
A16: Region XI | B16: Mati City | C16: 129381 | D16: Rabat-Rocamora Mati CES II | E16: DAVAO ORIENTAL | F16: CITY OF MATI (Capital) | G16: 2nd District | H16: CENTRAL (POB.) | I16: School with no Annexes | J16: Public | K16: DepED Managed | L16: Kinder & Grade 1-6 | M16: Purely ES | N16: 0 | O16: 0 | P16: 0 | Q16: 0 | R16: 0 | S16: 0 | T16: 0 | U16: 0 | V16: 0 | W16: 0 | X16: 0 | Y16: 0 | Z16: 0 | AA16: 0 | AB16: 0 | AC16: 0 | AD16: 0 | AE16: 0 | AF16: 0 | AG16: 0 | AH16: 0 | AI16: 0 | AJ16: 0 | AK16: 0 | AL16: 0 | AM16: 0 | AN16: 0 | AO16: 0 | AP16: 0 | AQ16: 0 | AR16: 0 | AS16: 0 | AT16: 0 | AU16: 0 | AV16: 0 | AW16: 0 | AX16: 0 | AY16: 0 | AZ16: 0 | BA16: 0 | BB16: 0 | BC16: 0 | BD16: 0 | BE16: 0 | BF16: 0 | BG16: 0 | BH16: 0 | BI16: 0 | BJ16: 0 | BK16: 0 | BL16: 0 | BM16: 0 | BN16: 0 | BO16: 0 | BP16: 0 | BQ16: 0 | BR16: 0 | BS16: 0 | BT16: 0 | BU16: 0 | BV16: 0 | BW16: 0 | BX16: 0 | BY16: 0 | BZ16: 0 | CA16: 0 | CB16: 0 | CC16: 0 | CD16: 0 | CE16: 0 | CF16: 0 | CG16: 0 | CH16: 0 | CI16: 0 | CJ16: 0 | CK16: 0 | CL16: 0 | CM16: 0 | CN16: 0 | CO16: 0 | CP16: 0 | CQ16: 0 | CR16: 0 | CS16: 0 | CT16: 0 | CU16: 0 | CV16: 0 | CW16: 0 | CX16: 0 | CY16: 0 | CZ16: 0 | DA16: 0 | DB16: 0 | DC16: 0 | DD16: 0 | DE16: 0 | DF16: 0 | DG16: 0 | DH16: 0 | DI16: 0 | DJ16: 0 | DK16: 0 | DL16: 0 | DM16: 0 | DN16: 0 | DO16: 0 | DP16: 0 | DQ16: 0 | DR16: 0 | DS16: 0 | DT16: 0 | DU16: 0 | DV16: 0 | DW16: 0 | DX16: 0 | DY16: 0 | DZ16: 1 | EA16: 0 | EB16: 0 | EC16: 0 | ED16: 0 | EE16: 0 | EF16: 0 | EG16: 0 | EH16: 0 | EI16: 0 | EJ16: 0 | EK16: 0 | EL16: 0 | EM16: 0 | EN16: 1 | EO16: 0 | EP16: 1 | EQ16: 0 | ER16: 0 | ES16: 0 | ET16: 0 | EU16: 0 | EV16: 0 | EW16: 0 | EX16: 0 | EY16: 0 | EZ16: 0 | FA16: 0 | FB16: 0 | FC16: 0 | FD16: 0 | FE16: 0 | FF16: 0 | FG16: 0 | FH16: 0 | FI16: 0 | FJ16: 0 | FK16: 0 | FL16: 0 | FM16: 0 | FN16: 0 | FO16: 0 | FP16: 0 | FQ16: 0 | FR16: 0 | FS16: 0 | FT16: 0 | FU16: 0 | FV16: 0 | FW16: 0 | FX16: 0 | FY16: 0 | FZ16: 0 | GA16: 0 | GB16: 0 | GC16: 0 | GD16: 0 | GE16: 0 | GF16: 0 | GG16: 0 | GH16: 0 | GI16: 0 | GJ16: 0 | GK16: 0 | GL16: 0 | GM16: 0 | GN16: 0 | GO16: 0 | GP16: 0 | GQ16: 0 | GR16: 0 | GS16: 0 | GT16: 0 | GU16: 0 | GV16: 0 | GW16: 0 | GX16: 0 | GY16: 0 | GZ16: 0 | HA16: 0 | HB16: 0 | HC16: 0 | HD16: 0 | HE16: 0 | HF16: 0 | HG16: 0 | HH16: 0 | HI16: 0 | HJ16: 0 | HK16: 0 | HL16: 0 | HM16: 0 | HN16: 0 | HO16: 0 | HP16: 0 | HQ16: 0 | HR16: 0 | HS16: 0 | HT16: 0 | HU16: 0 | HV16: 0 | HW16: 0 | HX16: 0 | HY16: 0 | HZ16: 0 | IA16: 0 | IB16: 0 | IC16: 0 | ID16: 0 | IE16: 0 | IF16: 0 | IG16: 0 | IH16: 0 | II16: 0 | IJ16: 0 | IK16: 0 | IL16: 0 | IM16: 0 | IN16: 0 | IO16: 0 | IP16: 0 | IQ16: 0 | IR16: 0 | IS16: 0 | IT16: 0 | IU16: 0 | IV16: 0 | IW16: 0 | IX16: 0 | IY16: 0 | IZ16: 0 | JA16: 0 | JB16: 0 | JC16: 0 | JD16: 0 | JE16: 0 | JF16: 0 | JG16: 0 | JH16: 0 | JI16: 0 | JJ16: 0 | JK16: 0 | JL16: 0 | JM16: 0 | JN16: 0 | JO16: 0 | JP16: 0 | JQ16: 0 | JR16: 0 | JS16: 0 | JT16: 0 | JU16: 0 | JV16: 0 | JW16: 0 | JX16: 0 | JY16: 0 | JZ16: 0 | KA16: 0 | KB16: 0 | KC16: 0 | KD16: 0 | KE16: 0 | KF16: 0 | KG16: 0 | KH16: 0 | KI16: 0 | KJ16: 0 | KK16: 0 | KL16: 0 | KM16: 0 | KN16: 0 | KO16: 0 | KP16: 0 | KQ16: 0 | KR16: 0 | KS16: 0 | KT16: 0 | KU16: 0 | KV16: 0 | KW16: 0 | KX16: 0 | KY16: 0 | KZ16: 0 | LA16: 0 | LB16: 0 | LC16: 0 | LD16: 0 | LE16: 0 | LF16: 0 | LG16: 0 | LH16: 0 | LI16: 0 | LJ16: 0 | LK16: 0 | LL16: 0 | LM16: 0 | LN16: 0 | LO16: 0 | LP16: 0 | LQ16: 0 | LR16: 0 | LS16: 0 | LT16: 0 | LU16: 0 | LV16: 0 | LW16: 0 | LX16: 0 | LY16: 0 | LZ16: 0 | MA16: 0 | MB16: 0 | MC16: 0 | MD16: 0 | ME16: 0 | MF16: 0 | MG16: 0 | MH16: 0 | MI16: 0 | MJ16: 0 | MK16: 0 | ML16: 0 | MM16: 0 | MN16: 0 | MO16: 0 | MP16: 0 | MQ16: 0 | MR16: =SUMIF($N$7:$MQ$7,"*"&MR$7&"*",$N16:$MQ16) -> 0 | MS16: =SUMIF($N$7:$MQ$7,"*"&MS$7&"*",$N16:$MQ16) -> 0 | MT16: =SUMIF($N$7:$MQ$7,"*"&MT$7&"*",$N16:$MQ16) -> 1 | MU16: =SUMIF($N$7:$MQ$7,"*"&MU$7&"*",$N16:$MQ16) -> 0 | MV16: =SUMIF($N$7:$MQ$7,"*"&MV$7&"*",$N16:$MQ16) -> 0 | MW16: =SUMIF($N$7:$MQ$7,"*"&MW$7&"*",$N16:$MQ16) -> 0 | MX16: =SUMIF($N$7:$MQ$7,"*"&MX$7&"*",$N16:$MQ16) -> 0 | MY16: =SUMIF($N$7:$MQ$7,"*"&MY$7&"*",$N16:$MQ16) -> 0 | ... NG16: =SUMIF($N$7:$MQ$7,"*"&NG$7&"*",$N16:$MQ16) -> 0 | NH16: =SUMIF($MR$5:$NG$5,NH$7,$MR16:$NG16) -> 1 | NI16: =SUMIF($MR$5:$NG$5,NI$7,$MR16:$NG16) -> 0 | NJ16: =SUM(NH16:NI16) -> 1
