Workbook
Name TableRegionDivision: List!$E$2:$E$229

Sheet List
A1: SEX | C1: RF13 Codes | E1: Region-Divison | F1: Flitered List
A2: Male | C2: 1. Joint Transfer | E2: Region I-Alaminos City | F2: {=TRANSPOSE(_xlfn._xlws.FILTER(TableRegionDivision,ISNUMBER(SEARCH('RF08 (TRANSFER-RELATED ISSUES)'!$B13,TableRegionDivision)),"Not found"))} -> Region I-Alaminos City | G2: Region I-Batac City | H2: Region I-Candon City | I2: Region I-Dagupan City | J2: Region I-Ilocos Norte | K2: Region I-Ilocos Sur | L2: Region I-La Union | M2: Region I-Laoag City | N2: Region I-Pangasinan I, Lingayen | O2: Region I-Pangasinan II, Binalonan | P2: Region I-San Carlos City | Q2: Region I-San Fernando City | R2: Region I-Urdaneta City | S2: Region I-Vigan City | T2: Region II-Batanes | U2: Region II-Cagayan | V2: Region II-Cauayan City | W2: Region II-City of Ilagan | X2: Region II-Isabela | Y2: Region II-Nueva Vizcaya | Z2: Region II-Quirino | AA2: Region II-Santiago City | AB2: Region II-Tuguegarao City | AC2: Region III-Angeles City | AD2: Region III-Aurora | AE2: Region III-Balanga City | AF2: Region III-Bataan | AG2: Region III-Bulacan | AH2: Region III-Cabanatuan City | AI2: Region III-Gapan City | AJ2: Region III-Mabalacat City | AK2: Region III-Malolos City | AL2: Region III-Meycauayan City | AM2: Region III-Munoz Science City | AN2: Region III-Nueva Ecija | AO2: Region III-Olongapo City | AP2: Region III-Pampanga | AQ2: Region III-San Fernando City | AR2: Region III-San Jose City | AS2: Region III-San Jose del Monte City | AT2: Region III-Tarlac | AU2: Region III-Tarlac City | AV2: Region III-Zambales | AW2: Region IV-A-Antipolo City | AX2: Region IV-A-Bacoor City | AY2: Region IV-A-Batangas | AZ2: Region IV-A-Batangas City | BA2: Region IV-A-Binan City | BB2: Region IV-A-Cabuyao | BC2: Region IV-A-Calamba City | BD2: Region IV-A-Cavite | BE2: Region IV-A-Cavite City | BF2: Region IV-A-Dasmarinas City | BG2: Region IV-A-Imus City | BH2: Region IV-A-Laguna | BI2: Region IV-A-Lipa City | BJ2: Region IV-A-Lucena City | BK2: Region IV-A-Quezon | BL2: Region IV-A-Rizal | BM2: Region IV-A-San Pablo City | BN2: Region IV-A-San Pedro City | BO2: Region IV-A-Sta. Rosa City | BP2: Region IV-A-Sto. Tomas City | BQ2: Region IV-A-Tanauan City | BR2: Region IV-A-Tayabas City | BS2: Region IV-A-General Trias | BT2: Region V-Albay | BU2: Region V-Camarines Norte | BV2: Region V-Camarines Sur | BW2: Region V-Catanduanes | BX2: Region V-Iriga City | BY2: Region V-Legaspi City | BZ2: Region V-Ligao City | CA2: Region V-Masbate | CB2: Region V-Masbate City | CC2: Region V-Naga City | CD2: Region V-Sorsogon | CE2: Region V-Sorsogon City | CF2: Region V-Tabaco City | CG2: Region VI-Aklan | CH2: Region VI-Antique | CI2: Region VI-Capiz | CJ2: Region VI-Guimaras | CK2: Region VI-Iloilo | CL2: Region VI-Iloilo City | CM2: Region VI-Passi City | CN2: Region VI-Roxas City | CO2: Region VII-Bogo City | CP2: Region VII-Bohol | CQ2: Region VII-Carcar City | CR2: Region VII-Cebu | CS2: Region VII-Cebu City | CT2: Region VII-City of Naga Cebu | CU2: Region VII-Danao City | CV2: Region VII-Lapu-Lapu City | CW2: Region VII-Mandaue City | CX2: Region VII-Tagbilaran City | CY2: Region VII-Talisay City | CZ2: Region VII-Toledo City | DA2: Region VIII-Baybay City | DB2: Region VIII-Biliran | DC2: Region VIII-Borongan City | DD2: Region VIII-Calbayog City | DE2: Region VIII-Catbalogan City | DF2: Region VIII-Eastern Samar | DG2: Region VIII-Leyte | DH2: Region VIII-Maasin City | DI2: Region VIII-Northern Samar | DJ2: Region VIII-Ormoc City | DK2: Region VIII-Samar (Western Samar) | DL2: Region VIII-Southern Leyte | DM2: Region VIII-Tacloban City | DN2: NIR-Bacolod City | DO2: NIR-Bago City | DP2: NIR-Bais City | DQ2: NIR-Bayawan City | DR2: NIR-Cadiz City | DS2: NIR-Canlaon City | DT2: NIR-Dumaguete City | DU2: NIR-Escalante City | DV2: NIR-Guihulngan City | DW2: NIR-Himamaylan City | DX2: NIR-Kabankalan City | DY2: NIR-La Carlota City | DZ2: NIR-Negros Occidental | EA2: NIR-Negros Oriental | EB2: NIR-Sagay City | EC2: NIR-San Carlos City | ED2: NIR-Silay City | EE2: NIR-Sipalay City | EF2: NIR-Siquijor | EG2: NIR-Tanjay City | EH2: NIR-Victorias City | EI2: Region IX-Dapitan City | EJ2: Region IX-Dipolog City | EK2: Region IX-Isabela City | EL2: Region IX-Pagadian City | EM2: Region IX-Zamboanga City | EN2: Region IX-Zamboanga del Norte | EO2: Region IX-Zamboanga del Sur | EP2: Region IX-Zamboanga Sibugay | EQ2: Region X-Bukidnon | ER2: Region X-Cagayan de Oro City | ES2: Region X-Camiguin | ET2: Region X-El Salvador | EU2: Region X-Gingoog City | EV2: Region X-Iligan City | EW2: Region X-Lanao del Norte | EX2: Region X-Malaybalay City | EY2: Region X-Misamis Occidental | EZ2: Region X-Misamis Oriental | FA2: Region X-Oroquieta City | FB2: Region X-Ozamis City | FC2: Region X-Tangub City | FD2: Region X-Valencia City | FE2: Region XI-Davao de Oro | FF2: Region XI-Davao City | FG2: Region XI-Davao del Norte | FH2: Region XI-Davao del Sur | FI2: Region XI-Davao Oriental | FJ2: Region XI-Digos City | FK2: Region XI-Island Garden City of Samal | FL2: Region XI-Mati City | FM2: Region XI-Panabo City | FN2: Region XI-Tagum City | FO2: Region XI-Davao Occidental | FP2: Region XII-General Santos City | FQ2: Region XII-Kidapawan City | FR2: Region XII-Koronadal City | FS2: Region XII-North Cotabato | FT2: Region XII-Sarangani | FU2: Region XII-South Cotabato | FV2: Region XII-Sultan Kudarat | FW2: Region XII-Tacurong City | FX2: NCR-Caloocan City | FY2: NCR-City of San Juan | FZ2: NCR-Las Pinas City | GA2: NCR-Makati City | GB2: NCR-Malabon City | GC2: NCR-Mandaluyong City | GD2: NCR-Manila | GE2: NCR-Marikina City | GF2: NCR-Muntinlupa City | GG2: NCR-Navotas | GH2: NCR-Paranaque City | GI2: NCR-Pasay City | GJ2: NCR-Pasig City | GK2: NCR-Quezon City | GL2: NCR-Taguig | GM2: NCR-Valenzuela City | GN2: CAR-Abra | GO2: CAR-Apayao | GP2: CAR-Baguio City | GQ2: CAR-Benguet | GR2: CAR-Ifugao | GS2: CAR-Kalinga | GT2: CAR-Mt. Province | GU2: CAR-Tabuk City | GV2: BARMM-Basilan | GW2: BARMM-Cotabato City | GX2: BARMM-Lamitan City | GY2: BARMM-Lanao del Sur - I | GZ2: BARMM-Lanao del Sur - II | HA2: BARMM-Maguindanao I | HB2: BARMM-Maguindanao II | HC2: BARMM-Marawi City | HD2: BARMM-Sulu | HE2: BARMM-Tawi-Tawi | HF2: BARMM-Special Geographic Division | HG2: CARAGA-Agusan del Norte | HH2: CARAGA-Agusan del Sur | HI2: CARAGA-Bayugan City | HJ2: CARAGA-Bislig City | HK2: CARAGA-Butuan City | HL2: CARAGA-Cabadbaran City | HM2: CARAGA-Dinagat Island | HN2: CARAGA-Siargao | HO2: CARAGA-Surigao City | HP2: CARAGA-Surigao del Norte | HQ2: CARAGA-Surigao del Sur | HR2: CARAGA-Tandag City | HS2: MIMAROPA-Calapan City | HT2: MIMAROPA-Marinduque | HU2: MIMAROPA-Occidental Mindoro | HV2: MIMAROPA-Oriental Mindoro | HW2: MIMAROPA-Palawan | HX2: MIMAROPA-Puerto Princesa City | HY2: MIMAROPA-Romblon | HZ2: {=TRANSPOSE(_xlfn._xlws.FILTER(TableRegionDivision,ISNUMBER(SEARCH('RF08 (TRANSFER-RELATED ISSUES)'!$O13,TableRegionDivision)),"Not found"))} -> Region I-Alaminos City | IA2: Region I-Batac City | IB2: Region I-Candon City | IC2: Region I-Dagupan City | ID2: Region I-Ilocos Norte | IE2: Region I-Ilocos Sur | IF2: Region I-La Union | IG2: Region I-Laoag City | IH2: Region I-Pangasinan I, Lingayen | II2: Region I-Pangasinan II, Binalonan | IJ2: Region I-San Carlos City | IK2: Region I-San Fernando City | IL2: Region I-Urdaneta City | IM2: Region I-Vigan City | IN2: Region II-Batanes | IO2: Region II-Cagayan | IP2: Region II-Cauayan City | IQ2: Region II-City of Ilagan | IR2: Region II-Isabela | IS2: Region II-Nueva Vizcaya | IT2: Region II-Quirino | IU2: Region II-Santiago City | IV2: Region II-Tuguegarao City | IW2: Region III-Angeles City | IX2: Region III-Aurora | IY2: Region III-Balanga City | IZ2: Region III-Bataan | JA2: Region III-Bulacan | JB2: Region III-Cabanatuan City | JC2: Region III-Gapan City | JD2: Region III-Mabalacat City | JE2: Region III-Malolos City | JF2: Region III-Meycauayan City | JG2: Region III-Munoz Science City | JH2: Region III-Nueva Ecija | JI2: Region III-Olongapo City | JJ2: Region III-Pampanga | JK2: Region III-San Fernando City | JL2: Region III-San Jose City | JM2: Region III-San Jose del Monte City | JN2: Region III-Tarlac | JO2: Region III-Tarlac City | JP2: Region III-Zambales | JQ2: Region IV-A-Antipolo City | JR2: Region IV-A-Bacoor City | JS2: Region IV-A-Batangas | JT2: Region IV-A-Batangas City | JU2: Region IV-A-Binan City | JV2: Region IV-A-Cabuyao | JW2: Region IV-A-Calamba City | JX2: Region IV-A-Cavite | JY2: Region IV-A-Cavite City | JZ2: Region IV-A-Dasmarinas City | KA2: Region IV-A-Imus City | KB2: Region IV-A-Laguna | KC2: Region IV-A-Lipa City | KD2: Region IV-A-Lucena City | KE2: Region IV-A-Quezon | KF2: Region IV-A-Rizal | KG2: Region IV-A-San Pablo City | KH2: Region IV-A-San Pedro City | KI2: Region IV-A-Sta. Rosa City | KJ2: Region IV-A-Sto. Tomas City | KK2: Region IV-A-Tanauan City | KL2: Region IV-A-Tayabas City | KM2: Region IV-A-General Trias | KN2: Region V-Albay | KO2: Region V-Camarines Norte | KP2: Region V-Camarines Sur | KQ2: Region V-Catanduanes | KR2: Region V-Iriga City | KS2: Region V-Legaspi City | KT2: Region V-Ligao City | KU2: Region V-Masbate | KV2: Region V-Masbate City | KW2: Region V-Naga City | KX2: Region V-Sorsogon | KY2: Region V-Sorsogon City | KZ2: Region V-Tabaco City | LA2: Region VI-Aklan | LB2: Region VI-Antique | LC2: Region VI-Capiz | LD2: Region VI-Guimaras | LE2: Region VI-Iloilo | LF2: Region VI-Iloilo City | LG2: Region VI-Passi City | LH2: Region VI-Roxas City | LI2: Region VII-Bogo City | LJ2: Region VII-Bohol | LK2: Region VII-Carcar City | LL2: Region VII-Cebu | LM2: Region VII-Cebu City | LN2: Region VII-City of Naga Cebu | LO2: Region VII-Danao City | LP2: Region VII-Lapu-Lapu City | LQ2: Region VII-Mandaue City | LR2: Region VII-Tagbilaran City | LS2: Region VII-Talisay City | LT2: Region VII-Toledo City | LU2: Region VIII-Baybay City | LV2: Region VIII-Biliran | LW2: Region VIII-Borongan City | LX2: Region VIII-Calbayog City | LY2: Region VIII-Catbalogan City | LZ2: Region VIII-Eastern Samar | MA2: Region VIII-Leyte | MB2: Region VIII-Maasin City | MC2: Region VIII-Northern Samar | MD2: Region VIII-Ormoc City | ME2: Region VIII-Samar (Western Samar) | MF2: Region VIII-Southern Leyte | MG2: Region VIII-Tacloban City | MH2: NIR-Bacolod City | MI2: NIR-Bago City | MJ2: NIR-Bais City | MK2: NIR-Bayawan City | ML2: NIR-Cadiz City | MM2: NIR-Canlaon City | MN2: NIR-Dumaguete City | MO2: NIR-Escalante City | MP2: NIR-Guihulngan City | MQ2: NIR-Himamaylan City | MR2: NIR-Kabankalan City | MS2: NIR-La Carlota City | MT2: NIR-Negros Occidental | MU2: NIR-Negros Oriental | MV2: NIR-Sagay City | MW2: NIR-San Carlos City | MX2: NIR-Silay City | MY2: NIR-Sipalay City | MZ2: NIR-Siquijor | NA2: NIR-Tanjay City | NB2: NIR-Victorias City | NC2: Region IX-Dapitan City | ND2: Region IX-Dipolog City | NE2: Region IX-Isabela City | NF2: Region IX-Pagadian City | NG2: Region IX-Zamboanga City | NH2: Region IX-Zamboanga del Norte | NI2: Region IX-Zamboanga del Sur | NJ2: Region IX-Zamboanga Sibugay | NK2: Region X-Bukidnon | NL2: Region X-Cagayan de Oro City | NM2: Region X-Camiguin | NN2: Region X-El Salvador | NO2: Region X-Gingoog City | NP2: Region X-Iligan City | NQ2: Region X-Lanao del Norte | NR2: Region X-Malaybalay City | NS2: Region X-Misamis Occidental | NT2: Region X-Misamis Oriental | NU2: Region X-Oroquieta City | NV2: Region X-Ozamis City | NW2: Region X-Tangub City | NX2: Region X-Valencia City | NY2: Region XI-Davao de Oro | NZ2: Region XI-Davao City | OA2: Region XI-Davao del Norte | OB2: Region XI-Davao del Sur | OC2: Region XI-Davao Oriental | OD2: Region XI-Digos City | OE2: Region XI-Island Garden City of Samal | OF2: Region XI-Mati City | OG2: Region XI-Panabo City | OH2: Region XI-Tagum City | OI2: Region XI-Davao Occidental | OJ2: Region XII-General Santos City | OK2: Region XII-Kidapawan City | OL2: Region XII-Koronadal City | OM2: Region XII-North Cotabato | ON2: Region XII-Sarangani | OO2: Region XII-South Cotabato | OP2: Region XII-Sultan Kudarat | OQ2: Region XII-Tacurong City | OR2: NCR-Caloocan City | OS2: NCR-City of San Juan | OT2: NCR-Las Pinas City | OU2: NCR-Makati City | OV2: NCR-Malabon City | OW2: NCR-Mandaluyong City | OX2: NCR-Manila | OY2: NCR-Marikina City | OZ2: NCR-Muntinlupa City | PA2: NCR-Navotas | PB2: NCR-Paranaque City | PC2: NCR-Pasay City | PD2: NCR-Pasig City | PE2: NCR-Quezon City | PF2: NCR-Taguig | PG2: NCR-Valenzuela City | PH2: CAR-Abra | PI2: CAR-Apayao | PJ2: CAR-Baguio City | PK2: CAR-Benguet | PL2: CAR-Ifugao | PM2: CAR-Kalinga | PN2: CAR-Mt. Province | PO2: CAR-Tabuk City | PP2: BARMM-Basilan | PQ2: BARMM-Cotabato City | PR2: BARMM-Lamitan City | PS2: BARMM-Lanao del Sur - I | PT2: BARMM-Lanao del Sur - II | PU2: BARMM-Maguindanao I | PV2: BARMM-Maguindanao II | PW2: BARMM-Marawi City | PX2: BARMM-Sulu | PY2: BARMM-Tawi-Tawi | PZ2: BARMM-Special Geographic Division | QA2: CARAGA-Agusan del Norte | QB2: CARAGA-Agusan del Sur | QC2: CARAGA-Bayugan City | QD2: CARAGA-Bislig City | QE2: CARAGA-Butuan City | QF2: CARAGA-Cabadbaran City | QG2: CARAGA-Dinagat Island | QH2: CARAGA-Siargao | QI2: CARAGA-Surigao City | QJ2: CARAGA-Surigao del Norte | QK2: CARAGA-Surigao del Sur | QL2: CARAGA-Tandag City | QM2: MIMAROPA-Calapan City | QN2: MIMAROPA-Marinduque | QO2: MIMAROPA-Occidental Mindoro | QP2: MIMAROPA-Oriental Mindoro | QQ2: MIMAROPA-Palawan | QR2: MIMAROPA-Puerto Princesa City | QS2: MIMAROPA-Romblon
A3: Female | C3: 2. Transfer Dispute | E3: Region I-Batac City | F3: {=TRANSPOSE(_xlfn._xlws.FILTER(TableRegionDivision,ISNUMBER(SEARCH('RF08 (TRANSFER-RELATED ISSUES)'!$B14,TableRegionDivision)),"Not found"))} -> Region I-Alaminos City | G3: Region I-Batac City | H3: Region I-Candon City | I3: Region I-Dagupan City | J3: Region I-Ilocos Norte | K3: Region I-Ilocos Sur | L3: Region I-La Union | M3: Region I-Laoag City | N3: Region I-Pangasinan I, Lingayen | O3: Region I-Pangasinan II, Binalonan | P3: Region I-San Carlos City | Q3: Region I-San Fernando City | R3: Region I-Urdaneta City | S3: Region I-Vigan City | T3: Region II-Batanes | U3: Region II-Cagayan | V3: Region II-Cauayan City | W3: Region II-City of Ilagan | X3: Region II-Isabela | Y3: Region II-Nueva Vizcaya | Z3: Region II-Quirino | AA3: Region II-Santiago City | AB3: Region II-Tuguegarao City | AC3: Region III-Angeles City | AD3: Region III-Aurora | AE3: Region III-Balanga City | AF3: Region III-Bataan | AG3: Region III-Bulacan | AH3: Region III-Cabanatuan City | AI3: Region III-Gapan City | AJ3: Region III-Mabalacat City | AK3: Region III-Malolos City | AL3: Region III-Meycauayan City | AM3: Region III-Munoz Science City | AN3: Region III-Nueva Ecija | AO3: Region III-Olongapo City | AP3: Region III-Pampanga | AQ3: Region III-San Fernando City | AR3: Region III-San Jose City | AS3: Region III-San Jose del Monte City | AT3: Region III-Tarlac | AU3: Region III-Tarlac City | AV3: Region III-Zambales | AW3: Region IV-A-Antipolo City | AX3: Region IV-A-Bacoor City | AY3: Region IV-A-Batangas | AZ3: Region IV-A-Batangas City | BA3: Region IV-A-Binan City | BB3: Region IV-A-Cabuyao | BC3: Region IV-A-Calamba City | BD3: Region IV-A-Cavite | BE3: Region IV-A-Cavite City | BF3: Region IV-A-Dasmarinas City | BG3: Region IV-A-Imus City | BH3: Region IV-A-Laguna | BI3: Region IV-A-Lipa City | BJ3: Region IV-A-Lucena City | BK3: Region IV-A-Quezon | BL3: Region IV-A-Rizal | BM3: Region IV-A-San Pablo City | BN3: Region IV-A-San Pedro City | BO3: Region IV-A-Sta. Rosa City | BP3: Region IV-A-Sto. Tomas City | BQ3: Region IV-A-Tanauan City | BR3: Region IV-A-Tayabas City | BS3: Region IV-A-General Trias | BT3: Region V-Albay | BU3: Region V-Camarines Norte | BV3: Region V-Camarines Sur | BW3: Region V-Catanduanes | BX3: Region V-Iriga City | BY3: Region V-Legaspi City | BZ3: Region V-Ligao City | CA3: Region V-Masbate | CB3: Region V-Masbate City | CC3: Region V-Naga City | CD3: Region V-Sorsogon | CE3: Region V-Sorsogon City | CF3: Region V-Tabaco City | CG3: Region VI-Aklan | CH3: Region VI-Antique | CI3: Region VI-Capiz | CJ3: Region VI-Guimaras | CK3: Region VI-Iloilo | CL3: Region VI-Iloilo City | CM3: Region VI-Passi City | CN3: Region VI-Roxas City | CO3: Region VII-Bogo City | CP3: Region VII-Bohol | CQ3: Region VII-Carcar City | CR3: Region VII-Cebu | CS3: Region VII-Cebu City | CT3: Region VII-City of Naga Cebu | CU3: Region VII-Danao City | CV3: Region VII-Lapu-Lapu City | CW3: Region VII-Mandaue City | CX3: Region VII-Tagbilaran City | CY3: Region VII-Talisay City | CZ3: Region VII-Toledo City | DA3: Region VIII-Baybay City | DB3: Region VIII-Biliran | DC3: Region VIII-Borongan City | DD3: Region VIII-Calbayog City | DE3: Region VIII-Catbalogan City | DF3: Region VIII-Eastern Samar | DG3: Region VIII-Leyte | DH3: Region VIII-Maasin City | DI3: Region VIII-Northern Samar | DJ3: Region VIII-Ormoc City | DK3: Region VIII-Samar (Western Samar) | DL3: Region VIII-Southern Leyte | DM3: Region VIII-Tacloban City | DN3: NIR-Bacolod City | DO3: NIR-Bago City | DP3: NIR-Bais City | DQ3: NIR-Bayawan City | DR3: NIR-Cadiz City | DS3: NIR-Canlaon City | DT3: NIR-Dumaguete City | DU3: NIR-Escalante City | DV3: NIR-Guihulngan City | DW3: NIR-Himamaylan City | DX3: NIR-Kabankalan City | DY3: NIR-La Carlota City | DZ3: NIR-Negros Occidental | EA3: NIR-Negros Oriental | EB3: NIR-Sagay City | EC3: NIR-San Carlos City | ED3: NIR-Silay City | EE3: NIR-Sipalay City | EF3: NIR-Siquijor | EG3: NIR-Tanjay City | EH3: NIR-Victorias City | EI3: Region IX-Dapitan City | EJ3: Region IX-Dipolog City | EK3: Region IX-Isabela City | EL3: Region IX-Pagadian City | EM3: Region IX-Zamboanga City | EN3: Region IX-Zamboanga del Norte | EO3: Region IX-Zamboanga del Sur | EP3: Region IX-Zamboanga Sibugay | EQ3: Region X-Bukidnon | ER3: Region X-Cagayan de Oro City | ES3: Region X-Camiguin | ET3: Region X-El Salvador | EU3: Region X-Gingoog City | EV3: Region X-Iligan City | EW3: Region X-Lanao del Norte | EX3: Region X-Malaybalay City | EY3: Region X-Misamis Occidental | EZ3: Region X-Misamis Oriental | FA3: Region X-Oroquieta City | FB3: Region X-Ozamis City | FC3: Region X-Tangub City | FD3: Region X-Valencia City | FE3: Region XI-Davao de Oro | FF3: Region XI-Davao City | FG3: Region XI-Davao del Norte | FH3: Region XI-Davao del Sur | FI3: Region XI-Davao Oriental | FJ3: Region XI-Digos City | FK3: Region XI-Island Garden City of Samal | FL3: Region XI-Mati City | FM3: Region XI-Panabo City | FN3: Region XI-Tagum City | FO3: Region XI-Davao Occidental | FP3: Region XII-General Santos City | FQ3: Region XII-Kidapawan City | FR3: Region XII-Koronadal City | FS3: Region XII-North Cotabato | FT3: Region XII-Sarangani | FU3: Region XII-South Cotabato | FV3: Region XII-Sultan Kudarat | FW3: Region XII-Tacurong City | FX3: NCR-Caloocan City | FY3: NCR-City of San Juan | FZ3: NCR-Las Pinas City | GA3: NCR-Makati City | GB3: NCR-Malabon City | GC3: NCR-Mandaluyong City | GD3: NCR-Manila | GE3: NCR-Marikina City | GF3: NCR-Muntinlupa City | GG3: NCR-Navotas | GH3: NCR-Paranaque City | GI3: NCR-Pasay City | GJ3: NCR-Pasig City | GK3: NCR-Quezon City | GL3: NCR-Taguig | GM3: NCR-Valenzuela City | GN3: CAR-Abra | GO3: CAR-Apayao | GP3: CAR-Baguio City | GQ3: CAR-Benguet | GR3: CAR-Ifugao | GS3: CAR-Kalinga | GT3: CAR-Mt. Province | GU3: CAR-Tabuk City | GV3: BARMM-Basilan | GW3: BARMM-Cotabato City | GX3: BARMM-Lamitan City | GY3: BARMM-Lanao del Sur - I | GZ3: BARMM-Lanao del Sur - II | HA3: BARMM-Maguindanao I | HB3: BARMM-Maguindanao II | HC3: BARMM-Marawi City | HD3: BARMM-Sulu | HE3: BARMM-Tawi-Tawi | HF3: BARMM-Special Geographic Division | HG3: CARAGA-Agusan del Norte | HH3: CARAGA-Agusan del Sur | HI3: CARAGA-Bayugan City | HJ3: CARAGA-Bislig City | HK3: CARAGA-Butuan City | HL3: CARAGA-Cabadbaran City | HM3: CARAGA-Dinagat Island | HN3: CARAGA-Siargao | HO3: CARAGA-Surigao City | HP3: CARAGA-Surigao del Norte | HQ3: CARAGA-Surigao del Sur | HR3: CARAGA-Tandag City | HS3: MIMAROPA-Calapan City | HT3: MIMAROPA-Marinduque | HU3: MIMAROPA-Occidental Mindoro | HV3: MIMAROPA-Oriental Mindoro | HW3: MIMAROPA-Palawan | HX3: MIMAROPA-Puerto Princesa City | HY3: MIMAROPA-Romblon | HZ3: {=TRANSPOSE(_xlfn._xlws.FILTER(TableRegionDivision,ISNUMBER(SEARCH('RF08 (TRANSFER-RELATED ISSUES)'!$O14,TableRegionDivision)),"Not found"))} -> Region I-Alaminos City | IA3: Region I-Batac City | IB3: Region I-Candon City | IC3: Region I-Dagupan City | ID3: Region I-Ilocos Norte | IE3: Region I-Ilocos Sur | IF3: Region I-La Union | IG3: Region I-Laoag City | IH3: Region I-Pangasinan I, Lingayen | II3: Region I-Pangasinan II, Binalonan | IJ3: Region I-San Carlos City | IK3: Region I-San Fernando City | IL3: Region I-Urdaneta City | IM3: Region I-Vigan City | IN3: Region II-Batanes | IO3: Region II-Cagayan | IP3: Region II-Cauayan City | IQ3: Region II-City of Ilagan | IR3: Region II-Isabela | IS3: Region II-Nueva Vizcaya | IT3: Region II-Quirino | IU3: Region II-Santiago City | IV3: Region II-Tuguegarao City | IW3: Region III-Angeles City | IX3: Region III-Aurora | IY3: Region III-Balanga City | IZ3: Region III-Bataan | JA3: Region III-Bulacan | JB3: Region III-Cabanatuan City | JC3: Region III-Gapan City | JD3: Region III-Mabalacat City | JE3: Region III-Malolos City | JF3: Region III-Meycauayan City | JG3: Region III-Munoz Science City | JH3: Region III-Nueva Ecija | JI3: Region III-Olongapo City | JJ3: Region III-Pampanga | JK3: Region III-San Fernando City | JL3: Region III-San Jose City | JM3: Region III-San Jose del Monte City | JN3: Region III-Tarlac | JO3: Region III-Tarlac City | JP3: Region III-Zambales | JQ3: Region IV-A-Antipolo City | JR3: Region IV-A-Bacoor City | JS3: Region IV-A-Batangas | JT3: Region IV-A-Batangas City | JU3: Region IV-A-Binan City | JV3: Region IV-A-Cabuyao | JW3: Region IV-A-Calamba City | JX3: Region IV-A-Cavite | JY3: Region IV-A-Cavite City | JZ3: Region IV-A-Dasmarinas City | KA3: Region IV-A-Imus City | KB3: Region IV-A-Laguna | KC3: Region IV-A-Lipa City | KD3: Region IV-A-Lucena City | KE3: Region IV-A-Quezon | KF3: Region IV-A-Rizal | KG3: Region IV-A-San Pablo City | KH3: Region IV-A-San Pedro City | KI3: Region IV-A-Sta. Rosa City | KJ3: Region IV-A-Sto. Tomas City | KK3: Region IV-A-Tanauan City | KL3: Region IV-A-Tayabas City | KM3: Region IV-A-General Trias | KN3: Region V-Albay | KO3: Region V-Camarines Norte | KP3: Region V-Camarines Sur | KQ3: Region V-Catanduanes | KR3: Region V-Iriga City | KS3: Region V-Legaspi City | KT3: Region V-Ligao City | KU3: Region V-Masbate | KV3: Region V-Masbate City | KW3: Region V-Naga City | KX3: Region V-Sorsogon | KY3: Region V-Sorsogon City | KZ3: Region V-Tabaco City | LA3: Region VI-Aklan | LB3: Region VI-Antique | LC3: Region VI-Capiz | LD3: Region VI-Guimaras | LE3: Region VI-Iloilo | LF3: Region VI-Iloilo City | LG3: Region VI-Passi City | LH3: Region VI-Roxas City | LI3: Region VII-Bogo City | LJ3: Region VII-Bohol | LK3: Region VII-Carcar City | LL3: Region VII-Cebu | LM3: Region VII-Cebu City | LN3: Region VII-City of Naga Cebu | LO3: Region VII-Danao City | LP3: Region VII-Lapu-Lapu City | LQ3: Region VII-Mandaue City | LR3: Region VII-Tagbilaran City | LS3: Region VII-Talisay City | LT3: Region VII-Toledo City | LU3: Region VIII-Baybay City | LV3: Region VIII-Biliran | LW3: Region VIII-Borongan City | LX3: Region VIII-Calbayog City | LY3: Region VIII-Catbalogan City | LZ3: Region VIII-Eastern Samar | MA3: Region VIII-Leyte | MB3: Region VIII-Maasin City | MC3: Region VIII-Northern Samar | MD3: Region VIII-Ormoc City | ME3: Region VIII-Samar (Western Samar) | MF3: Region VIII-Southern Leyte | MG3: Region VIII-Tacloban City | MH3: NIR-Bacolod City | MI3: NIR-Bago City | MJ3: NIR-Bais City | MK3: NIR-Bayawan City | ML3: NIR-Cadiz City | MM3: NIR-Canlaon City | MN3: NIR-Dumaguete City | MO3: NIR-Escalante City | MP3: NIR-Guihulngan City | MQ3: NIR-Himamaylan City | MR3: NIR-Kabankalan City | MS3: NIR-La Carlota City | MT3: NIR-Negros Occidental | MU3: NIR-Negros Oriental | MV3: NIR-Sagay City | MW3: NIR-San Carlos City | MX3: NIR-Silay City | MY3: NIR-Sipalay City | MZ3: NIR-Siquijor | NA3: NIR-Tanjay City | NB3: NIR-Victorias City | NC3: Region IX-Dapitan City | ND3: Region IX-Dipolog City | NE3: Region IX-Isabela City | NF3: Region IX-Pagadian City | NG3: Region IX-Zamboanga City | NH3: Region IX-Zamboanga del Norte | NI3: Region IX-Zamboanga del Sur | NJ3: Region IX-Zamboanga Sibugay | NK3: Region X-Bukidnon | NL3: Region X-Cagayan de Oro City | NM3: Region X-Camiguin | NN3: Region X-El Salvador | NO3: Region X-Gingoog City | NP3: Region X-Iligan City | NQ3: Region X-Lanao del Norte | NR3: Region X-Malaybalay City | NS3: Region X-Misamis Occidental | NT3: Region X-Misamis Oriental | NU3: Region X-Oroquieta City | NV3: Region X-Ozamis City | NW3: Region X-Tangub City | NX3: Region X-Valencia City | NY3: Region XI-Davao de Oro | NZ3: Region XI-Davao City | OA3: Region XI-Davao del Norte | OB3: Region XI-Davao del Sur | OC3: Region XI-Davao Oriental | OD3: Region XI-Digos City | OE3: Region XI-Island Garden City of Samal | OF3: Region XI-Mati City | OG3: Region XI-Panabo City | OH3: Region XI-Tagum City | OI3: Region XI-Davao Occidental | OJ3: Region XII-General Santos City | OK3: Region XII-Kidapawan City | OL3: Region XII-Koronadal City | OM3: Region XII-North Cotabato | ON3: Region XII-Sarangani | OO3: Region XII-South Cotabato | OP3: Region XII-Sultan Kudarat | OQ3: Region XII-Tacurong City | OR3: NCR-Caloocan City | OS3: NCR-City of San Juan | OT3: NCR-Las Pinas City | OU3: NCR-Makati City | OV3: NCR-Malabon City | OW3: NCR-Mandaluyong City | OX3: NCR-Manila | OY3: NCR-Marikina City | OZ3: NCR-Muntinlupa City | PA3: NCR-Navotas | PB3: NCR-Paranaque City | PC3: NCR-Pasay City | PD3: NCR-Pasig City | PE3: NCR-Quezon City | PF3: NCR-Taguig | PG3: NCR-Valenzuela City | PH3: CAR-Abra | PI3: CAR-Apayao | PJ3: CAR-Baguio City | PK3: CAR-Benguet | PL3: CAR-Ifugao | PM3: CAR-Kalinga | PN3: CAR-Mt. Province | PO3: CAR-Tabuk City | PP3: BARMM-Basilan | PQ3: BARMM-Cotabato City | PR3: BARMM-Lamitan City | PS3: BARMM-Lanao del Sur - I | PT3: BARMM-Lanao del Sur - II | PU3: BARMM-Maguindanao I | PV3: BARMM-Maguindanao II | PW3: BARMM-Marawi City | PX3: BARMM-Sulu | PY3: BARMM-Tawi-Tawi | PZ3: BARMM-Special Geographic Division | QA3: CARAGA-Agusan del Norte | QB3: CARAGA-Agusan del Sur | QC3: CARAGA-Bayugan City | QD3: CARAGA-Bislig City | QE3: CARAGA-Butuan City | QF3: CARAGA-Cabadbaran City | QG3: CARAGA-Dinagat Island | QH3: CARAGA-Siargao | QI3: CARAGA-Surigao City | QJ3: CARAGA-Surigao del Norte | QK3: CARAGA-Surigao del Sur | QL3: CARAGA-Tandag City | QM3: MIMAROPA-Calapan City | QN3: MIMAROPA-Marinduque | QO3: MIMAROPA-Occidental Mindoro | QP3: MIMAROPA-Oriental Mindoro | QQ3: MIMAROPA-Palawan | QR3: MIMAROPA-Puerto Princesa City | QS3: MIMAROPA-Romblon
C4: 3. Confirmed/Declined but still Pending | E4: Region I-Candon City | F4: {=TRANSPOSE(_xlfn._xlws.FILTER(TableRegionDivision,ISNUMBER(SEARCH('RF08 (TRANSFER-RELATED ISSUES)'!$B15,TableRegionDivision)),"Not found"))} -> Region I-Alaminos City | G4: Region I-Batac City | H4: Region I-Candon City | I4: Region I-Dagupan City | J4: Region I-Ilocos Norte | K4: Region I-Ilocos Sur | L4: Region I-La Union | M4: Region I-Laoag City | N4: Region I-Pangasinan I, Lingayen | O4: Region I-Pangasinan II, Binalonan | P4: Region I-San Carlos City | Q4: Region I-San Fernando City | R4: Region I-Urdaneta City | S4: Region I-Vigan City | T4: Region II-Batanes | U4: Region II-Cagayan | V4: Region II-Cauayan City | W4: Region II-City of Ilagan | X4: Region II-Isabela | Y4: Region II-Nueva Vizcaya | Z4: Region II-Quirino | AA4: Region II-Santiago City | AB4: Region II-Tuguegarao City | AC4: Region III-Angeles City | AD4: Region III-Aurora | AE4: Region III-Balanga City | AF4: Region III-Bataan | AG4: Region III-Bulacan | AH4: Region III-Cabanatuan City | AI4: Region III-Gapan City | AJ4: Region III-Mabalacat City | AK4: Region III-Malolos City | AL4: Region III-Meycauayan City | AM4: Region III-Munoz Science City | AN4: Region III-Nueva Ecija | AO4: Region III-Olongapo City | AP4: Region III-Pampanga | AQ4: Region III-San Fernando City | AR4: Region III-San Jose City | AS4: Region III-San Jose del Monte City | AT4: Region III-Tarlac | AU4: Region III-Tarlac City | AV4: Region III-Zambales | AW4: Region IV-A-Antipolo City | AX4: Region IV-A-Bacoor City | AY4: Region IV-A-Batangas | AZ4: Region IV-A-Batangas City | BA4: Region IV-A-Binan City | BB4: Region IV-A-Cabuyao | BC4: Region IV-A-Calamba City | BD4: Region IV-A-Cavite | BE4: Region IV-A-Cavite City | BF4: Region IV-A-Dasmarinas City | BG4: Region IV-A-Imus City | BH4: Region IV-A-Laguna | BI4: Region IV-A-Lipa City | BJ4: Region IV-A-Lucena City | BK4: Region IV-A-Quezon | BL4: Region IV-A-Rizal | BM4: Region IV-A-San Pablo City | BN4: Region IV-A-San Pedro City | BO4: Region IV-A-Sta. Rosa City | BP4: Region IV-A-Sto. Tomas City | BQ4: Region IV-A-Tanauan City | BR4: Region IV-A-Tayabas City | BS4: Region IV-A-General Trias | BT4: Region V-Albay | BU4: Region V-Camarines Norte | BV4: Region V-Camarines Sur | BW4: Region V-Catanduanes | BX4: Region V-Iriga City | BY4: Region V-Legaspi City | BZ4: Region V-Ligao City | CA4: Region V-Masbate | CB4: Region V-Masbate City | CC4: Region V-Naga City | CD4: Region V-Sorsogon | CE4: Region V-Sorsogon City | CF4: Region V-Tabaco City | CG4: Region VI-Aklan | CH4: Region VI-Antique | CI4: Region VI-Capiz | CJ4: Region VI-Guimaras | CK4: Region VI-Iloilo | CL4: Region VI-Iloilo City | CM4: Region VI-Passi City | CN4: Region VI-Roxas City | CO4: Region VII-Bogo City | CP4: Region VII-Bohol | CQ4: Region VII-Carcar City | CR4: Region VII-Cebu | CS4: Region VII-Cebu City | CT4: Region VII-City of Naga Cebu | CU4: Region VII-Danao City | CV4: Region VII-Lapu-Lapu City | CW4: Region VII-Mandaue City | CX4: Region VII-Tagbilaran City | CY4: Region VII-Talisay City | CZ4: Region VII-Toledo City | DA4: Region VIII-Baybay City | DB4: Region VIII-Biliran | DC4: Region VIII-Borongan City | DD4: Region VIII-Calbayog City | DE4: Region VIII-Catbalogan City | DF4: Region VIII-Eastern Samar | DG4: Region VIII-Leyte | DH4: Region VIII-Maasin City | DI4: Region VIII-Northern Samar | DJ4: Region VIII-Ormoc City | DK4: Region VIII-Samar (Western Samar) | DL4: Region VIII-Southern Leyte | DM4: Region VIII-Tacloban City | DN4: NIR-Bacolod City | DO4: NIR-Bago City | DP4: NIR-Bais City | DQ4: NIR-Bayawan City | DR4: NIR-Cadiz City | DS4: NIR-Canlaon City | DT4: NIR-Dumaguete City | DU4: NIR-Escalante City | DV4: NIR-Guihulngan City | DW4: NIR-Himamaylan City | DX4: NIR-Kabankalan City | DY4: NIR-La Carlota City | DZ4: NIR-Negros Occidental | EA4: NIR-Negros Oriental | EB4: NIR-Sagay City | EC4: NIR-San Carlos City | ED4: NIR-Silay City | EE4: NIR-Sipalay City | EF4: NIR-Siquijor | EG4: NIR-Tanjay City | EH4: NIR-Victorias City | EI4: Region IX-Dapitan City | EJ4: Region IX-Dipolog City | EK4: Region IX-Isabela City | EL4: Region IX-Pagadian City | EM4: Region IX-Zamboanga City | EN4: Region IX-Zamboanga del Norte | EO4: Region IX-Zamboanga del Sur | EP4: Region IX-Zamboanga Sibugay | EQ4: Region X-Bukidnon | ER4: Region X-Cagayan de Oro City | ES4: Region X-Camiguin | ET4: Region X-El Salvador | EU4: Region X-Gingoog City | EV4: Region X-Iligan City | EW4: Region X-Lanao del Norte | EX4: Region X-Malaybalay City | EY4: Region X-Misamis Occidental | EZ4: Region X-Misamis Oriental | FA4: Region X-Oroquieta City | FB4: Region X-Ozamis City | FC4: Region X-Tangub City | FD4: Region X-Valencia City | FE4: Region XI-Davao de Oro | FF4: Region XI-Davao City | FG4: Region XI-Davao del Norte | FH4: Region XI-Davao del Sur | FI4: Region XI-Davao Oriental | FJ4: Region XI-Digos City | FK4: Region XI-Island Garden City of Samal | FL4: Region XI-Mati City | FM4: Region XI-Panabo City | FN4: Region XI-Tagum City | FO4: Region XI-Davao Occidental | FP4: Region XII-General Santos City | FQ4: Region XII-Kidapawan City | FR4: Region XII-Koronadal City | FS4: Region XII-North Cotabato | FT4: Region XII-Sarangani | FU4: Region XII-South Cotabato | FV4: Region XII-Sultan Kudarat | FW4: Region XII-Tacurong City | FX4: NCR-Caloocan City | FY4: NCR-City of San Juan | FZ4: NCR-Las Pinas City | GA4: NCR-Makati City | GB4: NCR-Malabon City | GC4: NCR-Mandaluyong City | GD4: NCR-Manila | GE4: NCR-Marikina City | GF4: NCR-Muntinlupa City | GG4: NCR-Navotas | GH4: NCR-Paranaque City | GI4: NCR-Pasay City | GJ4: NCR-Pasig City | GK4: NCR-Quezon City | GL4: NCR-Taguig | GM4: NCR-Valenzuela City | GN4: CAR-Abra | GO4: CAR-Apayao | GP4: CAR-Baguio City | GQ4: CAR-Benguet | GR4: CAR-Ifugao | GS4: CAR-Kalinga | GT4: CAR-Mt. Province | GU4: CAR-Tabuk City | GV4: BARMM-Basilan | GW4: BARMM-Cotabato City | GX4: BARMM-Lamitan City | GY4: BARMM-Lanao del Sur - I | GZ4: BARMM-Lanao del Sur - II | HA4: BARMM-Maguindanao I | HB4: BARMM-Maguindanao II | HC4: BARMM-Marawi City | HD4: BARMM-Sulu | HE4: BARMM-Tawi-Tawi | HF4: BARMM-Special Geographic Division | HG4: CARAGA-Agusan del Norte | HH4: CARAGA-Agusan del Sur | HI4: CARAGA-Bayugan City | HJ4: CARAGA-Bislig City | HK4: CARAGA-Butuan City | HL4: CARAGA-Cabadbaran City | HM4: CARAGA-Dinagat Island | HN4: CARAGA-Siargao | HO4: CARAGA-Surigao City | HP4: CARAGA-Surigao del Norte | HQ4: CARAGA-Surigao del Sur | HR4: CARAGA-Tandag City | HS4: MIMAROPA-Calapan City | HT4: MIMAROPA-Marinduque | HU4: MIMAROPA-Occidental Mindoro | HV4: MIMAROPA-Oriental Mindoro | HW4: MIMAROPA-Palawan | HX4: MIMAROPA-Puerto Princesa City | HY4: MIMAROPA-Romblon | HZ4: {=TRANSPOSE(_xlfn._xlws.FILTER(TableRegionDivision,ISNUMBER(SEARCH('RF08 (TRANSFER-RELATED ISSUES)'!$O15,TableRegionDivision)),"Not found"))} -> Region I-Alaminos City | IA4: Region I-Batac City | IB4: Region I-Candon City | IC4: Region I-Dagupan City | ID4: Region I-Ilocos Norte | IE4: Region I-Ilocos Sur | IF4: Region I-La Union | IG4: Region I-Laoag City | IH4: Region I-Pangasinan I, Lingayen | II4: Region I-Pangasinan II, Binalonan | IJ4: Region I-San Carlos City | IK4: Region I-San Fernando City | IL4: Region I-Urdaneta City | IM4: Region I-Vigan City | IN4: Region II-Batanes | IO4: Region II-Cagayan | IP4: Region II-Cauayan City | IQ4: Region II-City of Ilagan | IR4: Region II-Isabela | IS4: Region II-Nueva Vizcaya | IT4: Region II-Quirino | IU4: Region II-Santiago City | IV4: Region II-Tuguegarao City | IW4: Region III-Angeles City | IX4: Region III-Aurora | IY4: Region III-Balanga City | IZ4: Region III-Bataan | JA4: Region III-Bulacan | JB4: Region III-Cabanatuan City | JC4: Region III-Gapan City | JD4: Region III-Mabalacat City | JE4: Region III-Malolos City | JF4: Region III-Meycauayan City | JG4: Region III-Munoz Science City | JH4: Region III-Nueva Ecija | JI4: Region III-Olongapo City | JJ4: Region III-Pampanga | JK4: Region III-San Fernando City | JL4: Region III-San Jose City | JM4: Region III-San Jose del Monte City | JN4: Region III-Tarlac | JO4: Region III-Tarlac City | JP4: Region III-Zambales | JQ4: Region IV-A-Antipolo City | JR4: Region IV-A-Bacoor City | JS4: Region IV-A-Batangas | JT4: Region IV-A-Batangas City | JU4: Region IV-A-Binan City | JV4: Region IV-A-Cabuyao | JW4: Region IV-A-Calamba City | JX4: Region IV-A-Cavite | JY4: Region IV-A-Cavite City | JZ4: Region IV-A-Dasmarinas City | KA4: Region IV-A-Imus City | KB4: Region IV-A-Laguna | KC4: Region IV-A-Lipa City | KD4: Region IV-A-Lucena City | KE4: Region IV-A-Quezon | KF4: Region IV-A-Rizal | KG4: Region IV-A-San Pablo City | KH4: Region IV-A-San Pedro City | KI4: Region IV-A-Sta. Rosa City | KJ4: Region IV-A-Sto. Tomas City | KK4: Region IV-A-Tanauan City | KL4: Region IV-A-Tayabas City | KM4: Region IV-A-General Trias | KN4: Region V-Albay | KO4: Region V-Camarines Norte | KP4: Region V-Camarines Sur | KQ4: Region V-Catanduanes | KR4: Region V-Iriga City | KS4: Region V-Legaspi City | KT4: Region V-Ligao City | KU4: Region V-Masbate | KV4: Region V-Masbate City | KW4: Region V-Naga City | KX4: Region V-Sorsogon | KY4: Region V-Sorsogon City | KZ4: Region V-Tabaco City | LA4: Region VI-Aklan | LB4: Region VI-Antique | LC4: Region VI-Capiz | LD4: Region VI-Guimaras | LE4: Region VI-Iloilo | LF4: Region VI-Iloilo City | LG4: Region VI-Passi City | LH4: Region VI-Roxas City | LI4: Region VII-Bogo City | LJ4: Region VII-Bohol | LK4: Region VII-Carcar City | LL4: Region VII-Cebu | LM4: Region VII-Cebu City | LN4: Region VII-City of Naga Cebu | LO4: Region VII-Danao City | LP4: Region VII-Lapu-Lapu City | LQ4: Region VII-Mandaue City | LR4: Region VII-Tagbilaran City | LS4: Region VII-Talisay City | LT4: Region VII-Toledo City | LU4: Region VIII-Baybay City | LV4: Region VIII-Biliran | LW4: Region VIII-Borongan City | LX4: Region VIII-Calbayog City | LY4: Region VIII-Catbalogan City | LZ4: Region VIII-Eastern Samar | MA4: Region VIII-Leyte | MB4: Region VIII-Maasin City | MC4: Region VIII-Northern Samar | MD4: Region VIII-Ormoc City | ME4: Region VIII-Samar (Western Samar) | MF4: Region VIII-Southern Leyte | MG4: Region VIII-Tacloban City | MH4: NIR-Bacolod City | MI4: NIR-Bago City | MJ4: NIR-Bais City | MK4: NIR-Bayawan City | ML4: NIR-Cadiz City | MM4: NIR-Canlaon City | MN4: NIR-Dumaguete City | MO4: NIR-Escalante City | MP4: NIR-Guihulngan City | MQ4: NIR-Himamaylan City | MR4: NIR-Kabankalan City | MS4: NIR-La Carlota City | MT4: NIR-Negros Occidental | MU4: NIR-Negros Oriental | MV4: NIR-Sagay City | MW4: NIR-San Carlos City | MX4: NIR-Silay City | MY4: NIR-Sipalay City | MZ4: NIR-Siquijor | NA4: NIR-Tanjay City | NB4: NIR-Victorias City | NC4: Region IX-Dapitan City | ND4: Region IX-Dipolog City | NE4: Region IX-Isabela City | NF4: Region IX-Pagadian City | NG4: Region IX-Zamboanga City | NH4: Region IX-Zamboanga del Norte | NI4: Region IX-Zamboanga del Sur | NJ4: Region IX-Zamboanga Sibugay | NK4: Region X-Bukidnon | NL4: Region X-Cagayan de Oro City | NM4: Region X-Camiguin | NN4: Region X-El Salvador | NO4: Region X-Gingoog City | NP4: Region X-Iligan City | NQ4: Region X-Lanao del Norte | NR4: Region X-Malaybalay City | NS4: Region X-Misamis Occidental | NT4: Region X-Misamis Oriental | NU4: Region X-Oroquieta City | NV4: Region X-Ozamis City | NW4: Region X-Tangub City | NX4: Region X-Valencia City | NY4: Region XI-Davao de Oro | NZ4: Region XI-Davao City | OA4: Region XI-Davao del Norte | OB4: Region XI-Davao del Sur | OC4: Region XI-Davao Oriental | OD4: Region XI-Digos City | OE4: Region XI-Island Garden City of Samal | OF4: Region XI-Mati City | OG4: Region XI-Panabo City | OH4: Region XI-Tagum City | OI4: Region XI-Davao Occidental | OJ4: Region XII-General Santos City | OK4: Region XII-Kidapawan City | OL4: Region XII-Koronadal City | OM4: Region XII-North Cotabato | ON4: Region XII-Sarangani | OO4: Region XII-South Cotabato | OP4: Region XII-Sultan Kudarat | OQ4: Region XII-Tacurong City | OR4: NCR-Caloocan City | OS4: NCR-City of San Juan | OT4: NCR-Las Pinas City | OU4: NCR-Makati City | OV4: NCR-Malabon City | OW4: NCR-Mandaluyong City | OX4: NCR-Manila | OY4: NCR-Marikina City | OZ4: NCR-Muntinlupa City | PA4: NCR-Navotas | PB4: NCR-Paranaque City | PC4: NCR-Pasay City | PD4: NCR-Pasig City | PE4: NCR-Quezon City | PF4: NCR-Taguig | PG4: NCR-Valenzuela City | PH4: CAR-Abra | PI4: CAR-Apayao | PJ4: CAR-Baguio City | PK4: CAR-Benguet | PL4: CAR-Ifugao | PM4: CAR-Kalinga | PN4: CAR-Mt. Province | PO4: CAR-Tabuk City | PP4: BARMM-Basilan | PQ4: BARMM-Cotabato City | PR4: BARMM-Lamitan City | PS4: BARMM-Lanao del Sur - I | PT4: BARMM-Lanao del Sur - II | PU4: BARMM-Maguindanao I | PV4: BARMM-Maguindanao II | PW4: BARMM-Marawi City | PX4: BARMM-Sulu | PY4: BARMM-Tawi-Tawi | PZ4: BARMM-Special Geographic Division | QA4: CARAGA-Agusan del Norte | QB4: CARAGA-Agusan del Sur | QC4: CARAGA-Bayugan City | QD4: CARAGA-Bislig City | QE4: CARAGA-Butuan City | QF4: CARAGA-Cabadbaran City | QG4: CARAGA-Dinagat Island | QH4: CARAGA-Siargao | QI4: CARAGA-Surigao City | QJ4: CARAGA-Surigao del Norte | QK4: CARAGA-Surigao del Sur | QL4: CARAGA-Tandag City | QM4: MIMAROPA-Calapan City | QN4: MIMAROPA-Marinduque | QO4: MIMAROPA-Occidental Mindoro | QP4: MIMAROPA-Oriental Mindoro | QQ4: MIMAROPA-Palawan | QR4: MIMAROPA-Puerto Princesa City | QS4: MIMAROPA-Romblon
C5: 4. Transfer from Closed School | E5: Region I-Dagupan City | F5: {=TRANSPOSE(_xlfn._xlws.FILTER(TableRegionDivision,ISNUMBER(SEARCH('RF08 (TRANSFER-RELATED ISSUES)'!$B16,TableRegionDivision)),"Not found"))} -> Region I-Alaminos City | G5: Region I-Batac City | H5: Region I-Candon City | I5: Region I-Dagupan City | J5: Region I-Ilocos Norte | K5: Region I-Ilocos Sur | L5: Region I-La Union | M5: Region I-Laoag City | N5: Region I-Pangasinan I, Lingayen | O5: Region I-Pangasinan II, Binalonan | P5: Region I-San Carlos City | Q5: Region I-San Fernando City | R5: Region I-Urdaneta City | S5: Region I-Vigan City | T5: Region II-Batanes | U5: Region II-Cagayan | V5: Region II-Cauayan City | W5: Region II-City of Ilagan | X5: Region II-Isabela | Y5: Region II-Nueva Vizcaya | Z5: Region II-Quirino | AA5: Region II-Santiago City | AB5: Region II-Tuguegarao City | AC5: Region III-Angeles City | AD5: Region III-Aurora | AE5: Region III-Balanga City | AF5: Region III-Bataan | AG5: Region III-Bulacan | AH5: Region III-Cabanatuan City | AI5: Region III-Gapan City | AJ5: Region III-Mabalacat City | AK5: Region III-Malolos City | AL5: Region III-Meycauayan City | AM5: Region III-Munoz Science City | AN5: Region III-Nueva Ecija | AO5: Region III-Olongapo City | AP5: Region III-Pampanga | AQ5: Region III-San Fernando City | AR5: Region III-San Jose City | AS5: Region III-San Jose del Monte City | AT5: Region III-Tarlac | AU5: Region III-Tarlac City | AV5: Region III-Zambales | AW5: Region IV-A-Antipolo City | AX5: Region IV-A-Bacoor City | AY5: Region IV-A-Batangas | AZ5: Region IV-A-Batangas City | BA5: Region IV-A-Binan City | BB5: Region IV-A-Cabuyao | BC5: Region IV-A-Calamba City | BD5: Region IV-A-Cavite | BE5: Region IV-A-Cavite City | BF5: Region IV-A-Dasmarinas City | BG5: Region IV-A-Imus City | BH5: Region IV-A-Laguna | BI5: Region IV-A-Lipa City | BJ5: Region IV-A-Lucena City | BK5: Region IV-A-Quezon | BL5: Region IV-A-Rizal | BM5: Region IV-A-San Pablo City | BN5: Region IV-A-San Pedro City | BO5: Region IV-A-Sta. Rosa City | BP5: Region IV-A-Sto. Tomas City | BQ5: Region IV-A-Tanauan City | BR5: Region IV-A-Tayabas City | BS5: Region IV-A-General Trias | BT5: Region V-Albay | BU5: Region V-Camarines Norte | BV5: Region V-Camarines Sur | BW5: Region V-Catanduanes | BX5: Region V-Iriga City | BY5: Region V-Legaspi City | BZ5: Region V-Ligao City | CA5: Region V-Masbate | CB5: Region V-Masbate City | CC5: Region V-Naga City | CD5: Region V-Sorsogon | CE5: Region V-Sorsogon City | CF5: Region V-Tabaco City | CG5: Region VI-Aklan | CH5: Region VI-Antique | CI5: Region VI-Capiz | CJ5: Region VI-Guimaras | CK5: Region VI-Iloilo | CL5: Region VI-Iloilo City | CM5: Region VI-Passi City | CN5: Region VI-Roxas City | CO5: Region VII-Bogo City | CP5: Region VII-Bohol | CQ5: Region VII-Carcar City | CR5: Region VII-Cebu | CS5: Region VII-Cebu City | CT5: Region VII-City of Naga Cebu | CU5: Region VII-Danao City | CV5: Region VII-Lapu-Lapu City | CW5: Region VII-Mandaue City | CX5: Region VII-Tagbilaran City | CY5: Region VII-Talisay City | CZ5: Region VII-Toledo City | DA5: Region VIII-Baybay City | DB5: Region VIII-Biliran | DC5: Region VIII-Borongan City | DD5: Region VIII-Calbayog City | DE5: Region VIII-Catbalogan City | DF5: Region VIII-Eastern Samar | DG5: Region VIII-Leyte | DH5: Region VIII-Maasin City | DI5: Region VIII-Northern Samar | DJ5: Region VIII-Ormoc City | DK5: Region VIII-Samar (Western Samar) | DL5: Region VIII-Southern Leyte | DM5: Region VIII-Tacloban City | DN5: NIR-Bacolod City | DO5: NIR-Bago City | DP5: NIR-Bais City | DQ5: NIR-Bayawan City | DR5: NIR-Cadiz City | DS5: NIR-Canlaon City | DT5: NIR-Dumaguete City | DU5: NIR-Escalante City | DV5: NIR-Guihulngan City | DW5: NIR-Himamaylan City | DX5: NIR-Kabankalan City | DY5: NIR-La Carlota City | DZ5: NIR-Negros Occidental | EA5: NIR-Negros Oriental | EB5: NIR-Sagay City | EC5: NIR-San Carlos City | ED5: NIR-Silay City | EE5: NIR-Sipalay City | EF5: NIR-Siquijor | EG5: NIR-Tanjay City | EH5: NIR-Victorias City | EI5: Region IX-Dapitan City | EJ5: Region IX-Dipolog City | EK5: Region IX-Isabela City | EL5: Region IX-Pagadian City | EM5: Region IX-Zamboanga City | EN5: Region IX-Zamboanga del Norte | EO5: Region IX-Zamboanga del Sur | EP5: Region IX-Zamboanga Sibugay | EQ5: Region X-Bukidnon | ER5: Region X-Cagayan de Oro City | ES5: Region X-Camiguin | ET5: Region X-El Salvador | EU5: Region X-Gingoog City | EV5: Region X-Iligan City | EW5: Region X-Lanao del Norte | EX5: Region X-Malaybalay City | EY5: Region X-Misamis Occidental | EZ5: Region X-Misamis Oriental | FA5: Region X-Oroquieta City | FB5: Region X-Ozamis City | FC5: Region X-Tangub City | FD5: Region X-Valencia City | FE5: Region XI-Davao de Oro | FF5: Region XI-Davao City | FG5: Region XI-Davao del Norte | FH5: Region XI-Davao del Sur | FI5: Region XI-Davao Oriental | FJ5: Region XI-Digos City | FK5: Region XI-Island Garden City of Samal | FL5: Region XI-Mati City | FM5: Region XI-Panabo City | FN5: Region XI-Tagum City | FO5: Region XI-Davao Occidental | FP5: Region XII-General Santos City | FQ5: Region XII-Kidapawan City | FR5: Region XII-Koronadal City | FS5: Region XII-North Cotabato | FT5: Region XII-Sarangani | FU5: Region XII-South Cotabato | FV5: Region XII-Sultan Kudarat | FW5: Region XII-Tacurong City | FX5: NCR-Caloocan City | FY5: NCR-City of San Juan | FZ5: NCR-Las Pinas City | GA5: NCR-Makati City | GB5: NCR-Malabon City | GC5: NCR-Mandaluyong City | GD5: NCR-Manila | GE5: NCR-Marikina City | GF5: NCR-Muntinlupa City | GG5: NCR-Navotas | GH5: NCR-Paranaque City | GI5: NCR-Pasay City | GJ5: NCR-Pasig City | GK5: NCR-Quezon City | GL5: NCR-Taguig | GM5: NCR-Valenzuela City | GN5: CAR-Abra | GO5: CAR-Apayao | GP5: CAR-Baguio City | GQ5: CAR-Benguet | GR5: CAR-Ifugao | GS5: CAR-Kalinga | GT5: CAR-Mt. Province | GU5: CAR-Tabuk City | GV5: BARMM-Basilan | GW5: BARMM-Cotabato City | GX5: BARMM-Lamitan City | GY5: BARMM-Lanao del Sur - I | GZ5: BARMM-Lanao del Sur - II | HA5: BARMM-Maguindanao I | HB5: BARMM-Maguindanao II | HC5: BARMM-Marawi City | HD5: BARMM-Sulu | HE5: BARMM-Tawi-Tawi | HF5: BARMM-Special Geographic Division | HG5: CARAGA-Agusan del Norte | HH5: CARAGA-Agusan del Sur | HI5: CARAGA-Bayugan City | HJ5: CARAGA-Bislig City | HK5: CARAGA-Butuan City | HL5: CARAGA-Cabadbaran City | HM5: CARAGA-Dinagat Island | HN5: CARAGA-Siargao | HO5: CARAGA-Surigao City | HP5: CARAGA-Surigao del Norte | HQ5: CARAGA-Surigao del Sur | HR5: CARAGA-Tandag City | HS5: MIMAROPA-Calapan City | HT5: MIMAROPA-Marinduque | HU5: MIMAROPA-Occidental Mindoro | HV5: MIMAROPA-Oriental Mindoro | HW5: MIMAROPA-Palawan | HX5: MIMAROPA-Puerto Princesa City | HY5: MIMAROPA-Romblon | HZ5: {=TRANSPOSE(_xlfn._xlws.FILTER(TableRegionDivision,ISNUMBER(SEARCH('RF08 (TRANSFER-RELATED ISSUES)'!$O16,TableRegionDivision)),"Not found"))} -> Region I-Alaminos City | IA5: Region I-Batac City | IB5: Region I-Candon City | IC5: Region I-Dagupan City | ID5: Region I-Ilocos Norte | IE5: Region I-Ilocos Sur | IF5: Region I-La Union | IG5: Region I-Laoag City | IH5: Region I-Pangasinan I, Lingayen | II5: Region I-Pangasinan II, Binalonan | IJ5: Region I-San Carlos City | IK5: Region I-San Fernando City | IL5: Region I-Urdaneta City | IM5: Region I-Vigan City | IN5: Region II-Batanes | IO5: Region II-Cagayan | IP5: Region II-Cauayan City | IQ5: Region II-City of Ilagan | IR5: Region II-Isabela | IS5: Region II-Nueva Vizcaya | IT5: Region II-Quirino | IU5: Region II-Santiago City | IV5: Region II-Tuguegarao City | IW5: Region III-Angeles City | IX5: Region III-Aurora | IY5: Region III-Balanga City | IZ5: Region III-Bataan | JA5: Region III-Bulacan | JB5: Region III-Cabanatuan City | JC5: Region III-Gapan City | JD5: Region III-Mabalacat City | JE5: Region III-Malolos City | JF5: Region III-Meycauayan City | JG5: Region III-Munoz Science City | JH5: Region III-Nueva Ecija | JI5: Region III-Olongapo City | JJ5: Region III-Pampanga | JK5: Region III-San Fernando City | JL5: Region III-San Jose City | JM5: Region III-San Jose del Monte City | JN5: Region III-Tarlac | JO5: Region III-Tarlac City | JP5: Region III-Zambales | JQ5: Region IV-A-Antipolo City | JR5: Region IV-A-Bacoor City | JS5: Region IV-A-Batangas | JT5: Region IV-A-Batangas City | JU5: Region IV-A-Binan City | JV5: Region IV-A-Cabuyao | JW5: Region IV-A-Calamba City | JX5: Region IV-A-Cavite | JY5: Region IV-A-Cavite City | JZ5: Region IV-A-Dasmarinas City | KA5: Region IV-A-Imus City | KB5: Region IV-A-Laguna | KC5: Region IV-A-Lipa City | KD5: Region IV-A-Lucena City | KE5: Region IV-A-Quezon | KF5: Region IV-A-Rizal | KG5: Region IV-A-San Pablo City | KH5: Region IV-A-San Pedro City | KI5: Region IV-A-Sta. Rosa City | KJ5: Region IV-A-Sto. Tomas City | KK5: Region IV-A-Tanauan City | KL5: Region IV-A-Tayabas City | KM5: Region IV-A-General Trias | KN5: Region V-Albay | KO5: Region V-Camarines Norte | KP5: Region V-Camarines Sur | KQ5: Region V-Catanduanes | KR5: Region V-Iriga City | KS5: Region V-Legaspi City | KT5: Region V-Ligao City | KU5: Region V-Masbate | KV5: Region V-Masbate City | KW5: Region V-Naga City | KX5: Region V-Sorsogon | KY5: Region V-Sorsogon City | KZ5: Region V-Tabaco City | LA5: Region VI-Aklan | LB5: Region VI-Antique | LC5: Region VI-Capiz | LD5: Region VI-Guimaras | LE5: Region VI-Iloilo | LF5: Region VI-Iloilo City | LG5: Region VI-Passi City | LH5: Region VI-Roxas City | LI5: Region VII-Bogo City | LJ5: Region VII-Bohol | LK5: Region VII-Carcar City | LL5: Region VII-Cebu | LM5: Region VII-Cebu City | LN5: Region VII-City of Naga Cebu | LO5: Region VII-Danao City | LP5: Region VII-Lapu-Lapu City | LQ5: Region VII-Mandaue City | LR5: Region VII-Tagbilaran City | LS5: Region VII-Talisay City | LT5: Region VII-Toledo City | LU5: Region VIII-Baybay City | LV5: Region VIII-Biliran | LW5: Region VIII-Borongan City | LX5: Region VIII-Calbayog City | LY5: Region VIII-Catbalogan City | LZ5: Region VIII-Eastern Samar | MA5: Region VIII-Leyte | MB5: Region VIII-Maasin City | MC5: Region VIII-Northern Samar | MD5: Region VIII-Ormoc City | ME5: Region VIII-Samar (Western Samar) | MF5: Region VIII-Southern Leyte | MG5: Region VIII-Tacloban City | MH5: NIR-Bacolod City | MI5: NIR-Bago City | MJ5: NIR-Bais City | MK5: NIR-Bayawan City | ML5: NIR-Cadiz City | MM5: NIR-Canlaon City | MN5: NIR-Dumaguete City | MO5: NIR-Escalante City | MP5: NIR-Guihulngan City | MQ5: NIR-Himamaylan City | MR5: NIR-Kabankalan City | MS5: NIR-La Carlota City | MT5: NIR-Negros Occidental | MU5: NIR-Negros Oriental | MV5: NIR-Sagay City | MW5: NIR-San Carlos City | MX5: NIR-Silay City | MY5: NIR-Sipalay City | MZ5: NIR-Siquijor | NA5: NIR-Tanjay City | NB5: NIR-Victorias City | NC5: Region IX-Dapitan City | ND5: Region IX-Dipolog City | NE5: Region IX-Isabela City | NF5: Region IX-Pagadian City | NG5: Region IX-Zamboanga City | NH5: Region IX-Zamboanga del Norte | NI5: Region IX-Zamboanga del Sur | NJ5: Region IX-Zamboanga Sibugay | NK5: Region X-Bukidnon | NL5: Region X-Cagayan de Oro City | NM5: Region X-Camiguin | NN5: Region X-El Salvador | NO5: Region X-Gingoog City | NP5: Region X-Iligan City | NQ5: Region X-Lanao del Norte | NR5: Region X-Malaybalay City | NS5: Region X-Misamis Occidental | NT5: Region X-Misamis Oriental | NU5: Region X-Oroquieta City | NV5: Region X-Ozamis City | NW5: Region X-Tangub City | NX5: Region X-Valencia City | NY5: Region XI-Davao de Oro | NZ5: Region XI-Davao City | OA5: Region XI-Davao del Norte | OB5: Region XI-Davao del Sur | OC5: Region XI-Davao Oriental | OD5: Region XI-Digos City | OE5: Region XI-Island Garden City of Samal | OF5: Region XI-Mati City | OG5: Region XI-Panabo City | OH5: Region XI-Tagum City | OI5: Region XI-Davao Occidental | OJ5: Region XII-General Santos City | OK5: Region XII-Kidapawan City | OL5: Region XII-Koronadal City | OM5: Region XII-North Cotabato | ON5: Region XII-Sarangani | OO5: Region XII-South Cotabato | OP5: Region XII-Sultan Kudarat | OQ5: Region XII-Tacurong City | OR5: NCR-Caloocan City | OS5: NCR-City of San Juan | OT5: NCR-Las Pinas City | OU5: NCR-Makati City | OV5: NCR-Malabon City | OW5: NCR-Mandaluyong City | OX5: NCR-Manila | OY5: NCR-Marikina City | OZ5: NCR-Muntinlupa City | PA5: NCR-Navotas | PB5: NCR-Paranaque City | PC5: NCR-Pasay City | PD5: NCR-Pasig City | PE5: NCR-Quezon City | PF5: NCR-Taguig | PG5: NCR-Valenzuela City | PH5: CAR-Abra | PI5: CAR-Apayao | PJ5: CAR-Baguio City | PK5: CAR-Benguet | PL5: CAR-Ifugao | PM5: CAR-Kalinga | PN5: CAR-Mt. Province | PO5: CAR-Tabuk City | PP5: BARMM-Basilan | PQ5: BARMM-Cotabato City | PR5: BARMM-Lamitan City | PS5: BARMM-Lanao del Sur - I | PT5: BARMM-Lanao del Sur - II | PU5: BARMM-Maguindanao I | PV5: BARMM-Maguindanao II | PW5: BARMM-Marawi City | PX5: BARMM-Sulu | PY5: BARMM-Tawi-Tawi | PZ5: BARMM-Special Geographic Division | QA5: CARAGA-Agusan del Norte | QB5: CARAGA-Agusan del Sur | QC5: CARAGA-Bayugan City | QD5: CARAGA-Bislig City | QE5: CARAGA-Butuan City | QF5: CARAGA-Cabadbaran City | QG5: CARAGA-Dinagat Island | QH5: CARAGA-Siargao | QI5: CARAGA-Surigao City | QJ5: CARAGA-Surigao del Norte | QK5: CARAGA-Surigao del Sur | QL5: CARAGA-Tandag City | QM5: MIMAROPA-Calapan City | QN5: MIMAROPA-Marinduque | QO5: MIMAROPA-Occidental Mindoro | QP5: MIMAROPA-Oriental Mindoro | QQ5: MIMAROPA-Palawan | QR5: MIMAROPA-Puerto Princesa City | QS5: MIMAROPA-Romblon
