Workbook

Sheet REGION XI_SNED
A1: SCHOOL LEVEL DATA ON SPECIAL NEEDS EDUCATION (SNEd) | B1: SCHOOL LEVEL DATA ON SPECIAL NEEDS EDUCATION (SNEd)
A2: SY 2024-2025 | B2: SY 2024-2025
A3: Based on LIS, as of December 31, 2024 | B3: Based on LIS, as of December 31, 2024
Q5: ES MAINSTREAMED LEARNERS DATA | JW5: MAINSTREAMED LEARNERS DATA | KA5: ES SELFCONTAINED LEARNERS DATA | UG5: SELFCONTAINED LEARNERS DATA | UK5: With Diagnosis from Licensed Medical Specialist | YQ5: With Manifestations: | ABS5: Total Non-Graded | ABW5: JHS MAINSTREAMED LEARNERS DATA | AHW5: JHS SELF-CONTAINED
Q6: MAINSTREAMED LEARNERS DATA (With Diagnosis from Licensed Medical Specialist:) | FO6: MAINSTREAM ED LEARNERS DATA (With Manifestations) | KA6: SELF-CONTAINED LEARNERS DATA (With Diagnosis from Licensed Medical Specialist:) | PY6: SELF-CONTAINED LEARNERS DATA (With Manifestations) | UK6: Visual Impairment | UU6: Hearing Impairment | VE6: Learning Disability | VO6: Intellectual Disability | VY6: Autism Spectrum Disorder | WI6: Emotional-Behavioral Disorder | WS6: Orthopedic/Physical Handicap | XC6: Speech/Language Disorder | XM6: Cerebral Palsy | XW6: Special health Problem/Chronic Disease | YG6: Multiple Disabilities | YQ6: Difficulty in Seeing | ZA6: Difficulty in Hearing | ZK6: Difficulty in Applying Knowledge | ZU6: Difficulty in Remembering, Concentrating, Paying Attention and Understanding | AAE6: Difficulty in Applying Adaptive Skills | AAO6: Difficulty in Displaying Inter-Personal Behavior | AAY6: Difficulty in Mobility (Walking, Climbing and Grasping) | ABI6: Difficulty in Communicating | ABW6: With Diagnosis from Licensed Medical Specialist: | AFG6: With Manifestation | AHS6: Total MAINSTREAMED Learners | AHW6: With Diagnosis from Licensed Medical Specialist: | ALG6: With Manifestation | ANS6: Total JHS SELF CONTAINED
Q7: Visual Impairment | AE7: Hearing Impairment | AS7: Learning Disability | BG7: Intellectual Disability | BU7: Autism Spectrum Disorder | CI7: Emotional-Behavioral Disorder | CW7: Orthopedic/ Physical Handicap | DK7: Speech / Language Disorder | DY7: Cerebral Palsy | EM7: Special Health Problem/ Chronic Disease | FA7: Multiple Disabilities | FO7: Difficulty in Seeing | GC7: Difficulty in Hearing | GQ7: Difficulty in Applying Knowledge | HE7: Difficulty in Remembering, Concentrating, Paying Attention and Understanding | HS7: Difficulty in Applying Adaptive Skills | IG7: Difficulty in Displaying Inter-Personal Behavior | IU7: Difficulty in Mobility (Walking, Climbing and Grasping) | JI7: Difficulty in Communicating | KA7: Visual Impairment | KO7: Hearing Impairment | LC7: Learning Disability | LQ7: Intellectual Disability | ME7: Autism Spectrum Disorder | MS7: Emotional-Behavioral Disorder | NG7: Orthopedic/ Physical Handicap | NU7: Speech / Language Disorder | OI7: Cerebral Palsy | OW7: Special Health Problem/ Chronic Disease | PK7: Multiple Disabilities | PY7: Difficulty in Seeing | QM7: Difficulty in Hearing | RA7: Difficulty in Applying Knowledge | RO7: Difficulty in Remembering, Concentrating, Paying Attention and Understanding | SC7: Difficulty in Applying Adaptive Skills | SQ7: Difficulty in Displaying Inter-Personal Behavior | TE7: Difficulty in Mobility (Walking, Climbing and Grasping) | TS7: Difficulty in Communicating | UK7: Kindergarten | UM7: Primary Level | US7: Transition | UU7: Kindergarten | UW7: Primary Level | VC7: Transition | VE7: Kindergarten | VG7: Primary Level | VM7: Transition | VO7: Kindergarten | VQ7: Primary Level | VW7: Transition | VY7: Kindergarten | WA7: Primary Level | WG7: Transition | WI7: Kindergarten | WK7: Primary Level | WQ7: Transition | WS7: Kindergarten | WU7: Primary Level | XA7: Transition | XC7: Kindergarten | XE7: Primary Level | XK7: Transition | XM7: Kindergarten | XO7: Primary Level | XU7: Transition | XW7: Kindergarten | XY7: Primary Level | YE7: Transition | YG7: Kindergarten | YI7: Primary Level | YO7: Transition | YQ7: Kindergarten | YS7: Primary Level | YY7: Transition | ZA7: Kindergarten | ZC7: Primary Level | ZI7: Transition | ZK7: Kindergarten | ZM7: Primary Level | ZS7: Transition | ZU7: Kindergarten | ZW7: Primary Level | AAC7: Transition | AAE7: Kindergarten | AAG7: Primary Level | AAM7: Transition | AAO7: Kindergarten | AAQ7: Primary Level | AAW7: Transition | AAY7: Kindergarten | ABA7: Primary Level | ABG7: Transition | ABI7: Kindergarten | ABK7: Primary Level | ABQ7: Transition | ABW7: Visual Impairment | ACE7: Hearing Impairment | ACM7: Learning Disability | ACU7: Intellectual Disability | ADC7: Autism Spectrum Disorder | ADK7: Emotional-Behavioral Disorder | ADS7: Orthopedic / Physical Handicap | AEA7: Speech / Language Disorder | AEI7: Cerebral Palsy | AEQ7: Special Health Problem / Chronic Disease | AEY7: Multiple Disabilities | AFG7: Difficulty in Seeing | AFO7: Difficulty in Hearing | AFW7: Difficulty in Applying Knowledge | AGE7: Difficulty in Remembering, Concentrating, Paying Attention and Understanding | AGM7: Difficulty in Applying Adaptive Skills | AGU7: Difficulty in Displaying Inter-Personal Behavior | AHC7: Difficulty in Mobility (Walking, Climbing and Grasping) | AHK7: Difficulty in Communicating | AHW7: Visual Impairment | AIE7: Hearing Impairment | AIM7: Learning Disability | AIU7: Intellectual Disability | AJC7: Autism Spectrum Disorder | AJK7: Emotional-Behavioral Disorder | AJS7: Orthopedic / Physical Handicap | AKA7: Speech / Language Disorder | AKI7: Cerebral Palsy | AKQ7: Special Health Problem / Chronic Disease | AKY7: Multiple Disabilities | ALG7: Difficulty in Seeing | ALO7: Difficulty in Hearing | ALW7: Difficulty in Applying Knowledge | AME7: Difficulty in Remembering, Concentrating, Paying Attention and Understanding | AMM7: Difficulty in Applying Adaptive Skills | AMU7: Difficulty in Displaying Inter-Personal Behavior | ANC7: Difficulty in Mobility (Walking, Climbing and Grasping) | ANK7: Difficulty in Communicating | ANW7: Visual Impairment | AOA7: Hearing Impairment | AOE7: Learning Disability | AOI7: Intellectual Disability | AOM7: Autism Spectrum Disorder | AOQ7: Emotional-Behavioral Disorder | AOU7: Orthopedic/ Physical Handicap | AOY7: Speech / Language Disorder | APC7: Cerebral Palsy | APG7: Special Health Prob/ Chronic Disease | APK7: Multiple Disabilities | APO7: Dif. in Seein | APS7: Dif. in Hearing | APW7: Dif. in Applying Knowledge | AQA7: Dif. in Remembering, & CPAU | AQE7: Dif. in Applying Adaptive Skills | AQI7: Dif. in Disp. Inter-Personal Behavior | AQM7: Dif. in Mobility | AQQ7: Dif. in Communicating | AQU7: SHS Grand Total
Q8: Kindergarten | S8: Grade 1 | U8: Grade 2 | W8: Grade 3 | Y8: Grade 4 | AA8: Grade 5 | AC8: Grade 6 | AE8: Kindergarten | AG8: Grade 1 | AI8: Grade 2 | AK8: Grade 3 | AM8: Grade 4 | AO8: Grade 5 | AQ8: Grade 6 | AS8: Kindergarten | AU8: Grade 1 | AW8: Grade 2 | AY8: Grade 3 | BA8: Grade 4 | BC8: Grade 5 | BE8: Grade 6 | BG8: Kindergarten | BI8: Grade 1 | BK8: Grade 2 | BM8: Grade 3 | BO8: Grade 4 | BQ8: Grade 5 | BS8: Grade 6 | BU8: Kindergarten | BW8: Grade 1 | BY8: Grade 2 | CA8: Grade 3 | CC8: Grade 4 | CE8: Grade 5 | CG8: Grade 6 | CI8: Kindergarten | CK8: Grade 1 | CM8: Grade 2 | CO8: Grade 3 | CQ8: Grade 4 | CS8: Grade 5 | CU8: Grade 6 | CW8: Kindergarten | CY8: Grade 1 | DA8: Grade 2 | DC8: Grade 3 | DE8: Grade 4 | DG8: Grade 5 | DI8: Grade 6 | DK8: Kindergarten | DM8: Grade 1 | DO8: Grade 2 | DQ8: Grade 3 | DS8: Grade 4 | DU8: Grade 5 | DW8: Grade 6 | DY8: Kindergarten | EA8: Grade 1 | EC8: Grade 2 | EE8: Grade 3 | EG8: Grade 4 | EI8: Grade 5 | EK8: Grade 6 | EM8: Kindergarten | EO8: Grade 1 | EQ8: Grade 2 | ES8: Grade 3 | EU8: Grade 4 | EW8: Grade 5 | EY8: Grade 6 | FA8: Kindergarten | FC8: Grade 1 | FE8: Grade 2 | FG8: Grade 3 | FI8: Grade 4 | FK8: Grade 5 | FM8: Grade 6 | FO8: Kindergarten | FQ8: Grade 1 | FS8: Grade 2 | FU8: Grade 3 | FW8: Grade 4 | FY8: Grade 5 | GA8: Grade 6 | GC8: Kindergarten | GE8: Grade 1 | GG8: Grade 2 | GI8: Grade 3 | GK8: Grade 4 | GM8: Grade 5 | GO8: Grade 6 | GQ8: Kindergarten | GS8: Grade 1 | GU8: Grade 2 | GW8: Grade 3 | GY8: Grade 4 | HA8: Grade 5 | HC8: Grade 6 | HE8: Kindergarten | HG8: Grade 1 | HI8: Grade 2 | HK8: Grade 3 | HM8: Grade 4 | HO8: Grade 5 | HQ8: Grade 6 | HS8: Kindergarten | HU8: Grade 1 | HW8: Grade 2 | HY8: Grade 3 | IA8: Grade 4 | IC8: Grade 5 | IE8: Grade 6 | IG8: Kindergarten | II8: Grade 1 | IK8: Grade 2 | IM8: Grade 3 | IO8: Grade 4 | IQ8: Grade 5 | IS8: Grade 6 | IU8: Kindergarten | IW8: Grade 1 | IY8: Grade 2 | JA8: Grade 3 | JC8: Grade 4 | JE8: Grade 5 | JG8: Grade 6 | JI8: Kindergarten | JK8: Grade 1 | JM8: Grade 2 | JO8: Grade 3 | JQ8: Grade 4 | JS8: Grade 5 | JU8: Grade 6 | KA8: Kindergarten | KC8: Grade 1 | KE8: Grade 2 | KG8: Grade 3 | KI8: Grade 4 | KK8: Grade 5 | KM8: Grade 6 | KO8: Kindergarten | KQ8: Grade 1 | KS8: Grade 2 | KU8: Grade 3 | KW8: Grade 4 | KY8: Grade 5 | LA8: Grade 6 | LC8: Kindergarten | LE8: Grade 1 | LG8: Grade 2 | LI8: Grade 3 | LK8: Grade 4 | LM8: Grade 5 | LO8: Grade 6 | LQ8: Kindergarten | LS8: Grade 1 | LU8: Grade 2 | LW8: Grade 3 | LY8: Grade 4 | MA8: Grade 5 | MC8: Grade 6 | ME8: Kindergarten | MG8: Grade 1 | MI8: Grade 2 | MK8: Grade 3 | MM8: Grade 4 | MO8: Grade 5 | MQ8: Grade 6 | MS8: Kindergarten | MU8: Grade 1 | MW8: Grade 2 | MY8: Grade 3 | NA8: Grade 4 | NC8: Grade 5 | NE8: Grade 6 | NG8: Kindergarten | NI8: Grade 1 | NK8: Grade 2 | NM8: Grade 3 | NO8: Grade 4 | NQ8: Grade 5 | NS8: Grade 6 | NU8: Kindergarten | NW8: Grade 1 | NY8: Grade 2 | OA8: Grade 3 | OC8: Grade 4 | OE8: Grade 5 | OG8: Grade 6 | OI8: Kindergarten | OK8: Grade 1 | OM8: Grade 2 | OO8: Grade 3 | OQ8: Grade 4 | OS8: Grade 5 | OU8: Grade 6 | OW8: Kindergarten | OY8: Grade 1 | PA8: Grade 2 | PC8: Grade 3 | PE8: Grade 4 | PG8: Grade 5 | PI8: Grade 6 | PK8: Kindergarten | PM8: Grade 1 | PO8: Grade 2 | PQ8: Grade 3 | PS8: Grade 4 | PU8: Grade 5 | PW8: Grade 6 | PY8: Kindergarten | QA8: Grade 1 | QC8: Grade 2 | QE8: Grade 3 | QG8: Grade 4 | QI8: Grade 5 | QK8: Grade 6 | QM8: Kindergarten | QO8: Grade 1 | QQ8: Grade 2 | QS8: Grade 3 | QU8: Grade 4 | QW8: Grade 5 | QY8: Grade 6 | RA8: Kindergarten | RC8: Grade 1 | RE8: Grade 2 | RG8: Grade 3 | RI8: Grade 4 | RK8: Grade 5 | RM8: Grade 6 | RO8: Kindergarten | RQ8: Grade 1 | RS8: Grade 2 | RU8: Grade 3 | RW8: Grade 4 | RY8: Grade 5 | SA8: Grade 6 | SC8: Kindergarten | SE8: Grade 1 | SG8: Grade 2 | SI8: Grade 3 | SK8: Grade 4 | SM8: Grade 5 | SO8: Grade 6 | SQ8: Kindergarten | SS8: Grade 1 | SU8: Grade 2 | SW8: Grade 3 | SY8: Grade 4 | TA8: Grade 5 | TC8: Grade 6 | TE8: Kindergarten | TG8: Grade 1 | TI8: Grade 2 | TK8: Grade 3 | TM8: Grade 4 | TO8: Grade 5 | TQ8: Grade 6 | TS8: Kindergarten | TU8: Grade 1 | TW8: Grade 2 | TY8: Grade 3 | UA8: Grade 4 | UC8: Grade 5 | UE8: Grade 6 | UM8: Level I | UO8: Level II | UQ8: Level III | UW8: Level I | UY8: Level II | VA8: Level III | VG8: Level I | VI8: Level II | VK8: Level III | VQ8: Level I | VS8: Level II | VU8: Level III | WA8: Level I | WC8: Level II | WE8: Level III | WK8: Level I | WM8: Level II | WO8: Level III | WU8: Level I | WW8: Level II | WY8: Level III | XE8: Level I | XG8: Level II | XI8: Level III | XO8: Level I | XQ8: Level II | XS8: Level III | XY8: Level I | YA8: Level II | YC8: Level III | YI8: Level I | YK8: Level II | YM8: Level III | YS8: Level I | YU8: Level II | YW8: Level III | ZC8: Level I | ZE8: Level II | ZG8: Level III | ZM8: Level I | ZO8: Level II | ZQ8: Level III | ZW8: Level I | ZY8: Level II | AAA8: Level III | AAG8: Level I | AAI8: Level II | AAK8: Level III | AAQ8: Level I | AAS8: Level II | AAU8: Level III | ABA8: Level I | ABC8: Level II | ABE8: Level III | ABK8: Level I | ABM8: Level II | ABO8: Level III | ABW8: Grade 7 | ABY8: Grade 8 | ACA8: Grade 9 | ACC8: Grade 10 | ACE8: Grade 7 | ACG8: Grade 8 | ACI8: Grade 9 | ACK8: Grade 10 | ACM8: Grade 7 | ACO8: Grade 8 | ACQ8: Grade 9 | ACS8: Grade 10 | ACU8: Grade 7 | ACW8: Grade 8 | ACY8: Grade 9 | ADA8: Grade 10 | ADC8: Grade 7 | ADE8: Grade 8 | ADG8: Grade 9 | ADI8: Grade 10 | ADK8: Grade 7 | ADM8: Grade 8 | ADO8: Grade 9 | ADQ8: Grade 10 | ADS8: Grade 7 | ADU8: Grade 8 | ADW8: Grade 9 | ADY8: Grade 10 | AEA8: Grade 7 | AEC8: Grade 8 | AEE8: Grade 9 | AEG8: Grade 10 | AEI8: Grade 7 | AEK8: Grade 8 | AEM8: Grade 9 | AEO8: Grade 10 | AEQ8: Grade 7 | AES8: Grade 8 | AEU8: Grade 9 | AEW8: Grade 10 | AEY8: Grade 7 | AFA8: Grade 8 | AFC8: Grade 9 | AFE8: Grade 10 | AFG8: Grade 7 | AFI8: Grade 8 | AFK8: Grade 9 | AFM8: Grade 10 | AFO8: Grade 7 | AFQ8: Grade 8 | AFS8: Grade 9 | AFU8: Grade 10 | AFW8: Grade 7 | AFY8: Grade 8 | AGA8: Grade 9 | AGC8: Grade 10 | AGE8: Grade 7 | AGG8: Grade 8 | AGI8: Grade 9 | AGK8: Grade 10 | AGM8: Grade 7 | AGO8: Grade 8 | AGQ8: Grade 9 | AGS8: Grade 10 | AGU8: Grade 7 | AGW8: Grade 8 | AGY8: Grade 9 | AHA8: Grade 10 | AHC8: Grade 7 | AHE8: Grade 8 | AHG8: Grade 9 | AHI8: Grade 10 | AHK8: Grade 7 | AHM8: Grade 8 | AHO8: Grade 9 | AHQ8: Grade 10 | AHW8: Grade 7 | AHY8: Grade 8 | AIA8: Grade 9 | AIC8: Grade 10 | AIE8: Grade 7 | AIG8: Grade 8 | AII8: Grade 9 | AIK8: Grade 10 | AIM8: Grade 7 | AIO8: Grade 8 | AIQ8: Grade 9 | AIS8: Grade 10 | AIU8: Grade 7 | AIW8: Grade 8 | AIY8: Grade 9 | AJA8: Grade 10 | AJC8: Grade 7 | AJE8: Grade 8 | AJG8: Grade 9 | AJI8: Grade 10 | AJK8: Grade 7 | AJM8: Grade 8 | AJO8: Grade 9 | AJQ8: Grade 10 | AJS8: Grade 7 | AJU8: Grade 8 | AJW8: Grade 9 | AJY8: Grade 10 | AKA8: Grade 7 | AKC8: Grade 8 | AKE8: Grade 9 | AKG8: Grade 10 | AKI8: Grade 7 | AKK8: Grade 8 | AKM8: Grade 9 | AKO8: Grade 10 | AKQ8: Grade 7 | AKS8: Grade 8 | AKU8: Grade 9 | AKW8: Grade 10 | AKY8: Grade 7 | ALA8: Grade 8 | ALC8: Grade 9 | ALE8: Grade 10 | ALG8: Grade 7 | ALI8: Grade 8 | ALK8: Grade 9 | ALM8: Grade 10 | ALO8: Grade 7 | ALQ8: Grade 8 | ALS8: Grade 9 | ALU8: Grade 10 | ALW8: Grade 7 | ALY8: Grade 8 | AMA8: Grade 9 | AMC8: Grade 10 | AME8: Grade 7 | AMG8: Grade 8 | AMI8: Grade 9 | AMK8: Grade 10 | AMM8: Grade 7 | AMO8: Grade 8 | AMQ8: Grade 9 | AMS8: Grade 10 | AMU8: Grade 7 | AMW8: Grade 8 | AMY8: Grade 9 | ANA8: Grade 10 | ANC8: Grade 7 | ANE8: Grade 8 | ANG8: Grade 9 | ANI8: Grade 10 | ANK8: Grade 7 | ANM8: Grade 8 | ANO8: Grade 9 | ANQ8: Grade 10 | ANW8: Grade 11 | ANY8: Grade 12 | AOA8: Grade 11 | AOC8: Grade 12 | AOE8: Grade 11 | AOG8: Grade 12 | AOI8: Grade 11 | AOK8: Grade 12 | AOM8: Grade 11 | AOO8: Grade 12 | AOQ8: Grade 11 | AOS8: Grade 12 | AOU8: Grade 11 | AOW8: Grade 12 | AOY8: Grade 11 | APA8: Grade 12 | APC8: Grade 11 | APE8: Grade 12 | APG8: Grade 11 | API8: Grade 12 | APK8: Grade 11 | APM8: Grade 12 | APO8: Grade 11 | APQ8: Grade 12 | APS8: Grade 11 | APU8: Grade 12 | APW8: Grade 11 | APY8: Grade 12 | AQA8: Grade 11 | AQC8: Grade 12 | AQE8: Grade 11 | AQG8: Grade 12 | AQI8: Grade 11 | AQK8: Grade 12 | AQM8: Grade 11 | AQO8: Grade 12 | AQQ8: Grade 11 | AQS8: Grade 12 | AQU8: Grade 11 | AQW8: Grade 12 | AQY8: Grand Total
Q9: Male | R9: Female | S9: Male | T9: Female | U9: Male | V9: Female | W9: Male | X9: Female | Y9: Male | Z9: Female | AA9: Male | AB9: Female | AC9: Male | AD9: Female | AE9: Male | AF9: Female | AG9: Male | AH9: Female | AI9: Male | AJ9: Female | AK9: Male | AL9: Female | AM9: Male | AN9: Female | AO9: Male | AP9: Female | AQ9: Male | AR9: Female | AS9: Male | AT9: Female | AU9: Male | AV9: Female | AW9: Male | AX9: Female | AY9: Male | AZ9: Female | BA9: Male | BB9: Female | BC9: Male | BD9: Female | BE9: Male | BF9: Female | BG9: Male | BH9: Female | BI9: Male | BJ9: Female | BK9: Male | BL9: Female | BM9: Male | BN9: Female | BO9: Male | BP9: Female | BQ9: Male | BR9: Female | BS9: Male | BT9: Female | BU9: Male | BV9: Female | BW9: Male | BX9: Female | BY9: Male | BZ9: Female | CA9: Male | CB9: Female | CC9: Male | CD9: Female | CE9: Male | CF9: Female | CG9: Male | CH9: Female | CI9: Male | CJ9: Female | CK9: Male | CL9: Female | CM9: Male | CN9: Female | CO9: Male | CP9: Female | CQ9: Male | CR9: Female | CS9: Male | CT9: Female | CU9: Male | CV9: Female | CW9: Male | CX9: Female | CY9: Male | CZ9: Female | DA9: Male | DB9: Female | DC9: Male | DD9: Female | DE9: Male | DF9: Female | DG9: Male | DH9: Female | DI9: Male | DJ9: Female | DK9: Male | DL9: Female | DM9: Male | DN9: Female | DO9: Male | DP9: Female | DQ9: Male | DR9: Female | DS9: Male | DT9: Female | DU9: Male | DV9: Female | DW9: Male | DX9: Female | DY9: Male | DZ9: Female | EA9: Male | EB9: Female | EC9: Male | ED9: Female | EE9: Male | EF9: Female | EG9: Male | EH9: Female | EI9: Male | EJ9: Female | EK9: Male | EL9: Female | EM9: Male | EN9: Female | EO9: Male | EP9: Female | EQ9: Male | ER9: Female | ES9: Male | ET9: Female | EU9: Male | EV9: Female | EW9: Male | EX9: Female | EY9: Male | EZ9: Female | FA9: Male | FB9: Female | FC9: Male | FD9: Female | FE9: Male | FF9: Female | FG9: Male | FH9: Female | FI9: Male | FJ9: Female | FK9: Male | FL9: Female | FM9: Male | FN9: Female | FO9: Male | FP9: Female | FQ9: Male | FR9: Female | FS9: Male | FT9: Female | FU9: Male | FV9: Female | FW9: Male | FX9: Female | FY9: Male | FZ9: Female | GA9: Male | GB9: Female | GC9: Male | GD9: Female | GE9: Male | GF9: Female | GG9: Male | GH9: Female | GI9: Male | GJ9: Female | GK9: Male | GL9: Female | GM9: Male | GN9: Female | GO9: Male | GP9: Female | GQ9: Male | GR9: Female | GS9: Male | GT9: Female | GU9: Male | GV9: Female | GW9: Male | GX9: Female | GY9: Male | GZ9: Female | HA9: Male | HB9: Female | HC9: Male | HD9: Female | HE9: Male | HF9: Female | HG9: Male | HH9: Female | HI9: Male | HJ9: Female | HK9: Male | HL9: Female | HM9: Male | HN9: Female | HO9: Male | HP9: Female | HQ9: Male | HR9: Female | HS9: Male | HT9: Female | HU9: Male | HV9: Female | HW9: Male | HX9: Female | HY9: Male | HZ9: Female | IA9: Male | IB9: Female | IC9: Male | ID9: Female | IE9: Male | IF9: Female | IG9: Male | IH9: Female | II9: Male | IJ9: Female | IK9: Male | IL9: Female | IM9: Male | IN9: Female | IO9: Male | IP9: Female | IQ9: Male | IR9: Female | IS9: Male | IT9: Female | IU9: Male | IV9: Female | IW9: Male | IX9: Female | IY9: Male | IZ9: Female | JA9: Male | JB9: Female | JC9: Male | JD9: Female | JE9: Male | JF9: Female | JG9: Male | JH9: Female | JI9: Male | JJ9: Female | JK9: Male | JL9: Female | JM9: Male | JN9: Female | JO9: Male | JP9: Female | JQ9: Male | JR9: Female | JS9: Male | JT9: Female | JU9: Male | JV9: Female | KA9: Male | KB9: Female | KC9: Male | KD9: Female | KE9: Male | KF9: Female | KG9: Male | KH9: Female | KI9: Male | KJ9: Female | KK9: Male | KL9: Female | KM9: Male | KN9: Female | KO9: Male | KP9: Female | KQ9: Male | KR9: Female | KS9: Male | KT9: Female | KU9: Male | KV9: Female | KW9: Male | KX9: Female | KY9: Male | KZ9: Female | LA9: Male | LB9: Female | LC9: Male | LD9: Female | LE9: Male | LF9: Female | LG9: Male | LH9: Female | LI9: Male | LJ9: Female | LK9: Male | LL9: Female | LM9: Male | LN9: Female | LO9: Male | LP9: Female | LQ9: Male | LR9: Female | LS9: Male | LT9: Female | LU9: Male | LV9: Female | LW9: Male | LX9: Female | LY9: Male | LZ9: Female | MA9: Male | MB9: Female | MC9: Male | MD9: Female | ME9: Male | MF9: Female | MG9: Male | MH9: Female | MI9: Male | MJ9: Female | MK9: Male | ML9: Female | MM9: Male | MN9: Female | MO9: Male | MP9: Female | MQ9: Male | MR9: Female | MS9: Male | MT9: Female | MU9: Male | MV9: Female | MW9: Male | MX9: Female | MY9: Male | MZ9: Female | NA9: Male | NB9: Female | NC9: Male | ND9: Female | NE9: Male | NF9: Female | NG9: Male | NH9: Female | NI9: Male | NJ9: Female | NK9: Male | NL9: Female | NM9: Male | NN9: Female | NO9: Male | NP9: Female | NQ9: Male | NR9: Female | NS9: Male | NT9: Female | NU9: Male | NV9: Female | NW9: Male | NX9: Female | NY9: Male | NZ9: Female | OA9: Male | OB9: Female | OC9: Male | OD9: Female | OE9: Male | OF9: Female | OG9: Male | OH9: Female | OI9: Male | OJ9: Female | OK9: Male | OL9: Female | OM9: Male | ON9: Female | OO9: Male | OP9: Female | OQ9: Male | OR9: Female | OS9: Male | OT9: Female | OU9: Male | OV9: Female | OW9: Male | OX9: Female | OY9: Male | OZ9: Female | PA9: Male | PB9: Female | PC9: Male | PD9: Female | PE9: Male | PF9: Female | PG9: Male | PH9: Female | PI9: Male | PJ9: Female | PK9: Male | PL9: Female | PM9: Male | PN9: Female | PO9: Male | PP9: Female | PQ9: Male | PR9: Female | PS9: Male | PT9: Female | PU9: Male | PV9: Female | PW9: Male | PX9: Female | PY9: Male | PZ9: Female | QA9: Male | QB9: Female | QC9: Male | QD9: Female | QE9: Male | QF9: Female | QG9: Male | QH9: Female | QI9: Male | QJ9: Female | QK9: Male | QL9: Female | QM9: Male | QN9: Female | QO9: Male | QP9: Female | QQ9: Male | QR9: Female | QS9: Male | QT9: Female | QU9: Male | QV9: Female | QW9: Male | QX9: Female | QY9: Male | QZ9: Female | RA9: Male | RB9: Female | RC9: Male | RD9: Female | RE9: Male | RF9: Female | RG9: Male | RH9: Female | RI9: Male | RJ9: Female | RK9: Male | RL9: Female | RM9: Male | RN9: Female | RO9: Male | RP9: Female | RQ9: Male | RR9: Female | RS9: Male | RT9: Female | RU9: Male | RV9: Female | RW9: Male | RX9: Female | RY9: Male | RZ9: Female | SA9: Male | SB9: Female | SC9: Male | SD9: Female | SE9: Male | SF9: Female | SG9: Male | SH9: Female | SI9: Male | SJ9: Female | SK9: Male | SL9: Female | SM9: Male | SN9: Female | SO9: Male | SP9: Female | SQ9: Male | SR9: Female | SS9: Male | ST9: Female | SU9: Male | SV9: Female | SW9: Male | SX9: Female | SY9: Male | SZ9: Female | TA9: Male | TB9: Female | TC9: Male | TD9: Female | TE9: Male | TF9: Female | TG9: Male | TH9: Female | TI9: Male | TJ9: Female | TK9: Male | TL9: Female | TM9: Male | TN9: Female | TO9: Male | TP9: Female | TQ9: Male | TR9: Female | TS9: Male | TT9: Female | TU9: Male | TV9: Female | TW9: Male | TX9: Female | TY9: Male | TZ9: Female | UA9: Male | UB9: Female | UC9: Male | UD9: Female | UE9: Male | UF9: Female | UG9: Male | UH9: Female | UI9: Total | UK9: Male | UL9: Female | UM9: Male | UN9: Female | UO9: Male | UP9: Female | UQ9: Male | UR9: Female | US9: Male | UT9: Female | UU9: Male | UV9: Female | UW9: Male | UX9: Female | UY9: Male | UZ9: Female | VA9: Male | VB9: Female | VC9: Male | VD9: Female | VE9: Male | VF9: Female | VG9: Male | VH9: Female | VI9: Male | VJ9: Female | VK9: Male | VL9: Female | VM9: Male | VN9: Female | VO9: Male | VP9: Female | VQ9: Male | VR9: Female | VS9: Male | VT9: Female | VU9: Male | VV9: Female | VW9: Male | VX9: Female | VY9: Male | VZ9: Female | WA9: Male | WB9: Female | WC9: Male | WD9: Female | WE9: Male | WF9: Female | WG9: Male | WH9: Female | WI9: Male | WJ9: Female | WK9: Male | WL9: Female | WM9: Male | WN9: Female | WO9: Male | WP9: Female | WQ9: Male | WR9: Female | WS9: Male | WT9: Female | WU9: Male | WV9: Female | WW9: Male | WX9: Female | WY9: Male | WZ9: Female | XA9: Male | XB9: Female | XC9: Male | XD9: Female | XE9: Male | XF9: Female | XG9: Male | XH9: Female | XI9: Male | XJ9: Female | XK9: Male | XL9: Female | XM9: Male | XN9: Female | XO9: Male | XP9: Female | XQ9: Male | XR9: Female | XS9: Male | XT9: Female | XU9: Male | XV9: Female | XW9: Male | XX9: Female | XY9: Male | XZ9: Female | YA9: Male | YB9: Female | YC9: Male | YD9: Female | YE9: Male | YF9: Female | YG9: Male | YH9: Female | YI9: Male | YJ9: Female | YK9: Male | YL9: Female | YM9: Male | YN9: Female | YO9: Male | YP9: Female | YQ9: Male | YR9: Female | YS9: Male | YT9: Female | YU9: Male | YV9: Female | YW9: Male | YX9: Female | YY9: Male | YZ9: Female | ZA9: Male | ZB9: Female | ZC9: Male | ZD9: Female | ZE9: Male | ZF9: Female | ZG9: Male | ZH9: Female | ZI9: Male | ZJ9: Female | ZK9: Male | ZL9: Female | ZM9: Male | ZN9: Female | ZO9: Male | ZP9: Female | ZQ9: Male | ZR9: Female | ZS9: Male | ZT9: Female | ZU9: Male | ZV9: Female | ZW9: Male | ZX9: Female | ZY9: Male | ZZ9: Female | AAA9: Male | AAB9: Female | AAC9: Male | AAD9: Female | AAE9: Male | AAF9: Female | AAG9: Male | AAH9: Female | AAI9: Male | AAJ9: Female | AAK9: Male | AAL9: Female | AAM9: Male | AAN9: Female | AAO9: Male | AAP9: Female | AAQ9: Male | AAR9: Female | AAS9: Male | AAT9: Female | AAU9: Male | AAV9: Female | AAW9: Male | AAX9: Female | AAY9: Male | AAZ9: Female | ABA9: Male | ABB9: Female | ABC9: Male | ABD9: Female | ABE9: Male | ABF9: Female | ABG9: Male | ABH9: Female | ABI9: Male | ABJ9: Female | ABK9: Male | ABL9: Female | ABM9: Male | ABN9: Female | ABO9: Male | ABP9: Female | ABQ9: Male | ABR9: Female | ABS9: Male | ABT9: Female | ABU9: Total | ABW9: Male | ABX9: Female | ABY9: Male | ABZ9: Female | ACA9: Male | ACB9: Female | ACC9: Male | ACD9: Female | ACE9: Male | ACF9: Female | ACG9: Male | ACH9: Female | ACI9: Male | ACJ9: Female | ACK9: Male | ACL9: Female | ACM9: Male | ACN9: Female | ACO9: Male | ACP9: Female | ACQ9: Male | ACR9: Female | ACS9: Male | ACT9: Female | ACU9: Male | ACV9: Female | ACW9: Male | ACX9: Female | ACY9: Male | ACZ9: Female | ADA9: Male | ADB9: Female | ADC9: Male | ADD9: Female | ADE9: Male | ADF9: Female | ADG9: Male | ADH9: Female | ADI9: Male | ADJ9: Female | ADK9: Male | ADL9: Female | ADM9: Male | ADN9: Female | ADO9: Male | ADP9: Female | ADQ9: Male | ADR9: Female | ADS9: Male | ADT9: Female | ADU9: Male | ADV9: Female | ADW9: Male | ADX9: Female | ADY9: Male | ADZ9: Female | AEA9: Male | AEB9: Female | AEC9: Male | AED9: Female | AEE9: Male | AEF9: Female | AEG9: Male | AEH9: Female | AEI9: Male | AEJ9: Female | AEK9: Male | AEL9: Female | AEM9: Male | AEN9: Female | AEO9: Male | AEP9: Female | AEQ9: Male | AER9: Female | AES9: Male | AET9: Female | AEU9: Male | AEV9: Female | AEW9: Male | AEX9: Female | AEY9: Male | AEZ9: Female | AFA9: Male | AFB9: Female | AFC9: Male | AFD9: Female | AFE9: Male | AFF9: Female | AFG9: Male | AFH9: Female | AFI9: Male | AFJ9: Female | AFK9: Male | AFL9: Female | AFM9: Male | AFN9: Female | AFO9: Male | AFP9: Female | AFQ9: Male | AFR9: Female | AFS9: Male | AFT9: Female | AFU9: Male | AFV9: Female | AFW9: Male | AFX9: Female | AFY9: Male | AFZ9: Female | AGA9: Male | AGB9: Female | AGC9: Male | AGD9: Female | AGE9: Male | AGF9: Female | AGG9: Male | AGH9: Female | AGI9: Male | AGJ9: Female | AGK9: Male | AGL9: Female | AGM9: Male | AGN9: Female | AGO9: Male | AGP9: Female | AGQ9: Male | AGR9: Female | AGS9: Male | AGT9: Female | AGU9: Male | AGV9: Female | AGW9: Male | AGX9: Female | AGY9: Male | AGZ9: Female | AHA9: Male | AHB9: Female | AHC9: Male | AHD9: Female | AHE9: Male | AHF9: Female | AHG9: Male | AHH9: Female | AHI9: Male | AHJ9: Female | AHK9: Male | AHL9: Female | AHM9: Male | AHN9: Female | AHO9: Male | AHP9: Female | AHQ9: Male | AHR9: Female | AHS9: Male | AHT9: Female | AHU9: Total | AHW9: Male | AHX9: Female | AHY9: Male | AHZ9: Female | AIA9: Male | AIB9: Female | AIC9: Male | AID9: Female | AIE9: Male | AIF9: Female | AIG9: Male | AIH9: Female | AII9: Male | AIJ9: Female | AIK9: Male | AIL9: Female | AIM9: Male | AIN9: Female | AIO9: Male | AIP9: Female | AIQ9: Male | AIR9: Female | AIS9: Male | AIT9: Female | AIU9: Male | AIV9: Female | AIW9: Male | AIX9: Female | AIY9: Male | AIZ9: Female | AJA9: Male | AJB9: Female | AJC9: Male | AJD9: Female | AJE9: Male | AJF9: Female | AJG9: Male | AJH9: Female | AJI9: Male | AJJ9: Female | AJK9: Male | AJL9: Female | AJM9: Male | AJN9: Female | AJO9: Male | AJP9: Female | AJQ9: Male | AJR9: Female | AJS9: Male | AJT9: Female | AJU9: Male | AJV9: Female | AJW9: Male | AJX9: Female | AJY9: Male | AJZ9: Female | AKA9: Male | AKB9: Female | AKC9: Male | AKD9: Female | AKE9: Male | AKF9: Female | AKG9: Male | AKH9: Female | AKI9: Male | AKJ9: Female | AKK9: Male | AKL9: Female | AKM9: Male | AKN9: Female | AKO9: Male | AKP9: Female | AKQ9: Male | AKR9: Female | AKS9: Male | AKT9: Female | AKU9: Male | AKV9: Female | AKW9: Male | AKX9: Female | AKY9: Male | AKZ9: Female | ALA9: Male | ALB9: Female | ALC9: Male | ALD9: Female | ALE9: Male | ALF9: Female | ALG9: Male | ALH9: Female | ALI9: Male | ALJ9: Female | ALK9: Male | ALL9: Female | ALM9: Male | ALN9: Female | ALO9: Male | ALP9: Female | ALQ9: Male | ALR9: Female | ALS9: Male | ALT9: Female | ALU9: Male | ALV9: Female | ALW9: Male | ALX9: Female | ALY9: Male | ALZ9: Female | AMA9: Male | AMB9: Female | AMC9: Male | AMD9: Female | AME9: Male | AMF9: Female | AMG9: Male | AMH9: Female | AMI9: Male | AMJ9: Female | AMK9: Male | AML9: Female | AMM9: Male | AMN9: Female | AMO9: Male | AMP9: Female | AMQ9: Male | AMR9: Female | AMS9: Male | AMT9: Female | AMU9: Male | AMV9: Female | AMW9: Male | AMX9: Female | AMY9: Male | AMZ9: Female | ANA9: Male | ANB9: Female | ANC9: Male | AND9: Female | ANE9: Male | ANF9: Female | ANG9: Male | ANH9: Female | ANI9: Male | ANJ9: Female | ANK9: Male | ANL9: Female | ANM9: Male | ANN9: Female | ANO9: Male | ANP9: Female | ANQ9: Male | ANR9: Female | ANS9: Male | ANT9: Female | ANU9: Total | ANW9: Male | ANX9: Female | ANY9: Male | ANZ9: Female | AOA9: Male | AOB9: Female | AOC9: Male | AOD9: Female | AOE9: Male | AOF9: Female | AOG9: Male | AOH9: Female | AOI9: Male | AOJ9: Female | AOK9: Male | AOL9: Female | AOM9: Male | AON9: Female | AOO9: Male | AOP9: Female | AOQ9: Male | AOR9: Female | AOS9: Male | AOT9: Female | AOU9: Male | AOV9: Female | AOW9: Male | AOX9: Female | AOY9: Male | AOZ9: Female | APA9: Male | APB9: Female | APC9: Male | APD9: Female | APE9: Male | APF9: Female | APG9: Male | APH9: Female | API9: Male | APJ9: Female | APK9: Male | APL9: Female | APM9: Male | APN9: Female | APO9: Male | APP9: Female | APQ9: Male | APR9: Female | APS9: Male | APT9: Female | APU9: Male | APV9: Female | APW9: Male | APX9: Female | APY9: Male | APZ9: Female | AQA9: Male | AQB9: Female | AQC9: Male | AQD9: Female | AQE9: Male | AQF9: Female | AQG9: Male | AQH9: Female | AQI9: Male | AQJ9: Female | AQK9: Male | AQL9: Female | AQM9: Male | AQN9: Female | AQO9: Male | AQP9: Female | AQQ9: Male | AQR9: Female | AQS9: Male | AQT9: Female | AQU9: Male | AQV9: Female | AQW9: Male | AQX9: Female | AQY9: Male | AQZ9: Female | ARA9: Total
Q10: VI | R10: VI | S10: VI | T10: VI | U10: VI | V10: VI | W10: VI | X10: VI | Y10: VI | Z10: VI | AA10: VI | AB10: VI | AC10: VI | AD10: VI | AE10: HI | AF10: HI | AG10: HI | AH10: HI | AI10: HI | AJ10: HI | AK10: HI | AL10: HI | AM10: HI | AN10: HI | AO10: HI | AP10: HI | AQ10: HI | AR10: HI | AS10: LD | AT10: LD | AU10: LD | AV10: LD | AW10: LD | AX10: LD | AY10: LD | AZ10: LD | BA10: LD | BB10: LD | BC10: LD | BD10: LD | BE10: LD | BF10: LD | BG10: ID | BH10: ID | BI10: ID | BJ10: ID | BK10: ID | BL10: ID | BM10: ID | BN10: ID | BO10: ID | BP10: ID | BQ10: ID | BR10: ID | BS10: ID | BT10: ID | BU10: ASD | BV10: ASD | BW10: ASD | BX10: ASD | BY10: ASD | BZ10: ASD | CA10: ASD | CB10: ASD | CC10: ASD | CD10: ASD | CE10: ASD | CF10: ASD | CG10: ASD | CH10: ASD | CI10: EBD | CJ10: EBD | CK10: EBD | CL10: EBD | CM10: EBD | CN10: EBD | CO10: EBD | CP10: EBD | CQ10: EBD | CR10: EBD | CS10: EBD | CT10: EBD | CU10: EBD | CV10: EBD | CW10: OrthoPH | CX10: OrthoPH | CY10: OrthoPH | CZ10: OrthoPH | DA10: OrthoPH | DB10: OrthoPH | DC10: OrthoPH | DD10: OrthoPH | DE10: OrthoPH | DF10: OrthoPH | DG10: OrthoPH | DH10: OrthoPH | DI10: OrthoPH | DJ10: OrthoPH | DK10: LanD | DL10: LanD | DM10: LanD | DN10: LanD | DO10: LanD | DP10: LanD | DQ10: LanD | DR10: LanD | DS10: LanD | DT10: LanD | DU10: LanD | DV10: LanD | DW10: LanD | DX10: LanD | DY10: CP | DZ10: CP | EA10: CP | EB10: CP | EC10: CP | ED10: CP | EE10: CP | EF10: CP | EG10: CP | EH10: CP | EI10: CP | EJ10: CP | EK10: CP | EL10: CP | EM10: Chronic | EN10: Chronic | EO10: Chronic | EP10: Chronic | EQ10: Chronic | ER10: Chronic | ES10: Chronic | ET10: Chronic | EU10: Chronic | EV10: Chronic | EW10: Chronic | EX10: Chronic | EY10: Chronic | EZ10: Chronic | FA10: MultiD | FB10: MultiD | FC10: MultiD | FD10: MultiD | FE10: MultiD | FF10: MultiD | FG10: MultiD | FH10: MultiD | FI10: MultiD | FJ10: MultiD | FK10: MultiD | FL10: MultiD | FM10: MultiD | FN10: MultiD | FO10: Diff.See | FP10: Diff.See | FQ10: Diff.See | FR10: Diff.See | FS10: Diff.See | FT10: Diff.See | FU10: Diff.See | FV10: Diff.See | FW10: Diff.See | FX10: Diff.See | FY10: Diff.See | FZ10: Diff.See | GA10: Diff.See | GB10: Diff.See | GC10: Diff.Hear | GD10: Diff.Hear | GE10: Diff.Hear | GF10: Diff.Hear | GG10: Diff.Hear | GH10: Diff.Hear | GI10: Diff.Hear | GJ10: Diff.Hear | GK10: Diff.Hear | GL10: Diff.Hear | GM10: Diff.Hear | GN10: Diff.Hear | GO10: Diff.Hear | GP10: Diff.Hear | GQ10: Diff.Know | GR10: Diff.Know | GS10: Diff.Know | GT10: Diff.Know | GU10: Diff.Know | GV10: Diff.Know | GW10: Diff.Know | GX10: Diff.Know | GY10: Diff.Know | GZ10: Diff.Know | HA10: Diff.Know | HB10: Diff.Know | HC10: Diff.Know | HD10: Diff.Know | HE10: Diff.RCPAU | HF10: Diff.RCPAU | HG10: Diff.RCPAU | HH10: Diff.RCPAU | HI10: Diff.RCPAU | HJ10: Diff.RCPAU | HK10: Diff.RCPAU | HL10: Diff.RCPAU | HM10: Diff.RCPAU | HN10: Diff.RCPAU | HO10: Diff.RCPAU | HP10: Diff.RCPAU | HQ10: Diff.RCPAU | HR10: Diff.RCPAU | HS10: Dif.AAS | HT10: Dif.AAS | HU10: Dif.AAS | HV10: Dif.AAS | HW10: Dif.AAS | HX10: Dif.AAS | HY10: Dif.AAS | HZ10: Dif.AAS | IA10: Dif.AAS | IB10: Dif.AAS | IC10: Dif.AAS | ID10: Dif.AAS | IE10: Dif.AAS | IF10: Dif.AAS | IG10: Diff.DIPB | IH10: Diff.DIPB | II10: Diff.DIPB | IJ10: Diff.DIPB | IK10: Diff.DIPB | IL10: Diff.DIPB | IM10: Diff.DIPB | IN10: Diff.DIPB | IO10: Diff.DIPB | IP10: Diff.DIPB | IQ10: Diff.DIPB | IR10: Diff.DIPB | IS10: Diff.DIPB | IT10: Diff.DIPB | IU10: Diff.Mob | IV10: Diff.Mob | IW10: Diff.Mob | IX10: Diff.Mob | IY10: Diff.Mob | IZ10: Diff.Mob | JA10: Diff.Mob | JB10: Diff.Mob | JC10: Diff.Mob | JD10: Diff.Mob | JE10: Diff.Mob | JF10: Diff.Mob | JG10: Diff.Mob | JH10: Diff.Mob | JI10: Diff.Com | JJ10: Diff.Com | JK10: Diff.Com | JL10: Diff.Com | JM10: Diff.Com | JN10: Diff.Com | JO10: Diff.Com | JP10: Diff.Com | JQ10: Diff.Com | JR10: Diff.Com | JS10: Diff.Com | JT10: Diff.Com | JU10: Diff.Com | JV10: Diff.Com | JW10: Male | JX10: Female | JY10: Total | KA10: VI | KB10: VI | KC10: VI | KD10: VI | KE10: VI | KF10: VI | KG10: VI | KH10: VI | KI10: VI | KJ10: VI | KK10: VI | KL10: VI | KM10: VI | KN10: VI | KO10: HI | KP10: HI | KQ10: HI | KR10: HI | KS10: HI | KT10: HI | KU10: HI | KV10: HI | KW10: HI | KX10: HI | KY10: HI | KZ10: HI | LA10: HI | LB10: HI | LC10: LD | LD10: LD | LE10: LD | LF10: LD | LG10: LD | LH10: LD | LI10: LD | LJ10: LD | LK10: LD | LL10: LD | LM10: LD | LN10: LD | LO10: LD | LP10: LD | LQ10: ID | LR10: ID | LS10: ID | LT10: ID | LU10: ID | LV10: ID | LW10: ID | LX10: ID | LY10: ID | LZ10: ID | MA10: ID | MB10: ID | MC10: ID | MD10: ID | ME10: ASD | MF10: ASD | MG10: ASD | MH10: ASD | MI10: ASD | MJ10: ASD | MK10: ASD | ML10: ASD | MM10: ASD | MN10: ASD | MO10: ASD | MP10: ASD | MQ10: ASD | MR10: ASD | MS10: EBD | MT10: EBD | MU10: EBD | MV10: EBD | MW10: EBD | MX10: EBD | MY10: EBD | MZ10: EBD | NA10: EBD | NB10: EBD | NC10: EBD | ND10: EBD | NE10: EBD | NF10: EBD | NG10: OrthoPH | NH10: OrthoPH | NI10: OrthoPH | NJ10: OrthoPH | NK10: OrthoPH | NL10: OrthoPH | NM10: OrthoPH | NN10: OrthoPH | NO10: OrthoPH | NP10: OrthoPH | NQ10: OrthoPH | NR10: OrthoPH | NS10: OrthoPH | NT10: OrthoPH | NU10: LanD | NV10: LanD | NW10: LanD | NX10: LanD | NY10: LanD | NZ10: LanD | OA10: LanD | OB10: LanD | OC10: LanD | OD10: LanD | OE10: LanD | OF10: LanD | OG10: LanD | OH10: LanD | OI10: CP | OJ10: CP | OK10: CP | OL10: CP | OM10: CP | ON10: CP | OO10: CP | OP10: CP | OQ10: CP | OR10: CP | OS10: CP | OT10: CP | OU10: CP | OV10: CP | OW10: Chronic | OX10: Chronic | OY10: Chronic | OZ10: Chronic | PA10: Chronic | PB10: Chronic | PC10: Chronic | PD10: Chronic | PE10: Chronic | PF10: Chronic | PG10: Chronic | PH10: Chronic | PI10: Chronic | PJ10: Chronic | PK10: MultiD | PL10: MultiD | PM10: MultiD | PN10: MultiD | PO10: MultiD | PP10: MultiD | PQ10: MultiD | PR10: MultiD | PS10: MultiD | PT10: MultiD | PU10: MultiD | PV10: MultiD | PW10: MultiD | PX10: MultiD | PY10: Diff.See | PZ10: Diff.See | QA10: Diff.See | QB10: Diff.See | QC10: Diff.See | QD10: Diff.See | QE10: Diff.See | QF10: Diff.See | QG10: Diff.See | QH10: Diff.See | QI10: Diff.See | QJ10: Diff.See | QK10: Diff.See | QL10: Diff.See | QM10: Diff.Hear | QN10: Diff.Hear | QO10: Diff.Hear | QP10: Diff.Hear | QQ10: Diff.Hear | QR10: Diff.Hear | QS10: Diff.Hear | QT10: Diff.Hear | QU10: Diff.Hear | QV10: Diff.Hear | QW10: Diff.Hear | QX10: Diff.Hear | QY10: Diff.Hear | QZ10: Diff.Hear | RA10: Diff.Know | RB10: Diff.Know | RC10: Diff.Know | RD10: Diff.Know | RE10: Diff.Know | RF10: Diff.Know | RG10: Diff.Know | RH10: Diff.Know | RI10: Diff.Know | RJ10: Diff.Know | RK10: Diff.Know | RL10: Diff.Know | RM10: Diff.Know | RN10: Diff.Know | RO10: Diff.RCPAU | RP10: Diff.RCPAU | RQ10: Diff.RCPAU | RR10: Diff.RCPAU | RS10: Diff.RCPAU | RT10: Diff.RCPAU | RU10: Diff.RCPAU | RV10: Diff.RCPAU | RW10: Diff.RCPAU | RX10: Diff.RCPAU | RY10: Diff.RCPAU | RZ10: Diff.RCPAU | SA10: Diff.RCPAU | SB10: Diff.RCPAU | SC10: Dif.AAS | SD10: Dif.AAS | SE10: Dif.AAS | SF10: Dif.AAS | SG10: Dif.AAS | SH10: Dif.AAS | SI10: Dif.AAS | SJ10: Dif.AAS | SK10: Dif.AAS | SL10: Dif.AAS | SM10: Dif.AAS | SN10: Dif.AAS | SO10: Dif.AAS | SP10: Dif.AAS | SQ10: Diff.DIPB | SR10: Diff.DIPB | SS10: Diff.DIPB | ST10: Diff.DIPB | SU10: Diff.DIPB | SV10: Diff.DIPB | SW10: Diff.DIPB | SX10: Diff.DIPB | SY10: Diff.DIPB | SZ10: Diff.DIPB | TA10: Diff.DIPB | TB10: Diff.DIPB | TC10: Diff.DIPB | TD10: Diff.DIPB | TE10: Diff.Mob | TF10: Diff.Mob | TG10: Diff.Mob | TH10: Diff.Mob | TI10: Diff.Mob | TJ10: Diff.Mob | TK10: Diff.Mob | TL10: Diff.Mob | TM10: Diff.Mob | TN10: Diff.Mob | TO10: Diff.Mob | TP10: Diff.Mob | TQ10: Diff.Mob | TR10: Diff.Mob | TS10: Diff.Com | TT10: Diff.Com | TU10: Diff.Com | TV10: Diff.Com | TW10: Diff.Com | TX10: Diff.Com | TY10: Diff.Com | TZ10: Diff.Com | UA10: Diff.Com | UB10: Diff.Com | UC10: Diff.Com | UD10: Diff.Com | UE10: Diff.Com | UF10: Diff.Com | UG10: Male | UH10: Female | UI10: Total | UK10: VI | UL10: VI | UM10: VI | UN10: VI | UO10: VI | UP10: VI | UQ10: VI | UR10: VI | US10: VI | UT10: VI | UU10: HI | UV10: HI | UW10: HI | UX10: HI | UY10: HI | UZ10: HI | VA10: HI | VB10: HI | VC10: HI | VD10: HI | VE10: LD | VF10: LD | VG10: LD | VH10: LD | VI10: LD | VJ10: LD | VK10: LD | VL10: LD | VM10: LD | VN10: LD | VO10: ID | VP10: ID | VQ10: ID | VR10: ID | VS10: ID | VT10: ID | VU10: ID | VV10: ID | VW10: ID | VX10: ID | VY10: ASD | VZ10: ASD | WA10: ASD | WB10: ASD | WC10: ASD | WD10: ASD | WE10: ASD | WF10: ASD | WG10: ASD | WH10: ASD | WI10: EBD | WJ10: EBD | WK10: EBD | WL10: EBD | WM10: EBD | WN10: EBD | WO10: EBD | WP10: EBD | WQ10: EBD | WR10: EBD | WS10: OrthoPH | WT10: OrthoPH | WU10: OrthoPH | WV10: OrthoPH | WW10: OrthoPH | WX10: OrthoPH | WY10: OrthoPH | WZ10: OrthoPH | XA10: OrthoPH | XB10: OrthoPH | XC10: LanD | XD10: LanD | XE10: LanD | XF10: LanD | XG10: LanD | XH10: LanD | XI10: LanD | XJ10: LanD | XK10: LanD | XL10: LanD | XM10: CP | XN10: CP | XO10: CP | XP10: CP | XQ10: CP | XR10: CP | XS10: CP | XT10: CP | XU10: CP | XV10: CP | XW10: Chronic | XX10: Chronic | XY10: Chronic | XZ10: Chronic | YA10: Chronic | YB10: Chronic | YC10: Chronic | YD10: Chronic | YE10: Chronic | YF10: Chronic | YG10: MultiD | YH10: MultiD | YI10: MultiD | YJ10: MultiD | YK10: MultiD | YL10: MultiD | YM10: MultiD | YN10: MultiD | YO10: MultiD | YP10: MultiD | YQ10: Diff.See | YR10: Diff.See | YS10: Diff.See | YT10: Diff.See | YU10: Diff.See | YV10: Diff.See | YW10: Diff.See | YX10: Diff.See | YY10: Diff.See | YZ10: Diff.See | ZA10: Diff.Hear | ZB10: Diff.Hear | ZC10: Diff.Hear | ZD10: Diff.Hear | ZE10: Diff.Hear | ZF10: Diff.Hear | ZG10: Diff.Hear | ZH10: Diff.Hear | ZI10: Diff.Hear | ZJ10: Diff.Hear | ZK10: Diff.Know | ZL10: Diff.Know | ZM10: Diff.Know | ZN10: Diff.Know | ZO10: Diff.Know | ZP10: Diff.Know | ZQ10: Diff.Know | ZR10: Diff.Know | ZS10: Diff.Know | ZT10: Diff.Know | ZU10: Diff.RCPAU | ZV10: Diff.RCPAU | ZW10: Diff.RCPAU | ZX10: Diff.RCPAU | ZY10: Diff.RCPAU | ZZ10: Diff.RCPAU | AAA10: Diff.RCPAU | AAB10: Diff.RCPAU | AAC10: Diff.RCPAU | AAD10: Diff.RCPAU | AAE10: Dif.AAS | AAF10: Dif.AAS | AAG10: Dif.AAS | AAH10: Dif.AAS | AAI10: Dif.AAS | AAJ10: Dif.AAS | AAK10: Dif.AAS | AAL10: Dif.AAS | AAM10: Dif.AAS | AAN10: Dif.AAS | AAO10: Diff.DIPB | AAP10: Diff.DIPB | AAQ10: Diff.DIPB | AAR10: Diff.DIPB | AAS10: Diff.DIPB | AAT10: Diff.DIPB | AAU10: Diff.DIPB | AAV10: Diff.DIPB | AAW10: Diff.DIPB | AAX10: Diff.DIPB | AAY10: Diff.Mob | AAZ10: Diff.Mob | ABA10: Diff.Mob | ABB10: Diff.Mob | ABC10: Diff.Mob | ABD10: Diff.Mob | ABE10: Diff.Mob | ABF10: Diff.Mob | ABG10: Diff.Mob | ABH10: Diff.Mob | ABI10: Diff.Com | ABJ10: Diff.Com | ABK10: Diff.Com | ABL10: Diff.Com | ABM10: Diff.Com | ABN10: Diff.Com | ABO10: Diff.Com | ABP10: Diff.Com | ABQ10: Diff.Com | ABR10: Diff.Com | ABW10: VI | ABX10: VI | ABY10: VI | ABZ10: VI | ACA10: VI | ACB10: VI | ACC10: VI | ACD10: VI | ACE10: HI | ACF10: HI | ACG10: HI | ACH10: HI | ACI10: HI | ACJ10: HI | ACK10: HI | ACL10: HI | ACM10: LD | ACN10: LD | ACO10: LD | ACP10: LD | ACQ10: LD | ACR10: LD | ACS10: LD | ACT10: LD | ACU10: ID | ACV10: ID | ACW10: ID | ACX10: ID | ACY10: ID | ACZ10: ID | ADA10: ID | ADB10: ID | ADC10: ASD | ADD10: ASD | ADE10: ASD | ADF10: ASD | ADG10: ASD | ADH10: ASD | ADI10: ASD | ADJ10: ASD | ADK10: EBD | ADL10: EBD | ADM10: EBD | ADN10: EBD | ADO10: EBD | ADP10: EBD | ADQ10: EBD | ADR10: EBD | ADS10: OrthoPH | ADT10: OrthoPH | ADU10: OrthoPH | ADV10: OrthoPH | ADW10: OrthoPH | ADX10: OrthoPH | ADY10: OrthoPH | ADZ10: OrthoPH | AEA10: LanD | AEB10: LanD | AEC10: LanD | AED10: LanD | AEE10: LanD | AEF10: LanD | AEG10: LanD | AEH10: LanD | AEI10: CP | AEJ10: CP | AEK10: CP | AEL10: CP | AEM10: CP | AEN10: CP | AEO10: CP | AEP10: CP | AEQ10: Chronic | AER10: Chronic | AES10: Chronic | AET10: Chronic | AEU10: Chronic | AEV10: Chronic | AEW10: Chronic | AEX10: Chronic | AEY10: MultiD | AEZ10: MultiD | AFA10: MultiD | AFB10: MultiD | AFC10: MultiD | AFD10: MultiD | AFE10: MultiD | AFF10: MultiD | AFG10: Diff.See | AFH10: Diff.See | AFI10: Diff.See | AFJ10: Diff.See | AFK10: Diff.See | AFL10: Diff.See | AFM10: Diff.See | AFN10: Diff.See | AFO10: Diff.Hear | AFP10: Diff.Hear | AFQ10: Diff.Hear | AFR10: Diff.Hear | AFS10: Diff.Hear | AFT10: Diff.Hear | AFU10: Diff.Hear | AFV10: Diff.Hear | AFW10: Diff.Know | AFX10: Diff.Know | AFY10: Diff.Know | AFZ10: Diff.Know | AGA10: Diff.Know | AGB10: Diff.Know | AGC10: Diff.Know | AGD10: Diff.Know | AGE10: Diff.RCPAU | AGF10: Diff.RCPAU | AGG10: Diff.RCPAU | AGH10: Diff.RCPAU | AGI10: Diff.RCPAU | AGJ10: Diff.RCPAU | AGK10: Diff.RCPAU | AGL10: Diff.RCPAU | AGM10: Dif.AAS | AGN10: Dif.AAS | AGO10: Dif.AAS | AGP10: Dif.AAS | AGQ10: Dif.AAS | AGR10: Dif.AAS | AGS10: Dif.AAS | AGT10: Dif.AAS | AGU10: Diff.DIPB | AGV10: Diff.DIPB | AGW10: Diff.DIPB | AGX10: Diff.DIPB | AGY10: Diff.DIPB | AGZ10: Diff.DIPB | AHA10: Diff.DIPB | AHB10: Diff.DIPB | AHC10: Diff.Mob | AHD10: Diff.Mob | AHE10: Diff.Mob | AHF10: Diff.Mob | AHG10: Diff.Mob | AHH10: Diff.Mob | AHI10: Diff.Mob | AHJ10: Diff.Mob | AHK10: Diff.Com | AHL10: Diff.Com | AHM10: Diff.Com | AHN10: Diff.Com | AHO10: Diff.Com | AHP10: Diff.Com | AHQ10: Diff.Com | AHR10: Diff.Com | AHW10: VI | AHX10: VI | AHY10: VI | AHZ10: VI | AIA10: VI | AIB10: VI | AIC10: VI | AID10: VI | AIE10: HI | AIF10: HI | AIG10: HI | AIH10: HI | AII10: HI | AIJ10: HI | AIK10: HI | AIL10: HI | AIM10: LD | AIN10: LD | AIO10: LD | AIP10: LD | AIQ10: LD | AIR10: LD | AIS10: LD | AIT10: LD | AIU10: ID | AIV10: ID | AIW10: ID | AIX10: ID | AIY10: ID | AIZ10: ID | AJA10: ID | AJB10: ID | AJC10: ASD | AJD10: ASD | AJE10: ASD | AJF10: ASD | AJG10: ASD | AJH10: ASD | AJI10: ASD | AJJ10: ASD | AJK10: EBD | AJL10: EBD | AJM10: EBD | AJN10: EBD | AJO10: EBD | AJP10: EBD | AJQ10: EBD | AJR10: EBD | AJS10: OrthoPH | AJT10: OrthoPH | AJU10: OrthoPH | AJV10: OrthoPH | AJW10: OrthoPH | AJX10: OrthoPH | AJY10: OrthoPH | AJZ10: OrthoPH | AKA10: LanD | AKB10: LanD | AKC10: LanD | AKD10: LanD | AKE10: LanD | AKF10: LanD | AKG10: LanD | AKH10: LanD | AKI10: CP | AKJ10: CP | AKK10: CP | AKL10: CP | AKM10: CP | AKN10: CP | AKO10: CP | AKP10: CP | AKQ10: Chronic | AKR10: Chronic | AKS10: Chronic | AKT10: Chronic | AKU10: Chronic | AKV10: Chronic | AKW10: Chronic | AKX10: Chronic | AKY10: MultiD | AKZ10: MultiD | ALA10: MultiD | ALB10: MultiD | ALC10: MultiD | ALD10: MultiD | ALE10: MultiD | ALF10: MultiD | ALG10: Diff.See | ALH10: Diff.See | ALI10: Diff.See | ALJ10: Diff.See | ALK10: Diff.See | ALL10: Diff.See | ALM10: Diff.See | ALN10: Diff.See | ALO10: Diff.Hear | ALP10: Diff.Hear | ALQ10: Diff.Hear | ALR10: Diff.Hear | ALS10: Diff.Hear | ALT10: Diff.Hear | ALU10: Diff.Hear | ALV10: Diff.Hear | ALW10: Diff.Know | ALX10: Diff.Know | ALY10: Diff.Know | ALZ10: Diff.Know | AMA10: Diff.Know | AMB10: Diff.Know | AMC10: Diff.Know | AMD10: Diff.Know | AME10: Diff.RCPAU | AMF10: Diff.RCPAU | AMG10: Diff.RCPAU | AMH10: Diff.RCPAU | AMI10: Diff.RCPAU | AMJ10: Diff.RCPAU | AMK10: Diff.RCPAU | AML10: Diff.RCPAU | AMM10: Dif.AAS | AMN10: Dif.AAS | AMO10: Dif.AAS | AMP10: Dif.AAS | AMQ10: Dif.AAS | AMR10: Dif.AAS | AMS10: Dif.AAS | AMT10: Dif.AAS | AMU10: Diff.DIPB | AMV10: Diff.DIPB | AMW10: Diff.DIPB | AMX10: Diff.DIPB | AMY10: Diff.DIPB | AMZ10: Diff.DIPB | ANA10: Diff.DIPB | ANB10: Diff.DIPB | ANC10: Diff.Mob | AND10: Diff.Mob | ANE10: Diff.Mob | ANF10: Diff.Mob | ANG10: Diff.Mob | ANH10: Diff.Mob | ANI10: Diff.Mob | ANJ10: Diff.Mob | ANK10: Diff.Com | ANL10: Diff.Com | ANM10: Diff.Com | ANN10: Diff.Com | ANO10: Diff.Com | ANP10: Diff.Com | ANQ10: Diff.Com | ANR10: Diff.Com | ANW10: VI | ANX10: VI | ANY10: VI | ANZ10: VI | AOA10: HI | AOB10: HI | AOC10: HI | AOD10: HI | AOE10: LD | AOF10: LD | AOG10: LD | AOH10: LD | AOI10: ID | AOJ10: ID | AOK10: ID | AOL10: ID | AOM10: ASD | AON10: ASD | AOO10: ASD | AOP10: ASD | AOQ10: EBD | AOR10: EBD | AOS10: EBD | AOT10: EBD | AOU10: OrthoPH | AOV10: OrthoPH | AOW10: OrthoPH | AOX10: OrthoPH | AOY10: LanD | AOZ10: LanD | APA10: LanD | APB10: LanD | APC10: CP | APD10: CP | APE10: CP | APF10: CP | APG10: Chronic | APH10: Chronic | API10: Chronic | APJ10: Chronic | APK10: MultiD | APL10: MultiD | APM10: MultiD | APN10: MultiD | APO10: Diff.See | APP10: Diff.See | APQ10: Diff.See | APR10: Diff.See | APS10: Diff.Hear | APT10: Diff.Hear | APU10: Diff.Hear | APV10: Diff.Hear | APW10: Diff.Know | APX10: Diff.Know | APY10: Diff.Know | APZ10: Diff.Know | AQA10: Diff.RCPAU | AQB10: Diff.RCPAU | AQC10: Diff.RCPAU | AQD10: Diff.RCPAU | AQE10: Dif.AAS | AQF10: Dif.AAS | AQG10: Dif.AAS | AQH10: Dif.AAS | AQI10: Diff.DIPB | AQJ10: Diff.DIPB | AQK10: Diff.DIPB | AQL10: Diff.DIPB | AQM10: Diff.Mob | AQN10: Diff.Mob | AQO10: Diff.Mob | AQP10: Diff.Mob | AQQ10: Diff.Com | AQR10: Diff.Com | AQS10: Diff.Com | AQT10: Diff.Com
Q11: =SUM(Q$13:Q$84) -> 0 | R11: =SUM(R$13:R$84) -> 0 | S11: =SUM(S$13:S$84) -> 0 | T11: =SUM(T$13:T$84) -> 0 | U11: =SUM(U$13:U$84) -> 1 | V11: =SUM(V$13:V$84) -> 0 | W11: =SUM(W$13:W$84) -> 0 | X11: =SUM(X$13:X$84) -> 1 | ... JY11: =SUM(JY$13:JY$84) -> 2714 | KA11: =SUM(KA$13:KA$84) -> 4 | KB11: =SUM(KB$13:KB$84) -> 1 | KC11: =SUM(KC$13:KC$84) -> 0 | KD11: =SUM(KD$13:KD$84) -> 0 | KE11: =SUM(KE$13:KE$84) -> 0 | KF11: =SUM(KF$13:KF$84) -> 0 | KG11: =SUM(KG$13:KG$84) -> 0 | KH11: =SUM(KH$13:KH$84) -> 0 | ... UI11: =SUM(UI$13:UI$84) -> 99 | UK11: =SUM(UK$13:UK$84) -> 0 | UL11: =SUM(UL$13:UL$84) -> 1 | UM11: =SUM(UM$13:UM$84) -> 0 | UN11: =SUM(UN$13:UN$84) -> 0 | UO11: =SUM(UO$13:UO$84) -> 0 | UP11: =SUM(UP$13:UP$84) -> 0 | UQ11: =SUM(UQ$13:UQ$84) -> 0 | UR11: =SUM(UR$13:UR$84) -> 0 | ... ABU11: =SUM(ABU$13:ABU$84) -> 78 | ABW11: =SUM(ABW$13:ABW$84) -> 0 | ABX11: =SUM(ABX$13:ABX$84) -> 0 | ABY11: =SUM(ABY$13:ABY$84) -> 0 | ABZ11: =SUM(ABZ$13:ABZ$84) -> 1 | ACA11: =SUM(ACA$13:ACA$84) -> 0 | ACB11: =SUM(ACB$13:ACB$84) -> 0 | ACC11: =SUM(ACC$13:ACC$84) -> 2 | ACD11: =SUM(ACD$13:ACD$84) -> 1 | ... AHU11: =SUM(AHU$13:AHU$84) -> 602 | AHW11: =SUM(AHW$13:AHW$84) -> 0 | AHX11: =SUM(AHX$13:AHX$84) -> 0 | AHY11: =SUM(AHY$13:AHY$84) -> 0 | AHZ11: =SUM(AHZ$13:AHZ$84) -> 0 | AIA11: =SUM(AIA$13:AIA$84) -> 0 | AIB11: =SUM(AIB$13:AIB$84) -> 0 | AIC11: =SUM(AIC$13:AIC$84) -> 0 | AID11: =SUM(AID$13:AID$84) -> 0 | ... ANU11: =SUM(ANU$13:ANU$84) -> 0 | ANW11: =SUM(ANW$13:ANW$84) -> 0 | ANX11: =SUM(ANX$13:ANX$84) -> 1 | ANY11: =SUM(ANY$13:ANY$84) -> 0 | ANZ11: =SUM(ANZ$13:ANZ$84) -> 0 | AOA11: =SUM(AOA$13:AOA$84) -> 0 | AOB11: =SUM(AOB$13:AOB$84) -> 0 | AOC11: =SUM(AOC$13:AOC$84) -> 0 | AOD11: =SUM(AOD$13:AOD$84) -> 0 | ... ARA11: =SUM(ARA$13:ARA$84) -> 49
