Workbook

Sheet ES
A1: END OF SCHOOL YEAR DATABASE CAUSES OF DROPOUT (ALL SECTOR) ELEMENTARY
A2: SY 2022-2023 | L2: Had to Take Care Siblings | AE2: Early Marriage/Pregnancy | AX2: Parents Attitude Toward Schooling | BQ2: Family problems/Feuds | CJ2: Illness | DC2: Overage | DV2: Drug Abuse | EO2: Poor Academic Performance | FH2: Lack of interest/Distractions | GA2: Hunger/Malnutrition | GT2: Teacher Factors | HM2: Physical Conditions of Classrooms | IF2: Peer Influences | IY2: Distance between Home and School | JR2: Armed Conflict | KK2: Calamities/Disasters | LD2: Child Labor, Work | LW2: Others | MP2: Grand Total (Dropout ES)
A3: Based on End of School Year (EOSY) LIS Cut-off Date as of September 15, 2023 | L3: Kindergarten | N3: Grade 1 | P3: Grade 2 | R3: Grade 3 | T3: Grade 4 | V3: Grade 5 | X3: Grade 6 | Z3: Non-Graded (SNED) | AB3: Total | AE3: Kindergarten | AG3: Grade 1 | AI3: Grade 2 | AK3: Grade 3 | AM3: Grade 4 | AO3: Grade 5 | AQ3: Grade 6 | AS3: Non-Graded (SNED) | AU3: Total | AX3: Kindergarten | AZ3: Grade 1 | BB3: Grade 2 | BD3: Grade 3 | BF3: Grade 4 | BH3: Grade 5 | BJ3: Grade 6 | BL3: Non-Graded (SNED) | BN3: Total | BQ3: Kindergarten | BS3: Grade 1 | BU3: Grade 2 | BW3: Grade 3 | BY3: Grade 4 | CA3: Grade 5 | CC3: Grade 6 | CE3: Non-Graded (SNED) | CG3: Total | CJ3: Kindergarten | CL3: Grade 1 | CN3: Grade 2 | CP3: Grade 3 | CR3: Grade 4 | CT3: Grade 5 | CV3: Grade 6 | CX3: Non-Graded (SNED) | CZ3: Total | DC3: Kindergarten | DE3: Grade 1 | DG3: Grade 2 | DI3: Grade 3 | DK3: Grade 4 | DM3: Grade 5 | DO3: Grade 6 | DQ3: Non-Graded (SNED) | DS3: Total | DV3: Kindergarten | DX3: Grade 1 | DZ3: Grade 2 | EB3: Grade 3 | ED3: Grade 4 | EF3: Grade 5 | EH3: Grade 6 | EJ3: Non-Graded (SNED) | EL3: Total | EO3: Kindergarten | EQ3: Grade 1 | ES3: Grade 2 | EU3: Grade 3 | EW3: Grade 4 | EY3: Grade 5 | FA3: Grade 6 | FC3: Non-Graded (SNED) | FE3: Total | FH3: Kindergarten | FJ3: Grade 1 | FL3: Grade 2 | FN3: Grade 3 | FP3: Grade 4 | FR3: Grade 5 | FT3: Grade 6 | FV3: Non-Graded (SNED) | FX3: Total | GA3: Kindergarten | GC3: Grade 1 | GE3: Grade 2 | GG3: Grade 3 | GI3: Grade 4 | GK3: Grade 5 | GM3: Grade 6 | GO3: Non-Graded (SNED) | GQ3: Total | GT3: Kindergarten | GV3: Grade 1 | GX3: Grade 2 | GZ3: Grade 3 | HB3: Grade 4 | HD3: Grade 5 | HF3: Grade 6 | HH3: Non-Graded (SNED) | HJ3: Total | HM3: Kindergarten | HO3: Grade 1 | HQ3: Grade 2 | HS3: Grade 3 | HU3: Grade 4 | HW3: Grade 5 | HY3: Grade 6 | IA3: Non-Graded (SNED) | IC3: Total | IF3: Kindergarten | IH3: Grade 1 | IJ3: Grade 2 | IL3: Grade 3 | IN3: Grade 4 | IP3: Grade 5 | IR3: Grade 6 | IT3: Non-Graded (SNED) | IV3: Total | IY3: Kindergarten | JA3: Grade 1 | JC3: Grade 2 | JE3: Grade 3 | JG3: Grade 4 | JI3: Grade 5 | JK3: Grade 6 | JM3: Non-Graded (SNED) | JO3: Total | JR3: Kindergarten | JT3: Grade 1 | JV3: Grade 2 | JX3: Grade 3 | JZ3: Grade 4 | KB3: Grade 5 | KD3: Grade 6 | KF3: Non-Graded (SNED) | KH3: Total | KK3: Kindergarten | KM3: Grade 1 | KO3: Grade 2 | KQ3: Grade 3 | KS3: Grade 4 | KU3: Grade 5 | KW3: Grade 6 | KY3: Non-Graded (SNED) | LA3: Total | LD3: Kindergarten | LF3: Grade 1 | LH3: Grade 2 | LJ3: Grade 3 | LL3: Grade 4 | LN3: Grade 5 | LP3: Grade 6 | LR3: Non-Graded (SNED) | LT3: Total | LW3: Kindergarten | LY3: Grade 1 | MA3: Grade 2 | MC3: Grade 3 | ME3: Grade 4 | MG3: Grade 5 | MI3: Grade 6 | MK3: Non-Graded (SNED) | MM3: Total | MP3: Kindergarten | MR3: Grade 1 | MT3: Grade 2 | MV3: Grade 3 | MX3: Grade 4 | MZ3: Grade 5 | NB3: Grade 6 | ND3: Non-Graded (SNED) | NF3: Total
L4: Male | M4: Female | N4: Male | O4: Female | P4: Male | Q4: Female | R4: Male | S4: Female | T4: Male | U4: Female | V4: Male | W4: Female | X4: Male | Y4: Female | Z4: Male | AA4: Female | AB4: Male | AC4: Female | AD4: Total | AE4: Male | AF4: Female | AG4: Male | AH4: Female | AI4: Male | AJ4: Female | AK4: Male | AL4: Female | AM4: Male | AN4: Female | AO4: Male | AP4: Female | AQ4: Male | AR4: Female | AS4: Male | AT4: Female | AU4: Male | AV4: Female | AW4: Total | AX4: Male | AY4: Female | AZ4: Male | BA4: Female | BB4: Male | BC4: Female | BD4: Male | BE4: Female | BF4: Male | BG4: Female | BH4: Male | BI4: Female | BJ4: Male | BK4: Female | BL4: Male | BM4: Female | BN4: Male | BO4: Female | BP4: Total | BQ4: Male | BR4: Female | BS4: Male | BT4: Female | BU4: Male | BV4: Female | BW4: Male | BX4: Female | BY4: Male | BZ4: Female | CA4: Male | CB4: Female | CC4: Male | CD4: Female | CE4: Male | CF4: Female | CG4: Male | CH4: Female | CI4: Total | CJ4: Male | CK4: Female | CL4: Male | CM4: Female | CN4: Male | CO4: Female | CP4: Male | CQ4: Female | CR4: Male | CS4: Female | CT4: Male | CU4: Female | CV4: Male | CW4: Female | CX4: Male | CY4: Female | CZ4: Male | DA4: Female | DB4: Total | DC4: Male | DD4: Female | DE4: Male | DF4: Female | DG4: Male | DH4: Female | DI4: Male | DJ4: Female | DK4: Male | DL4: Female | DM4: Male | DN4: Female | DO4: Male | DP4: Female | DQ4: Male | DR4: Female | DS4: Male | DT4: Female | DU4: Total | DV4: Male | DW4: Female | DX4: Male | DY4: Female | DZ4: Male | EA4: Female | EB4: Male | EC4: Female | ED4: Male | EE4: Female | EF4: Male | EG4: Female | EH4: Male | EI4: Female | EJ4: Male | EK4: Female | EL4: Male | EM4: Female | EN4: Total | EO4: Male | EP4: Female | EQ4: Male | ER4: Female | ES4: Male | ET4: Female | EU4: Male | EV4: Female | EW4: Male | EX4: Female | EY4: Male | EZ4: Female | FA4: Male | FB4: Female | FC4: Male | FD4: Female | FE4: Male | FF4: Female | FG4: Total | FH4: Male | FI4: Female | FJ4: Male | FK4: Female | FL4: Male | FM4: Female | FN4: Male | FO4: Female | FP4: Male | FQ4: Female | FR4: Male | FS4: Female | FT4: Male | FU4: Female | FV4: Male | FW4: Female | FX4: Male | FY4: Female | FZ4: Total | GA4: Male | GB4: Female | GC4: Male | GD4: Female | GE4: Male | GF4: Female | GG4: Male | GH4: Female | GI4: Male | GJ4: Female | GK4: Male | GL4: Female | GM4: Male | GN4: Female | GO4: Male | GP4: Female | GQ4: Male | GR4: Female | GS4: Total | GT4: Male | GU4: Female | GV4: Male | GW4: Female | GX4: Male | GY4: Female | GZ4: Male | HA4: Female | HB4: Male | HC4: Female | HD4: Male | HE4: Female | HF4: Male | HG4: Female | HH4: Male | HI4: Female | HJ4: Male | HK4: Female | HL4: Total | HM4: Male | HN4: Female | HO4: Male | HP4: Female | HQ4: Male | HR4: Female | HS4: Male | HT4: Female | HU4: Male | HV4: Female | HW4: Male | HX4: Female | HY4: Male | HZ4: Female | IA4: Male | IB4: Female | IC4: Male | ID4: Female | IE4: Total | IF4: Male | IG4: Female | IH4: Male | II4: Female | IJ4: Male | IK4: Female | IL4: Male | IM4: Female | IN4: Male | IO4: Female | IP4: Male | IQ4: Female | IR4: Male | IS4: Female | IT4: Male | IU4: Female | IV4: Male | IW4: Female | IX4: Total | IY4: Male | IZ4: Female | JA4: Male | JB4: Female | JC4: Male | JD4: Female | JE4: Male | JF4: Female | JG4: Male | JH4: Female | JI4: Male | JJ4: Female | JK4: Male | JL4: Female | JM4: Male | JN4: Female | JO4: Male | JP4: Female | JQ4: Total | JR4: Male | JS4: Female | JT4: Male | JU4: Female | JV4: Male | JW4: Female | JX4: Male | JY4: Female | JZ4: Male | KA4: Female | KB4: Male | KC4: Female | KD4: Male | KE4: Female | KF4: Male | KG4: Female | KH4: Male | KI4: Female | KJ4: Total | KK4: Male | KL4: Female | KM4: Male | KN4: Female | KO4: Male | KP4: Female | KQ4: Male | KR4: Female | KS4: Male | KT4: Female | KU4: Male | KV4: Female | KW4: Male | KX4: Female | KY4: Male | KZ4: Female | LA4: Male | LB4: Female | LC4: Total | LD4: Male | LE4: Female | LF4: Male | LG4: Female | LH4: Male | LI4: Female | LJ4: Male | LK4: Female | LL4: Male | LM4: Female | LN4: Male | LO4: Female | LP4: Male | LQ4: Female | LR4: Male | LS4: Female | LT4: Male | LU4: Female | LV4: Total | LW4: Male | LX4: Female | LY4: Male | LZ4: Female | MA4: Male | MB4: Female | MC4: Male | MD4: Female | ME4: Male | MF4: Female | MG4: Male | MH4: Female | MI4: Male | MJ4: Female | MK4: Male | ML4: Female | MM4: Male | MN4: Female | MO4: Total | MP4: Male | MQ4: Female | MR4: Male | MS4: Female | MT4: Male | MU4: Female | MV4: Male | MW4: Female | MX4: Male | MY4: Female | MZ4: Male | NA4: Female | NB4: Male | NC4: Female | ND4: Male | NE4: Female | NF4: Male | NG4: Female | NH4: Total
A5: Region | B5: Division | C5: Province | D5: Municipality | E5: BEIS School ID | F5: School Name | G5: School Subclassification | H5: Sector | I5: Curricular Offering Classification | J5: School Type | K5: Modified COC | L5: take_care_siblings_k_male | M5: take_care_siblings_k_female | N5: take_care_siblings_g1_male | O5: take_care_siblings_g1_female | P5: take_care_siblings_g2_male | Q5: take_care_siblings_g2_female | R5: take_care_siblings_g3_male | S5: take_care_siblings_g3_female | T5: take_care_siblings_g4_male | U5: take_care_siblings_g4_female | V5: take_care_siblings_g5_male | W5: take_care_siblings_g5_female | X5: take_care_siblings_g6_male | Y5: take_care_siblings_g6_female | Z5: take_care_siblings_ng_male | AA5: take_care_siblings_ng_female | AB5: Male | AC5: Female | AD5: Total | AE5: marr_preg_k_male | AF5: marr_preg_k_female | AG5: marr_preg_g1_male | AH5: marr_preg_g1_female | AI5: marr_preg_g2_male | AJ5: marr_preg_g2_female | AK5: marr_preg_g3_male | AL5: marr_preg_g3_female | AM5: marr_preg_g4_male | AN5: marr_preg_g4_female | AO5: marr_preg_g5_male | AP5: marr_preg_g5_female | AQ5: marr_preg_g6_male | AR5: marr_preg_g6_female | AS5: marr_preg_ng_male | AT5: marr_preg_ng_female | AU5: Male | AV5: Female | AW5: Total | AX5: parents_toward_school_k_male | AY5: parents_toward_school_k_female | AZ5: parents_toward_school_g1_male | BA5: parents_toward_school_g1_female | BB5: parents_toward_school_g2_male | BC5: parents_toward_school_g2_female | BD5: parents_toward_school_g3_male | BE5: parents_toward_school_g3_female | BF5: parents_toward_school_g4_male | BG5: parents_toward_school_g4_female | BH5: parents_toward_school_g5_male | BI5: parents_toward_school_g5_female | BJ5: parents_toward_school_g6_male | BK5: parents_toward_school_g6_female | BL5: parents_toward_school_ng_male | BM5: parents_toward_school_ng_female | BN5: Male | BO5: Female | BP5: Total | BQ5: fam_prob_feuds_k_male | BR5: fam_prob_feuds_k_female | BS5: fam_prob_feuds_g1_male | BT5: fam_prob_feuds_g1_female | BU5: fam_prob_feuds_g2_male | BV5: fam_prob_feuds_g2_female | BW5: fam_prob_feuds_g3_male | BX5: fam_prob_feuds_g3_female | BY5: fam_prob_feuds_g4_male | BZ5: fam_prob_feuds_g4_female | CA5: fam_prob_feuds_g5_male | CB5: fam_prob_feuds_g5_female | CC5: fam_prob_feuds_g6_male | CD5: fam_prob_feuds_g6_female | CE5: fam_prob_feuds_ng_male | CF5: fam_prob_feuds_ng_female | CG5: Male | CH5: Female | CI5: Total | CJ5: illness_k_male | CK5: illness_k_female | CL5: illness_g1_male | CM5: illness_g1_female | CN5: illness_g2_male | CO5: illness_g2_female | CP5: illness_g3_male | CQ5: illness_g3_female | CR5: illness_g4_male | CS5: illness_g4_female | CT5: illness_g5_male | CU5: illness_g5_female | CV5: illness_g6_male | CW5: illness_g6_female | CX5: illness_ng_male | CY5: illness_ng_female | CZ5: Male | DA5: Female | DB5: Total | DC5: overage_k_male | DD5: overage_k_female | DE5: overage_g1_male | DF5: overage_g1_female | DG5: overage_g2_male | DH5: overage_g2_female | DI5: overage_g3_male | DJ5: overage_g3_female | DK5: overage_g4_male | DL5: overage_g4_female | DM5: overage_g5_male | DN5: overage_g5_female | DO5: overage_g6_male | DP5: overage_g6_female | DQ5: overage_ng_male | DR5: overage_ng_female | DS5: Male | DT5: Female | DU5: Total | DV5: drug_abuse_k_male | DW5: drug_abuse_k_female | DX5: drug_abuse_g1_male | DY5: drug_abuse_g1_female | DZ5: drug_abuse_g2_male | EA5: drug_abuse_g2_female | EB5: drug_abuse_g3_male | EC5: drug_abuse_g3_female | ED5: drug_abuse_g4_male | EE5: drug_abuse_g4_female | EF5: drug_abuse_g5_male | EG5: drug_abuse_g5_female | EH5: drug_abuse_g6_male | EI5: drug_abuse_g6_female | EJ5: drug_abuse_ng_male | EK5: drug_abuse_ng_female | EL5: Male | EM5: Female | EN5: Total | EO5: poor_acad_perf_k_male | EP5: poor_acad_perf_k_female | EQ5: poor_acad_perf_g1_male | ER5: poor_acad_perf_g1_female | ES5: poor_acad_perf_g2_male | ET5: poor_acad_perf_g2_female | EU5: poor_acad_perf_g3_male | EV5: poor_acad_perf_g3_female | EW5: poor_acad_perf_g4_male | EX5: poor_acad_perf_g4_female | EY5: poor_acad_perf_g5_male | EZ5: poor_acad_perf_g5_female | FA5: poor_acad_perf_g6_male | FB5: poor_acad_perf_g6_female | FC5: poor_acad_perf_ng_male | FD5: poor_acad_perf_ng_female | FE5: Male | FF5: Female | FG5: Total | FH5: lack_of_interest_k_male | FI5: lack_of_interest_k_female | FJ5: lack_of_interest_g1_male | FK5: lack_of_interest_g1_female | FL5: lack_of_interest_g2_male | FM5: lack_of_interest_g2_female | FN5: lack_of_interest_g3_male | FO5: lack_of_interest_g3_female | FP5: lack_of_interest_g4_male | FQ5: lack_of_interest_g4_female | FR5: lack_of_interest_g5_male | FS5: lack_of_interest_g5_female | FT5: lack_of_interest_g6_male | FU5: lack_of_interest_g6_female | FV5: lack_of_interest_ng_male | FW5: lack_of_interest_ng_female | FX5: Male | FY5: Female | FZ5: Total | GA5: hunger_malnu_k_male | GB5: hunger_malnu_k_female | GC5: hunger_malnu_g1_male | GD5: hunger_malnu_g1_female | GE5: hunger_malnu_g2_male | GF5: hunger_malnu_g2_female | GG5: hunger_malnu_g3_male | GH5: hunger_malnu_g3_female | GI5: hunger_malnu_g4_male | GJ5: hunger_malnu_g4_female | GK5: hunger_malnu_g5_male | GL5: hunger_malnu_g5_female | GM5: hunger_malnu_g6_male | GN5: hunger_malnu_g6_female | GO5: hunger_malnu_ng_male | GP5: hunger_malnu_ng_female | GQ5: Male | GR5: Female | GS5: Total | GT5: teacher_factor_k_male | GU5: teacher_factor_k_female | GV5: teacher_factor_g1_male | GW5: teacher_factor_g1_female | GX5: teacher_factor_g2_male | GY5: teacher_factor_g2_female | GZ5: teacher_factor_g3_male | HA5: teacher_factor_g3_female | HB5: teacher_factor_g4_male | HC5: teacher_factor_g4_female | HD5: teacher_factor_g5_male | HE5: teacher_factor_g5_female | HF5: teacher_factor_g6_male | HG5: teacher_factor_g6_female | HH5: teacher_factor_ng_male | HI5: teacher_factor_ng_female | HJ5: Male | HK5: Female | HL5: Total | HM5: physical_cond_classroom_k_male | HN5: physical_cond_classroom_k_female | HO5: physical_cond_classroom_g1_male | HP5: physical_cond_classroom_g1_female | HQ5: physical_cond_classroom_g2_male | HR5: physical_cond_classroom_g2_female | HS5: physical_cond_classroom_g3_male | HT5: physical_cond_classroom_g3_female | HU5: physical_cond_classroom_g4_male | HV5: physical_cond_classroom_g4_female | HW5: physical_cond_classroom_g5_male | HX5: physical_cond_classroom_g5_female | HY5: physical_cond_classroom_g6_male | HZ5: physical_cond_classroom_g6_female | IA5: physical_cond_classroom_ng_male | IB5: physical_cond_classroom_ng_female | IC5: Male | ID5: Female | IE5: Total | IF5: peer_influ_k_male | IG5: peer_influ_k_female | IH5: peer_influ_g1_male | II5: peer_influ_g1_female | IJ5: peer_influ_g2_male | IK5: peer_influ_g2_female | IL5: peer_influ_g3_male | IM5: peer_influ_g3_female | IN5: peer_influ_g4_male | IO5: peer_influ_g4_female | IP5: peer_influ_g5_male | IQ5: peer_influ_g5_female | IR5: peer_influ_g6_male | IS5: peer_influ_g6_female | IT5: peer_influ_ng_male | IU5: peer_influ_ng_female | IV5: Male | IW5: Female | IX5: Total | IY5: distance_home_school_k_male | IZ5: distance_home_school_k_female | JA5: distance_home_school_g1_male | JB5: distance_home_school_g1_female | JC5: distance_home_school_g2_male | JD5: distance_home_school_g2_female | JE5: distance_home_school_g3_male | JF5: distance_home_school_g3_female | JG5: distance_home_school_g4_male | JH5: distance_home_school_g4_female | JI5: distance_home_school_g5_male | JJ5: distance_home_school_g5_female | JK5: distance_home_school_g6_male | JL5: distance_home_school_g6_female | JM5: distance_home_school_ng_male | JN5: distance_home_school_ng_female | JO5: Male | JP5: Female | JQ5: Total | JR5: armed_conflict_k_male | JS5: armed_conflict_k_female | JT5: armed_conflict_g1_male | JU5: armed_conflict_g1_female | JV5: armed_conflict_g2_male | JW5: armed_conflict_g2_female | JX5: armed_conflict_g3_male | JY5: armed_conflict_g3_female | JZ5: armed_conflict_g4_male | KA5: armed_conflict_g4_female | KB5: armed_conflict_g5_male | KC5: armed_conflict_g5_female | KD5: armed_conflict_g6_male | KE5: armed_conflict_g6_female | KF5: armed_conflict_ng_male | KG5: armed_conflict_ng_female | KH5: Male | KI5: Female | KJ5: Total | KK5: calamities_k_male | KL5: calamities_k_female | KM5: calamities_g1_male | KN5: calamities_g1_female | KO5: calamities_g2_male | KP5: calamities_g2_female | KQ5: calamities_g3_male | KR5: calamities_g3_female | KS5: calamities_g4_male | KT5: calamities_g4_female | KU5: calamities_g5_male | KV5: calamities_g5_female | KW5: calamities_g6_male | KX5: calamities_g6_female | KY5: calamities_ng_male | KZ5: calamities_ng_female | LA5: Male | LB5: Female | LC5: Total | LD5: child_labor_k_male | LE5: child_labor_k_female | LF5: child_labor_g1_male | LG5: child_labor_g1_female | LH5: child_labor_g2_male | LI5: child_labor_g2_female | LJ5: child_labor_g3_male | LK5: child_labor_g3_female | LL5: child_labor_g4_male | LM5: child_labor_g4_female | LN5: child_labor_g5_male | LO5: child_labor_g5_female | LP5: child_labor_g6_male | LQ5: child_labor_g6_female | LR5: child_labor_ng_male | LS5: child_labor_ng_female | LT5: Male | LU5: Female | LV5: Total | LW5: others_k_male | LX5: others_k_female | LY5: others_g1_male | LZ5: others_g1_female | MA5: others_g2_male | MB5: others_g2_female | MC5: others_g3_male | MD5: others_g3_female | ME5: others_g4_male | MF5: others_g4_female | MG5: others_g5_male | MH5: others_g5_female | MI5: others_g6_male | MJ5: others_g6_female | MK5: others_ng_male | ML5: others_ng_female | MM5: Male | MN5: Female | MO5: Total | MP5: Male | MQ5: Female | MR5: Male | MS5: Female | MT5: Male | MU5: Female | MV5: Male | MW5: Female | MX5: Male | MY5: Female | MZ5: Male | NA5: Female | NB5: Male | NC5: Female | ND5: Male | NE5: Female | NF5: Male | NG5: Female | NH5: Total
A6: Region XI | B6: Mati City | C6: DAVAO ORIENTAL | D6: CITY OF MATI (Capital) | E6: 129374 | F6: Badas ES | G6: DepED Managed | H6: Public | I6: Kinder & Grade 1-6 | J6: School with no Annexes | K6: Purely ES | L6: 0 | M6: 0 | N6: 0 | O6: 0 | P6: 0 | Q6: 0 | R6: 0 | S6: 0 | T6: 0 | U6: 0 | V6: 0 | W6: 0 | X6: 0 | Y6: 0 | Z6: 0 | AA6: 0 | AB6: 0 | AC6: 0 | AD6: 0 | AE6: 0 | AF6: 0 | AG6: 0 | AH6: 0 | AI6: 0 | AJ6: 0 | AK6: 0 | AL6: 0 | AM6: 0 | AN6: 0 | AO6: 0 | AP6: 0 | AQ6: 0 | AR6: 0 | AS6: 0 | AT6: 0 | AU6: 0 | AV6: 0 | AW6: 0 | AX6: 3 | AY6: 0 | AZ6: 0 | BA6: 0 | BB6: 0 | BC6: 0 | BD6: 0 | BE6: 0 | BF6: 0 | BG6: 0 | BH6: 0 | BI6: 0 | BJ6: 0 | BK6: 0 | BL6: 0 | BM6: 0 | BN6: 3 | BO6: 0 | BP6: 3 | BQ6: 0 | BR6: 0 | BS6: 0 | BT6: 0 | BU6: 0 | BV6: 0 | BW6: 0 | BX6: 0 | BY6: 0 | BZ6: 0 | CA6: 0 | CB6: 0 | CC6: 0 | CD6: 0 | CE6: 0 | CF6: 0 | CG6: 0 | CH6: 0 | CI6: 0 | CJ6: 0 | CK6: 0 | CL6: 0 | CM6: 0 | CN6: 0 | CO6: 0 | CP6: 0 | CQ6: 0 | CR6: 0 | CS6: 0 | CT6: 0 | CU6: 0 | CV6: 0 | CW6: 0 | CX6: 0 | CY6: 0 | CZ6: 0 | DA6: 0 | DB6: 0 | DC6: 1 | DD6: 0 | DE6: 0 | DF6: 0 | DG6: 0 | DH6: 0 | DI6: 0 | DJ6: 0 | DK6: 0 | DL6: 0 | DM6: 0 | DN6: 0 | DO6: 0 | DP6: 0 | DQ6: 0 | DR6: 0 | DS6: 1 | DT6: 0 | DU6: 1 | DV6: 0 | DW6: 0 | DX6: 0 | DY6: 0 | DZ6: 0 | EA6: 0 | EB6: 0 | EC6: 0 | ED6: 0 | EE6: 0 | EF6: 0 | EG6: 0 | EH6: 0 | EI6: 0 | EJ6: 0 | EK6: 0 | EL6: 0 | EM6: 0 | EN6: 0 | EO6: 0 | EP6: 0 | EQ6: 0 | ER6: 0 | ES6: 0 | ET6: 0 | EU6: 0 | EV6: 0 | EW6: 0 | EX6: 0 | EY6: 0 | EZ6: 0 | FA6: 0 | FB6: 0 | FC6: 0 | FD6: 0 | FE6: 0 | FF6: 0 | FG6: 0 | FH6: 0 | FI6: 0 | FJ6: 0 | FK6: 0 | FL6: 0 | FM6: 0 | FN6: 0 | FO6: 0 | FP6: 0 | FQ6: 0 | FR6: 0 | FS6: 0 | FT6: 0 | FU6: 0 | FV6: 0 | FW6: 0 | FX6: 0 | FY6: 0 | FZ6: 0 | GA6: 0 | GB6: 0 | GC6: 0 | GD6: 0 | GE6: 0 | GF6: 0 | GG6: 0 | GH6: 0 | GI6: 0 | GJ6: 0 | GK6: 0 | GL6: 0 | GM6: 0 | GN6: 0 | GO6: 0 | GP6: 0 | GQ6: 0 | GR6: 0 | GS6: 0 | GT6: 0 | GU6: 0 | GV6: 0 | GW6: 0 | GX6: 0 | GY6: 0 | GZ6: 0 | HA6: 0 | HB6: 0 | HC6: 0 | HD6: 0 | HE6: 0 | HF6: 0 | HG6: 0 | HH6: 0 | HI6: 0 | HJ6: 0 | HK6: 0 | HL6: 0 | HM6: 0 | HN6: 0 | HO6: 0 | HP6: 0 | HQ6: 0 | HR6: 0 | HS6: 0 | HT6: 0 | HU6: 0 | HV6: 0 | HW6: 0 | HX6: 0 | HY6: 0 | HZ6: 0 | IA6: 0 | IB6: 0 | IC6: 0 | ID6: 0 | IE6: 0 | IF6: 0 | IG6: 0 | IH6: 0 | II6: 0 | IJ6: 0 | IK6: 0 | IL6: 0 | IM6: 0 | IN6: 0 | IO6: 0 | IP6: 0 | IQ6: 0 | IR6: 0 | IS6: 0 | IT6: 0 | IU6: 0 | IV6: 0 | IW6: 0 | IX6: 0 | IY6: 0 | IZ6: 0 | JA6: 0 | JB6: 0 | JC6: 0 | JD6: 0 | JE6: 0 | JF6: 0 | JG6: 0 | JH6: 0 | JI6: 0 | JJ6: 0 | JK6: 0 | JL6: 0 | JM6: 0 | JN6: 0 | JO6: 0 | JP6: 0 | JQ6: 0 | JR6: 0 | JS6: 0 | JT6: 0 | JU6: 0 | JV6: 0 | JW6: 0 | JX6: 0 | JY6: 0 | JZ6: 0 | KA6: 0 | KB6: 0 | KC6: 0 | KD6: 0 | KE6: 0 | KF6: 0 | KG6: 0 | KH6: 0 | KI6: 0 | KJ6: 0 | KK6: 0 | KL6: 0 | KM6: 0 | KN6: 0 | KO6: 0 | KP6: 0 | KQ6: 0 | KR6: 0 | KS6: 0 | KT6: 0 | KU6: 0 | KV6: 0 | KW6: 0 | KX6: 0 | KY6: 0 | KZ6: 0 | LA6: 0 | LB6: 0 | LC6: 0 | LD6: 0 | LE6: 0 | LF6: 0 | LG6: 0 | LH6: 0 | LI6: 0 | LJ6: 0 | LK6: 0 | LL6: 0 | LM6: 0 | LN6: 0 | LO6: 0 | LP6: 0 | LQ6: 0 | LR6: 0 | LS6: 0 | LT6: 0 | LU6: 0 | LV6: 0 | LW6: 0 | LX6: 0 | LY6: 0 | LZ6: 0 | MA6: 0 | MB6: 0 | MC6: 0 | MD6: 0 | ME6: 0 | MF6: 0 | MG6: 0 | MH6: 0 | MI6: 0 | MJ6: 0 | MK6: 0 | ML6: 0 | MM6: 0 | MN6: 0 | MO6: 0 | MP6: 4 | MQ6: 0 | MR6: 0 | MS6: 0 | MT6: 0 | MU6: 0 | MV6: 0 | MW6: 0 | MX6: 0 | MY6: 0 | MZ6: 0 | NA6: 0 | NB6: 0 | NC6: 0 | ND6: 0 | NE6: 0 | NF6: 4 | NG6: 0 | NH6: 4
A7: Region XI | B7: Mati City | C7: DAVAO ORIENTAL | D7: CITY OF MATI (Capital) | E7: 129375 | F7: Baso ES | G7: DepED Managed | H7: Public | I7: Kinder & Grade 1-6 | J7: School with no Annexes | K7: Purely ES | L7: 0 | M7: 0 | N7: 0 | O7: 0 | P7: 0 | Q7: 0 | R7: 0 | S7: 0 | T7: 0 | U7: 0 | V7: 0 | W7: 0 | X7: 0 | Y7: 0 | Z7: 0 | AA7: 0 | AB7: 0 | AC7: 0 | AD7: 0 | AE7: 0 | AF7: 0 | AG7: 0 | AH7: 0 | AI7: 0 | AJ7: 0 | AK7: 0 | AL7: 0 | AM7: 0 | AN7: 0 | AO7: 0 | AP7: 0 | AQ7: 0 | AR7: 0 | AS7: 0 | AT7: 0 | AU7: 0 | AV7: 0 | AW7: 0 | AX7: 0 | AY7: 0 | AZ7: 0 | BA7: 0 | BB7: 0 | BC7: 0 | BD7: 0 | BE7: 0 | BF7: 0 | BG7: 0 | BH7: 0 | BI7: 0 | BJ7: 0 | BK7: 0 | BL7: 0 | BM7: 0 | BN7: 0 | BO7: 0 | BP7: 0 | BQ7: 0 | BR7: 0 | BS7: 0 | BT7: 0 | BU7: 0 | BV7: 0 | BW7: 0 | BX7: 0 | BY7: 0 | BZ7: 0 | CA7: 0 | CB7: 0 | CC7: 0 | CD7: 0 | CE7: 0 | CF7: 0 | CG7: 0 | CH7: 0 | CI7: 0 | CJ7: 0 | CK7: 0 | CL7: 0 | CM7: 0 | CN7: 0 | CO7: 0 | CP7: 0 | CQ7: 0 | CR7: 0 | CS7: 0 | CT7: 0 | CU7: 0 | CV7: 0 | CW7: 0 | CX7: 0 | CY7: 0 | CZ7: 0 | DA7: 0 | DB7: 0 | DC7: 0 | DD7: 0 | DE7: 0 | DF7: 0 | DG7: 0 | DH7: 0 | DI7: 0 | DJ7: 0 | DK7: 0 | DL7: 0 | DM7: 0 | DN7: 0 | DO7: 0 | DP7: 0 | DQ7: 0 | DR7: 0 | DS7: 0 | DT7: 0 | DU7: 0 | DV7: 0 | DW7: 0 | DX7: 0 | DY7: 0 | DZ7: 0 | EA7: 0 | EB7: 0 | EC7: 0 | ED7: 0 | EE7: 0 | EF7: 0 | EG7: 0 | EH7: 0 | EI7: 0 | EJ7: 0 | EK7: 0 | EL7: 0 | EM7: 0 | EN7: 0 | EO7: 0 | EP7: 0 | EQ7: 0 | ER7: 0 | ES7: 0 | ET7: 0 | EU7: 0 | EV7: 0 | EW7: 0 | EX7: 0 | EY7: 0 | EZ7: 0 | FA7: 0 | FB7: 0 | FC7: 0 | FD7: 0 | FE7: 0 | FF7: 0 | FG7: 0 | FH7: 0 | FI7: 0 | FJ7: 0 | FK7: 0 | FL7: 0 | FM7: 0 | FN7: 0 | FO7: 0 | FP7: 0 | FQ7: 0 | FR7: 0 | FS7: 0 | FT7: 0 | FU7: 0 | FV7: 0 | FW7: 0 | FX7: 0 | FY7: 0 | FZ7: 0 | GA7: 0 | GB7: 0 | GC7: 0 | GD7: 0 | GE7: 0 | GF7: 0 | GG7: 0 | GH7: 0 | GI7: 0 | GJ7: 0 | GK7: 0 | GL7: 0 | GM7: 0 | GN7: 0 | GO7: 0 | GP7: 0 | GQ7: 0 | GR7: 0 | GS7: 0 | GT7: 0 | GU7: 0 | GV7: 0 | GW7: 0 | GX7: 0 | GY7: 0 | GZ7: 0 | HA7: 0 | HB7: 0 | HC7: 0 | HD7: 0 | HE7: 0 | HF7: 0 | HG7: 0 | HH7: 0 | HI7: 0 | HJ7: 0 | HK7: 0 | HL7: 0 | HM7: 0 | HN7: 0 | HO7: 0 | HP7: 0 | HQ7: 0 | HR7: 0 | HS7: 0 | HT7: 0 | HU7: 0 | HV7: 0 | HW7: 0 | HX7: 0 | HY7: 0 | HZ7: 0 | IA7: 0 | IB7: 0 | IC7: 0 | ID7: 0 | IE7: 0 | IF7: 0 | IG7: 0 | IH7: 0 | II7: 0 | IJ7: 0 | IK7: 0 | IL7: 0 | IM7: 0 | IN7: 0 | IO7: 0 | IP7: 0 | IQ7: 0 | IR7: 0 | IS7: 0 | IT7: 0 | IU7: 0 | IV7: 0 | IW7: 0 | IX7: 0 | IY7: 0 | IZ7: 0 | JA7: 0 | JB7: 0 | JC7: 0 | JD7: 0 | JE7: 0 | JF7: 0 | JG7: 0 | JH7: 0 | JI7: 0 | JJ7: 0 | JK7: 0 | JL7: 0 | JM7: 0 | JN7: 0 | JO7: 0 | JP7: 0 | JQ7: 0 | JR7: 0 | JS7: 0 | JT7: 0 | JU7: 0 | JV7: 0 | JW7: 0 | JX7: 0 | JY7: 0 | JZ7: 0 | KA7: 0 | KB7: 0 | KC7: 0 | KD7: 0 | KE7: 0 | KF7: 0 | KG7: 0 | KH7: 0 | KI7: 0 | KJ7: 0 | KK7: 0 | KL7: 0 | KM7: 0 | KN7: 0 | KO7: 0 | KP7: 0 | KQ7: 0 | KR7: 0 | KS7: 0 | KT7: 0 | KU7: 0 | KV7: 0 | KW7: 0 | KX7: 0 | KY7: 0 | KZ7: 0 | LA7: 0 | LB7: 0 | LC7: 0 | LD7: 0 | LE7: 0 | LF7: 0 | LG7: 0 | LH7: 0 | LI7: 0 | LJ7: 0 | LK7: 0 | LL7: 0 | LM7: 0 | LN7: 0 | LO7: 0 | LP7: 0 | LQ7: 0 | LR7: 0 | LS7: 0 | LT7: 0 | LU7: 0 | LV7: 0 | LW7: 0 | LX7: 0 | LY7: 0 | LZ7: 0 | MA7: 0 | MB7: 0 | MC7: 0 | MD7: 0 | ME7: 0 | MF7: 0 | MG7: 0 | MH7: 0 | MI7: 0 | MJ7: 0 | MK7: 0 | ML7: 0 | MM7: 0 | MN7: 0 | MO7: 0 | MP7: 0 | MQ7: 0 | MR7: 0 | MS7: 0 | MT7: 0 | MU7: 0 | MV7: 0 | MW7: 0 | MX7: 0 | MY7: 0 | MZ7: 0 | NA7: 0 | NB7: 0 | NC7: 0 | ND7: 0 | NE7: 0 | NF7: 0 | NG7: 0 | NH7: 0
A8: Region XI | B8: Mati City | C8: DAVAO ORIENTAL | D8: CITY OF MATI (Capital) | E8: 129376 | F8: Belsonda ES | G8: DepED Managed | H8: Public | I8: Kinder & Grade 1-6 | J8: School with no Annexes | K8: Purely ES | L8: 0 | M8: 0 | N8: 0 | O8: 0 | P8: 0 | Q8: 0 | R8: 0 | S8: 0 | T8: 0 | U8: 0 | V8: 0 | W8: 0 | X8: 0 | Y8: 0 | Z8: 0 | AA8: 0 | AB8: 0 | AC8: 0 | AD8: 0 | AE8: 0 | AF8: 0 | AG8: 0 | AH8: 0 | AI8: 0 | AJ8: 0 | AK8: 0 | AL8: 0 | AM8: 0 | AN8: 0 | AO8: 0 | AP8: 0 | AQ8: 0 | AR8: 0 | AS8: 0 | AT8: 0 | AU8: 0 | AV8: 0 | AW8: 0 | AX8: 0 | AY8: 1 | AZ8: 0 | BA8: 0 | BB8: 0 | BC8: 0 | BD8: 0 | BE8: 0 | BF8: 0 | BG8: 0 | BH8: 0 | BI8: 0 | BJ8: 0 | BK8: 0 | BL8: 0 | BM8: 0 | BN8: 0 | BO8: 1 | BP8: 1 | BQ8: 1 | BR8: 0 | BS8: 0 | BT8: 0 | BU8: 0 | BV8: 0 | BW8: 0 | BX8: 0 | BY8: 0 | BZ8: 0 | CA8: 0 | CB8: 0 | CC8: 0 | CD8: 0 | CE8: 0 | CF8: 0 | CG8: 1 | CH8: 0 | CI8: 1 | CJ8: 0 | CK8: 0 | CL8: 0 | CM8: 0 | CN8: 0 | CO8: 0 | CP8: 0 | CQ8: 0 | CR8: 0 | CS8: 0 | CT8: 0 | CU8: 0 | CV8: 0 | CW8: 0 | CX8: 0 | CY8: 0 | CZ8: 0 | DA8: 0 | DB8: 0 | DC8: 0 | DD8: 0 | DE8: 0 | DF8: 0 | DG8: 0 | DH8: 0 | DI8: 0 | DJ8: 0 | DK8: 0 | DL8: 0 | DM8: 0 | DN8: 0 | DO8: 0 | DP8: 0 | DQ8: 0 | DR8: 0 | DS8: 0 | DT8: 0 | DU8: 0 | DV8: 0 | DW8: 0 | DX8: 0 | DY8: 0 | DZ8: 0 | EA8: 0 | EB8: 0 | EC8: 0 | ED8: 0 | EE8: 0 | EF8: 0 | EG8: 0 | EH8: 0 | EI8: 0 | EJ8: 0 | EK8: 0 | EL8: 0 | EM8: 0 | EN8: 0 | EO8: 0 | EP8: 0 | EQ8: 0 | ER8: 0 | ES8: 0 | ET8: 0 | EU8: 0 | EV8: 0 | EW8: 0 | EX8: 0 | EY8: 0 | EZ8: 0 | FA8: 0 | FB8: 0 | FC8: 0 | FD8: 0 | FE8: 0 | FF8: 0 | FG8: 0 | FH8: 0 | FI8: 0 | FJ8: 0 | FK8: 0 | FL8: 0 | FM8: 0 | FN8: 0 | FO8: 0 | FP8: 0 | FQ8: 0 | FR8: 0 | FS8: 0 | FT8: 0 | FU8: 0 | FV8: 0 | FW8: 0 | FX8: 0 | FY8: 0 | FZ8: 0 | GA8: 0 | GB8: 0 | GC8: 0 | GD8: 0 | GE8: 0 | GF8: 0 | GG8: 0 | GH8: 0 | GI8: 0 | GJ8: 0 | GK8: 0 | GL8: 0 | GM8: 0 | GN8: 0 | GO8: 0 | GP8: 0 | GQ8: 0 | GR8: 0 | GS8: 0 | GT8: 0 | GU8: 0 | GV8: 0 | GW8: 0 | GX8: 0 | GY8: 0 | GZ8: 0 | HA8: 0 | HB8: 0 | HC8: 0 | HD8: 0 | HE8: 0 | HF8: 0 | HG8: 0 | HH8: 0 | HI8: 0 | HJ8: 0 | HK8: 0 | HL8: 0 | HM8: 0 | HN8: 0 | HO8: 0 | HP8: 0 | HQ8: 0 | HR8: 0 | HS8: 0 | HT8: 0 | HU8: 0 | HV8: 0 | HW8: 0 | HX8: 0 | HY8: 0 | HZ8: 0 | IA8: 0 | IB8: 0 | IC8: 0 | ID8: 0 | IE8: 0 | IF8: 0 | IG8: 0 | IH8: 0 | II8: 0 | IJ8: 0 | IK8: 0 | IL8: 0 | IM8: 0 | IN8: 0 | IO8: 0 | IP8: 0 | IQ8: 0 | IR8: 0 | IS8: 0 | IT8: 0 | IU8: 0 | IV8: 0 | IW8: 0 | IX8: 0 | IY8: 0 | IZ8: 0 | JA8: 0 | JB8: 0 | JC8: 0 | JD8: 0 | JE8: 0 | JF8: 0 | JG8: 0 | JH8: 0 | JI8: 0 | JJ8: 0 | JK8: 0 | JL8: 0 | JM8: 0 | JN8: 0 | JO8: 0 | JP8: 0 | JQ8: 0 | JR8: 0 | JS8: 0 | JT8: 0 | JU8: 0 | JV8: 0 | JW8: 0 | JX8: 0 | JY8: 0 | JZ8: 0 | KA8: 0 | KB8: 0 | KC8: 0 | KD8: 0 | KE8: 0 | KF8: 0 | KG8: 0 | KH8: 0 | KI8: 0 | KJ8: 0 | KK8: 0 | KL8: 0 | KM8: 0 | KN8: 0 | KO8: 0 | KP8: 0 | KQ8: 0 | KR8: 0 | KS8: 0 | KT8: 0 | KU8: 0 | KV8: 0 | KW8: 0 | KX8: 0 | KY8: 0 | KZ8: 0 | LA8: 0 | LB8: 0 | LC8: 0 | LD8: 0 | LE8: 0 | LF8: 0 | LG8: 0 | LH8: 0 | LI8: 0 | LJ8: 0 | LK8: 0 | LL8: 0 | LM8: 0 | LN8: 0 | LO8: 0 | LP8: 0 | LQ8: 0 | LR8: 0 | LS8: 0 | LT8: 0 | LU8: 0 | LV8: 0 | LW8: 0 | LX8: 0 | LY8: 0 | LZ8: 0 | MA8: 0 | MB8: 0 | MC8: 0 | MD8: 0 | ME8: 0 | MF8: 0 | MG8: 0 | MH8: 0 | MI8: 0 | MJ8: 0 | MK8: 0 | ML8: 0 | MM8: 0 | MN8: 0 | MO8: 0 | MP8: 1 | MQ8: 1 | MR8: 0 | MS8: 0 | MT8: 0 | MU8: 0 | MV8: 0 | MW8: 0 | MX8: 0 | MY8: 0 | MZ8: 0 | NA8: 0 | NB8: 0 | NC8: 0 | ND8: 0 | NE8: 0 | NF8: 1 | NG8: 1 | NH8: 2
A9: Region XI | B9: Mati City | C9: DAVAO ORIENTAL | D9: CITY OF MATI (Capital) | E9: 129377 | F9: Bagong Lipunan Improvement Site and Services Elementary School | G9: DepED Managed | H9: Public | I9: Kinder & Grade 1-6 | J9: School with no Annexes | K9: Purely ES | L9: 0 | M9: 0 | N9: 0 | O9: 0 | P9: 0 | Q9: 0 | R9: 0 | S9: 0 | T9: 0 | U9: 0 | V9: 0 | W9: 0 | X9: 0 | Y9: 0 | Z9: 0 | AA9: 0 | AB9: 0 | AC9: 0 | AD9: 0 | AE9: 0 | AF9: 0 | AG9: 0 | AH9: 0 | AI9: 0 | AJ9: 0 | AK9: 0 | AL9: 0 | AM9: 0 | AN9: 0 | AO9: 0 | AP9: 0 | AQ9: 0 | AR9: 1 | AS9: 0 | AT9: 0 | AU9: 0 | AV9: 1 | AW9: 1 | AX9: 0 | AY9: 0 | AZ9: 0 | BA9: 0 | BB9: 1 | BC9: 0 | BD9: 0 | BE9: 0 | BF9: 0 | BG9: 0 | BH9: 0 | BI9: 0 | BJ9: 0 | BK9: 0 | BL9: 0 | BM9: 0 | BN9: 1 | BO9: 0 | BP9: 1 | BQ9: 1 | BR9: 1 | BS9: 0 | BT9: 0 | BU9: 0 | BV9: 0 | BW9: 0 | BX9: 0 | BY9: 0 | BZ9: 0 | CA9: 0 | CB9: 0 | CC9: 1 | CD9: 0 | CE9: 0 | CF9: 0 | CG9: 2 | CH9: 1 | CI9: 3 | CJ9: 0 | CK9: 0 | CL9: 0 | CM9: 0 | CN9: 0 | CO9: 0 | CP9: 0 | CQ9: 0 | CR9: 0 | CS9: 0 | CT9: 0 | CU9: 0 | CV9: 0 | CW9: 0 | CX9: 0 | CY9: 0 | CZ9: 0 | DA9: 0 | DB9: 0 | DC9: 0 | DD9: 0 | DE9: 0 | DF9: 0 | DG9: 0 | DH9: 0 | DI9: 0 | DJ9: 0 | DK9: 0 | DL9: 0 | DM9: 0 | DN9: 0 | DO9: 0 | DP9: 0 | DQ9: 0 | DR9: 0 | DS9: 0 | DT9: 0 | DU9: 0 | DV9: 0 | DW9: 0 | DX9: 0 | DY9: 0 | DZ9: 0 | EA9: 0 | EB9: 0 | EC9: 0 | ED9: 0 | EE9: 0 | EF9: 0 | EG9: 0 | EH9: 0 | EI9: 0 | EJ9: 0 | EK9: 0 | EL9: 0 | EM9: 0 | EN9: 0 | EO9: 0 | EP9: 0 | EQ9: 0 | ER9: 0 | ES9: 0 | ET9: 0 | EU9: 0 | EV9: 0 | EW9: 0 | EX9: 0 | EY9: 0 | EZ9: 0 | FA9: 0 | FB9: 0 | FC9: 0 | FD9: 0 | FE9: 0 | FF9: 0 | FG9: 0 | FH9: 1 | FI9: 0 | FJ9: 0 | FK9: 0 | FL9: 1 | FM9: 0 | FN9: 0 | FO9: 0 | FP9: 0 | FQ9: 0 | FR9: 0 | FS9: 0 | FT9: 1 | FU9: 0 | FV9: 0 | FW9: 0 | FX9: 3 | FY9: 0 | FZ9: 3 | GA9: 0 | GB9: 0 | GC9: 0 | GD9: 0 | GE9: 0 | GF9: 0 | GG9: 0 | GH9: 0 | GI9: 0 | GJ9: 0 | GK9: 0 | GL9: 0 | GM9: 0 | GN9: 0 | GO9: 0 | GP9: 0 | GQ9: 0 | GR9: 0 | GS9: 0 | GT9: 0 | GU9: 0 | GV9: 0 | GW9: 0 | GX9: 0 | GY9: 0 | GZ9: 0 | HA9: 0 | HB9: 0 | HC9: 0 | HD9: 0 | HE9: 0 | HF9: 0 | HG9: 0 | HH9: 0 | HI9: 0 | HJ9: 0 | HK9: 0 | HL9: 0 | HM9: 0 | HN9: 0 | HO9: 0 | HP9: 0 | HQ9: 0 | HR9: 0 | HS9: 0 | HT9: 0 | HU9: 0 | HV9: 0 | HW9: 0 | HX9: 0 | HY9: 0 | HZ9: 0 | IA9: 0 | IB9: 0 | IC9: 0 | ID9: 0 | IE9: 0 | IF9: 0 | IG9: 0 | IH9: 0 | II9: 0 | IJ9: 0 | IK9: 0 | IL9: 0 | IM9: 0 | IN9: 0 | IO9: 0 | IP9: 0 | IQ9: 0 | IR9: 2 | IS9: 0 | IT9: 0 | IU9: 0 | IV9: 2 | IW9: 0 | IX9: 2 | IY9: 0 | IZ9: 0 | JA9: 0 | JB9: 0 | JC9: 0 | JD9: 1 | JE9: 0 | JF9: 0 | JG9: 1 | JH9: 0 | JI9: 0 | JJ9: 0 | JK9: 0 | JL9: 0 | JM9: 0 | JN9: 0 | JO9: 1 | JP9: 1 | JQ9: 2 | JR9: 0 | JS9: 0 | JT9: 0 | JU9: 0 | JV9: 0 | JW9: 0 | JX9: 0 | JY9: 0 | JZ9: 0 | KA9: 0 | KB9: 0 | KC9: 0 | KD9: 0 | KE9: 0 | KF9: 0 | KG9: 0 | KH9: 0 | KI9: 0 | KJ9: 0 | KK9: 0 | KL9: 0 | KM9: 0 | KN9: 0 | KO9: 0 | KP9: 0 | KQ9: 0 | KR9: 0 | KS9: 0 | KT9: 0 | KU9: 0 | KV9: 0 | KW9: 0 | KX9: 0 | KY9: 0 | KZ9: 0 | LA9: 0 | LB9: 0 | LC9: 0 | LD9: 0 | LE9: 0 | LF9: 0 | LG9: 0 | LH9: 0 | LI9: 0 | LJ9: 0 | LK9: 0 | LL9: 0 | LM9: 0 | LN9: 0 | LO9: 0 | LP9: 1 | LQ9: 0 | LR9: 0 | LS9: 0 | LT9: 1 | LU9: 0 | LV9: 1 | LW9: 0 | LX9: 0 | LY9: 0 | LZ9: 0 | MA9: 0 | MB9: 0 | MC9: 0 | MD9: 0 | ME9: 0 | MF9: 0 | MG9: 0 | MH9: 0 | MI9: 0 | MJ9: 0 | MK9: 0 | ML9: 0 | MM9: 0 | MN9: 0 | MO9: 0 | MP9: 2 | MQ9: 1 | MR9: 0 | MS9: 0 | MT9: 2 | MU9: 1 | MV9: 0 | MW9: 0 | MX9: 1 | MY9: 0 | MZ9: 0 | NA9: 0 | NB9: 5 | NC9: 1 | ND9: 0 | NE9: 0 | NF9: 10 | NG9: 3 | NH9: 13
A10: Region XI | B10: Mati City | C10: DAVAO ORIENTAL | D10: CITY OF MATI (Capital) | E10: 129380 | F10: Rabat-Rocamora Mati CES I | G10: DepED Managed | H10: Public | I10: Kinder & Grade 1-6 | J10: School with no Annexes | K10: Purely ES | L10: 0 | M10: 0 | N10: 0 | O10: 0 | P10: 0 | Q10: 0 | R10: 0 | S10: 0 | T10: 0 | U10: 0 | V10: 0 | W10: 0 | X10: 0 | Y10: 0 | Z10: 0 | AA10: 0 | AB10: 0 | AC10: 0 | AD10: 0 | AE10: 0 | AF10: 0 | AG10: 0 | AH10: 0 | AI10: 0 | AJ10: 0 | AK10: 0 | AL10: 0 | AM10: 0 | AN10: 0 | AO10: 0 | AP10: 0 | AQ10: 0 | AR10: 0 | AS10: 0 | AT10: 0 | AU10: 0 | AV10: 0 | AW10: 0 | AX10: 2 | AY10: 0 | AZ10: 0 | BA10: 0 | BB10: 1 | BC10: 0 | BD10: 1 | BE10: 0 | BF10: 0 | BG10: 0 | BH10: 0 | BI10: 0 | BJ10: 0 | BK10: 0 | BL10: 0 | BM10: 0 | BN10: 4 | BO10: 0 | BP10: 4 | BQ10: 3 | BR10: 1 | BS10: 0 | BT10: 1 | BU10: 1 | BV10: 0 | BW10: 0 | BX10: 3 | BY10: 0 | BZ10: 0 | CA10: 3 | CB10: 0 | CC10: 0 | CD10: 1 | CE10: 0 | CF10: 0 | CG10: 7 | CH10: 6 | CI10: 13 | CJ10: 1 | CK10: 0 | CL10: 0 | CM10: 0 | CN10: 0 | CO10: 0 | CP10: 0 | CQ10: 0 | CR10: 0 | CS10: 0 | CT10: 0 | CU10: 0 | CV10: 0 | CW10: 0 | CX10: 0 | CY10: 0 | CZ10: 1 | DA10: 0 | DB10: 1 | DC10: 0 | DD10: 0 | DE10: 0 | DF10: 0 | DG10: 0 | DH10: 0 | DI10: 0 | DJ10: 0 | DK10: 0 | DL10: 0 | DM10: 0 | DN10: 0 | DO10: 2 | DP10: 0 | DQ10: 0 | DR10: 0 | DS10: 2 | DT10: 0 | DU10: 2 | DV10: 0 | DW10: 0 | DX10: 0 | DY10: 0 | DZ10: 0 | EA10: 0 | EB10: 0 | EC10: 0 | ED10: 0 | EE10: 0 | EF10: 0 | EG10: 0 | EH10: 0 | EI10: 0 | EJ10: 0 | EK10: 0 | EL10: 0 | EM10: 0 | EN10: 0 | EO10: 0 | EP10: 0 | EQ10: 0 | ER10: 0 | ES10: 0 | ET10: 0 | EU10: 0 | EV10: 1 | EW10: 0 | EX10: 0 | EY10: 0 | EZ10: 0 | FA10: 0 | FB10: 0 | FC10: 0 | FD10: 0 | FE10: 0 | FF10: 1 | FG10: 1 | FH10: 3 | FI10: 0 | FJ10: 4 | FK10: 0 | FL10: 1 | FM10: 2 | FN10: 6 | FO10: 1 | FP10: 0 | FQ10: 0 | FR10: 1 | FS10: 1 | FT10: 2 | FU10: 4 | FV10: 0 | FW10: 0 | FX10: 17 | FY10: 8 | FZ10: 25 | GA10: 0 | GB10: 0 | GC10: 0 | GD10: 0 | GE10: 0 | GF10: 0 | GG10: 0 | GH10: 0 | GI10: 0 | GJ10: 0 | GK10: 0 | GL10: 0 | GM10: 0 | GN10: 0 | GO10: 0 | GP10: 0 | GQ10: 0 | GR10: 0 | GS10: 0 | GT10: 0 | GU10: 0 | GV10: 0 | GW10: 0 | GX10: 0 | GY10: 0 | GZ10: 0 | HA10: 0 | HB10: 0 | HC10: 0 | HD10: 0 | HE10: 0 | HF10: 0 | HG10: 0 | HH10: 0 | HI10: 0 | HJ10: 0 | HK10: 0 | HL10: 0 | HM10: 0 | HN10: 0 | HO10: 0 | HP10: 0 | HQ10: 0 | HR10: 0 | HS10: 0 | HT10: 0 | HU10: 0 | HV10: 0 | HW10: 0 | HX10: 0 | HY10: 0 | HZ10: 0 | IA10: 0 | IB10: 0 | IC10: 0 | ID10: 0 | IE10: 0 | IF10: 0 | IG10: 0 | IH10: 0 | II10: 0 | IJ10: 0 | IK10: 0 | IL10: 0 | IM10: 0 | IN10: 0 | IO10: 0 | IP10: 0 | IQ10: 0 | IR10: 0 | IS10: 0 | IT10: 0 | IU10: 0 | IV10: 0 | IW10: 0 | IX10: 0 | IY10: 0 | IZ10: 0 | JA10: 0 | JB10: 0 | JC10: 0 | JD10: 0 | JE10: 0 | JF10: 0 | JG10: 0 | JH10: 0 | JI10: 0 | JJ10: 0 | JK10: 2 | JL10: 1 | JM10: 0 | JN10: 0 | JO10: 2 | JP10: 1 | JQ10: 3 | JR10: 0 | JS10: 0 | JT10: 0 | JU10: 0 | JV10: 0 | JW10: 0 | JX10: 0 | JY10: 0 | JZ10: 0 | KA10: 0 | KB10: 0 | KC10: 0 | KD10: 0 | KE10: 0 | KF10: 0 | KG10: 0 | KH10: 0 | KI10: 0 | KJ10: 0 | KK10: 0 | KL10: 0 | KM10: 0 | KN10: 0 | KO10: 0 | KP10: 0 | KQ10: 0 | KR10: 0 | KS10: 0 | KT10: 0 | KU10: 0 | KV10: 0 | KW10: 0 | KX10: 0 | KY10: 0 | KZ10: 0 | LA10: 0 | LB10: 0 | LC10: 0 | LD10: 0 | LE10: 0 | LF10: 0 | LG10: 0 | LH10: 0 | LI10: 0 | LJ10: 0 | LK10: 0 | LL10: 0 | LM10: 0 | LN10: 1 | LO10: 0 | LP10: 0 | LQ10: 0 | LR10: 0 | LS10: 0 | LT10: 1 | LU10: 0 | LV10: 1 | LW10: 0 | LX10: 0 | LY10: 0 | LZ10: 0 | MA10: 0 | MB10: 0 | MC10: 0 | MD10: 0 | ME10: 0 | MF10: 0 | MG10: 0 | MH10: 0 | MI10: 0 | MJ10: 0 | MK10: 0 | ML10: 0 | MM10: 0 | MN10: 0 | MO10: 0 | MP10: 9 | MQ10: 1 | MR10: 4 | MS10: 1 | MT10: 3 | MU10: 2 | MV10: 7 | MW10: 5 | MX10: 0 | MY10: 0 | MZ10: 5 | NA10: 1 | NB10: 6 | NC10: 6 | ND10: 0 | NE10: 0 | NF10: 34 | NG10: 16 | NH10: 50
A11: Region XI | B11: Mati City | C11: DAVAO ORIENTAL | D11: CITY OF MATI (Capital) | E11: 129381 | F11: Rabat-Rocamora Mati CES II | G11: DepED Managed | H11: Public | I11: Kinder & Grade 1-6 | J11: School with no Annexes | K11: Purely ES | L11: 0 | M11: 0 | N11: 0 | O11: 0 | P11: 0 | Q11: 0 | R11: 0 | S11: 0 | T11: 0 | U11: 0 | V11: 0 | W11: 0 | X11: 0 | Y11: 0 | Z11: 0 | AA11: 0 | AB11: 0 | AC11: 0 | AD11: 0 | AE11: 0 | AF11: 0 | AG11: 0 | AH11: 0 | AI11: 0 | AJ11: 0 | AK11: 0 | AL11: 0 | AM11: 0 | AN11: 0 | AO11: 0 | AP11: 0 | AQ11: 0 | AR11: 0 | AS11: 0 | AT11: 0 | AU11: 0 | AV11: 0 | AW11: 0 | AX11: 2 | AY11: 0 | AZ11: 0 | BA11: 0 | BB11: 0 | BC11: 0 | BD11: 0 | BE11: 0 | BF11: 0 | BG11: 0 | BH11: 0 | BI11: 0 | BJ11: 0 | BK11: 0 | BL11: 0 | BM11: 0 | BN11: 2 | BO11: 0 | BP11: 2 | BQ11: 2 | BR11: 0 | BS11: 0 | BT11: 0 | BU11: 0 | BV11: 0 | BW11: 0 | BX11: 0 | BY11: 0 | BZ11: 0 | CA11: 0 | CB11: 0 | CC11: 0 | CD11: 0 | CE11: 0 | CF11: 0 | CG11: 2 | CH11: 0 | CI11: 2 | CJ11: 0 | CK11: 0 | CL11: 0 | CM11: 0 | CN11: 0 | CO11: 0 | CP11: 0 | CQ11: 0 | CR11: 0 | CS11: 0 | CT11: 0 | CU11: 0 | CV11: 0 | CW11: 1 | CX11: 0 | CY11: 0 | CZ11: 0 | DA11: 1 | DB11: 1 | DC11: 0 | DD11: 0 | DE11: 0 | DF11: 0 | DG11: 0 | DH11: 0 | DI11: 0 | DJ11: 0 | DK11: 1 | DL11: 0 | DM11: 0 | DN11: 0 | DO11: 0 | DP11: 0 | DQ11: 0 | DR11: 0 | DS11: 1 | DT11: 0 | DU11: 1 | DV11: 0 | DW11: 0 | DX11: 0 | DY11: 0 | DZ11: 0 | EA11: 0 | EB11: 0 | EC11: 0 | ED11: 0 | EE11: 0 | EF11: 0 | EG11: 0 | EH11: 0 | EI11: 0 | EJ11: 0 | EK11: 0 | EL11: 0 | EM11: 0 | EN11: 0 | EO11: 0 | EP11: 0 | EQ11: 0 | ER11: 0 | ES11: 0 | ET11: 0 | EU11: 0 | EV11: 0 | EW11: 0 | EX11: 0 | EY11: 0 | EZ11: 0 | FA11: 0 | FB11: 0 | FC11: 0 | FD11: 0 | FE11: 0 | FF11: 0 | FG11: 0 | FH11: 2 | FI11: 1 | FJ11: 0 | FK11: 0 | FL11: 0 | FM11: 0 | FN11: 0 | FO11: 0 | FP11: 0 | FQ11: 0 | FR11: 0 | FS11: 0 | FT11: 1 | FU11: 0 | FV11: 0 | FW11: 0 | FX11: 3 | FY11: 1 | FZ11: 4 | GA11: 0 | GB11: 0 | GC11: 0 | GD11: 0 | GE11: 0 | GF11: 0 | GG11: 0 | GH11: 0 | GI11: 0 | GJ11: 0 | GK11: 0 | GL11: 0 | GM11: 0 | GN11: 0 | GO11: 0 | GP11: 0 | GQ11: 0 | GR11: 0 | GS11: 0 | GT11: 0 | GU11: 0 | GV11: 0 | GW11: 0 | GX11: 0 | GY11: 0 | GZ11: 0 | HA11: 0 | HB11: 0 | HC11: 0 | HD11: 0 | HE11: 0 | HF11: 0 | HG11: 0 | HH11: 0 | HI11: 0 | HJ11: 0 | HK11: 0 | HL11: 0 | HM11: 0 | HN11: 0 | HO11: 0 | HP11: 0 | HQ11: 0 | HR11: 0 | HS11: 0 | HT11: 0 | HU11: 0 | HV11: 0 | HW11: 0 | HX11: 0 | HY11: 0 | HZ11: 0 | IA11: 0 | IB11: 0 | IC11: 0 | ID11: 0 | IE11: 0 | IF11: 0 | IG11: 0 | IH11: 0 | II11: 0 | IJ11: 0 | IK11: 0 | IL11: 0 | IM11: 0 | IN11: 0 | IO11: 0 | IP11: 0 | IQ11: 0 | IR11: 0 | IS11: 0 | IT11: 0 | IU11: 0 | IV11: 0 | IW11: 0 | IX11: 0 | IY11: 3 | IZ11: 0 | JA11: 0 | JB11: 0 | JC11: 0 | JD11: 0 | JE11: 0 | JF11: 0 | JG11: 0 | JH11: 0 | JI11: 0 | JJ11: 0 | JK11: 0 | JL11: 0 | JM11: 0 | JN11: 0 | JO11: 3 | JP11: 0 | JQ11: 3 | JR11: 0 | JS11: 0 | JT11: 0 | JU11: 0 | JV11: 0 | JW11: 0 | JX11: 0 | JY11: 0 | JZ11: 0 | KA11: 0 | KB11: 0 | KC11: 0 | KD11: 0 | KE11: 0 | KF11: 0 | KG11: 0 | KH11: 0 | KI11: 0 | KJ11: 0 | KK11: 0 | KL11: 0 | KM11: 0 | KN11: 0 | KO11: 0 | KP11: 0 | KQ11: 0 | KR11: 0 | KS11: 0 | KT11: 0 | KU11: 0 | KV11: 0 | KW11: 0 | KX11: 0 | KY11: 0 | KZ11: 0 | LA11: 0 | LB11: 0 | LC11: 0 | LD11: 0 | LE11: 0 | LF11: 0 | LG11: 0 | LH11: 0 | LI11: 0 | LJ11: 0 | LK11: 0 | LL11: 0 | LM11: 0 | LN11: 0 | LO11: 0 | LP11: 0 | LQ11: 0 | LR11: 0 | LS11: 0 | LT11: 0 | LU11: 0 | LV11: 0 | LW11: 0 | LX11: 0 | LY11: 0 | LZ11: 0 | MA11: 0 | MB11: 0 | MC11: 0 | MD11: 0 | ME11: 0 | MF11: 0 | MG11: 0 | MH11: 0 | MI11: 0 | MJ11: 0 | MK11: 0 | ML11: 0 | MM11: 0 | MN11: 0 | MO11: 0 | MP11: 9 | MQ11: 1 | MR11: 0 | MS11: 0 | MT11: 0 | MU11: 0 | MV11: 0 | MW11: 0 | MX11: 1 | MY11: 0 | MZ11: 0 | NA11: 0 | NB11: 1 | NC11: 1 | ND11: 0 | NE11: 0 | NF11: 11 | NG11: 2 | NH11: 13
A12: Region XI | B12: Mati City | C12: DAVAO ORIENTAL | D12: CITY OF MATI (Capital) | E12: 129382 | F12: Mayor Luisito G. Rabat MS | G12: DepED Managed | H12: Public | I12: Kinder & Grade 1-6 | J12: School with no Annexes | K12: Purely ES | L12: 0 | M12: 0 | N12: 0 | O12: 0 | P12: 0 | Q12: 0 | R12: 0 | S12: 0 | T12: 0 | U12: 0 | V12: 0 | W12: 0 | X12: 0 | Y12: 0 | Z12: 0 | AA12: 0 | AB12: 0 | AC12: 0 | AD12: 0 | AE12: 0 | AF12: 0 | AG12: 0 | AH12: 0 | AI12: 0 | AJ12: 0 | AK12: 0 | AL12: 0 | AM12: 0 | AN12: 0 | AO12: 0 | AP12: 0 | AQ12: 0 | AR12: 1 | AS12: 0 | AT12: 0 | AU12: 0 | AV12: 1 | AW12: 1 | AX12: 3 | AY12: 0 | AZ12: 0 | BA12: 0 | BB12: 0 | BC12: 1 | BD12: 0 | BE12: 0 | BF12: 0 | BG12: 1 | BH12: 1 | BI12: 0 | BJ12: 0 | BK12: 0 | BL12: 0 | BM12: 0 | BN12: 4 | BO12: 2 | BP12: 6 | BQ12: 2 | BR12: 0 | BS12: 0 | BT12: 0 | BU12: 3 | BV12: 1 | BW12: 0 | BX12: 1 | BY12: 0 | BZ12: 1 | CA12: 2 | CB12: 0 | CC12: 0 | CD12: 1 | CE12: 0 | CF12: 0 | CG12: 7 | CH12: 4 | CI12: 11 | CJ12: 0 | CK12: 0 | CL12: 0 | CM12: 0 | CN12: 0 | CO12: 0 | CP12: 0 | CQ12: 0 | CR12: 0 | CS12: 0 | CT12: 0 | CU12: 0 | CV12: 0 | CW12: 0 | CX12: 0 | CY12: 0 | CZ12: 0 | DA12: 0 | DB12: 0 | DC12: 0 | DD12: 0 | DE12: 0 | DF12: 0 | DG12: 0 | DH12: 0 | DI12: 0 | DJ12: 0 | DK12: 0 | DL12: 1 | DM12: 0 | DN12: 0 | DO12: 0 | DP12: 0 | DQ12: 0 | DR12: 0 | DS12: 0 | DT12: 1 | DU12: 1 | DV12: 0 | DW12: 0 | DX12: 0 | DY12: 0 | DZ12: 0 | EA12: 0 | EB12: 0 | EC12: 0 | ED12: 0 | EE12: 0 | EF12: 0 | EG12: 0 | EH12: 0 | EI12: 0 | EJ12: 0 | EK12: 0 | EL12: 0 | EM12: 0 | EN12: 0 | EO12: 0 | EP12: 0 | EQ12: 0 | ER12: 0 | ES12: 0 | ET12: 0 | EU12: 0 | EV12: 0 | EW12: 0 | EX12: 0 | EY12: 1 | EZ12: 0 | FA12: 0 | FB12: 1 | FC12: 0 | FD12: 0 | FE12: 1 | FF12: 1 | FG12: 2 | FH12: 3 | FI12: 3 | FJ12: 1 | FK12: 0 | FL12: 5 | FM12: 0 | FN12: 1 | FO12: 0 | FP12: 1 | FQ12: 2 | FR12: 4 | FS12: 1 | FT12: 7 | FU12: 0 | FV12: 0 | FW12: 0 | FX12: 22 | FY12: 6 | FZ12: 28 | GA12: 0 | GB12: 0 | GC12: 0 | GD12: 0 | GE12: 0 | GF12: 0 | GG12: 0 | GH12: 0 | GI12: 0 | GJ12: 0 | GK12: 0 | GL12: 0 | GM12: 0 | GN12: 0 | GO12: 0 | GP12: 0 | GQ12: 0 | GR12: 0 | GS12: 0 | GT12: 0 | GU12: 0 | GV12: 0 | GW12: 0 | GX12: 0 | GY12: 0 | GZ12: 0 | HA12: 0 | HB12: 0 | HC12: 0 | HD12: 0 | HE12: 0 | HF12: 0 | HG12: 0 | HH12: 0 | HI12: 0 | HJ12: 0 | HK12: 0 | HL12: 0 | HM12: 0 | HN12: 0 | HO12: 0 | HP12: 0 | HQ12: 0 | HR12: 0 | HS12: 0 | HT12: 0 | HU12: 0 | HV12: 0 | HW12: 0 | HX12: 0 | HY12: 0 | HZ12: 0 | IA12: 0 | IB12: 0 | IC12: 0 | ID12: 0 | IE12: 0 | IF12: 0 | IG12: 0 | IH12: 0 | II12: 0 | IJ12: 0 | IK12: 0 | IL12: 0 | IM12: 0 | IN12: 0 | IO12: 0 | IP12: 0 | IQ12: 0 | IR12: 0 | IS12: 0 | IT12: 0 | IU12: 0 | IV12: 0 | IW12: 0 | IX12: 0 | IY12: 1 | IZ12: 0 | JA12: 0 | JB12: 0 | JC12: 0 | JD12: 0 | JE12: 0 | JF12: 0 | JG12: 1 | JH12: 1 | JI12: 0 | JJ12: 0 | JK12: 0 | JL12: 0 | JM12: 0 | JN12: 0 | JO12: 2 | JP12: 1 | JQ12: 3 | JR12: 0 | JS12: 0 | JT12: 0 | JU12: 0 | JV12: 0 | JW12: 0 | JX12: 0 | JY12: 0 | JZ12: 0 | KA12: 0 | KB12: 0 | KC12: 0 | KD12: 0 | KE12: 0 | KF12: 0 | KG12: 0 | KH12: 0 | KI12: 0 | KJ12: 0 | KK12: 0 | KL12: 0 | KM12: 0 | KN12: 0 | KO12: 0 | KP12: 0 | KQ12: 0 | KR12: 0 | KS12: 0 | KT12: 0 | KU12: 0 | KV12: 0 | KW12: 0 | KX12: 0 | KY12: 0 | KZ12: 0 | LA12: 0 | LB12: 0 | LC12: 0 | LD12: 0 | LE12: 0 | LF12: 0 | LG12: 0 | LH12: 0 | LI12: 0 | LJ12: 0 | LK12: 0 | LL12: 1 | LM12: 0 | LN12: 0 | LO12: 0 | LP12: 0 | LQ12: 0 | LR12: 0 | LS12: 0 | LT12: 1 | LU12: 0 | LV12: 1 | LW12: 0 | LX12: 0 | LY12: 0 | LZ12: 0 | MA12: 0 | MB12: 0 | MC12: 0 | MD12: 0 | ME12: 0 | MF12: 0 | MG12: 0 | MH12: 0 | MI12: 0 | MJ12: 0 | MK12: 0 | ML12: 0 | MM12: 0 | MN12: 0 | MO12: 0 | MP12: 9 | MQ12: 3 | MR12: 1 | MS12: 0 | MT12: 8 | MU12: 2 | MV12: 1 | MW12: 1 | MX12: 3 | MY12: 6 | MZ12: 8 | NA12: 1 | NB12: 7 | NC12: 3 | ND12: 0 | NE12: 0 | NF12: 37 | NG12: 16 | NH12: 53
A13: Region XI | B13: Mati City | C13: DAVAO ORIENTAL | D13: CITY OF MATI (Capital) | E13: 129383 | F13: Mayor Santiago Garcia MS | G13: DepED Managed | H13: Public | I13: Kinder & Grade 1-6 | J13: School with no Annexes | K13: Purely ES | L13: 0 | M13: 0 | N13: 0 | O13: 0 | P13: 0 | Q13: 0 | R13: 0 | S13: 0 | T13: 0 | U13: 0 | V13: 0 | W13: 0 | X13: 0 | Y13: 0 | Z13: 0 | AA13: 0 | AB13: 0 | AC13: 0 | AD13: 0 | AE13: 0 | AF13: 0 | AG13: 0 | AH13: 0 | AI13: 0 | AJ13: 0 | AK13: 0 | AL13: 0 | AM13: 0 | AN13: 0 | AO13: 0 | AP13: 0 | AQ13: 0 | AR13: 0 | AS13: 0 | AT13: 0 | AU13: 0 | AV13: 0 | AW13: 0 | AX13: 0 | AY13: 0 | AZ13: 0 | BA13: 0 | BB13: 0 | BC13: 0 | BD13: 0 | BE13: 0 | BF13: 0 | BG13: 0 | BH13: 0 | BI13: 0 | BJ13: 0 | BK13: 0 | BL13: 0 | BM13: 0 | BN13: 0 | BO13: 0 | BP13: 0 | BQ13: 0 | BR13: 0 | BS13: 0 | BT13: 0 | BU13: 0 | BV13: 0 | BW13: 0 | BX13: 0 | BY13: 1 | BZ13: 0 | CA13: 0 | CB13: 0 | CC13: 2 | CD13: 0 | CE13: 0 | CF13: 0 | CG13: 3 | CH13: 0 | CI13: 3 | CJ13: 0 | CK13: 0 | CL13: 0 | CM13: 0 | CN13: 0 | CO13: 0 | CP13: 0 | CQ13: 0 | CR13: 1 | CS13: 0 | CT13: 0 | CU13: 0 | CV13: 0 | CW13: 0 | CX13: 0 | CY13: 0 | CZ13: 1 | DA13: 0 | DB13: 1 | DC13: 0 | DD13: 0 | DE13: 0 | DF13: 0 | DG13: 0 | DH13: 0 | DI13: 0 | DJ13: 0 | DK13: 0 | DL13: 0 | DM13: 0 | DN13: 0 | DO13: 0 | DP13: 0 | DQ13: 0 | DR13: 0 | DS13: 0 | DT13: 0 | DU13: 0 | DV13: 0 | DW13: 0 | DX13: 0 | DY13: 0 | DZ13: 0 | EA13: 0 | EB13: 0 | EC13: 0 | ED13: 0 | EE13: 0 | EF13: 0 | EG13: 0 | EH13: 0 | EI13: 0 | EJ13: 0 | EK13: 0 | EL13: 0 | EM13: 0 | EN13: 0 | EO13: 0 | EP13: 0 | EQ13: 1 | ER13: 0 | ES13: 0 | ET13: 0 | EU13: 0 | EV13: 0 | EW13: 0 | EX13: 0 | EY13: 0 | EZ13: 0 | FA13: 2 | FB13: 0 | FC13: 0 | FD13: 0 | FE13: 3 | FF13: 0 | FG13: 3 | FH13: 9 | FI13: 1 | FJ13: 5 | FK13: 0 | FL13: 3 | FM13: 3 | FN13: 3 | FO13: 1 | FP13: 3 | FQ13: 1 | FR13: 7 | FS13: 1 | FT13: 6 | FU13: 0 | FV13: 0 | FW13: 0 | FX13: 36 | FY13: 7 | FZ13: 43 | GA13: 0 | GB13: 0 | GC13: 0 | GD13: 0 | GE13: 0 | GF13: 0 | GG13: 0 | GH13: 0 | GI13: 0 | GJ13: 0 | GK13: 0 | GL13: 0 | GM13: 0 | GN13: 0 | GO13: 0 | GP13: 0 | GQ13: 0 | GR13: 0 | GS13: 0 | GT13: 0 | GU13: 0 | GV13: 0 | GW13: 0 | GX13: 0 | GY13: 0 | GZ13: 0 | HA13: 0 | HB13: 0 | HC13: 0 | HD13: 0 | HE13: 0 | HF13: 0 | HG13: 0 | HH13: 0 | HI13: 0 | HJ13: 0 | HK13: 0 | HL13: 0 | HM13: 0 | HN13: 0 | HO13: 0 | HP13: 0 | HQ13: 0 | HR13: 0 | HS13: 0 | HT13: 0 | HU13: 0 | HV13: 0 | HW13: 0 | HX13: 0 | HY13: 0 | HZ13: 0 | IA13: 0 | IB13: 0 | IC13: 0 | ID13: 0 | IE13: 0 | IF13: 0 | IG13: 0 | IH13: 0 | II13: 0 | IJ13: 0 | IK13: 0 | IL13: 0 | IM13: 0 | IN13: 0 | IO13: 0 | IP13: 0 | IQ13: 0 | IR13: 0 | IS13: 0 | IT13: 0 | IU13: 0 | IV13: 0 | IW13: 0 | IX13: 0 | IY13: 0 | IZ13: 0 | JA13: 0 | JB13: 0 | JC13: 0 | JD13: 0 | JE13: 0 | JF13: 0 | JG13: 0 | JH13: 0 | JI13: 0 | JJ13: 0 | JK13: 1 | JL13: 0 | JM13: 0 | JN13: 0 | JO13: 1 | JP13: 0 | JQ13: 1 | JR13: 0 | JS13: 0 | JT13: 0 | JU13: 0 | JV13: 0 | JW13: 0 | JX13: 0 | JY13: 0 | JZ13: 0 | KA13: 0 | KB13: 0 | KC13: 0 | KD13: 0 | KE13: 0 | KF13: 0 | KG13: 0 | KH13: 0 | KI13: 0 | KJ13: 0 | KK13: 0 | KL13: 0 | KM13: 0 | KN13: 0 | KO13: 0 | KP13: 0 | KQ13: 0 | KR13: 0 | KS13: 0 | KT13: 0 | KU13: 0 | KV13: 0 | KW13: 0 | KX13: 0 | KY13: 0 | KZ13: 0 | LA13: 0 | LB13: 0 | LC13: 0 | LD13: 0 | LE13: 0 | LF13: 0 | LG13: 0 | LH13: 0 | LI13: 0 | LJ13: 0 | LK13: 0 | LL13: 0 | LM13: 0 | LN13: 0 | LO13: 0 | LP13: 0 | LQ13: 0 | LR13: 0 | LS13: 0 | LT13: 0 | LU13: 0 | LV13: 0 | LW13: 0 | LX13: 0 | LY13: 0 | LZ13: 0 | MA13: 0 | MB13: 0 | MC13: 0 | MD13: 0 | ME13: 0 | MF13: 0 | MG13: 0 | MH13: 0 | MI13: 0 | MJ13: 0 | MK13: 0 | ML13: 0 | MM13: 0 | MN13: 0 | MO13: 0 | MP13: 9 | MQ13: 1 | MR13: 6 | MS13: 0 | MT13: 3 | MU13: 3 | MV13: 3 | MW13: 1 | MX13: 5 | MY13: 1 | MZ13: 7 | NA13: 1 | NB13: 11 | NC13: 0 | ND13: 0 | NE13: 0 | NF13: 44 | NG13: 7 | NH13: 51
A14: Region XI | B14: Mati City | C14: DAVAO ORIENTAL | D14: CITY OF MATI (Capital) | E14: 129384 | F14: Sudlon Elementary School | G14: DepED Managed | H14: Public | I14: Kinder & Grade 1-6 | J14: School with no Annexes | K14: Purely ES | L14: 0 | M14: 0 | N14: 0 | O14: 0 | P14: 0 | Q14: 0 | R14: 0 | S14: 0 | T14: 0 | U14: 0 | V14: 0 | W14: 0 | X14: 0 | Y14: 0 | Z14: 0 | AA14: 0 | AB14: 0 | AC14: 0 | AD14: 0 | AE14: 0 | AF14: 0 | AG14: 0 | AH14: 0 | AI14: 0 | AJ14: 0 | AK14: 0 | AL14: 0 | AM14: 0 | AN14: 0 | AO14: 0 | AP14: 0 | AQ14: 0 | AR14: 0 | AS14: 0 | AT14: 0 | AU14: 0 | AV14: 0 | AW14: 0 | AX14: 0 | AY14: 0 | AZ14: 0 | BA14: 0 | BB14: 0 | BC14: 0 | BD14: 0 | BE14: 0 | BF14: 0 | BG14: 0 | BH14: 0 | BI14: 0 | BJ14: 0 | BK14: 0 | BL14: 0 | BM14: 0 | BN14: 0 | BO14: 0 | BP14: 0 | BQ14: 0 | BR14: 0 | BS14: 0 | BT14: 0 | BU14: 0 | BV14: 0 | BW14: 0 | BX14: 0 | BY14: 0 | BZ14: 0 | CA14: 0 | CB14: 0 | CC14: 0 | CD14: 0 | CE14: 0 | CF14: 0 | CG14: 0 | CH14: 0 | CI14: 0 | CJ14: 0 | CK14: 0 | CL14: 0 | CM14: 0 | CN14: 0 | CO14: 0 | CP14: 0 | CQ14: 0 | CR14: 0 | CS14: 0 | CT14: 0 | CU14: 0 | CV14: 0 | CW14: 0 | CX14: 0 | CY14: 0 | CZ14: 0 | DA14: 0 | DB14: 0 | DC14: 0 | DD14: 0 | DE14: 0 | DF14: 0 | DG14: 0 | DH14: 0 | DI14: 0 | DJ14: 0 | DK14: 0 | DL14: 0 | DM14: 0 | DN14: 0 | DO14: 0 | DP14: 0 | DQ14: 0 | DR14: 0 | DS14: 0 | DT14: 0 | DU14: 0 | DV14: 0 | DW14: 0 | DX14: 0 | DY14: 0 | DZ14: 0 | EA14: 0 | EB14: 0 | EC14: 0 | ED14: 0 | EE14: 0 | EF14: 0 | EG14: 0 | EH14: 0 | EI14: 0 | EJ14: 0 | EK14: 0 | EL14: 0 | EM14: 0 | EN14: 0 | EO14: 0 | EP14: 0 | EQ14: 0 | ER14: 0 | ES14: 0 | ET14: 0 | EU14: 0 | EV14: 0 | EW14: 0 | EX14: 0 | EY14: 0 | EZ14: 0 | FA14: 0 | FB14: 0 | FC14: 0 | FD14: 0 | FE14: 0 | FF14: 0 | FG14: 0 | FH14: 0 | FI14: 0 | FJ14: 0 | FK14: 0 | FL14: 0 | FM14: 0 | FN14: 0 | FO14: 0 | FP14: 1 | FQ14: 0 | FR14: 0 | FS14: 0 | FT14: 2 | FU14: 0 | FV14: 0 | FW14: 0 | FX14: 3 | FY14: 0 | FZ14: 3 | GA14: 0 | GB14: 0 | GC14: 0 | GD14: 0 | GE14: 0 | GF14: 0 | GG14: 0 | GH14: 0 | GI14: 0 | GJ14: 0 | GK14: 0 | GL14: 0 | GM14: 0 | GN14: 0 | GO14: 0 | GP14: 0 | GQ14: 0 | GR14: 0 | GS14: 0 | GT14: 0 | GU14: 0 | GV14: 0 | GW14: 0 | GX14: 0 | GY14: 0 | GZ14: 0 | HA14: 0 | HB14: 0 | HC14: 0 | HD14: 0 | HE14: 0 | HF14: 0 | HG14: 0 | HH14: 0 | HI14: 0 | HJ14: 0 | HK14: 0 | HL14: 0 | HM14: 0 | HN14: 0 | HO14: 0 | HP14: 0 | HQ14: 0 | HR14: 0 | HS14: 0 | HT14: 0 | HU14: 0 | HV14: 0 | HW14: 0 | HX14: 0 | HY14: 0 | HZ14: 0 | IA14: 0 | IB14: 0 | IC14: 0 | ID14: 0 | IE14: 0 | IF14: 0 | IG14: 0 | IH14: 0 | II14: 0 | IJ14: 0 | IK14: 0 | IL14: 0 | IM14: 0 | IN14: 0 | IO14: 0 | IP14: 0 | IQ14: 0 | IR14: 0 | IS14: 0 | IT14: 0 | IU14: 0 | IV14: 0 | IW14: 0 | IX14: 0 | IY14: 0 | IZ14: 0 | JA14: 0 | JB14: 0 | JC14: 0 | JD14: 0 | JE14: 0 | JF14: 0 | JG14: 0 | JH14: 0 | JI14: 0 | JJ14: 0 | JK14: 0 | JL14: 0 | JM14: 0 | JN14: 0 | JO14: 0 | JP14: 0 | JQ14: 0 | JR14: 0 | JS14: 0 | JT14: 0 | JU14: 0 | JV14: 0 | JW14: 0 | JX14: 0 | JY14: 0 | JZ14: 0 | KA14: 0 | KB14: 0 | KC14: 0 | KD14: 0 | KE14: 0 | KF14: 0 | KG14: 0 | KH14: 0 | KI14: 0 | KJ14: 0 | KK14: 0 | KL14: 0 | KM14: 0 | KN14: 0 | KO14: 0 | KP14: 0 | KQ14: 0 | KR14: 0 | KS14: 0 | KT14: 0 | KU14: 0 | KV14: 0 | KW14: 0 | KX14: 0 | KY14: 0 | KZ14: 0 | LA14: 0 | LB14: 0 | LC14: 0 | LD14: 0 | LE14: 0 | LF14: 0 | LG14: 0 | LH14: 0 | LI14: 0 | LJ14: 0 | LK14: 0 | LL14: 0 | LM14: 0 | LN14: 0 | LO14: 0 | LP14: 0 | LQ14: 0 | LR14: 0 | LS14: 0 | LT14: 0 | LU14: 0 | LV14: 0 | LW14: 0 | LX14: 0 | LY14: 0 | LZ14: 0 | MA14: 0 | MB14: 0 | MC14: 0 | MD14: 0 | ME14: 0 | MF14: 0 | MG14: 0 | MH14: 0 | MI14: 0 | MJ14: 0 | MK14: 0 | ML14: 0 | MM14: 0 | MN14: 0 | MO14: 0 | MP14: 0 | MQ14: 0 | MR14: 0 | MS14: 0 | MT14: 0 | MU14: 0 | MV14: 0 | MW14: 0 | MX14: 1 | MY14: 0 | MZ14: 0 | NA14: 0 | NB14: 2 | NC14: 0 | ND14: 0 | NE14: 0 | NF14: 3 | NG14: 0 | NH14: 3
A15: Region XI | B15: Mati City | C15: DAVAO ORIENTAL | D15: CITY OF MATI (Capital) | E15: 129385 | F15: Tagawisan ES | G15: DepED Managed | H15: Public | I15: Kinder & Grade 1-6 | J15: School with no Annexes | K15: Purely ES | L15: 0 | M15: 0 | N15: 0 | O15: 0 | P15: 0 | Q15: 0 | R15: 0 | S15: 0 | T15: 0 | U15: 0 | V15: 0 | W15: 0 | X15: 0 | Y15: 0 | Z15: 0 | AA15: 0 | AB15: 0 | AC15: 0 | AD15: 0 | AE15: 0 | AF15: 0 | AG15: 0 | AH15: 0 | AI15: 0 | AJ15: 0 | AK15: 0 | AL15: 0 | AM15: 0 | AN15: 0 | AO15: 0 | AP15: 0 | AQ15: 0 | AR15: 0 | AS15: 0 | AT15: 0 | AU15: 0 | AV15: 0 | AW15: 0 | AX15: 0 | AY15: 3 | AZ15: 1 | BA15: 1 | BB15: 1 | BC15: 0 | BD15: 0 | BE15: 0 | BF15: 0 | BG15: 0 | BH15: 0 | BI15: 0 | BJ15: 0 | BK15: 0 | BL15: 0 | BM15: 0 | BN15: 2 | BO15: 4 | BP15: 6 | BQ15: 0 | BR15: 0 | BS15: 0 | BT15: 1 | BU15: 0 | BV15: 0 | BW15: 1 | BX15: 0 | BY15: 3 | BZ15: 2 | CA15: 2 | CB15: 1 | CC15: 2 | CD15: 1 | CE15: 0 | CF15: 0 | CG15: 8 | CH15: 5 | CI15: 13 | CJ15: 0 | CK15: 0 | CL15: 0 | CM15: 0 | CN15: 0 | CO15: 0 | CP15: 0 | CQ15: 0 | CR15: 2 | CS15: 0 | CT15: 0 | CU15: 0 | CV15: 0 | CW15: 0 | CX15: 0 | CY15: 0 | CZ15: 2 | DA15: 0 | DB15: 2 | DC15: 0 | DD15: 0 | DE15: 0 | DF15: 0 | DG15: 0 | DH15: 0 | DI15: 0 | DJ15: 0 | DK15: 0 | DL15: 0 | DM15: 0 | DN15: 0 | DO15: 0 | DP15: 0 | DQ15: 0 | DR15: 0 | DS15: 0 | DT15: 0 | DU15: 0 | DV15: 0 | DW15: 0 | DX15: 0 | DY15: 0 | DZ15: 0 | EA15: 0 | EB15: 0 | EC15: 0 | ED15: 0 | EE15: 0 | EF15: 0 | EG15: 0 | EH15: 0 | EI15: 0 | EJ15: 0 | EK15: 0 | EL15: 0 | EM15: 0 | EN15: 0 | EO15: 0 | EP15: 0 | EQ15: 0 | ER15: 0 | ES15: 0 | ET15: 0 | EU15: 0 | EV15: 0 | EW15: 0 | EX15: 0 | EY15: 0 | EZ15: 0 | FA15: 0 | FB15: 0 | FC15: 0 | FD15: 0 | FE15: 0 | FF15: 0 | FG15: 0 | FH15: 0 | FI15: 0 | FJ15: 1 | FK15: 0 | FL15: 1 | FM15: 0 | FN15: 0 | FO15: 3 | FP15: 1 | FQ15: 0 | FR15: 0 | FS15: 0 | FT15: 0 | FU15: 0 | FV15: 0 | FW15: 0 | FX15: 3 | FY15: 3 | FZ15: 6 | GA15: 0 | GB15: 0 | GC15: 0 | GD15: 0 | GE15: 0 | GF15: 0 | GG15: 0 | GH15: 0 | GI15: 0 | GJ15: 0 | GK15: 0 | GL15: 0 | GM15: 0 | GN15: 0 | GO15: 0 | GP15: 0 | GQ15: 0 | GR15: 0 | GS15: 0 | GT15: 0 | GU15: 0 | GV15: 0 | GW15: 0 | GX15: 0 | GY15: 0 | GZ15: 0 | HA15: 0 | HB15: 0 | HC15: 0 | HD15: 0 | HE15: 0 | HF15: 0 | HG15: 0 | HH15: 0 | HI15: 0 | HJ15: 0 | HK15: 0 | HL15: 0 | HM15: 0 | HN15: 0 | HO15: 0 | HP15: 0 | HQ15: 0 | HR15: 0 | HS15: 0 | HT15: 0 | HU15: 0 | HV15: 0 | HW15: 0 | HX15: 0 | HY15: 0 | HZ15: 0 | IA15: 0 | IB15: 0 | IC15: 0 | ID15: 0 | IE15: 0 | IF15: 0 | IG15: 0 | IH15: 0 | II15: 0 | IJ15: 0 | IK15: 0 | IL15: 0 | IM15: 0 | IN15: 0 | IO15: 0 | IP15: 0 | IQ15: 0 | IR15: 0 | IS15: 0 | IT15: 0 | IU15: 0 | IV15: 0 | IW15: 0 | IX15: 0 | IY15: 0 | IZ15: 0 | JA15: 0 | JB15: 0 | JC15: 0 | JD15: 0 | JE15: 0 | JF15: 0 | JG15: 0 | JH15: 0 | JI15: 0 | JJ15: 0 | JK15: 0 | JL15: 0 | JM15: 0 | JN15: 0 | JO15: 0 | JP15: 0 | JQ15: 0 | JR15: 0 | JS15: 0 | JT15: 0 | JU15: 0 | JV15: 0 | JW15: 0 | JX15: 0 | JY15: 0 | JZ15: 0 | KA15: 0 | KB15: 0 | KC15: 0 | KD15: 0 | KE15: 0 | KF15: 0 | KG15: 0 | KH15: 0 | KI15: 0 | KJ15: 0 | KK15: 0 | KL15: 0 | KM15: 0 | KN15: 0 | KO15: 0 | KP15: 0 | KQ15: 0 | KR15: 0 | KS15: 0 | KT15: 0 | KU15: 0 | KV15: 0 | KW15: 0 | KX15: 0 | KY15: 0 | KZ15: 0 | LA15: 0 | LB15: 0 | LC15: 0 | LD15: 0 | LE15: 0 | LF15: 0 | LG15: 0 | LH15: 0 | LI15: 0 | LJ15: 0 | LK15: 0 | LL15: 0 | LM15: 0 | LN15: 0 | LO15: 0 | LP15: 0 | LQ15: 0 | LR15: 0 | LS15: 0 | LT15: 0 | LU15: 0 | LV15: 0 | LW15: 0 | LX15: 0 | LY15: 0 | LZ15: 0 | MA15: 0 | MB15: 0 | MC15: 0 | MD15: 0 | ME15: 0 | MF15: 0 | MG15: 0 | MH15: 0 | MI15: 0 | MJ15: 0 | MK15: 0 | ML15: 0 | MM15: 0 | MN15: 0 | MO15: 0 | MP15: 0 | MQ15: 3 | MR15: 2 | MS15: 2 | MT15: 2 | MU15: 0 | MV15: 1 | MW15: 3 | MX15: 6 | MY15: 2 | MZ15: 2 | NA15: 1 | NB15: 2 | NC15: 1 | ND15: 0 | NE15: 0 | NF15: 15 | NG15: 12 | NH15: 27
A16: Region XI | B16: Mati City | C16: DAVAO ORIENTAL | D16: CITY OF MATI (Capital) | E16: 129386 | F16: Onotan Daganio Tagbobolo ES | G16: DepED Managed | H16: Public | I16: Kinder & Grade 1-6 | J16: School with no Annexes | K16: Purely ES | L16: 0 | M16: 0 | N16: 0 | O16: 0 | P16: 0 | Q16: 0 | R16: 0 | S16: 0 | T16: 0 | U16: 0 | V16: 0 | W16: 0 | X16: 0 | Y16: 0 | Z16: 0 | AA16: 0 | AB16: 0 | AC16: 0 | AD16: 0 | AE16: 0 | AF16: 0 | AG16: 0 | AH16: 0 | AI16: 0 | AJ16: 0 | AK16: 0 | AL16: 0 | AM16: 0 | AN16: 0 | AO16: 0 | AP16: 0 | AQ16: 0 | AR16: 0 | AS16: 0 | AT16: 0 | AU16: 0 | AV16: 0 | AW16: 0 | AX16: 0 | AY16: 0 | AZ16: 0 | BA16: 0 | BB16: 0 | BC16: 0 | BD16: 0 | BE16: 0 | BF16: 0 | BG16: 0 | BH16: 0 | BI16: 0 | BJ16: 0 | BK16: 0 | BL16: 0 | BM16: 0 | BN16: 0 | BO16: 0 | BP16: 0 | BQ16: 0 | BR16: 0 | BS16: 0 | BT16: 0 | BU16: 0 | BV16: 0 | BW16: 0 | BX16: 0 | BY16: 0 | BZ16: 0 | CA16: 0 | CB16: 0 | CC16: 0 | CD16: 0 | CE16: 0 | CF16: 0 | CG16: 0 | CH16: 0 | CI16: 0 | CJ16: 0 | CK16: 0 | CL16: 0 | CM16: 0 | CN16: 0 | CO16: 0 | CP16: 0 | CQ16: 0 | CR16: 0 | CS16: 0 | CT16: 0 | CU16: 0 | CV16: 0 | CW16: 0 | CX16: 0 | CY16: 0 | CZ16: 0 | DA16: 0 | DB16: 0 | DC16: 0 | DD16: 0 | DE16: 0 | DF16: 0 | DG16: 0 | DH16: 0 | DI16: 0 | DJ16: 0 | DK16: 0 | DL16: 0 | DM16: 0 | DN16: 0 | DO16: 0 | DP16: 0 | DQ16: 0 | DR16: 0 | DS16: 0 | DT16: 0 | DU16: 0 | DV16: 0 | DW16: 0 | DX16: 0 | DY16: 0 | DZ16: 0 | EA16: 0 | EB16: 0 | EC16: 0 | ED16: 0 | EE16: 0 | EF16: 0 | EG16: 0 | EH16: 0 | EI16: 0 | EJ16: 0 | EK16: 0 | EL16: 0 | EM16: 0 | EN16: 0 | EO16: 0 | EP16: 0 | EQ16: 0 | ER16: 0 | ES16: 0 | ET16: 0 | EU16: 0 | EV16: 0 | EW16: 0 | EX16: 0 | EY16: 0 | EZ16: 0 | FA16: 0 | FB16: 0 | FC16: 0 | FD16: 0 | FE16: 0 | FF16: 0 | FG16: 0 | FH16: 0 | FI16: 0 | FJ16: 0 | FK16: 0 | FL16: 0 | FM16: 0 | FN16: 0 | FO16: 0 | FP16: 0 | FQ16: 0 | FR16: 0 | FS16: 0 | FT16: 0 | FU16: 0 | FV16: 0 | FW16: 0 | FX16: 0 | FY16: 0 | FZ16: 0 | GA16: 0 | GB16: 0 | GC16: 0 | GD16: 0 | GE16: 0 | GF16: 0 | GG16: 0 | GH16: 0 | GI16: 0 | GJ16: 0 | GK16: 0 | GL16: 0 | GM16: 0 | GN16: 0 | GO16: 0 | GP16: 0 | GQ16: 0 | GR16: 0 | GS16: 0 | GT16: 0 | GU16: 0 | GV16: 0 | GW16: 0 | GX16: 0 | GY16: 0 | GZ16: 0 | HA16: 0 | HB16: 0 | HC16: 0 | HD16: 0 | HE16: 0 | HF16: 0 | HG16: 0 | HH16: 0 | HI16: 0 | HJ16: 0 | HK16: 0 | HL16: 0 | HM16: 0 | HN16: 0 | HO16: 0 | HP16: 0 | HQ16: 0 | HR16: 0 | HS16: 0 | HT16: 0 | HU16: 0 | HV16: 0 | HW16: 0 | HX16: 0 | HY16: 0 | HZ16: 0 | IA16: 0 | IB16: 0 | IC16: 0 | ID16: 0 | IE16: 0 | IF16: 0 | IG16: 0 | IH16: 0 | II16: 0 | IJ16: 0 | IK16: 0 | IL16: 0 | IM16: 0 | IN16: 0 | IO16: 0 | IP16: 0 | IQ16: 0 | IR16: 0 | IS16: 0 | IT16: 0 | IU16: 0 | IV16: 0 | IW16: 0 | IX16: 0 | IY16: 0 | IZ16: 0 | JA16: 0 | JB16: 0 | JC16: 0 | JD16: 0 | JE16: 0 | JF16: 0 | JG16: 0 | JH16: 0 | JI16: 0 | JJ16: 0 | JK16: 0 | JL16: 0 | JM16: 0 | JN16: 0 | JO16: 0 | JP16: 0 | JQ16: 0 | JR16: 0 | JS16: 0 | JT16: 0 | JU16: 0 | JV16: 0 | JW16: 0 | JX16: 0 | JY16: 0 | JZ16: 0 | KA16: 0 | KB16: 0 | KC16: 0 | KD16: 0 | KE16: 0 | KF16: 0 | KG16: 0 | KH16: 0 | KI16: 0 | KJ16: 0 | KK16: 0 | KL16: 0 | KM16: 0 | KN16: 0 | KO16: 0 | KP16: 0 | KQ16: 0 | KR16: 0 | KS16: 0 | KT16: 0 | KU16: 0 | KV16: 0 | KW16: 0 | KX16: 0 | KY16: 0 | KZ16: 0 | LA16: 0 | LB16: 0 | LC16: 0 | LD16: 0 | LE16: 0 | LF16: 0 | LG16: 0 | LH16: 0 | LI16: 0 | LJ16: 0 | LK16: 0 | LL16: 0 | LM16: 0 | LN16: 0 | LO16: 0 | LP16: 0 | LQ16: 0 | LR16: 0 | LS16: 0 | LT16: 0 | LU16: 0 | LV16: 0 | LW16: 0 | LX16: 0 | LY16: 0 | LZ16: 0 | MA16: 0 | MB16: 0 | MC16: 0 | MD16: 0 | ME16: 0 | MF16: 0 | MG16: 0 | MH16: 0 | MI16: 0 | MJ16: 0 | MK16: 0 | ML16: 0 | MM16: 0 | MN16: 0 | MO16: 0 | MP16: 0 | MQ16: 0 | MR16: 0 | MS16: 0 | MT16: 0 | MU16: 0 | MV16: 0 | MW16: 0 | MX16: 0 | MY16: 0 | MZ16: 0 | NA16: 0 | NB16: 0 | NC16: 0 | ND16: 0 | NE16: 0 | NF16: 0 | NG16: 0 | NH16: 0
