Workbook
Name __xlnm.Print_Area_4: #REF!
Name AgeProfileWorks: #REF!
Name cmd_shifting: #REF!
Name PRINT_AREA_MI: #REF!
Name PRINT_AREA_MI: #REF!
Name PRINT_AREA_MI: #REF!
Name PRINT_AREA_MI: #REF!
Name PRINT_AREA_MI: #REF!
Name PRINT_AREA_MI: #REF!
Name PRINT_AREA_MI: #REF!
Name PRINT_AREA_MI: #REF!
Name PRINT_AREA_MI: #REF!

Sheet Kto6 CSR, CR, Coeffcnt,YrInput
A1: DEPARTMENT OF EDUCATION
A2: BASIC EDUCATION INFORMATION SYSTEM
A3: COHORT SURVIVAL RATES & COMPLETION RATES IN PUBLIC AND PRIVATE ELEMENTARY SCHOOLS
A4: (KINDERGARTEN TO GRADE 6)
A5: SY 2022-2023
A8: Note: Computed using UNESCO's template for assessing internal efficiency (Including SUCs)
A10: REGION/DIVISION | B10: Sex | C10: Survival Rates | I10: (CSR) | J10: Completion | K10: Coefficient | L10: Years Input | M10: GPI | N10: GPI | O10: GPI
C11: Kinder | D11: Grade I | E11: Grade II | F11: Grade III | G11: Grade IV | H11: Grade V | I11: Grade VI | J11: Rate | K11: of Efficiency | L11: Per Graduate | M11: Cohort | N11: Completion | O11: Coefficient
A12: Region XI - Davao City | B12: Total (M & F) | C12: 1 | D12: 1 | E12: 1 | F12: 1 | G12: 1 | H12: 1 | I12: 1 | J12: 1 | K12: 0.98577689 | L12: 7.1009983 | M12: =I14/I13 -> 1 | N12: =J14/J13 -> 1 | O12: =K14/K13 -> 1.0077136
B13: Male (M) | C13: 1 | D13: 1 | E13: 1 | F13: 1 | G13: 1 | H13: 0.99999999 | I13: 0.99999999 | J13: 0.99999999 | K13: 0.98212771 | L13: 7.1273826
B14: Female (F) | C14: 1 | D14: 1 | E14: 1 | F14: 1 | G14: 1 | H14: 1 | I14: 1 | J14: 1 | K14: 0.98970346 | L14: 7.0728256
A15: Region XI - Davao de Oro (Compostela Valley) | B15: Total (M & F) | C15: 1 | D15: 1 | E15: 1 | F15: 1 | G15: 0.99999999 | H15: 0.99999999 | I15: 0.99367326 | J15: 0.99298124 | K15: 0.97472495 | L15: 7.1815131 | M15: =I17/I16 -> 1.0085627 | N15: =J17/J16 -> 1.0113383 | O15: =K17/K16 -> 1.0227648
B16: Male (M) | C16: 1 | D16: 1 | E16: 1 | F16: 1 | G16: 0.99999998 | H16: 0.99999995 | I16: 0.98963128 | J16: 0.98691522 | K16: 0.96354588 | L16: 7.2648331
B17: Female (F) | C17: 1 | D17: 1 | E17: 1 | F17: 1 | G17: 1 | H17: 1 | I17: 0.99810516 | J17: 0.99810516 | K17: 0.98548079 | L17: 7.1031319
A18: Region XI - Davao del Norte | B18: Total (M & F) | C18: 1 | D18: 0.99718054 | E18: 0.99552133 | F18: 0.99552133 | G18: 0.98889698 | H18: 0.98501099 | I18: 0.98210749 | J18: 0.98210749 | K18: 0.98262424 | L18: 7.1237811 | M18: =I20/I19 -> 1.0143801 | N18: =J20/J19 -> 1.0143801 | O18: =K20/K19 -> 1.01221
B19: Male (M) | C19: 1 | D19: 0.99434329 | E19: 0.99114376 | F19: 0.99114376 | G19: 0.98555365 | H19: 0.97807058 | I19: 0.97348624 | J19: 0.97348624 | K19: 0.97610921 | L19: 7.1713287
B20: Female (F) | C20: 1 | D20: 1 | E20: 1 | F20: 0.99614065 | G20: 0.98850544 | H20: 0.98850544 | I20: 0.98748505 | J20: 0.98748505 | K20: 0.98802755 | L20: 7.0848227
A21: Region XI - Davao del Sur | B21: Total (M & F) | C21: 1 | D21: 1 | E21: 1 | F21: 1 | G21: 1 | H21: 1 | I21: 1 | J21: 1 | K21: 0.98616783 | L21: 7.0981833 | M21: =I23/I22 -> 1 | N21: =J23/J22 -> 1.0002127 | O21: =K23/K22 -> 1.0086754
B22: Male (M) | C22: 1 | D22: 1 | E22: 1 | F22: 1 | G22: 1 | H22: 0.99999999 | I22: 0.99999999 | J22: 0.99978736 | K22: 0.98195259 | L22: 7.1286537
B23: Female (F) | C23: 1 | D23: 1 | E23: 1 | F23: 1 | G23: 1 | H23: 1 | I23: 1 | J23: 1 | K23: 0.99047142 | L23: 7.0673417
A24: Region XI - Davao Occidental | B24: Total (M & F) | C24: 1 | D24: 1 | E24: 1 | F24: 1 | G24: 0.99999999 | H24: 0.99999998 | I24: 0.97315212 | J24: 0.97315212 | K24: 0.95626239 | L24: 7.3201666 | M24: =I26/I25 -> 1.0138926 | N24: =J26/J25 -> 1.0123684 | O24: =K26/K25 -> 1.0251637
B25: Male (M) | C25: 1 | D25: 1 | E25: 1 | F25: 1 | G25: 0.99999997 | H25: 0.99999993 | I25: 0.9666666 | J25: 0.96666659 | K25: 0.94409239 | L25: 7.4145285
B26: Female (F) | C26: 1 | D26: 1 | E26: 1 | F26: 1 | G26: 1 | H26: 1 | I26: 0.98009609 | J26: 0.9786227 | K26: 0.96784923 | L26: 7.2325315
A27: Region XI - Davao Oriental | B27: Total (M & F) | C27: 1 | D27: 1 | E27: 1 | F27: 0.99999998 | G27: 0.99999992 | H27: 0.99999982 | I27: 0.98240831 | J27: 0.97323077 | K27: 0.94646936 | L27: 7.3959076 | M27: =I29/I28 -> 1.0260697 | N27: =J29/J28 -> 1.0457977 | O27: =K29/K28 -> 1.0643772
B28: Male (M) | C28: 1 | D28: 1 | E28: 1 | F28: 0.99999993 | G28: 0.99999969 | H28: 0.99999922 | I28: 0.97010038 | J28: 0.95180033 | K28: 0.91783139 | L28: 7.6266731
B29: Female (F) | C29: 1 | D29: 1 | E29: 1 | F29: 1 | G29: 0.99999999 | H29: 0.99999998 | I29: 0.99539057 | J29: 0.99539056 | K29: 0.97691884 | L29: 7.1653854
A30: Region XI - Digos City | B30: Total (M & F) | C30: 1 | D30: 1 | E30: 1 | F30: 1 | G30: 1 | H30: 1 | I30: 1 | J30: 1 | K30: 0.98735475 | L30: 7.0896504 | M30: =I32/I31 -> 1 | N30: =J32/J31 -> 1 | O30: =K32/K31 -> 1.007656
B31: Male (M) | C31: 1 | D31: 1 | E31: 1 | F31: 1 | G31: 1 | H31: 1 | I31: 1 | J31: 1 | K31: 0.98372623 | L31: 7.1158009
B32: Female (F) | C32: 1 | D32: 1 | E32: 1 | F32: 1 | G32: 1 | H32: 1 | I32: 1 | J32: 1 | K32: 0.99125761 | L32: 7.0617364
A33: Region XI - Island Garden City of Samal | B33: Total (M & F) | C33: 1 | D33: 1 | E33: 1 | F33: 0.99999999 | G33: 0.99999997 | H33: 0.99999988 | I33: 0.99999988 | J33: 0.98941319 | K33: 0.96329128 | L33: 7.2667532 | M33: =I35/I34 -> 1.0000006 | N33: =J35/J34 -> 1.0072453 | O33: =K35/K34 -> 1.0269985
B34: Male (M) | C34: 1 | D34: 1 | E34: 1 | F34: 0.99999998 | G34: 0.99999985 | H34: 0.99999941 | I34: 0.99999938 | J34: 0.98582752 | K34: 0.95074102 | L34: 7.362678
B35: Female (F) | C35: 1 | D35: 1 | E35: 1 | F35: 1 | G35: 1 | H35: 0.99999999 | I35: 0.99999999 | J35: 0.99297011 | K35: 0.97640961 | L35: 7.1691224
A36: Region XI - Mati City | B36: Total (M & F) | C36: 1 | D36: 1 | E36: 1 | F36: 0.99999995 | G36: 0.99999973 | H36: 0.99999924 | I36: 0.99999918 | J36: 0.99095519 | K36: 0.95100367 | L36: 7.3606446 | M36: =I38/I37 -> 1.0095538 | N36: =J38/J37 -> 1.0221071 | O36: =K38/K37 -> 1.0515749
B37: Male (M) | C37: 1 | D37: 1 | E37: 0.99999999 | F37: 0.99999979 | G37: 0.99999875 | H37: 0.99999646 | I37: 0.99053651 | J37: 0.97574269 | K37: 0.92434891 | L37: 7.572898
B38: Female (F) | C38: 1 | D38: 1 | E38: 1 | F38: 0.99999999 | G38: 0.99999997 | H38: 0.99999992 | I38: 0.99999992 | J38: 0.99731355 | K38: 0.9720221 | L38: 7.2014823
A39: Region XI - Panabo City | B39: Total (M & F) | C39: 1 | D39: 1 | E39: 1 | F39: 1 | G39: 1 | H39: 1 | I39: 1 | J39: 1 | K39: 0.99185788 | L39: 7.0574627 | M39: =I41/I40 -> 1 | N39: =J41/J40 -> 1 | O39: =K41/K40 -> 1.0045685
B40: Male (M) | C40: 1 | D40: 1 | E40: 1 | F40: 1 | G40: 1 | H40: 1 | I40: 1 | J40: 1 | K40: 0.98964406 | L40: 7.0732501
B41: Female (F) | C41: 1 | D41: 1 | E41: 1 | F41: 1 | G41: 1 | H41: 1 | I41: 1 | J41: 1 | K41: 0.99416523 | L41: 7.0410831
A42: Region XI - Tagum City | B42: Total (M & F) | C42: 1 | D42: 1 | E42: 1 | F42: 1 | G42: 1 | H42: 1 | I42: 1 | J42: 1 | K42: 0.98480509 | L42: 7.1080055 | M42: =I44/I43 -> 1.0003937 | N42: =J44/J43 -> 1.0003937 | O42: =K44/K43 -> 1.0079533
B43: Male (M) | C43: 1 | D43: 1 | E43: 1 | F43: 1 | G43: 1 | H43: 0.99999999 | I43: 0.99960644 | J43: 0.99960644 | K43: 0.98086379 | L43: 7.1365669
...

Sheet Kto6 Promo & Grad
A1: DEPARTMENT OF EDUCATION
A2: BASIC EDUCATION INFORMATION SYSTEM
A3: PROMOTION RATES AND GRADUATION RATES IN PUBLIC AND PRIVATE ELEMENTARY SCHOOLS
A4: (KINDERGARTEN TO GRADE 6)
A5: ='Kto6 CSR, CR, Coeffcnt,YrInput'!A5:O5 -> SY 2022-2023
A8: Note: Computed using UNESCO's template for assessing internal efficiency (Including SUCs)
A10: REGION/DIVISION | B10: Sex | C10: Kinder | D10: Grade I | E10: Grade II | F10: Grade III | G10: Grade IV | H10: Grade V | I10: Grade VI | J10: Ave. Promotion | K10: Gender
I11: Grad. Rate | J11: Rate | K11: Parity Index
A12: Region XI - Davao City | B12: Total (M & F) | C12: 0.97910407 | D12: 0.98008518 | E12: 0.98479948 | F12: 0.9865867 | G12: 0.98902486 | H12: 0.98957085 | I12: 0.99140442 | J12: 0.98567735 | K12: 1.0077393
B13: Male (M) | C13: 0.97534031 | D13: 0.97618783 | E13: 0.98102647 | F13: 0.98356589 | G13: 0.98536193 | H13: 0.98642082 | I13: 0.98713215 | J13: 0.982
B14: Female (F) | C14: 0.98313253 | D14: 0.98428162 | E14: 0.98897491 | F14: 0.9898339 | G14: 0.99286356 | H14: 0.99311326 | I14: 0.99585861 | J14: 0.9896
A15: Region XI - Davao de Oro (Compostela Valley) | B15: Total (M & F) | C15: 0.98408695 | D15: 0.97302158 | E15: 0.97257724 | F15: 0.97958619 | G15: 0.98304488 | H15: 0.9786366 | I15: 0.98748749 | J15: 0.97963786 | K15: 1.0141844
B16: Male (M) | C16: 0.98317115 | D16: 0.96614047 | E16: 0.96410316 | F16: 0.97183555 | G16: 0.9773559 | H16: 0.96897913 | I16: 0.98013732 | J16: 0.9729
B17: Female (F) | C17: 0.98509725 | D17: 0.98059965 | E17: 0.98229028 | F17: 0.98773981 | G17: 0.98903747 | H17: 0.98935671 | I17: 0.99374042 | J17: 0.9867
A18: Region XI - Davao del Norte | B18: Total (M & F) | C18: 0.99096168 | D18: 0.98792536 | E18: 0.9910054 | F18: 0.98561029 | G18: 0.98874113 | H18: 0.98927614 | I18: 0.99657599 | J18: 0.98997614 | K18: 1.0067917
B19: Male (M) | C19: 0.98597721 | D19: 0.98272823 | E19: 0.98944989 | F19: 0.98360101 | G19: 0.98358132 | H19: 0.98561151 | I19: 0.99502946 | J19: 0.9865
B20: Female (F) | C20: 0.99608136 | D20: 0.99353366 | E20: 0.98893146 | F20: 0.98762502 | G20: 0.99429413 | H20: 0.9933282 | I20: 0.99822904 | J20: 0.9932
A21: Region XI - Davao del Sur | B21: Total (M & F) | C21: 0.98540073 | D21: 0.97952662 | E21: 0.983866 | F21: 0.98482405 | G21: 0.98955311 | H21: 0.98851537 | I21: 0.99158859 | J21: 0.98609102 | K21: 1.008554
B22: Male (M) | C22: 0.98230594 | D22: 0.97481254 | E22: 0.980484 | F22: 0.98080753 | G22: 0.98394105 | H22: 0.98424102 | I22: 0.98843809 | J22: 0.982
B23: Female (F) | C23: 0.98878039 | D23: 0.98462178 | E23: 0.98762752 | F23: 0.98924303 | G23: 0.99544103 | H23: 0.99307616 | I23: 0.99460626 | J23: 0.9904
A24: Region XI - Davao Occidental | B24: Total (M & F) | C24: 0.99137331 | D24: 0.96836143 | E24: 0.97050147 | F24: 0.97734139 | G24: 0.97995607 | H24: 0.95526273 | I24: 0.98347723 | J24: 0.97510452 | K24: 1.0162274
B25: Male (M) | C25: 0.99014909 | D25: 0.96330029 | E25: 0.96167832 | F25: 0.96912114 | G25: 0.9709476 | H25: 0.94191131 | I25: 0.97503715 | J25: 0.9675
B26: Female (F) | C26: 0.99271349 | D26: 0.97375178 | E26: 0.98034321 | F26: 0.98625823 | G26: 0.98916968 | H26: 0.96977929 | I26: 0.99045631 | J26: 0.9832
A27: Region XI - Davao Oriental | B27: Total (M & F) | C27: 0.97954908 | D27: 0.95324803 | E27: 0.96055544 | F27: 0.96574913 | G27: 0.97216981 | H27: 0.95886149 | I27: 0.97489929 | J27: 0.96614333 | K27: 1.0281158
B28: Male (M) | C28: 0.97724665 | D28: 0.94205361 | E28: 0.94749626 | F28: 0.95441202 | G28: 0.9603073 | H28: 0.93608522 | I28: 0.95809717 | J28: 0.9532
B29: Female (F) | C29: 0.98206091 | D29: 0.96544632 | E29: 0.9757959 | F29: 0.97799329 | G29: 0.98480421 | H29: 0.98346117 | I29: 0.99198481 | J29: 0.98
A30: Region XI - Digos City | B30: Total (M & F) | C30: 0.99230399 | D30: 0.98600439 | E30: 0.98631334 | F30: 0.97959184 | G30: 0.98608004 | H30: 0.98703352 | I30: 0.99429549 | J30: 0.98733395 | K30: 1.0075219
B31: Male (M) | C31: 0.99166281 | D31: 0.98387097 | E31: 0.98190789 | F31: 0.97425935 | G31: 0.98145506 | H31: 0.97946484 | I31: 0.99374645 | J31: 0.9838
B32: Female (F) | C32: 0.9929965 | D32: 0.9883856 | E32: 0.99130435 | F32: 0.98534031 | G32: 0.99114583 | H32: 0.99485531 | I32: 0.99484831 | J32: 0.9912
A33: Region XI - Island Garden City of Samal | B33: Total (M & F) | C33: 0.98584715 | D33: 0.9625498 | E33: 0.96132151 | F33: 0.95975702 | G33: 0.98050915 | H33: 0.98128079 | I33: 0.97437011 | J33: 0.97176645 | K33: 1.0206839
B34: Male (M) | C34: 0.98743126 | D34: 0.95603577 | E34: 0.94607088 | F34: 0.9439941 | G34: 0.97511664 | H34: 0.96808511 | I34: 0.96197061 | J34: 0.9621
B35: Female (F) | C35: 0.98416667 | D35: 0.97003425 | E35: 0.97804054 | F35: 0.97650744 | G35: 0.98615635 | H35: 0.99497992 | I35: 0.98689956 | J35: 0.982
A36: Region XI - Mati City | B36: Total (M & F) | C36: 0.97329733 | D36: 0.94877765 | E36: 0.94548652 | F36: 0.95224274 | G36: 0.95914397 | H36: 0.96638079 | I36: 0.96447658 | J36: 0.95804925 | K36: 1.0332095
B37: Male (M) | C37: 0.96967963 | D37: 0.9345898 | E37: 0.92731403 | F37: 0.93743642 | G37: 0.94009459 | H37: 0.93974359 | I37: 0.95189417 | J37: 0.9425
B38: Female (F) | C38: 0.97728707 | D38: 0.96446078 | E38: 0.96486978 | F38: 0.96820175 | G38: 0.98053097 | H38: 0.98671587 | I38: 0.97826087 | J38: 0.9738
A39: Region XI - Panabo City | B39: Total (M & F) | C39: 0.99182444 | D39: 0.98676573 | E39: 0.99070223 | F39: 0.99361838 | G39: 0.99387755 | H39: 0.99156233 | I39: 0.99469752 | J39: 0.99189351 | K39: 1.0043443
B40: Male (M) | C40: 0.99216495 | D40: 0.98453843 | E40: 0.98886827 | F40: 0.99219428 | G40: 0.99118554 | H40: 0.98657358 | I40: 0.9920412 | J40: 0.9898
B41: Female (F) | C41: 0.99145299 | D41: 0.98908918 | E41: 0.99274987 | F41: 0.99498956 | G41: 0.9967305 | H41: 0.99668874 | I41: 0.99751615 | J41: 0.9941
A42: Region XI - Tagum City | B42: Total (M & F) | C42: 0.98219132 | D42: 0.97751394 | E42: 0.98245935 | F42: 0.9841558 | G42: 0.98758389 | H42: 0.98905775 | I42: 0.9908034 | J42: 0.98479001 | K42: 1.0077464
B43: Male (M) | C43: 0.97823937 | D43: 0.97510373 | E43: 0.97770812 | F43: 0.97985705 | G43: 0.98308393 | H43: 0.98564222 | I43: 0.98848629 | J43: 0.9811
...

Sheet Kto6 Repetition
A1: DEPARTMENT OF EDUCATION
A2: BASIC EDUCATION INFORMATION SYSTEM
A3: REPETITION RATES IN PUBLIC AND PRIVATE ELEMENTARY SCHOOLS
A4: (KINDERGARTEN TO GRADE 6)
A5: ='Kto6 CSR, CR, Coeffcnt,YrInput'!A5:O5 -> SY 2022-2023
A8: Note: Computed using UNESCO's template for assessing internal efficiency (Including SUCs)
A10: REGION/DIVISION | B10: Sex | C10: Repetition Rate | J10: Ave. Repetition | K10: Gender
C11: Kinder | D11: Grade I | E11: Grade II | F11: Grade III | G11: Grade IV | H11: Grade V | I11: Grade VI | J11: Rate | K11: Parity Index
A12: Region XI - Davao City | B12: Total (M & F) | C12: 0.020895926 | D12: 0.019914815 | E12: 0.015200517 | F12: 0.013413295 | G12: 0.010975141 | H12: 0.010429145 | I12: 0.0085955794 | J12: 0.014322649 | K12: 0.57777778
B13: Male (M) | C13: 0.024659686 | D13: 0.023812167 | E13: 0.018973527 | F13: 0.016434109 | G13: 0.01463807 | H13: 0.013579179 | I13: 0.012867853 | J13: 0.018
B14: Female (F) | C14: 0.01686747 | D14: 0.015718384 | E14: 0.011025085 | F14: 0.010166102 | G14: 0.0071364352 | H14: 0.006886743 | I14: 0.0041413906 | J14: 0.0104
A15: Region XI - Davao de Oro (Compostela Valley) | B15: Total (M & F) | C15: 0.015913049 | D15: 0.026978417 | E15: 0.027422757 | F15: 0.020413808 | G15: 0.016955119 | H15: 0.015132409 | I15: 0.011824324 | J15: 0.019362137 | K15: 0.51383399
B16: Male (M) | C16: 0.016828849 | D16: 0.033859529 | E16: 0.03589684 | F16: 0.028164455 | G16: 0.022644099 | H16: 0.020868584 | I16: 0.017165277 | J16: 0.0253
B17: Female (F) | C17: 0.014902753 | D17: 0.019400353 | E17: 0.01770972 | F17: 0.012260188 | G17: 0.010962535 | H17: 0.008765065 | I17: 0.006259581 | J17: 0.013
A18: Region XI - Davao del Norte | B18: Total (M & F) | C18: 0.0062364425 | D18: 0.010428101 | E18: 0.0089946032 | F18: 0.0077873709 | G18: 0.007358156 | H18: 0.0077991713 | I18: 0.0034240061 | J18: 0.0074238647 | K18: 0.51546392
B19: Male (M) | C19: 0.0084136722 | D19: 0.014099401 | E19: 0.010550113 | F19: 0.010819949 | G19: 0.0088934496 | H19: 0.0097470411 | I19: 0.0049705449 | J19: 0.0097
B20: Female (F) | C20: 0.0039186415 | D20: 0.006466337 | E20: 0.0072371222 | F20: 0.0047465672 | G20: 0.0057058715 | H20: 0.0056453682 | I20: 0.0017709563 | J20: 0.005
A21: Region XI - Davao del Sur | B21: Total (M & F) | C21: 0.014599265 | D21: 0.020473385 | E21: 0.016134005 | F21: 0.015175946 | G21: 0.010446895 | H21: 0.011484627 | I21: 0.008411414 | J21: 0.013908978 | K21: 0.53333333
B22: Male (M) | C22: 0.017694064 | D22: 0.025187464 | E22: 0.019516003 | F22: 0.019192468 | G22: 0.016058946 | H22: 0.01575898 | I22: 0.011351692 | J22: 0.018
B23: Female (F) | C23: 0.011219614 | D23: 0.015378221 | E23: 0.012372477 | F23: 0.010756972 | G23: 0.0045589693 | H23: 0.0069238378 | I23: 0.0053937433 | J23: 0.0096
A24: Region XI - Davao Occidental | B24: Total (M & F) | C24: 0.0086266871 | D24: 0.031638574 | E24: 0.029498525 | F24: 0.02265861 | G24: 0.020043932 | H24: 0.018382951 | I24: 0.016522775 | J24: 0.021095485 | K24: 0.49462366
B25: Male (M) | C25: 0.0098509052 | D25: 0.036699705 | E25: 0.038321678 | F25: 0.03087886 | G25: 0.029052403 | H25: 0.025608994 | I25: 0.024962853 | J25: 0.0279
B26: Female (F) | C26: 0.0072865054 | D26: 0.026248217 | E26: 0.019656786 | F26: 0.013741769 | G26: 0.010830325 | H26: 0.010526316 | I26: 0.0080524903 | J26: 0.0138
A27: Region XI - Davao Oriental | B27: Total (M & F) | C27: 0.020450918 | D27: 0.046751969 | E27: 0.039444556 | F27: 0.034250874 | G27: 0.027830189 | H27: 0.023968656 | I27: 0.015907448 | J27: 0.030056668 | K27: 0.4825
B28: Male (M) | C28: 0.022753346 | D28: 0.057946395 | E28: 0.052503737 | F28: 0.045587981 | G28: 0.039692702 | H28: 0.035064359 | I28: 0.023481781 | J28: 0.04
B29: Female (F) | C29: 0.017939091 | D29: 0.034553682 | E29: 0.024204099 | F29: 0.022006714 | G29: 0.015195792 | H29: 0.01198466 | I29: 0.0080151867 | J29: 0.0193
A30: Region XI - Digos City | B30: Total (M & F) | C30: 0.0076960077 | D30: 0.013995609 | E30: 0.013686663 | F30: 0.020408163 | G30: 0.01391996 | H30: 0.012966477 | I30: 0.0057045066 | J30: 0.012666049 | K30: 0.54320988
B31: Male (M) | C31: 0.0083371931 | D31: 0.016129032 | E31: 0.018092105 | F31: 0.025740651 | G31: 0.018544936 | H31: 0.020535159 | I31: 0.0062535532 | J31: 0.0162
B32: Female (F) | C32: 0.0070035018 | D32: 0.011614402 | E32: 0.0086956522 | F32: 0.014659686 | G32: 0.0088541667 | H32: 0.0051446945 | I32: 0.0051516886 | J32: 0.0088
A33: Region XI - Island Garden City of Samal | B33: Total (M & F) | C33: 0.014152851 | D33: 0.037450199 | E33: 0.038678485 | F33: 0.040242976 | G33: 0.019490851 | H33: 0.018719212 | I33: 0.01520417 | J33: 0.02673355 | K33: 0.4735376
B34: Male (M) | C34: 0.012568735 | D34: 0.043964232 | E34: 0.053929122 | F34: 0.056005895 | G34: 0.024883359 | H34: 0.031914894 | I34: 0.024200519 | J34: 0.0359
B35: Female (F) | C35: 0.015833333 | D35: 0.029965753 | E35: 0.021959459 | F35: 0.023492561 | G35: 0.013843648 | H35: 0.0050200803 | I35: 0.0061135371 | J35: 0.017
A36: Region XI - Mati City | B36: Total (M & F) | C36: 0.02670267 | D36: 0.051222352 | E36: 0.054513482 | F36: 0.047757256 | G36: 0.040856031 | H36: 0.033619211 | I36: 0.026721157 | J36: 0.04065075 | K36: 0.47601476
B37: Male (M) | C37: 0.030320366 | D37: 0.0654102 | E37: 0.072685974 | F37: 0.062563581 | G37: 0.059905413 | H37: 0.051282051 | I37: 0.033674083 | J37: 0.0542
B38: Female (F) | C38: 0.022712934 | D38: 0.035539216 | E38: 0.035130224 | F38: 0.031798246 | G38: 0.019469027 | H38: 0.013284133 | I38: 0.019104084 | J38: 0.0258
A39: Region XI - Panabo City | B39: Total (M & F) | C39: 0.0081755594 | D39: 0.01323427 | E39: 0.0092977734 | F39: 0.0063816209 | G39: 0.006122449 | H39: 0.0084376701 | I39: 0.0053024825 | J39: 0.0081064852 | K39: 0.57843137
B40: Male (M) | C40: 0.0078350515 | D40: 0.015461573 | E40: 0.011131725 | F40: 0.0078057242 | G40: 0.0088144557 | H40: 0.013426423 | I40: 0.0079588015 | J40: 0.0102
B41: Female (F) | C41: 0.0085470085 | D41: 0.010910816 | E41: 0.0072501295 | F41: 0.0050104384 | G41: 0.0032695002 | H41: 0.0033112583 | I41: 0.0024838549 | J41: 0.0059
A42: Region XI - Tagum City | B42: Total (M & F) | C42: 0.017808684 | D42: 0.022486059 | E42: 0.017540654 | F42: 0.015844199 | G42: 0.012416107 | H42: 0.010942249 | I42: 0.009196599 | J42: 0.015209989 | K42: 0.60106383
B43: Male (M) | C43: 0.021760633 | D43: 0.024896266 | E43: 0.022291884 | F43: 0.02014295 | G43: 0.01691607 | H43: 0.013969732 | I43: 0.011513715 | J43: 0.0188
...

Sheet Kto6 SchoolLeaver
A1: DEPARTMENT OF EDUCATION
A2: BASIC EDUCATION INFORMATION SYSTEM
A3: SCHOOL LEAVER RATES IN PUBLIC AND PRIVATE ELEMENTARY SCHOOLS
A4: (KINDERGARTEN TO GRADE 6)
A5: ='Kto6 CSR, CR, Coeffcnt,YrInput'!A5:O5 -> SY 2022-2023
A8: Note: Computed using UNESCO's template for assessing internal efficiency (Including SUCs)
A10: REGION/DIVISION | B10: Sex | C10: School Leaver Rate | J10: Ave. School | K10: Gender
C11: Kinder | D11: Grade I | E11: Grade II | F11: Grade III | G11: Grade IV | H11: Grade V | I11: Grade VI | J11: Leaver Rate | K11: Parity Index
A12: Region XI - Davao City | B12: Total (M & F) | C12: 0 | D12: 0 | E12: 0 | F12: 0 | G12: 0 | H12: 0 | I12: 0 | J12: 0 | K12: #DIV/0!
B13: Male (M) | C13: 0 | D13: 0 | E13: 0 | F13: 0 | G13: 0 | H13: 0 | I13: 0 | J13: 0
B14: Female (F) | C14: 0 | D14: 0 | E14: 0 | F14: 0 | G14: 0 | H14: 0 | I14: 0 | J14: 0
A15: Region XI - Davao de Oro (Compostela Valley) | B15: Total (M & F) | C15: 0 | D15: 0 | E15: 0 | F15: 0 | G15: 0 | H15: 0.0062309918 | I15: 0.00068818819 | J15: 0.001 | K15: 0.16666667
B16: Male (M) | C16: 0 | D16: 0 | E16: 0 | F16: 0 | G16: 0 | H16: 0.010152284 | I16: 0.0026974007 | J16: 0.0018
B17: Female (F) | C17: 0 | D17: 0 | E17: 0 | F17: 0 | G17: 0 | H17: 0.0018782282 | I17: 0 | J17: 0.0003
A18: Region XI - Davao del Norte | B18: Total (M & F) | C18: 0.00280188 | D18: 0.0016465423 | E18: 0 | F18: 0.0066023362 | G18: 0.0039007092 | H18: 0.0029246893 | I18: 0 | J18: 0.0026 | K18: 0.47368421
B19: Male (M) | C19: 0.0056091148 | D19: 0.0031723652 | E19: 0 | F19: 0.0055790363 | G19: 0.0075252266 | H19: 0.0046414481 | I19: 0 | J19: 0.0038
B20: Female (F) | C20: 0 | D20: 0 | E20: 0.0038314176 | F20: 0.0076284116 | G20: 0 | H20: 0.0010264306 | I20: 0 | J20: 0.0018
A21: Region XI - Davao del Sur | B21: Total (M & F) | C21: 0 | D21: 0 | E21: 0 | F21: 0 | G21: 0 | H21: 0 | I21: 0 | J21: 0 | K21: #DIV/0!
B22: Male (M) | C22: 0 | D22: 0 | E22: 0 | F22: 0 | G22: 0 | H22: 0 | I22: 0.00021021652 | J22: 0
B23: Female (F) | C23: 0 | D23: 0 | E23: 0 | F23: 0 | G23: 0 | H23: 0 | I23: 0 | J23: 0
A24: Region XI - Davao Occidental | B24: Total (M & F) | C24: 0 | D24: 0 | E24: 0 | F24: 0 | G24: 0 | H24: 0.026354319 | I24: 0 | J24: 0.0038 | K24: 0.65217391
B25: Male (M) | C25: 0 | D25: 0 | E25: 0 | F25: 0 | G25: 0 | H25: 0.0324797 | I25: 0 | J25: 0.0046
B26: Female (F) | C26: 0 | D26: 0 | E26: 0 | F26: 0 | G26: 0 | H26: 0.019694397 | I26: 0.0014912019 | J26: 0.003
A27: Region XI - Davao Oriental | B27: Total (M & F) | C27: 0 | D27: 0 | E27: 0 | F27: 0 | G27: 0 | H27: 0.017169855 | I27: 0.0091932652 | J27: 0.0038 | K27: 0.10294118
B28: Male (M) | C28: 0 | D28: 0 | E28: 0 | F28: 0 | G28: 0 | H28: 0.028850422 | I28: 0.018421053 | J28: 0.0068
B29: Female (F) | C29: 0 | D29: 0 | E29: 0 | F29: 0 | G29: 0 | H29: 0.0045541707 | I29: 0 | J29: 0.0007
A30: Region XI - Digos City | B30: Total (M & F) | C30: 0 | D30: 0 | E30: 0 | F30: 0 | G30: 0 | H30: 0 | I30: 0 | J30: 0 | K30: #DIV/0!
B31: Male (M) | C31: 0 | D31: 0 | E31: 0 | F31: 0 | G31: 0 | H31: 0 | I31: 0 | J31: 0
B32: Female (F) | C32: 0 | D32: 0 | E32: 0 | F32: 0 | G32: 0 | H32: 0 | I32: 0 | J32: 0
A33: Region XI - Island Garden City of Samal | B33: Total (M & F) | C33: 0 | D33: 0 | E33: 0 | F33: 0 | G33: 0 | H33: 0 | I33: 0.010425717 | J33: 0.0015 | K33: 0.5
B34: Male (M) | C34: 0 | D34: 0 | E34: 0 | F34: 0 | G34: 0 | H34: 0 | I34: 0.013828868 | J34: 0.002
B35: Female (F) | C35: 0 | D35: 0 | E35: 0 | F35: 0 | G35: 0 | H35: 0 | I35: 0.0069868996 | J35: 0.001
A36: Region XI - Mati City | B36: Total (M & F) | C36: 0 | D36: 0 | E36: 0 | F36: 0 | G36: 0 | H36: 0 | I36: 0.0088022634 | J36: 0.0013 | K36: 0.12121212
B37: Male (M) | C37: 0 | D37: 0 | E37: 0 | F37: 0 | G37: 0 | H37: 0.008974359 | I37: 0.01443175 | J37: 0.0033
B38: Female (F) | C38: 0 | D38: 0 | E38: 0 | F38: 0 | G38: 0 | H38: 0 | I38: 0.0026350461 | J38: 0.0004
A39: Region XI - Panabo City | B39: Total (M & F) | C39: 0 | D39: 0 | E39: 0 | F39: 0 | G39: 0 | H39: 0 | I39: 0 | J39: 0 | K39: #DIV/0!
B40: Male (M) | C40: 0 | D40: 0 | E40: 0 | F40: 0 | G40: 0 | H40: 0 | I40: 0 | J40: 0
B41: Female (F) | C41: 0 | D41: 0 | E41: 0 | F41: 0 | G41: 0 | H41: 0 | I41: 0 | J41: 0
A42: Region XI - Tagum City | B42: Total (M & F) | C42: 0 | D42: 0 | E42: 0 | F42: 0 | G42: 0 | H42: 0 | I42: 0 | J42: 0 | K42: 0
B43: Male (M) | C43: 0 | D43: 0 | E43: 0 | F43: 0 | G43: 0 | H43: 0.00038804812 | I43: 0 | J43: 0.0001
...

Sheet G1to6 CSR,CR,Coeffcnt,YrInput
A1: DEPARTMENT OF EDUCATION
A2: BASIC EDUCATION INFORMATION SYSTEM
A3: COHORT SURVIVAL RATES & COMPLETION RATES IN PUBLIC AND PRIVATE ELEMENTARY SCHOOLS
A4: (GRADE 1 TO GRADE 6)
A5: SY 2022 - 2023
A8: Note: Computed using UNESCO's template for assessing internal efficiency (Including SUCs)
A10: REGION/DIVISION | B10: Sex | C10: Survival Rates | H10: (CSR) | I10: Completion | J10: Coefficient | K10: Years Input | L10: GPI | M10: GPI | N10: GPI
C11: Grade I | D11: Grade II | E11: Grade III | F11: Grade IV | G11: Grade V | H11: Grade VI | I11: Rate | J11: of Efficiency | K11: Per Graduate | L11: Cohort | M11: Completion | N11: Coefficient
A12: Region XI - Davao City | B12: Total (MF) | C12: 1 | D12: 1 | E12: 1 | F12: 1 | G12: 1 | H12: 1 | I12: 1 | J12: 0.98689788 | K12: 6.0796564 | L12: =H14/H13 -> 1 | M12: =I14/I13 -> 1 | N12: =J14/J13 -> 1.0076673
B13: Male (M) | C13: 1 | D13: 1 | E13: 1 | F13: 1 | G13: 1 | H13: 1 | I13: 1 | J13: 0.98326814 | K13: 6.1020994
B14: Female (F) | C14: 1 | D14: 1 | E14: 1 | F14: 1 | G14: 1 | H14: 1 | I14: 1 | J14: 0.99080717 | K14: 6.0556687
A15: Region XI - Davao de Oro (Compostela Valley) | B15: Total (MF) | C15: 1 | D15: 1 | E15: 1 | F15: 1 | G15: 0.99999999 | H15: 0.99367326 | I15: 0.99298124 | J15: 0.97431699 | K15: 6.1581601 | L15: =H17/H16 -> 1.0085627 | M15: =I17/I16 -> 1.0113383 | N15: =J17/J16 -> 1.0243432
B16: Male (M) | C16: 1 | D16: 1 | E16: 1 | F16: 0.99999999 | G16: 0.99999997 | H16: 0.98963127 | I16: 0.98691522 | J16: 0.96242824 | K16: 6.234231
B17: Female (F) | C17: 1 | D17: 1 | E17: 1 | F17: 1 | G17: 1 | H17: 0.99810516 | I17: 0.99810516 | J17: 0.98585681 | K17: 6.0860765
A18: Region XI - Davao del Norte | B18: Total (MF) | C18: 1 | D18: 0.99833611 | E18: 0.99833611 | F18: 0.99169302 | G18: 0.98779604 | H18: 0.98488434 | I18: 0.98488434 | J18: 0.98373997 | K18: 6.0991727 | L18: =H20/H19 -> 1.008642 | M18: =I20/I19 -> 1.008642 | N18: =J20/J19 -> 1.0110761
B19: Male (M) | C19: 1 | D19: 0.99678227 | E19: 0.99678227 | F19: 0.99116035 | G19: 0.98363472 | H19: 0.97902429 | I19: 0.97902429 | J19: 0.97793507 | K19: 6.1353766
B20: Female (F) | C20: 1 | D20: 1 | E20: 0.99614065 | F20: 0.98850544 | G20: 0.98850544 | H20: 0.98748505 | I20: 0.98748505 | J20: 0.98876675 | K20: 6.0681652
A21: Region XI - Davao del Sur | B21: Total (MF) | C21: 1 | D21: 1 | E21: 1 | F21: 1 | G21: 1 | H21: 1 | I21: 1 | J21: 0.9862958 | K21: 6.0833677 | L21: =H23/H22 -> 1 | M21: =I23/I22 -> 1.0002127 | N21: =J23/J22 -> 1.0089877
B22: Male (M) | C22: 1 | D22: 1 | E22: 1 | F22: 1 | G22: 1 | H22: 0.99999999 | I22: 0.99978736 | J22: 0.98192852 | K22: 6.1104244
B23: Female (F) | C23: 1 | D23: 1 | E23: 1 | F23: 1 | G23: 1 | H23: 1 | I23: 1 | J23: 0.99075383 | K23: 6.0559948
A24: Region XI - Davao Occidental | B24: Total (MF) | C24: 1 | D24: 1 | E24: 1 | F24: 0.99999999 | G24: 0.99999999 | H24: 0.97315211 | I24: 0.97315211 | J24: 0.95486114 | K24: 6.2836362 | L24: =H26/H25 -> 1.0138926 | M24: =I26/I25 -> 1.0123684 | N24: =J26/J25 -> 1.0268519
B25: Male (M) | C25: 1 | D25: 1 | E25: 1 | F25: 0.99999998 | G25: 0.99999995 | H25: 0.96666655 | I25: 0.96666654 | J25: 0.94195161 | K25: 6.3697539
B26: Female (F) | C26: 1 | D26: 1 | E26: 1 | F26: 1 | G26: 1 | H26: 0.98009608 | I26: 0.9786227 | J26: 0.96724476 | K26: 6.2031869
A27: Region XI - Davao Oriental | B27: Total (MF) | C27: 1 | D27: 1 | E27: 1 | F27: 1 | G27: 0.99999999 | H27: 0.98110326 | I27: 0.96807659 | J27: 0.94956848 | K27: 6.3186596 | L27: =H29/H28 -> 1.0260699 | M27: =I29/I28 -> 1.0457979 | N27: =J29/J28 -> 1.0666138
B28: Male (M) | C28: 1 | D28: 1 | E28: 0.99999995 | F28: 0.99999979 | G28: 0.99999945 | H28: 0.97010012 | I28: 0.95180011 | J28: 0.91581076 | K28: 6.5515719
B29: Female (F) | C29: 1 | D29: 1 | E29: 1 | F29: 0.99999999 | G29: 0.99999999 | H29: 0.99539057 | I29: 0.99539057 | J29: 0.97681636 | K29: 6.1424033
A30: Region XI - Digos City | B30: Total (MF) | C30: 1 | D30: 1 | E30: 1 | F30: 1 | G30: 1 | H30: 1 | I30: 1 | J30: 0.99567366 | K30: 6.0260709 | L30: =H32/H31 -> 1 | M30: =I32/I31 -> 1 | N30: =J32/J31 -> 1.0087057
B31: Male (M) | C31: 1 | D31: 1 | E31: 1 | F31: 1 | G31: 1 | H31: 0.99999999 | I31: 0.99999999 | J31: 0.9824158 | K31: 6.1073936
B32: Female (F) | C32: 1 | D32: 1 | E32: 1 | F32: 1 | G32: 1 | H32: 1 | I32: 1 | J32: 0.99096839 | K32: 6.0546835
A33: Region XI - Island Garden City of Samal | B33: Total (MF) | C33: 1 | D33: 1 | E33: 1 | F33: 0.99999998 | G33: 0.99999991 | H33: 0.99999986 | I33: 0.98941318 | J33: 0.96130067 | K33: 6.2415436 | L33: =H35/H34 -> 1.0000007 | M33: =I35/I34 -> 1.0072454 | N33: =J35/J34 -> 1.030842
B34: Male (M) | C34: 1 | D34: 1 | E34: 0.99999999 | F34: 0.99999988 | G34: 0.99999951 | H34: 0.99999926 | I34: 0.98582741 | J34: 0.94706078 | K34: 6.3353907
B35: Female (F) | C35: 1 | D35: 1 | E35: 1 | F35: 1 | G35: 0.99999999 | H35: 0.99999999 | I35: 0.99297011 | J35: 0.97627001 | K35: 6.1458408
A36: Region XI - Mati City | B36: Total (MF) | C36: 1 | D36: 1 | E36: 0.99999997 | F36: 0.99999984 | G36: 0.99999951 | H36: 0.99999897 | I36: 0.99095501 | J36: 0.9487917 | K36: 6.3238327 | L36: =H38/H37 -> 1.0095555 | M36: =I38/I37 -> 1.0221086 | N36: =J38/J37 -> 1.0551397
B37: Male (M) | C37: 1 | D37: 0.99999999 | E37: 0.99999987 | F37: 0.99999918 | G37: 0.99999754 | H37: 0.99053486 | I37: 0.97574127 | J37: 0.92081035 | K37: 6.5159998
B38: Female (F) | C38: 1 | D38: 1 | E38: 1 | F38: 0.99999999 | G38: 0.99999996 | H38: 0.99999993 | I38: 0.99731356 | J38: 0.97158357 | K38: 6.1754853
A39: Region XI - Panabo City | B39: Total (MF) | C39: 1 | D39: 1 | E39: 1 | F39: 1 | G39: 1 | H39: 1 | I39: 1 | J39: 0.99449236 | K39: 6.0332288 | L39: =H41/H40 -> 1 | M39: =I41/I40 -> 1 | N39: =J41/J40 -> 1.0054523
B40: Male (M) | C40: 1 | D40: 1 | E40: 1 | F40: 1 | G40: 1 | H40: 1 | I40: 1 | J40: 0.98922516 | K40: 6.0653532
B41: Female (F) | C41: 1 | D41: 1 | E41: 1 | F41: 1 | G41: 1 | H41: 1 | I41: 1 | J41: 0.99461871 | K41: 6.0324624
A42: Region XI - Tagum City | B42: Total (MF) | C42: 1 | D42: 1 | E42: 1 | F42: 1 | G42: 1 | H42: 1 | I42: 0.99755927 | J42: 0.99131483 | K42: 6.0525676 | L42: =H44/H43 -> 1.0003937 | M42: =I44/I43 -> 1.0003937 | N42: =J44/J43 -> 1.0078257
B43: Male (M) | C43: 1 | D43: 1 | E43: 1 | F43: 1 | G43: 1 | H43: 0.99960645 | I43: 0.99960645 | J43: 0.98136716 | K43: 6.1139197
...

Sheet G1to6 Promo & Grad
A1: DEPARTMENT OF EDUCATION
A2: BASIC EDUCATION INFORMATION SYSTEM
A3: PROMOTION RATES AND GRADUATION RATES IN PUBLIC AND PRIVATE ELEMENTARY SCHOOLS
A4: (GRADE 1 TO GRADE 6)
A5: ='G1to6 SchoolLeaver'!A5 -> SY 2022 - 2023
A8: Note: Computed using UNESCO's template for assessing internal efficiency (Including SUCs)
A10: REGION/DIVISION | B10: Sex | C10: Grade I | D10: Grade II | E10: Grade III | F10: Grade IV | G10: Grade V | H10: Graduation | I10: Ave. Promotion | J10: Gender
H11: Rate | I11: Rate | J11: Parity Index
A12: Region XI - Davao City | B12: Total (MF) | C12: 0.98008518 | D12: 0.98479948 | E12: 0.9865867 | F12: 0.98902486 | G12: 0.98957085 | H12: 0.99140442 | I12: 0.98685648 | J12: 1.0077299
B13: Male (M) | C13: 0.97618783 | D13: 0.98102647 | E13: 0.98356589 | F13: 0.98536193 | G13: 0.98642082 | H13: 0.98713215 | I13: 0.9832
B14: Female (F) | C14: 0.98428162 | D14: 0.98897491 | E14: 0.9898339 | F14: 0.99286356 | G14: 0.99311326 | H14: 0.99585861 | I14: 0.9908
A15: Region XI - Davao de Oro (Compostela Valley) | B15: Total (MF) | C15: 0.97302158 | D15: 0.97257724 | E15: 0.97958619 | F15: 0.98304488 | G15: 0.9786366 | H15: 0.98748749 | I15: 0.97884806 | J15: 1.0163715
B16: Male (M) | C16: 0.96614047 | D16: 0.96410316 | E16: 0.97183555 | F16: 0.9773559 | G16: 0.96897913 | H16: 0.98013732 | I16: 0.9712
B17: Female (F) | C17: 0.98059965 | D17: 0.98229028 | E17: 0.98773981 | F17: 0.98903747 | G17: 0.98935671 | H17: 0.99374042 | I17: 0.9871
A18: Region XI - Davao del Norte | B18: Total (MF) | C18: 0.98792536 | D18: 0.9910054 | E18: 0.98561029 | F18: 0.98874113 | G18: 0.98927614 | H18: 0.99657599 | I18: 0.98986678 | J18: 1.0061829
B19: Male (M) | C19: 0.98272823 | D19: 0.98944989 | E19: 0.98360101 | F19: 0.98358132 | G19: 0.98561151 | H19: 0.99502946 | I19: 0.9866
B20: Female (F) | C20: 0.99353366 | D20: 0.98893146 | E20: 0.98762502 | F20: 0.99429413 | G20: 0.9933282 | H20: 0.99822904 | I20: 0.9927
A21: Region XI - Davao del Sur | B21: Total (MF) | C21: 0.97952662 | D21: 0.983866 | E21: 0.98482405 | F21: 0.98955311 | G21: 0.98851537 | H21: 0.99158859 | I21: 0.98621009 | J21: 1.0088595
B22: Male (M) | C22: 0.97481254 | D22: 0.980484 | E22: 0.98080753 | F22: 0.98394105 | G22: 0.98424102 | H22: 0.98843809 | I22: 0.982
B23: Female (F) | C23: 0.98462178 | D23: 0.98762752 | E23: 0.98924303 | F23: 0.99544103 | G23: 0.99307616 | H23: 0.99460626 | I23: 0.9907
A24: Region XI - Davao Occidental | B24: Total (MF) | C24: 0.96836143 | D24: 0.97050147 | E24: 0.97734139 | F24: 0.97995607 | G24: 0.95526273 | H24: 0.98347723 | I24: 0.9723425 | J24: 1.0187857
B25: Male (M) | C25: 0.96330029 | D25: 0.96167832 | E25: 0.96912114 | F25: 0.9709476 | G25: 0.94191131 | H25: 0.97503715 | I25: 0.9635
B26: Female (F) | C26: 0.97375178 | D26: 0.98034321 | E26: 0.98625823 | F26: 0.98916968 | G26: 0.96977929 | H26: 0.99045631 | I26: 0.9816
A27: Region XI - Davao Oriental | B27: Total (MF) | C27: 0.96978346 | D27: 0.97172469 | E27: 0.97632924 | F27: 0.9795283 | G27: 0.96324038 | H27: 0.97489929 | I27: 0.97239474 | J27: 1.0320236
B28: Male (M) | C28: 0.94205361 | D28: 0.94749626 | E28: 0.95441202 | F28: 0.9603073 | G28: 0.93608522 | H28: 0.95809717 | I28: 0.9493
B29: Female (F) | C29: 0.96544632 | D29: 0.9757959 | E29: 0.97799329 | F29: 0.98480421 | G29: 0.98346117 | H29: 0.99198481 | I29: 0.9797
A30: Region XI - Digos City | B30: Total (MF) | C30: 0.99451153 | D30: 0.99592312 | E30: 0.99294533 | F30: 0.9957743 | G30: 0.99746996 | H30: 0.99743297 | I30: 0.99558377 | J30: 1.0086532
B31: Male (M) | C31: 0.98387097 | D31: 0.98190789 | E31: 0.97425935 | F31: 0.98145506 | G31: 0.97946484 | H31: 0.99374645 | I31: 0.9823
B32: Female (F) | C32: 0.9883856 | D32: 0.99130435 | E32: 0.98534031 | F32: 0.99114583 | G32: 0.99485531 | H32: 0.99484831 | I32: 0.9908
A33: Region XI - Island Garden City of Samal | B33: Total (MF) | C33: 0.9625498 | D33: 0.96132151 | E33: 0.95975702 | F33: 0.98050915 | G33: 0.98128079 | H33: 0.97437011 | I33: 0.96941664 | J33: 1.024953
B34: Male (M) | C34: 0.95603577 | D34: 0.94607088 | E34: 0.9439941 | F34: 0.97511664 | G34: 0.96808511 | H34: 0.96197061 | I34: 0.9578
B35: Female (F) | C35: 0.97003425 | D35: 0.97804054 | E35: 0.97650744 | F35: 0.98615635 | G35: 0.99497992 | H35: 0.98689956 | I35: 0.9817
A36: Region XI - Mati City | B36: Total (MF) | C36: 0.94877765 | D36: 0.94548652 | E36: 0.95224274 | F36: 0.95914397 | G36: 0.96638079 | H36: 0.96447658 | I36: 0.95556276 | J36: 1.0376333
B37: Male (M) | C37: 0.9345898 | D37: 0.92731403 | E37: 0.93743642 | F37: 0.94009459 | G37: 0.93974359 | H37: 0.95189417 | I37: 0.938
B38: Female (F) | C38: 0.96446078 | D38: 0.96486978 | E38: 0.96820175 | F38: 0.98053097 | G38: 0.98671587 | H38: 0.97826087 | I38: 0.9733
A39: Region XI - Panabo City | B39: Total (MF) | C39: 0.99210587 | D39: 0.99412772 | E39: 0.99617103 | F39: 0.99546485 | G39: 0.99319543 | H39: 0.99590263 | I39: 0.99455148 | J39: 1.0053573
B40: Male (M) | C40: 0.98453843 | D40: 0.98886827 | E40: 0.99219428 | F40: 0.99118554 | G40: 0.98657358 | H40: 0.9920412 | I40: 0.9893
B41: Female (F) | C41: 0.98908918 | D41: 0.99274987 | E41: 0.99498956 | F41: 0.9967305 | G41: 0.99668874 | H41: 0.99751615 | I41: 0.9946
A42: Region XI - Tagum City | B42: Total (MF) | C42: 0.98992625 | D42: 0.99342225 | E42: 0.99356329 | F42: 0.99530201 | G42: 0.99493414 | H42: 0.99288565 | I42: 0.99334796 | J42: 1.0076406
B43: Male (M) | C43: 0.97510373 | D43: 0.97770812 | E43: 0.97985705 | F43: 0.98308393 | G43: 0.98564222 | H43: 0.98848629 | I43: 0.9816
...

Sheet G1to6 Repetition
A1: DEPARTMENT OF EDUCATION
A2: BASIC EDUCATION INFORMATION SYSTEM
A3: REPETITION RATES IN PUBLIC AND PRIVATE ELEMENTARY SCHOOLS
A4: (GRADE 1 TO GRADE 6)
A5: ='G1to6 SchoolLeaver'!A5 -> SY 2022 - 2023
A8: Note: Computed using UNESCO's template for assessing internal efficiency (Including SUCs)
A10: REGION/DIVISION | B10: Sex | C10: Grade I | D10: Grade II | E10: Grade III | F10: Grade IV | G10: Grade V | H10: Grade VI | I10: Ave. Repetition | J10: Gender
I11: Rate | J11: Parity Index
A12: Region XI - Davao City | B12: Total (MF) | C12: 0.019914815 | D12: 0.015200517 | E12: 0.013413295 | F12: 0.010975141 | G12: 0.010429145 | H12: 0.0085955794 | I12: 0.01314352 | J12: 0.54761905
B13: Male (M) | C13: 0.023812167 | D13: 0.018973527 | E13: 0.016434109 | F13: 0.01463807 | G13: 0.013579179 | H13: 0.012867853 | I13: 0.0168
B14: Female (F) | C14: 0.015718384 | D14: 0.011025085 | E14: 0.010166102 | F14: 0.0071364352 | G14: 0.006886743 | H14: 0.0041413906 | I14: 0.0092
A15: Region XI - Davao de Oro (Compostela Valley) | B15: Total (MF) | C15: 0.026978417 | D15: 0.027422757 | E15: 0.020413808 | F15: 0.016955119 | G15: 0.015132409 | H15: 0.011824324 | I15: 0.019951943 | J15: 0.47191011
B16: Male (M) | C16: 0.033859529 | D16: 0.03589684 | E16: 0.028164455 | F16: 0.022644099 | G16: 0.020868584 | H16: 0.017165277 | I16: 0.0267
B17: Female (F) | C17: 0.019400353 | D17: 0.01770972 | E17: 0.012260188 | F17: 0.010962535 | G17: 0.008765065 | H17: 0.006259581 | I17: 0.0126
A18: Region XI - Davao del Norte | B18: Total (MF) | C18: 0.010428101 | D18: 0.0089946032 | E18: 0.0077873709 | F18: 0.007358156 | G18: 0.0077991713 | H18: 0.0034240061 | I18: 0.0076332228 | J18: 0.52525253
B19: Male (M) | C19: 0.014099401 | D19: 0.010550113 | E19: 0.010819949 | F19: 0.0088934496 | G19: 0.0097470411 | H19: 0.0049705449 | I19: 0.0099
B20: Female (F) | C20: 0.006466337 | D20: 0.0072371222 | E20: 0.0047465672 | F20: 0.0057058715 | G20: 0.0056453682 | H20: 0.0017709563 | I20: 0.0052
A21: Region XI - Davao del Sur | B21: Total (MF) | C21: 0.020473385 | D21: 0.016134005 | E21: 0.015175946 | F21: 0.010446895 | G21: 0.011484627 | H21: 0.008411414 | I21: 0.013789914 | J21: 0.51666667
B22: Male (M) | C22: 0.025187464 | D22: 0.019516003 | E22: 0.019192468 | F22: 0.016058946 | G22: 0.01575898 | H22: 0.011351692 | I22: 0.018
B23: Female (F) | C23: 0.015378221 | D23: 0.012372477 | E23: 0.010756972 | F23: 0.0045589693 | G23: 0.0069238378 | H23: 0.0053937433 | I23: 0.0093
A24: Region XI - Davao Occidental | B24: Total (MF) | C24: 0.031638574 | D24: 0.029498525 | E24: 0.02265861 | F24: 0.020043932 | G24: 0.018382951 | H24: 0.016522775 | I24: 0.023257497 | J24: 0.47909968
B25: Male (M) | C25: 0.036699705 | D25: 0.038321678 | E25: 0.03087886 | F25: 0.029052403 | G25: 0.025608994 | H25: 0.024962853 | I25: 0.0311
B26: Female (F) | C26: 0.026248217 | D26: 0.019656786 | E26: 0.013741769 | F26: 0.010830325 | G26: 0.010526316 | H26: 0.0080524903 | I26: 0.0149
A27: Region XI - Davao Oriental | B27: Total (MF) | C27: 0.030216535 | D27: 0.028275307 | E27: 0.023670761 | F27: 0.020471698 | G27: 0.01820696 | H27: 0.011982233 | I27: 0.022305265 | J27: 0.45560748
B28: Male (M) | C28: 0.057946395 | D28: 0.052503737 | E28: 0.045587981 | F28: 0.039692702 | G28: 0.035064359 | H28: 0.023481781 | I28: 0.0428
B29: Female (F) | C29: 0.034553682 | D29: 0.024204099 | E29: 0.022006714 | F29: 0.015195792 | G29: 0.01198466 | H29: 0.0080151867 | I29: 0.0195
A30: Region XI - Digos City | B30: Total (MF) | C30: 0.0054884742 | D30: 0.0040768783 | E30: 0.0070546737 | F30: 0.0042257022 | G30: 0.0025300443 | H30: 0.002567028 | I30: 0.0044162296 | J30: 0.51977401
B31: Male (M) | C31: 0.016129032 | D31: 0.018092105 | E31: 0.025740651 | F31: 0.018544936 | G31: 0.020535159 | H31: 0.0062535532 | I31: 0.0177
B32: Female (F) | C32: 0.011614402 | D32: 0.0086956522 | E32: 0.014659686 | F32: 0.0088541667 | G32: 0.0051446945 | H32: 0.0051516886 | I32: 0.0092
A33: Region XI - Island Garden City of Samal | B33: Total (MF) | C33: 0.037450199 | D33: 0.038678485 | E33: 0.040242976 | F33: 0.019490851 | G33: 0.018719212 | H33: 0.01520417 | I33: 0.028883361 | J33: 0.42857143
B34: Male (M) | C34: 0.043964232 | D34: 0.053929122 | E34: 0.056005895 | F34: 0.024883359 | G34: 0.031914894 | H34: 0.024200519 | I34: 0.0399
B35: Female (F) | C35: 0.029965753 | D35: 0.021959459 | E35: 0.023492561 | F35: 0.013843648 | G35: 0.0050200803 | H35: 0.0061135371 | I35: 0.0171
A36: Region XI - Mati City | B36: Total (MF) | C36: 0.051222352 | D36: 0.054513482 | E36: 0.047757256 | F36: 0.040856031 | G36: 0.033619211 | H36: 0.026721157 | I36: 0.042937242 | J36: 0.45266781
B37: Male (M) | C37: 0.0654102 | D37: 0.072685974 | E37: 0.062563581 | F37: 0.059905413 | G37: 0.051282051 | H37: 0.033674083 | I37: 0.0581
B38: Female (F) | C38: 0.035539216 | D38: 0.035130224 | E38: 0.031798246 | F38: 0.019469027 | G38: 0.013284133 | H38: 0.019104084 | I38: 0.0263
A39: Region XI - Panabo City | B39: Total (MF) | C39: 0.0078941258 | D39: 0.005872278 | E39: 0.0038289726 | F39: 0.0045351474 | G39: 0.0068045727 | H39: 0.0040973729 | I39: 0.0054485155 | J39: 0.5046729
B40: Male (M) | C40: 0.015461573 | D40: 0.011131725 | E40: 0.0078057242 | F40: 0.0088144557 | G40: 0.013426423 | H40: 0.0079588015 | I40: 0.0107
B41: Female (F) | C41: 0.010910816 | D41: 0.0072501295 | E41: 0.0050104384 | F41: 0.0032695002 | G41: 0.0033112583 | H41: 0.0024838549 | I41: 0.0054
A42: Region XI - Tagum City | B42: Total (MF) | C42: 0.010073754 | D42: 0.0065777453 | E42: 0.0064367057 | F42: 0.0046979866 | G42: 0.0050658561 | H42: 0.0046850599 | I42: 0.0062520371 | J42: 0.59562842
B43: Male (M) | C43: 0.024896266 | D43: 0.022291884 | E43: 0.02014295 | F43: 0.01691607 | G43: 0.013969732 | H43: 0.011513715 | I43: 0.0183
...

Sheet G1to6 SchoolLeaver
A1: DEPARTMENT OF EDUCATION
A2: BASIC EDUCATION INFORMATION SYSTEM
A3: SCHOOL LEAVER RATES IN PUBLIC AND PRIVATE ELEMENTARY SCHOOLS
A4: (GRADE 1 TO GRADE 6)
A5: SY 2022 - 2023
A8: Note: Computed using UNESCO's template for assessing internal efficiency (Including SUCs)
A10: REGION/DIVISION | B10: Sex | C10: Grade I | D10: Grade II | E10: Grade III | F10: Grade IV | G10: Grade V | H10: Grade VI | I10: Ave. School | J10: Gender
I11: Leaver Rate | J11: Parity Index
A12: Region XI - Davao City | B12: Total (MF) | C12: 0 | D12: 0 | E12: 0 | F12: 0 | G12: 0 | H12: 0 | I12: 0 | J12: #DIV/0!
B13: Male (M) | C13: 0 | D13: 0 | E13: 0 | F13: 0 | G13: 0 | H13: 0 | I13: 0
B14: Female (F) | C14: 0 | D14: 0 | E14: 0 | F14: 0 | G14: 0 | H14: 0 | I14: 0
A15: Region XI - Davao de Oro (Compostela Valley) | B15: Total (MF) | C15: 0 | D15: 0 | E15: 0 | F15: 0 | G15: 0.0062309918 | H15: 0.00068818819 | I15: 0.0012 | J15: 0.14285714
B16: Male (M) | C16: 0 | D16: 0 | E16: 0 | F16: 0 | G16: 0.010152284 | H16: 0.0026974007 | I16: 0.0021
B17: Female (F) | C17: 0 | D17: 0 | E17: 0 | F17: 0 | G17: 0.0018782282 | H17: 0 | I17: 0.0003
A18: Region XI - Davao del Norte | B18: Total (MF) | C18: 0.0016465423 | D18: 0 | E18: 0.0066023362 | F18: 0.0039007092 | G18: 0.0029246893 | H18: 0 | I18: 0.0025 | J18: 0.6
B19: Male (M) | C19: 0.0031723652 | D19: 0 | E19: 0.0055790363 | F19: 0.0075252266 | G19: 0.0046414481 | H19: 0 | I19: 0.0035
B20: Female (F) | C20: 0 | D20: 0.0038314176 | E20: 0.0076284116 | F20: 0 | G20: 0.0010264306 | H20: 0 | I20: 0.0021
A21: Region XI - Davao del Sur | B21: Total (MF) | C21: 0 | D21: 0 | E21: 0 | F21: 0 | G21: 0 | H21: 0 | I21: 0 | J21: #DIV/0!
B22: Male (M) | C22: 0 | D22: 0 | E22: 0 | F22: 0 | G22: 0 | H22: 0.00021021652 | I22: 0
B23: Female (F) | C23: 0 | D23: 0 | E23: 0 | F23: 0 | G23: 0 | H23: 0 | I23: 0
A24: Region XI - Davao Occidental | B24: Total (MF) | C24: 0 | D24: 0 | E24: 0 | F24: 0 | G24: 0.026354319 | H24: 0 | I24: 0.0044 | J24: 0.64814815
B25: Male (M) | C25: 0 | D25: 0 | E25: 0 | F25: 0 | G25: 0.0324797 | H25: 0 | I25: 0.0054
B26: Female (F) | C26: 0 | D26: 0 | E26: 0 | F26: 0 | G26: 0.019694397 | H26: 0.0014912019 | I26: 0.0035
A27: Region XI - Davao Oriental | B27: Total (MF) | C27: 0 | D27: 0 | E27: 0 | F27: 0 | G27: 0.018552662 | H27: 0.013118479 | I27: 0.0053 | J27: 0.10126582
B28: Male (M) | C28: 0 | D28: 0 | E28: 0 | F28: 0 | G28: 0.028850422 | H28: 0.018421053 | I28: 0.0079
B29: Female (F) | C29: 0 | D29: 0 | E29: 0 | F29: 0 | G29: 0.0045541707 | H29: 0 | I29: 0.0008
A30: Region XI - Digos City | B30: Total (MF) | C30: 0 | D30: 0 | E30: 0 | F30: 0 | G30: 0 | H30: 0 | I30: 0 | J30: #DIV/0!
B31: Male (M) | C31: 0 | D31: 0 | E31: 0 | F31: 0 | G31: 0 | H31: 0 | I31: 0
B32: Female (F) | C32: 0 | D32: 0 | E32: 0 | F32: 0 | G32: 0 | H32: 0 | I32: 0
A33: Region XI - Island Garden City of Samal | B33: Total (MF) | C33: 0 | D33: 0 | E33: 0 | F33: 0 | G33: 0 | H33: 0.010425717 | I33: 0.0017 | J33: 0.52173913
B34: Male (M) | C34: 0 | D34: 0 | E34: 0 | F34: 0 | G34: 0 | H34: 0.013828868 | I34: 0.0023
B35: Female (F) | C35: 0 | D35: 0 | E35: 0 | F35: 0 | G35: 0 | H35: 0.0069868996 | I35: 0.0012
A36: Region XI - Mati City | B36: Total (MF) | C36: 0 | D36: 0 | E36: 0 | F36: 0 | G36: 0 | H36: 0.0088022634 | I36: 0.0015 | J36: 0.1025641
B37: Male (M) | C37: 0 | D37: 0 | E37: 0 | F37: 0 | G37: 0.008974359 | H37: 0.01443175 | I37: 0.0039
B38: Female (F) | C38: 0 | D38: 0 | E38: 0 | F38: 0 | G38: 0 | H38: 0.0026350461 | I38: 0.0004
A39: Region XI - Panabo City | B39: Total (MF) | C39: 0 | D39: 0 | E39: 0 | F39: 0 | G39: 0 | H39: 0 | I39: 0 | J39: #DIV/0!
B40: Male (M) | C40: 0 | D40: 0 | E40: 0 | F40: 0 | G40: 0 | H40: 0 | I40: 0
B41: Female (F) | C41: 0 | D41: 0 | E41: 0 | F41: 0 | G41: 0 | H41: 0 | I41: 0
A42: Region XI - Tagum City | B42: Total (MF) | C42: 0 | D42: 0 | E42: 0 | F42: 0 | G42: 0 | H42: 0.0024292903 | I42: 0.0004 | J42: 0
B43: Male (M) | C43: 0 | D43: 0 | E43: 0 | F43: 0 | G43: 0.00038804812 | H43: 0 | I43: 0.0001
...

Sheet G7toG10 CSR,CR,Coeffcnt,YrInput
A1: DEPARTMENT OF EDUCATION
A2: BASIC EDUCATION INFORMATION SYSTEM
A3: COHORT SURVIVAL RATE AND COMPLETION RATE IN PUBLIC AND PRIVATE JUNIOR HIGH SCHOOL
A4: (GRADE 7 TO GRADE 10)
A5: SY 2022-2023
A8: Note: Computed using UNESCO's template for assessing internal efficiency (Including SUCs)
A10: REGION/DIVISION | B10: Sex | C10: Survival Rates | F10: (CSR) | G10: Completion | H10: Coefficient | I10: Years Input | J10: GPI | K10: GPI | L10: GPI
C11: Grade 7 | D11: Grade 8 | E11: Grade 9 | F11: Grade 10 | G11: Rate | H11: of Efficiency | I11: Per Graduate | J11: Cohort | K11: Completion | L11: Coefficient
A12: Region XI - Davao City | B12: Total (MF) | C12: 1 | D12: 1 | E12: 1 | F12: 0.99386848 | G12: 0.99386848 | H12: 0.98258338 | I12: 4.0709014 | J12: =F14/F13 -> 0.9973527 | K12: =G14/G13 -> 0.9973527 | L12: =H14/H13 -> 1.007606
B13: Male (M) | C13: 1 | D13: 1 | E13: 0.99881804 | F13: 0.99459527 | G13: 0.99459527 | H13: 0.97856929 | I13: 4.0876002
B14: Female (F) | C14: 1 | D14: 1 | E14: 1 | F14: 0.99196228 | G14: 0.99196228 | H14: 0.98601224 | I14: 4.0567448
A15: Region XI - Davao de Oro (Compostela Valley) | B15: Total (MF) | C15: 1 | D15: 0.98174814 | E15: 0.95302894 | F15: 0.91907545 | G15: 0.91907545 | H15: 0.94415762 | I15: 4.2365807 | J15: =F17/F16 -> 1.0371571 | K15: =G17/G16 -> 1.0371571 | L15: =H17/H16 -> 1.0251389
B16: Male (M) | C16: 1 | D16: 0.97510169 | E16: 0.93427961 | F16: 0.90295982 | G16: 0.90295982 | H16: 0.93283902 | I16: 4.2879853
B17: Female (F) | C17: 1 | D17: 0.98873203 | E17: 0.9733937 | F17: 0.93651121 | G17: 0.93651121 | H17: 0.95628957 | I17: 4.1828334
A18: Region XI - Davao del Norte | B18: Total (MF) | C18: 1 | D18: 0.96725294 | E18: 0.90659805 | F18: 0.84237884 | G18: 0.84237884 | H18: 0.90080971 | I18: 4.4404495 | J18: =F20/F19 -> 1.0239874 | K18: =G20/G19 -> 1.0239874 | L18: =H20/H19 -> 1.0178804
B19: Male (M) | C19: 1 | D19: 0.96841705 | E19: 0.89315411 | F19: 0.83298654 | G19: 0.83298654 | H19: 0.89319506 | I19: 4.4783051
B20: Female (F) | C20: 1 | D20: 0.96603774 | E20: 0.92175546 | F20: 0.85296774 | G20: 0.85296774 | H20: 0.90916573 | I20: 4.3996379
A21: Region XI - Davao del Sur | B21: Total (MF) | C21: 1 | D21: 0.9659566 | E21: 0.91347023 | F21: 0.86014856 | G21: 0.86014855 | H21: 0.90987953 | I21: 4.3961864 | J21: =F23/F22 -> 1.0294577 | K21: =G23/G22 -> 1.0294577 | L21: =H23/H22 -> 1.0218979
B22: Male (M) | C22: 1 | D22: 0.96056504 | E22: 0.89735085 | F22: 0.84799483 | G22: 0.84799483 | H22: 0.90022214 | I22: 4.4433477
B23: Female (F) | C23: 1 | D23: 0.9715094 | E23: 0.93059756 | F23: 0.87297483 | G23: 0.87297483 | H23: 0.91993511 | I23: 4.3481328
A24: Region XI - Davao Occidental | B24: Total (MF) | C24: 1 | D24: 0.92910671 | E24: 0.8268938 | F24: 0.7213518 | G24: 0.7213518 | H24: 0.82134302 | I24: 4.8700724 | J24: =F26/F25 -> 1.0894671 | K24: =G26/G25 -> 1.0894671 | L24: =H26/H25 -> 1.0500423
B25: Male (M) | C25: 1 | D25: 0.91324483 | E25: 0.79431863 | F25: 0.69032646 | G25: 0.69032646 | H25: 0.80091276 | I25: 4.9943018
B26: Female (F) | C26: 1 | D26: 0.94407224 | E26: 0.85897559 | F26: 0.75208794 | G26: 0.75208794 | H26: 0.84099225 | I26: 4.7562864
A27: Region XI - Davao Oriental | B27: Total (MF) | C27: 1 | D27: 0.96616151 | E27: 0.91079438 | F27: 0.8522952 | G27: 0.84627192 | H27: 0.89207461 | I27: 4.4839299 | J27: =F29/F28 -> 1.0008529 | K27: =G29/G28 -> 0.99796789 | L27: =H29/H28 -> 1.0127044
B28: Male (M) | C28: 1 | D28: 0.96321886 | E28: 0.90726342 | F28: 0.85201401 | G28: 0.84731126 | H28: 0.88662482 | I28: 4.5114911
B29: Female (F) | C29: 1 | D29: 0.96923403 | E29: 0.91448435 | F29: 0.85274066 | G29: 0.84558943 | H29: 0.89788888 | I29: 4.4548942
A30: Region XI - Digos City | B30: Total (MF) | C30: 1 | D30: 1 | E30: 1 | F30: 1 | G30: 1 | H30: 0.9804949 | I30: 4.0795725 | J30: =F32/F31 -> 1 | K30: =G32/G31 -> 1 | L30: =H32/H31 -> 1.0199114
B31: Male (M) | C31: 1 | D31: 1 | E31: 1 | F31: 0.99999999 | G31: 0.99999997 | H31: 0.97067955 | I31: 4.1208244
B32: Female (F) | C32: 1 | D32: 1 | E32: 1 | F32: 1 | G32: 1 | H32: 0.99000714 | I32: 4.0403749
A33: Region XI - Island Garden City of Samal | B33: Total (MF) | C33: 1 | D33: 1 | E33: 0.98763462 | F33: 0.97294539 | G33: 0.96612193 | H33: 0.95742885 | I33: 4.1778561 | J33: =F35/F34 -> 1.0480699 | K33: =G35/G34 -> 1.0540245 | L33: =H35/H34 -> 1.0624436
B34: Male (M) | C34: 1 | D34: 1 | E34: 0.98060511 | F34: 0.94943466 | G34: 0.94013406 | H34: 0.92814019 | I34: 4.3096938
B35: Female (F) | C35: 1 | D35: 1 | E35: 0.99507389 | F35: 0.99507389 | G35: 0.99092429 | H35: 0.98609661 | I35: 4.0563977
A36: Region XI - Mati City | B36: Total (MF) | C36: 1 | D36: 0.96702317 | E36: 0.93538634 | F36: 0.88523924 | G36: 0.85822946 | H36: 0.88394826 | I36: 4.5251517 | J36: =F38/F37 -> 1.0937105 | K36: =G38/G37 -> 1.0864888 | L36: =H38/H37 -> 1.0717893
B37: Male (M) | C37: 1 | D37: 0.95727554 | E37: 0.91383895 | F37: 0.84594225 | G37: 0.82307889 | H37: 0.85350909 | I37: 4.6865347
B38: Female (F) | C38: 1 | D38: 0.97601371 | E38: 0.95632467 | F38: 0.92521596 | G38: 0.89426601 | H38: 0.91478191 | I38: 4.3726269
A39: Region XI - Panabo City | B39: Total (MF) | C39: 1 | D39: 1 | E39: 1 | F39: 0.99467259 | G39: 0.99467259 | H39: 0.98828303 | I39: 4.0474235 | J39: =F41/F40 -> 1.0233225 | K39: =G41/G40 -> 1.0233225 | L39: =H41/H40 -> 1.0236675
B40: Male (M) | C40: 1 | D40: 1 | E40: 0.99076923 | F40: 0.97720903 | G40: 0.97720903 | H40: 0.97340381 | I40: 4.1092915
B41: Female (F) | C41: 1 | D41: 1 | E41: 1 | F41: 1 | G41: 1 | H41: 0.9964418 | I41: 4.0142836
A42: Region XI - Tagum City | B42: Total (MF) | C42: 1 | D42: 1 | E42: 1 | F42: 0.99653106 | G42: 0.99653106 | H42: 0.98902443 | I42: 4.0443895 | J42: =F44/F43 -> 1.0108143 | K42: =G44/G43 -> 1.0108143 | L42: =H44/H43 -> 1.0143769
B43: Male (M) | C43: 1 | D43: 1 | E43: 0.99617591 | F43: 0.98930142 | G43: 0.98930142 | H43: 0.98108704 | I43: 4.0771102
...

Sheet G7toG10 Promo & Grad
A1: DEPARTMENT OF EDUCATION
A2: BASIC EDUCATION INFORMATION SYSTEM
A3: PROMOTION RATE AND GRADUATION RATE IN PUBLIC AND PRIVATE JUNIOR HIGH SCHOOL
A4: (GRADE 7 TO GRADE 10)
A5: ='G7toG10 School Leaver'!A5:H5 -> SY 2022-2023
A8: Note: Computed using UNESCO's template for assessing internal efficiency (Including SUCs)
A10: REGION/DIVISION | B10: Sex | C10: Grade 7 | D10: Grade 8 | E10: Grade 9 | F10: Grade 10 | G10: Ave. Promotion | H10: Gender
F11: Grad. Rate | G11: Rate | H11: Parity Index
A12: Region XI - Davao City | B12: Total (MF) | C12: 0.98652983 | D12: 0.98678414 | E12: 0.98169845 | F12: 0.98745331 | G12: 0.9856409 | H12: 1.0091743
B13: Male (M) | C13: 0.9808736 | D13: 0.98067773 | E13: 0.97916119 | F13: 0.98304627 | G13: 0.981
B14: Female (F) | C14: 0.99235233 | D14: 0.99178548 | E14: 0.98426202 | F14: 0.99163974 | G14: 0.99
A15: Region XI - Davao de Oro (Compostela Valley) | B15: Total (MF) | C15: 0.97041014 | D15: 0.9607486 | E15: 0.95437616 | F15: 0.99136912 | G15: 0.96921037 | H15: 1.02
B16: Male (M) | C16: 0.95774818 | D16: 0.94332614 | E16: 0.95184744 | F16: 0.98715403 | G16: 0.96
B17: Female (F) | C17: 0.98388968 | D17: 0.97993929 | E17: 0.95712435 | F17: 0.99569017 | G17: 0.9792
A18: Region XI - Davao del Norte | B18: Total (MF) | C18: 0.95960667 | D18: 0.93091076 | E18: 0.92339062 | F18: 0.99522248 | G18: 0.95228078 | H18: 1.0122518
B19: Male (M) | C19: 0.95640737 | D19: 0.91475694 | E19: 0.92347601 | F19: 0.99234217 | G19: 0.9468
B20: Female (F) | C20: 0.96297763 | D20: 0.94911937 | E20: 0.92329661 | F20: 0.99812065 | G20: 0.9584
A21: Region XI - Davao del Sur | B21: Total (MF) | C21: 0.95118604 | D21: 0.93373146 | E21: 0.93319049 | F21: 0.99345511 | G21: 0.95284551 | H21: 1.0184244
B22: Male (M) | C22: 0.93829053 | D22: 0.91685226 | E22: 0.9335479 | F22: 0.98936597 | G22: 0.9444
B23: Female (F) | C23: 0.964687 | D23: 0.95194233 | E23: 0.93281187 | F23: 0.99733486 | G23: 0.9618
A24: Region XI - Davao Occidental | B24: Total (MF) | C24: 0.91565731 | D24: 0.8824387 | E24: 0.8661953 | F24: 0.99017406 | G24: 0.91375034 | H24: 1.0290949
B25: Male (M) | C25: 0.89257695 | D25: 0.86003732 | E25: 0.86157582 | F25: 0.98657518 | G25: 0.9005
B26: Female (F) | C26: 0.93778935 | D26: 0.90458619 | E26: 0.8707124 | F26: 0.99337222 | G26: 0.9267
A27: Region XI - Davao Oriental | B27: Total (MF) | C27: 0.94708995 | D27: 0.92527562 | E27: 0.92088898 | F27: 0.97877436 | G27: 0.93109775 | H27: 1.0201911
B28: Male (M) | C28: 0.93325458 | D28: 0.91559342 | E28: 0.9169212 | F28: 0.97345549 | G28: 0.92199242
B29: Female (F) | C29: 0.96188671 | D29: 0.93556538 | E29: 0.92486729 | F29: 0.98336714 | G29: 0.9406085
A30: Region XI - Digos City | B30: Total (MF) | C30: 0.97819461 | D30: 0.97527253 | E30: 0.98104376 | F30: 0.98755284 | G30: 0.98067283 | H30: 1.0200886
B31: Male (M) | C31: 0.96493689 | D31: 0.9651715 | E31: 0.97155256 | F31: 0.98123732 | G31: 0.9707
B32: Female (F) | C32: 0.9915334 | D32: 0.98553055 | E32: 0.98999545 | F32: 0.99300087 | G32: 0.9902
A33: Region XI - Island Garden City of Samal | B33: Total (MF) | C33: 0.97526793 | D33: 0.96832225 | E33: 0.96943607 | F33: 0.97845528 | G33: 0.97286152 | H33: 1.0367424
B34: Male (M) | C34: 0.95728643 | D34: 0.94966191 | E34: 0.94626364 | F34: 0.96807662 | G34: 0.9553
B35: Female (F) | C35: 0.99269481 | D35: 0.98858075 | E35: 0.99116608 | F35: 0.98922949 | G35: 0.9904
A36: Region XI - Mati City | B36: Total (MF) | C36: 0.94156783 | D36: 0.94006753 | E36: 0.92280607 | F36: 0.95118662 | G36: 0.93459778 | H36: 1.0577809
B37: Male (M) | C37: 0.91696323 | D37: 0.91420613 | E37: 0.895157 | F37: 0.94736842 | G37: 0.90839552
B38: Female (F) | C38: 0.96499153 | D38: 0.96645821 | E38: 0.95146167 | F38: 0.95445445 | G38: 0.9608834
A39: Region XI - Panabo City | B39: Total (MF) | C39: 0.99124827 | D39: 0.99090707 | E39: 0.98722186 | F39: 0.99436561 | G39: 0.99100008 | H39: 1.0142494
B40: Male (M) | C40: 0.98526128 | D40: 0.97829861 | E40: 0.97554585 | F40: 0.99085764 | G40: 0.9825
B41: Female (F) | C41: 0.99762244 | D41: 0.99455782 | E41: 0.99599822 | F41: 0.99759519 | G41: 0.9965
A42: Region XI - Tagum City | B42: Total (MF) | C42: 0.98962232 | D42: 0.99034199 | E42: 0.98889063 | F42: 0.99415029 | G42: 0.99078383 | H42: 1.0098417
B43: Male (M) | C43: 0.98618875 | D43: 0.98270984 | E43: 0.98200993 | F43: 0.99092833 | G43: 0.9856
...

Sheet G7toG10 Repetition Rate
A1: DEPARTMENT OF EDUCATION
A2: BASIC EDUCATION INFORMATION SYSTEM
A3: REPETITION RATE IN PUBLIC AND PRIVATE JUNIOR HIGH SCHOOL
A4: (GRADE 7 TO GRADE 10)
A5: ='G7toG10 Promo & Grad'!A5:H5 -> SY 2022-2023
A8: Note: Computed using UNESCO's template for assessing internal efficiency (Including SUCs)
A10: REGION/DIVISION | B10: Sex | C10: Grade 7 | D10: Grade 8 | E10: Grade 9 | F10: Grade 10 | G10: Ave. Repetition | H10: Gender
G11: Rate | H11: Parity Index
A12: Region XI - Davao City | B12: Total (MF) | C12: 0.013470173 | D12: 0.013215859 | E12: 0.012245114 | F12: 0.012546688 | G12: 0.012859099 | H12: 0.4519774
B13: Male (M) | C13: 0.019126403 | D13: 0.018161773 | E13: 0.016681577 | F13: 0.016953728 | G13: 0.0177
B14: Female (F) | C14: 0.007647665 | D14: 0.0082145162 | E14: 0.0077626542 | F14: 0.0083602606 | G14: 0.008
A15: Region XI - Davao de Oro (Compostela Valley) | B15: Total (MF) | C15: 0.011548786 | D15: 0.010299567 | E15: 0.010366232 | F15: 0.008630882 | G15: 0.010189632 | H15: 0.30718954
B16: Male (M) | C16: 0.01779661 | D16: 0.015456506 | E16: 0.015137068 | F16: 0.012845965 | G16: 0.0153
B17: Female (F) | C17: 0.0048975383 | D17: 0.0046192424 | E17: 0.0051813472 | F17: 0.0043098288 | G17: 0.0047
A18: Region XI - Davao del Norte | B18: Total (MF) | C18: 0.0079051383 | D18: 0.0068077277 | E18: 0.0062141956 | F18: 0.0047775176 | G18: 0.006419215 | H18: 0.32631579
B19: Male (M) | C19: 0.012401353 | D19: 0.0081597222 | E19: 0.0098202705 | F19: 0.0076578259 | G19: 0.0095
B20: Female (F) | C20: 0.0031676896 | D20: 0.0052837573 | E20: 0.002243982 | F20: 0.001879346 | G20: 0.0031
A21: Region XI - Davao del Sur | B21: Total (MF) | C21: 0.015291119 | D21: 0.012617993 | E21: 0.0089598753 | F21: 0.0065448862 | G21: 0.010854487 | H21: 0.32716049
B22: Male (M) | C22: 0.023188961 | D22: 0.018559762 | E22: 0.012116622 | F22: 0.010634029 | G22: 0.0162
B23: Female (F) | C23: 0.0070224719 | D23: 0.0062074489 | E23: 0.005615724 | F23: 0.0026651437 | G23: 0.0053
A24: Region XI - Davao Occidental | B24: Total (MF) | C24: 0.014475628 | D24: 0.0084824387 | E24: 0.0070704376 | F24: 0.0098259405 | G24: 0.009849663 | H24: 0.44525547
B25: Male (M) | C25: 0.022631261 | D25: 0.011197014 | E25: 0.0086346465 | F25: 0.013424821 | G25: 0.0137
B26: Female (F) | C26: 0.0066550926 | D26: 0.0057986294 | E26: 0.0055408971 | F26: 0.0066277837 | G26: 0.0061
A27: Region XI - Davao Oriental | B27: Total (MF) | C27: 0.01973952 | D27: 0.018476929 | E27: 0.015903762 | F27: 0.014259279 | G27: 0.017141378 | H27: 0.31037632
B28: Male (M) | C28: 0.031108486 | D28: 0.027937389 | E28: 0.023620444 | F28: 0.021141649 | G28: 0.02617394
B29: Female (F) | C29: 0.0075805433 | D29: 0.0084228259 | E29: 0.0081665986 | F29: 0.00831643 | G29: 0.0081237711
A30: Region XI - Digos City | B30: Total (MF) | C30: 0.021805393 | D30: 0.024727466 | E30: 0.018956237 | F30: 0.012447158 | G30: 0.019327173 | H30: 0.33447099
B31: Male (M) | C31: 0.035063114 | D31: 0.034828496 | E31: 0.028447445 | F31: 0.018762677 | G31: 0.0293
B32: Female (F) | C32: 0.008466604 | D32: 0.014469453 | E32: 0.010004548 | F32: 0.0069991251 | G32: 0.0098
A33: Region XI - Island Garden City of Samal | B33: Total (MF) | C33: 0.024732069 | D33: 0.019554165 | E33: 0.01592768 | F33: 0.014634146 | G33: 0.01873848 | H33: 0.24496644
B34: Male (M) | C34: 0.042713568 | D34: 0.031555222 | E34: 0.022670025 | F34: 0.022346369 | G34: 0.0298
B35: Female (F) | C35: 0.0073051948 | D35: 0.0065252855 | E35: 0.0088339223 | F35: 0.0066280033 | G35: 0.0073
A36: Region XI - Mati City | B36: Total (MF) | C36: 0.026323402 | D36: 0.02813731 | E36: 0.024918743 | F36: 0.018878101 | G36: 0.024495177 | H36: 0.37537528
B37: Male (M) | C37: 0.042111507 | D37: 0.042339833 | E37: 0.032996275 | F37: 0.026315789 | G37: 0.03592645
