Workbook

Sheet COD-ES
A1: END OF SCHOOL YEAR - CAUSES OF DROPOUT IN ELEMENTARY LEVEL
A2: SY 2023-2024
A3: Based on official cut-off date of EOSY as of August 16, 2024 | K3: Had to Take Care Siblings | AD3: Early Marriage/Pregnancy | AW3: Parents Attitude Toward Schooling | BP3: Family problems/Feuds | CI3: Illness | DB3: Overage | DU3: Drug Abuse | EN3: Poor Academic Performance | FG3: Lack of interest/Distractions | FZ3: Hunger/Malnutrition | GS3: Teacher Factors | HL3: Physical Conditions of Classrooms | IE3: Peer Influences | IX3: Distance between Home and School | JQ3: Armed Conflict | KJ3: Calamities/Disasters | LC3: Child Labor, Work | LV3: Others | MO3: GRAND TOTAL | NI3: Death
K4: Kindergarten | M4: Grade 1 | O4: Grade 2 | Q4: Grade 3 | S4: Grade 4 | U4: Grade 5 | W4: Grade 6 | Y4: Non-Graded (SNED) | AA4: Total | AD4: Kindergarten | AF4: Grade 1 | AH4: Grade 2 | AJ4: Grade 3 | AL4: Grade 4 | AN4: Grade 5 | AP4: Grade 6 | AR4: Non-Graded (SNED) | AT4: Total | AW4: Kindergarten | AY4: Grade 1 | BA4: Grade 2 | BC4: Grade 3 | BE4: Grade 4 | BG4: Grade 5 | BI4: Grade 6 | BK4: Non-Graded (SNED) | BM4: Total | BP4: Kindergarten | BR4: Grade 1 | BT4: Grade 2 | BV4: Grade 3 | BX4: Grade 4 | BZ4: Grade 5 | CB4: Grade 6 | CD4: Non-Graded (SNED) | CF4: Total | CI4: Kindergarten | CK4: Grade 1 | CM4: Grade 2 | CO4: Grade 3 | CQ4: Grade 4 | CS4: Grade 5 | CU4: Grade 6 | CW4: Non-Graded (SNED) | CY4: Total | DB4: Kindergarten | DD4: Grade 1 | DF4: Grade 2 | DH4: Grade 3 | DJ4: Grade 4 | DL4: Grade 5 | DN4: Grade 6 | DP4: Non-Graded (SNED) | DR4: Total | DU4: Kindergarten | DW4: Grade 1 | DY4: Grade 2 | EA4: Grade 3 | EC4: Grade 4 | EE4: Grade 5 | EG4: Grade 6 | EI4: Non-Graded (SNED) | EK4: Total | EN4: Kindergarten | EP4: Grade 1 | ER4: Grade 2 | ET4: Grade 3 | EV4: Grade 4 | EX4: Grade 5 | EZ4: Grade 6 | FB4: Non-Graded (SNED) | FD4: Total | FG4: Kindergarten | FI4: Grade 1 | FK4: Grade 2 | FM4: Grade 3 | FO4: Grade 4 | FQ4: Grade 5 | FS4: Grade 6 | FU4: Non-Graded (SNED) | FW4: Total | FZ4: Kindergarten | GB4: Grade 1 | GD4: Grade 2 | GF4: Grade 3 | GH4: Grade 4 | GJ4: Grade 5 | GL4: Grade 6 | GN4: Non-Graded (SNED) | GP4: Total | GS4: Kindergarten | GU4: Grade 1 | GW4: Grade 2 | GY4: Grade 3 | HA4: Grade 4 | HC4: Grade 5 | HE4: Grade 6 | HG4: Non-Graded (SNED) | HI4: Total | HL4: Kindergarten | HN4: Grade 1 | HP4: Grade 2 | HR4: Grade 3 | HT4: Grade 4 | HV4: Grade 5 | HX4: Grade 6 | HZ4: Non-Graded (SNED) | IB4: Total | IE4: Kindergarten | IG4: Grade 1 | II4: Grade 2 | IK4: Grade 3 | IM4: Grade 4 | IO4: Grade 5 | IQ4: Grade 6 | IS4: Non-Graded (SNED) | IU4: Total | IX4: Kindergarten | IZ4: Grade 1 | JB4: Grade 2 | JD4: Grade 3 | JF4: Grade 4 | JH4: Grade 5 | JJ4: Grade 6 | JL4: Non-Graded (SNED) | JN4: Total | JQ4: Kindergarten | JS4: Grade 1 | JU4: Grade 2 | JW4: Grade 3 | JY4: Grade 4 | KA4: Grade 5 | KC4: Grade 6 | KE4: Non-Graded (SNED) | KG4: Total | KJ4: Kindergarten | KL4: Grade 1 | KN4: Grade 2 | KP4: Grade 3 | KR4: Grade 4 | KT4: Grade 5 | KV4: Grade 6 | KX4: Non-Graded (SNED) | KZ4: Total | LC4: Kindergarten | LE4: Grade 1 | LG4: Grade 2 | LI4: Grade 3 | LK4: Grade 4 | LM4: Grade 5 | LO4: Grade 6 | LQ4: Non-Graded (SNED) | LS4: Total | LV4: Kindergarten | LX4: Grade 1 | LZ4: Grade 2 | MB4: Grade 3 | MD4: Grade 4 | MF4: Grade 5 | MH4: Grade 6 | MJ4: Non-Graded (SNED) | ML4: Total | MO4: Kindergarten | MQ4: Grade 1 | MS4: Grade 2 | MU4: Grade 3 | MW4: Grade 4 | MY4: Grade 5 | NA4: Grade 6 | NC4: Non-Graded (SNED) | NE4: Total | NI4: Kindergarten | NK4: Grade 1 | NM4: Grade 2 | NO4: Grade 3 | NQ4: Grade 4 | NS4: Grade 5 | NU4: Grade 6 | NW4: Non-Graded (SNED) | NY4: Total
K5: Male | L5: Female | M5: Male | N5: Female | O5: Male | P5: Female | Q5: Male | R5: Female | S5: Male | T5: Female | U5: Male | V5: Female | W5: Male | X5: Female | Y5: Male | Z5: Female | AA5: Male | AB5: Female | AC5: Total | AD5: Male | AE5: Female | AF5: Male | AG5: Female | AH5: Male | AI5: Female | AJ5: Male | AK5: Female | AL5: Male | AM5: Female | AN5: Male | AO5: Female | AP5: Male | AQ5: Female | AR5: Male | AS5: Female | AT5: Male | AU5: Female | AV5: Total | AW5: Male | AX5: Female | AY5: Male | AZ5: Female | BA5: Male | BB5: Female | BC5: Male | BD5: Female | BE5: Male | BF5: Female | BG5: Male | BH5: Female | BI5: Male | BJ5: Female | BK5: Male | BL5: Female | BM5: Male | BN5: Female | BO5: Total | BP5: Male | BQ5: Female | BR5: Male | BS5: Female | BT5: Male | BU5: Female | BV5: Male | BW5: Female | BX5: Male | BY5: Female | BZ5: Male | CA5: Female | CB5: Male | CC5: Female | CD5: Male | CE5: Female | CF5: Male | CG5: Female | CH5: Total | CI5: Male | CJ5: Female | CK5: Male | CL5: Female | CM5: Male | CN5: Female | CO5: Male | CP5: Female | CQ5: Male | CR5: Female | CS5: Male | CT5: Female | CU5: Male | CV5: Female | CW5: Male | CX5: Female | CY5: Male | CZ5: Female | DA5: Total | DB5: Male | DC5: Female | DD5: Male | DE5: Female | DF5: Male | DG5: Female | DH5: Male | DI5: Female | DJ5: Male | DK5: Female | DL5: Male | DM5: Female | DN5: Male | DO5: Female | DP5: Male | DQ5: Female | DR5: Male | DS5: Female | DT5: Total | DU5: Male | DV5: Female | DW5: Male | DX5: Female | DY5: Male | DZ5: Female | EA5: Male | EB5: Female | EC5: Male | ED5: Female | EE5: Male | EF5: Female | EG5: Male | EH5: Female | EI5: Male | EJ5: Female | EK5: Male | EL5: Female | EM5: Total | EN5: Male | EO5: Female | EP5: Male | EQ5: Female | ER5: Male | ES5: Female | ET5: Male | EU5: Female | EV5: Male | EW5: Female | EX5: Male | EY5: Female | EZ5: Male | FA5: Female | FB5: Male | FC5: Female | FD5: Male | FE5: Female | FF5: Total | FG5: Male | FH5: Female | FI5: Male | FJ5: Female | FK5: Male | FL5: Female | FM5: Male | FN5: Female | FO5: Male | FP5: Female | FQ5: Male | FR5: Female | FS5: Male | FT5: Female | FU5: Male | FV5: Female | FW5: Male | FX5: Female | FY5: Total | FZ5: Male | GA5: Female | GB5: Male | GC5: Female | GD5: Male | GE5: Female | GF5: Male | GG5: Female | GH5: Male | GI5: Female | GJ5: Male | GK5: Female | GL5: Male | GM5: Female | GN5: Male | GO5: Female | GP5: Male | GQ5: Female | GR5: Total | GS5: Male | GT5: Female | GU5: Male | GV5: Female | GW5: Male | GX5: Female | GY5: Male | GZ5: Female | HA5: Male | HB5: Female | HC5: Male | HD5: Female | HE5: Male | HF5: Female | HG5: Male | HH5: Female | HI5: Male | HJ5: Female | HK5: Total | HL5: Male | HM5: Female | HN5: Male | HO5: Female | HP5: Male | HQ5: Female | HR5: Male | HS5: Female | HT5: Male | HU5: Female | HV5: Male | HW5: Female | HX5: Male | HY5: Female | HZ5: Male | IA5: Female | IB5: Male | IC5: Female | ID5: Total | IE5: Male | IF5: Female | IG5: Male | IH5: Female | II5: Male | IJ5: Female | IK5: Male | IL5: Female | IM5: Male | IN5: Female | IO5: Male | IP5: Female | IQ5: Male | IR5: Female | IS5: Male | IT5: Female | IU5: Male | IV5: Female | IW5: Total | IX5: Male | IY5: Female | IZ5: Male | JA5: Female | JB5: Male | JC5: Female | JD5: Male | JE5: Female | JF5: Male | JG5: Female | JH5: Male | JI5: Female | JJ5: Male | JK5: Female | JL5: Male | JM5: Female | JN5: Male | JO5: Female | JP5: Total | JQ5: Male | JR5: Female | JS5: Male | JT5: Female | JU5: Male | JV5: Female | JW5: Male | JX5: Female | JY5: Male | JZ5: Female | KA5: Male | KB5: Female | KC5: Male | KD5: Female | KE5: Male | KF5: Female | KG5: Male | KH5: Female | KI5: Total | KJ5: Male | KK5: Female | KL5: Male | KM5: Female | KN5: Male | KO5: Female | KP5: Male | KQ5: Female | KR5: Male | KS5: Female | KT5: Male | KU5: Female | KV5: Male | KW5: Female | KX5: Male | KY5: Female | KZ5: Male | LA5: Female | LB5: Total | LC5: Male | LD5: Female | LE5: Male | LF5: Female | LG5: Male | LH5: Female | LI5: Male | LJ5: Female | LK5: Male | LL5: Female | LM5: Male | LN5: Female | LO5: Male | LP5: Female | LQ5: Male | LR5: Female | LS5: Male | LT5: Female | LU5: Total | LV5: Male | LW5: Female | LX5: Male | LY5: Female | LZ5: Male | MA5: Female | MB5: Male | MC5: Female | MD5: Male | ME5: Female | MF5: Male | MG5: Female | MH5: Male | MI5: Female | MJ5: Male | MK5: Female | ML5: Male | MM5: Female | MN5: Total | MO5: Male | MP5: Female | MQ5: Male | MR5: Female | MS5: Male | MT5: Female | MU5: Male | MV5: Female | MW5: Male | MX5: Female | MY5: Male | MZ5: Female | NA5: Male | NB5: Female | NC5: Male | ND5: Female | NE5: Male | NF5: Female | NG5: Total | NI5: Male | NJ5: Female | NK5: Male | NL5: Female | NM5: Male | NN5: Female | NO5: Male | NP5: Female | NQ5: Male | NR5: Female | NS5: Male | NT5: Female | NU5: Male | NV5: Female | NW5: Male | NX5: Female | NY5: Male | NZ5: Female | OA5: Total
K6: =SUM(K8:K91) -> 0 | L6: =SUM(L8:L91) -> 0 | M6: =SUM(M8:M91) -> 0 | N6: =SUM(N8:N91) -> 0 | O6: =SUM(O8:O91) -> 0 | P6: =SUM(P8:P91) -> 0 | Q6: =SUM(Q8:Q91) -> 0 | R6: =SUM(R8:R91) -> 0 | ... NG6: =SUM(NG8:NG91) -> 273 | NI6: =SUM(NI8:NI91) -> 2 | NJ6: =SUM(NJ8:NJ91) -> 1 | NK6: =SUM(NK8:NK91) -> 1 | NL6: =SUM(NL8:NL91) -> 0 | NM6: =SUM(NM8:NM91) -> 0 | NN6: =SUM(NN8:NN91) -> 1 | NO6: =SUM(NO8:NO91) -> 0 | NP6: =SUM(NP8:NP91) -> 0 | ... OA6: =SUM(OA8:OA91) -> 6
A7: Region | B7: Division | C7: Province | D7: Municipality | E7: BEIS School ID | F7: School Name | G7: School Subclassification | H7: Sector | I7: Curricular Offering Classification | J7: School Type | K7: take_care_siblings_k_male | L7: take_care_siblings_k_female | M7: take_care_siblings_g1_male | N7: take_care_siblings_g1_female | O7: take_care_siblings_g2_male | P7: take_care_siblings_g2_female | Q7: take_care_siblings_g3_male | R7: take_care_siblings_g3_female | S7: take_care_siblings_g4_male | T7: take_care_siblings_g4_female | U7: take_care_siblings_g5_male | V7: take_care_siblings_g5_female | W7: take_care_siblings_g6_male | X7: take_care_siblings_g6_female | Y7: take_care_siblings_ng_male | Z7: take_care_siblings_ng_female | AA7: Male | AB7: Female | AC7: Total | AD7: marr_preg_k_male | AE7: marr_preg_k_female | AF7: marr_preg_g1_male | AG7: marr_preg_g1_female | AH7: marr_preg_g2_male | AI7: marr_preg_g2_female | AJ7: marr_preg_g3_male | AK7: marr_preg_g3_female | AL7: marr_preg_g4_male | AM7: marr_preg_g4_female | AN7: marr_preg_g5_male | AO7: marr_preg_g5_female | AP7: marr_preg_g6_male | AQ7: marr_preg_g6_female | AR7: marr_preg_ng_male | AS7: marr_preg_ng_female | AT7: Male | AU7: Female | AV7: Total | AW7: parents_toward_school_k_male | AX7: parents_toward_school_k_female | AY7: parents_toward_school_g1_male | AZ7: parents_toward_school_g1_female | BA7: parents_toward_school_g2_male | BB7: parents_toward_school_g2_female | BC7: parents_toward_school_g3_male | BD7: parents_toward_school_g3_female | BE7: parents_toward_school_g4_male | BF7: parents_toward_school_g4_female | BG7: parents_toward_school_g5_male | BH7: parents_toward_school_g5_female | BI7: parents_toward_school_g6_male | BJ7: parents_toward_school_g6_female | BK7: parents_toward_school_ng_male | BL7: parents_toward_school_ng_female | BM7: Male | BN7: Female | BO7: Total | BP7: fam_prob_feuds_k_male | BQ7: fam_prob_feuds_k_female | BR7: fam_prob_feuds_g1_male | BS7: fam_prob_feuds_g1_female | BT7: fam_prob_feuds_g2_male | BU7: fam_prob_feuds_g2_female | BV7: fam_prob_feuds_g3_male | BW7: fam_prob_feuds_g3_female | BX7: fam_prob_feuds_g4_male | BY7: fam_prob_feuds_g4_female | BZ7: fam_prob_feuds_g5_male | CA7: fam_prob_feuds_g5_female | CB7: fam_prob_feuds_g6_male | CC7: fam_prob_feuds_g6_female | CD7: fam_prob_feuds_ng_male | CE7: fam_prob_feuds_ng_female | CF7: Male | CG7: Female | CH7: Total | CI7: illness_k_male | CJ7: illness_k_female | CK7: illness_g1_male | CL7: illness_g1_female | CM7: illness_g2_male | CN7: illness_g2_female | CO7: illness_g3_male | CP7: illness_g3_female | CQ7: illness_g4_male | CR7: illness_g4_female | CS7: illness_g5_male | CT7: illness_g5_female | CU7: illness_g6_male | CV7: illness_g6_female | CW7: illness_ng_male | CX7: illness_ng_female | CY7: Male | CZ7: Female | DA7: Total | DB7: overage_k_male | DC7: overage_k_female | DD7: overage_g1_male | DE7: overage_g1_female | DF7: overage_g2_male | DG7: overage_g2_female | DH7: overage_g3_male | DI7: overage_g3_female | DJ7: overage_g4_male | DK7: overage_g4_female | DL7: overage_g5_male | DM7: overage_g5_female | DN7: overage_g6_male | DO7: overage_g6_female | DP7: overage_ng_male | DQ7: overage_ng_female | DR7: Male | DS7: Female | DT7: Total | DU7: drug_abuse_k_male | DV7: drug_abuse_k_female | DW7: drug_abuse_g1_male | DX7: drug_abuse_g1_female | DY7: drug_abuse_g2_male | DZ7: drug_abuse_g2_female | EA7: drug_abuse_g3_male | EB7: drug_abuse_g3_female | EC7: drug_abuse_g4_male | ED7: drug_abuse_g4_female | EE7: drug_abuse_g5_male | EF7: drug_abuse_g5_female | EG7: drug_abuse_g6_male | EH7: drug_abuse_g6_female | EI7: drug_abuse_ng_male | EJ7: drug_abuse_ng_female | EK7: Male | EL7: Female | EM7: Total | EN7: poor_acad_perf_k_male | EO7: poor_acad_perf_k_female | EP7: poor_acad_perf_g1_male | EQ7: poor_acad_perf_g1_female | ER7: poor_acad_perf_g2_male | ES7: poor_acad_perf_g2_female | ET7: poor_acad_perf_g3_male | EU7: poor_acad_perf_g3_female | EV7: poor_acad_perf_g4_male | EW7: poor_acad_perf_g4_female | EX7: poor_acad_perf_g5_male | EY7: poor_acad_perf_g5_female | EZ7: poor_acad_perf_g6_male | FA7: poor_acad_perf_g6_female | FB7: poor_acad_perf_ng_male | FC7: poor_acad_perf_ng_female | FD7: Male | FE7: Female | FF7: Total | FG7: lack_of_interest_k_male | FH7: lack_of_interest_k_female | FI7: lack_of_interest_g1_male | FJ7: lack_of_interest_g1_female | FK7: lack_of_interest_g2_male | FL7: lack_of_interest_g2_female | FM7: lack_of_interest_g3_male | FN7: lack_of_interest_g3_female | FO7: lack_of_interest_g4_male | FP7: lack_of_interest_g4_female | FQ7: lack_of_interest_g5_male | FR7: lack_of_interest_g5_female | FS7: lack_of_interest_g6_male | FT7: lack_of_interest_g6_female | FU7: lack_of_interest_ng_male | FV7: lack_of_interest_ng_female | FW7: Male | FX7: Female | FY7: Total | FZ7: hunger_malnu_k_male | GA7: hunger_malnu_k_female | GB7: hunger_malnu_g1_male | GC7: hunger_malnu_g1_female | GD7: hunger_malnu_g2_male | GE7: hunger_malnu_g2_female | GF7: hunger_malnu_g3_male | GG7: hunger_malnu_g3_female | GH7: hunger_malnu_g4_male | GI7: hunger_malnu_g4_female | GJ7: hunger_malnu_g5_male | GK7: hunger_malnu_g5_female | GL7: hunger_malnu_g6_male | GM7: hunger_malnu_g6_female | GN7: hunger_malnu_ng_male | GO7: hunger_malnu_ng_female | GP7: Male | GQ7: Female | GR7: Total | GS7: teacher_factor_k_male | GT7: teacher_factor_k_female | GU7: teacher_factor_g1_male | GV7: teacher_factor_g1_female | GW7: teacher_factor_g2_male | GX7: teacher_factor_g2_female | GY7: teacher_factor_g3_male | GZ7: teacher_factor_g3_female | HA7: teacher_factor_g4_male | HB7: teacher_factor_g4_female | HC7: teacher_factor_g5_male | HD7: teacher_factor_g5_female | HE7: teacher_factor_g6_male | HF7: teacher_factor_g6_female | HG7: teacher_factor_ng_male | HH7: teacher_factor_ng_female | HI7: Male | HJ7: Female | HK7: Total | HL7: physical_cond_classroom_k_male | HM7: physical_cond_classroom_k_female | HN7: physical_cond_classroom_g1_male | HO7: physical_cond_classroom_g1_female | HP7: physical_cond_classroom_g2_male | HQ7: physical_cond_classroom_g2_female | HR7: physical_cond_classroom_g3_male | HS7: physical_cond_classroom_g3_female | HT7: physical_cond_classroom_g4_male | HU7: physical_cond_classroom_g4_female | HV7: physical_cond_classroom_g5_male | HW7: physical_cond_classroom_g5_female | HX7: physical_cond_classroom_g6_male | HY7: physical_cond_classroom_g6_female | HZ7: physical_cond_classroom_ng_male | IA7: physical_cond_classroom_ng_female | IB7: Male | IC7: Female | ID7: Total | IE7: peer_influ_k_male | IF7: peer_influ_k_female | IG7: peer_influ_g1_male | IH7: peer_influ_g1_female | II7: peer_influ_g2_male | IJ7: peer_influ_g2_female | IK7: peer_influ_g3_male | IL7: peer_influ_g3_female | IM7: peer_influ_g4_male | IN7: peer_influ_g4_female | IO7: peer_influ_g5_male | IP7: peer_influ_g5_female | IQ7: peer_influ_g6_male | IR7: peer_influ_g6_female | IS7: peer_influ_ng_male | IT7: peer_influ_ng_female | IU7: Male | IV7: Female | IW7: Total | IX7: distance_home_school_k_male | IY7: distance_home_school_k_female | IZ7: distance_home_school_g1_male | JA7: distance_home_school_g1_female | JB7: distance_home_school_g2_male | JC7: distance_home_school_g2_female | JD7: distance_home_school_g3_male | JE7: distance_home_school_g3_female | JF7: distance_home_school_g4_male | JG7: distance_home_school_g4_female | JH7: distance_home_school_g5_male | JI7: distance_home_school_g5_female | JJ7: distance_home_school_g6_male | JK7: distance_home_school_g6_female | JL7: distance_home_school_ng_male | JM7: distance_home_school_ng_female | JN7: Male | JO7: Female | JP7: Total | JQ7: armed_conflict_k_male | JR7: armed_conflict_k_female | JS7: armed_conflict_g1_male | JT7: armed_conflict_g1_female | JU7: armed_conflict_g2_male | JV7: armed_conflict_g2_female | JW7: armed_conflict_g3_male | JX7: armed_conflict_g3_female | JY7: armed_conflict_g4_male | JZ7: armed_conflict_g4_female | KA7: armed_conflict_g5_male | KB7: armed_conflict_g5_female | KC7: armed_conflict_g6_male | KD7: armed_conflict_g6_female | KE7: armed_conflict_ng_male | KF7: armed_conflict_ng_female | KG7: Male | KH7: Female | KI7: Total | KJ7: calamities_k_male | KK7: calamities_k_female | KL7: calamities_g1_male | KM7: calamities_g1_female | KN7: calamities_g2_male | KO7: calamities_g2_female | KP7: calamities_g3_male | KQ7: calamities_g3_female | KR7: calamities_g4_male | KS7: calamities_g4_female | KT7: calamities_g5_male | KU7: calamities_g5_female | KV7: calamities_g6_male | KW7: calamities_g6_female | KX7: calamities_ng_male | KY7: calamities_ng_female | KZ7: Male | LA7: Female | LB7: Total | LC7: child_labor_k_male | LD7: child_labor_k_female | LE7: child_labor_g1_male | LF7: child_labor_g1_female | LG7: child_labor_g2_male | LH7: child_labor_g2_female | LI7: child_labor_g3_male | LJ7: child_labor_g3_female | LK7: child_labor_g4_male | LL7: child_labor_g4_female | LM7: child_labor_g5_male | LN7: child_labor_g5_female | LO7: child_labor_g6_male | LP7: child_labor_g6_female | LQ7: child_labor_ng_male | LR7: child_labor_ng_female | LS7: Male | LT7: Female | LU7: Total | LV7: others_k_male | LW7: others_k_female | LX7: others_g1_male | LY7: others_g1_female | LZ7: others_g2_male | MA7: others_g2_female | MB7: others_g3_male | MC7: others_g3_female | MD7: others_g4_male | ME7: others_g4_female | MF7: others_g5_male | MG7: others_g5_female | MH7: others_g6_male | MI7: others_g6_female | MJ7: others_ng_male | MK7: others_ng_female | ML7: Male | MM7: Female | MN7: Total | MO7: Male | MP7: Female | MQ7: Male | MR7: Female | MS7: Male | MT7: Female | MU7: Male | MV7: Female | MW7: Male | MX7: Female | MY7: Male | MZ7: Female | NA7: Male | NB7: Female | NC7: Male | ND7: Female | NE7: Male | NF7: Female | NG7: Total | NI7: death_k_male | NJ7: death_k_female | NK7: death_g1_male | NL7: death_g1_female | NM7: death_g2_male | NN7: death_g2_female | NO7: death_g3_male | NP7: death_g3_female | NQ7: death_g4_male | NR7: death_g4_female | NS7: death_g5_male | NT7: death_g5_female | NU7: death_g6_male | NV7: death_g6_female | NW7: death_ng_male | NX7: death_ng_female | NY7: Male | NZ7: Female | OA7: Total
A8: Region XI | B8: Mati City | C8: DAVAO ORIENTAL | D8: CITY OF MATI (Capital) | E8: 129374 | F8: Badas ES | G8: DepED Managed | H8: Public | I8: Kinder & Grade 1-6 | J8: School with no Annexes | K8: 0 | L8: 0 | M8: 0 | N8: 0 | O8: 0 | P8: 0 | Q8: 0 | R8: 0 | S8: 0 | T8: 0 | U8: 0 | V8: 0 | W8: 0 | X8: 0 | Y8: 0 | Z8: 0 | AA8: =K8+M8+O8+Q8+S8+U8+W8+Y8 -> 0 | AB8: =L8+N8+P8+R8+T8+V8+X8+Z8 -> 0 | AC8: =SUM(AA8:AB8) -> 0 | AD8: 0 | AE8: 0 | AF8: 0 | AG8: 0 | AH8: 0 | AI8: 0 | AJ8: 0 | AK8: 0 | AL8: 0 | AM8: 0 | AN8: 0 | AO8: 0 | AP8: 0 | AQ8: 0 | AR8: 0 | AS8: 0 | AT8: =AD8+AF8+AH8+AJ8+AL8+AN8+AP8+AR8 -> 0 | AU8: =AE8+AG8+AI8+AK8+AM8+AO8+AQ8+AS8 -> 0 | AV8: =SUM(AT8:AU8) -> 0 | AW8: 3 | AX8: 0 | AY8: 0 | AZ8: 0 | BA8: 0 | BB8: 0 | BC8: 0 | BD8: 0 | BE8: 0 | BF8: 0 | BG8: 0 | BH8: 0 | BI8: 0 | BJ8: 0 | BK8: 0 | BL8: 0 | BM8: =AW8+AY8+BA8+BC8+BE8+BG8+BI8+BK8 -> 3 | BN8: =AX8+AZ8+BB8+BD8+BF8+BH8+BJ8+BL8 -> 0 | BO8: =SUM(BM8:BN8) -> 3 | BP8: 0 | BQ8: 0 | BR8: 0 | BS8: 0 | BT8: 0 | BU8: 0 | BV8: 0 | BW8: 0 | BX8: 0 | BY8: 0 | BZ8: 0 | CA8: 0 | CB8: 0 | CC8: 0 | CD8: 0 | CE8: 0 | CF8: =BP8+BR8+BT8+BV8+BX8+BZ8+CB8+CD8 -> 0 | CG8: =BQ8+BS8+BU8+BW8+BY8+CA8+CC8+CE8 -> 0 | CH8: =SUM(CF8:CG8) -> 0 | CI8: 0 | CJ8: 0 | CK8: 0 | CL8: 0 | CM8: 0 | CN8: 0 | CO8: 0 | CP8: 0 | CQ8: 0 | CR8: 0 | CS8: 0 | CT8: 0 | CU8: 0 | CV8: 0 | CW8: 0 | CX8: 0 | CY8: =CI8+CK8+CM8+CO8+CQ8+CS8+CU8+CW8 -> 0 | CZ8: =CJ8+CL8+CN8+CP8+CR8+CT8+CV8+CX8 -> 0 | DA8: =SUM(CY8:CZ8) -> 0 | DB8: 0 | DC8: 0 | DD8: 0 | DE8: 0 | DF8: 0 | DG8: 0 | DH8: 0 | DI8: 0 | DJ8: 0 | DK8: 0 | DL8: 0 | DM8: 0 | DN8: 0 | DO8: 0 | DP8: 0 | DQ8: 0 | DR8: =DB8+DD8+DF8+DH8+DJ8+DL8+DN8+DP8 -> 0 | DS8: =DC8+DE8+DG8+DI8+DK8+DM8+DO8+DQ8 -> 0 | DT8: =SUM(DR8:DS8) -> 0 | DU8: 0 | DV8: 0 | DW8: 0 | DX8: 0 | DY8: 0 | DZ8: 0 | EA8: 0 | EB8: 0 | EC8: 0 | ED8: 0 | EE8: 0 | EF8: 0 | EG8: 0 | EH8: 0 | EI8: 0 | EJ8: 0 | EK8: =DU8+DW8+DY8+EA8+EC8+EE8+EG8+EI8 -> 0 | EL8: =DV8+DX8+DZ8+EB8+ED8+EF8+EH8+EJ8 -> 0 | EM8: =SUM(EK8:EL8) -> 0 | EN8: 0 | EO8: 0 | EP8: 0 | EQ8: 0 | ER8: 0 | ES8: 0 | ET8: 0 | EU8: 0 | EV8: 0 | EW8: 0 | EX8: 0 | EY8: 0 | EZ8: 0 | FA8: 0 | FB8: 0 | FC8: 0 | FD8: =EN8+EP8+ER8+ET8+EV8+EX8+EZ8+FB8 -> 0 | FE8: =EO8+EQ8+ES8+EU8+EW8+EY8+FA8+FC8 -> 0 | FF8: =SUM(FD8:FE8) -> 0 | FG8: 1 | FH8: 0 | FI8: 0 | FJ8: 0 | FK8: 0 | FL8: 0 | FM8: 0 | FN8: 0 | FO8: 0 | FP8: 0 | FQ8: 0 | FR8: 0 | FS8: 0 | FT8: 0 | FU8: 0 | FV8: 0 | FW8: =FG8+FI8+FK8+FM8+FO8+FQ8+FS8+FU8 -> 1 | FX8: =FH8+FJ8+FL8+FN8+FP8+FR8+FT8+FV8 -> 0 | FY8: =SUM(FW8:FX8) -> 1 | FZ8: 0 | GA8: 0 | GB8: 0 | GC8: 0 | GD8: 0 | GE8: 0 | GF8: 0 | GG8: 0 | GH8: 0 | GI8: 0 | GJ8: 0 | GK8: 0 | GL8: 0 | GM8: 0 | GN8: 0 | GO8: 0 | GP8: =FZ8+GB8+GD8+GF8+GH8+GJ8+GL8+GN8 -> 0 | GQ8: =GA8+GC8+GE8+GG8+GI8+GK8+GM8+GO8 -> 0 | GR8: =SUM(GP8:GQ8) -> 0 | GS8: 0 | GT8: 0 | GU8: 0 | GV8: 0 | GW8: 0 | GX8: 0 | GY8: 0 | GZ8: 0 | HA8: 0 | HB8: 0 | HC8: 0 | HD8: 0 | HE8: 0 | HF8: 0 | HG8: 0 | HH8: 0 | HI8: =GS8+GU8+GW8+GY8+HA8+HC8+HE8+HG8 -> 0 | HJ8: =GT8+GV8+GX8+GZ8+HB8+HD8+HF8+HH8 -> 0 | HK8: =SUM(HI8:HJ8) -> 0 | HL8: 0 | HM8: 0 | HN8: 0 | HO8: 0 | HP8: 0 | HQ8: 0 | HR8: 0 | HS8: 0 | HT8: 0 | HU8: 0 | HV8: 0 | HW8: 0 | HX8: 0 | HY8: 0 | HZ8: 0 | IA8: 0 | IB8: =HL8+HN8+HP8+HR8+HT8+HV8+HX8+HZ8 -> 0 | IC8: =HM8+HO8+HQ8+HS8+HU8+HW8+HY8+IA8 -> 0 | ID8: =SUM(IB8:IC8) -> 0 | IE8: 0 | IF8: 0 | IG8: 0 | IH8: 0 | II8: 0 | IJ8: 0 | IK8: 0 | IL8: 0 | IM8: 0 | IN8: 0 | IO8: 0 | IP8: 0 | IQ8: 0 | IR8: 0 | IS8: 0 | IT8: 0 | IU8: =IE8+IG8+II8+IK8+IM8+IO8+IQ8+IS8 -> 0 | IV8: =IF8+IH8+IJ8+IL8+IN8+IP8+IR8+IT8 -> 0 | IW8: =SUM(IU8:IV8) -> 0 | IX8: 0 | IY8: 0 | IZ8: 0 | JA8: 0 | JB8: 0 | JC8: 0 | JD8: 0 | JE8: 0 | JF8: 0 | JG8: 0 | JH8: 0 | JI8: 0 | JJ8: 0 | JK8: 0 | JL8: 0 | JM8: 0 | JN8: =IX8+IZ8+JB8+JD8+JF8+JH8+JJ8+JL8 -> 0 | JO8: =IY8+JA8+JC8+JE8+JG8+JI8+JK8+JM8 -> 0 | JP8: =SUM(JN8:JO8) -> 0 | JQ8: 0 | JR8: 0 | JS8: 0 | JT8: 0 | JU8: 0 | JV8: 0 | JW8: 0 | JX8: 0 | JY8: 0 | JZ8: 0 | KA8: 0 | KB8: 0 | KC8: 0 | KD8: 0 | KE8: 0 | KF8: 0 | KG8: =JQ8+JS8+JU8+JW8+JY8+KA8+KC8+KE8 -> 0 | KH8: =JR8+JT8+JV8+JX8+JZ8+KB8+KD8+KF8 -> 0 | KI8: =SUM(KG8:KH8) -> 0 | KJ8: 0 | KK8: 0 | KL8: 0 | KM8: 0 | KN8: 0 | KO8: 0 | KP8: 0 | KQ8: 0 | KR8: 0 | KS8: 0 | KT8: 0 | KU8: 0 | KV8: 0 | KW8: 0 | KX8: 0 | KY8: 0 | KZ8: =KJ8+KL8+KN8+KP8+KR8+KT8+KV8+KX8 -> 0 | LA8: =KK8+KM8+KO8+KQ8+KS8+KU8+KW8+KY8 -> 0 | LB8: =SUM(KZ8:LA8) -> 0 | LC8: 0 | LD8: 0 | LE8: 0 | LF8: 0 | LG8: 0 | LH8: 0 | LI8: 0 | LJ8: 0 | LK8: 0 | LL8: 0 | LM8: 0 | LN8: 0 | LO8: 0 | LP8: 0 | LQ8: 0 | LR8: 0 | LS8: =LC8+LE8+LG8+LI8+LK8+LM8+LO8+LQ8 -> 0 | LT8: =LD8+LF8+LH8+LJ8+LL8+LN8+LP8+LR8 -> 0 | LU8: =SUM(LS8:LT8) -> 0 | LV8: 0 | LW8: 0 | LX8: 0 | LY8: 0 | LZ8: 0 | MA8: 0 | MB8: 0 | MC8: 0 | MD8: 0 | ME8: 0 | MF8: 0 | MG8: 0 | MH8: 0 | MI8: 0 | MJ8: 0 | MK8: 0 | ML8: =LV8+LX8+LZ8+MB8+MD8+MF8+MH8+MJ8 -> 0 | MM8: =LW8+LY8+MA8+MC8+ME8+MG8+MI8+MK8 -> 0 | MN8: =SUM(ML8:MM8) -> 0 | MO8: =K8+AD8+AW8+BP8+CI8+DB8+DU8+EN8+FG8+FZ8+GS8+HL8+IE8+IX8+JQ8+KJ8+LC8+LV8 -> 4 | MP8: =L8+AE8+AX8+BQ8+CJ8+DC8+DV8+EO8+FH8+GA8+GT8+HM8+IF8+IY8+JR8+KK8+LD8+LW8 -> 0 | MQ8: =M8+AF8+AY8+BR8+CK8+DD8+DW8+EP8+FI8+GB8+GU8+HN8+IG8+IZ8+JS8+KL8+LE8+LX8 -> 0 | MR8: =N8+AG8+AZ8+BS8+CL8+DE8+DX8+EQ8+FJ8+GC8+GV8+HO8+IH8+JA8+JT8+KM8+LF8+LY8 -> 0 | MS8: =O8+AH8+BA8+BT8+CM8+DF8+DY8+ER8+FK8+GD8+GW8+HP8+II8+JB8+JU8+KN8+LG8+LZ8 -> 0 | MT8: =P8+AI8+BB8+BU8+CN8+DG8+DZ8+ES8+FL8+GE8+GX8+HQ8+IJ8+JC8+JV8+KO8+LH8+MA8 -> 0 | MU8: =Q8+AJ8+BC8+BV8+CO8+DH8+EA8+ET8+FM8+GF8+GY8+HR8+IK8+JD8+JW8+KP8+LI8+MB8 -> 0 | MV8: =R8+AK8+BD8+BW8+CP8+DI8+EB8+EU8+FN8+GG8+GZ8+HS8+IL8+JE8+JX8+KQ8+LJ8+MC8 -> 0 | ... NG8: =AC8+AV8+BO8+CH8+DA8+DT8+EM8+FF8+FY8+GR8+HK8+ID8+IW8+JP8+KI8+LB8+LU8+MN8 -> 4 | NI8: 0 | NJ8: 0 | NK8: 0 | NL8: 0 | NM8: 0 | NN8: 0 | NO8: 0 | NP8: 0 | NQ8: 0 | NR8: 0 | NS8: 0 | NT8: 0 | NU8: 0 | NV8: 0 | NW8: 0 | NX8: 0 | NY8: =NI8+NK8+NM8+NO8+NQ8+NS8+NU8+NW8 -> 0 | NZ8: =NJ8+NL8+NN8+NP8+NR8+NT8+NV8+NX8 -> 0 | OA8: =SUM(NY8:NZ8) -> 0
A9: Region XI | B9: Mati City | C9: DAVAO ORIENTAL | D9: CITY OF MATI (Capital) | E9: 129375 | F9: Baso ES | G9: DepED Managed | H9: Public | I9: Kinder & Grade 1-6 | J9: School with no Annexes | AA9: =K9+M9+O9+Q9+S9+U9+W9+Y9 -> 0 | AB9: =L9+N9+P9+R9+T9+V9+X9+Z9 -> 0 | AC9: =SUM(AA9:AB9) -> 0 | AT9: =AD9+AF9+AH9+AJ9+AL9+AN9+AP9+AR9 -> 0 | AU9: =AE9+AG9+AI9+AK9+AM9+AO9+AQ9+AS9 -> 0 | AV9: =SUM(AT9:AU9) -> 0 | BM9: =AW9+AY9+BA9+BC9+BE9+BG9+BI9+BK9 -> 0 | BN9: =AX9+AZ9+BB9+BD9+BF9+BH9+BJ9+BL9 -> 0 | BO9: =SUM(BM9:BN9) -> 0 | CF9: =BP9+BR9+BT9+BV9+BX9+BZ9+CB9+CD9 -> 0 | CG9: =BQ9+BS9+BU9+BW9+BY9+CA9+CC9+CE9 -> 0 | CH9: =SUM(CF9:CG9) -> 0 | CY9: =CI9+CK9+CM9+CO9+CQ9+CS9+CU9+CW9 -> 0 | CZ9: =CJ9+CL9+CN9+CP9+CR9+CT9+CV9+CX9 -> 0 | DA9: =SUM(CY9:CZ9) -> 0 | DR9: =DB9+DD9+DF9+DH9+DJ9+DL9+DN9+DP9 -> 0 | DS9: =DC9+DE9+DG9+DI9+DK9+DM9+DO9+DQ9 -> 0 | DT9: =SUM(DR9:DS9) -> 0 | EK9: =DU9+DW9+DY9+EA9+EC9+EE9+EG9+EI9 -> 0 | EL9: =DV9+DX9+DZ9+EB9+ED9+EF9+EH9+EJ9 -> 0 | EM9: =SUM(EK9:EL9) -> 0 | FD9: =EN9+EP9+ER9+ET9+EV9+EX9+EZ9+FB9 -> 0 | FE9: =EO9+EQ9+ES9+EU9+EW9+EY9+FA9+FC9 -> 0 | FF9: =SUM(FD9:FE9) -> 0 | FW9: =FG9+FI9+FK9+FM9+FO9+FQ9+FS9+FU9 -> 0 | FX9: =FH9+FJ9+FL9+FN9+FP9+FR9+FT9+FV9 -> 0 | FY9: =SUM(FW9:FX9) -> 0 | GP9: =FZ9+GB9+GD9+GF9+GH9+GJ9+GL9+GN9 -> 0 | GQ9: =GA9+GC9+GE9+GG9+GI9+GK9+GM9+GO9 -> 0 | GR9: =SUM(GP9:GQ9) -> 0 | HI9: =GS9+GU9+GW9+GY9+HA9+HC9+HE9+HG9 -> 0 | HJ9: =GT9+GV9+GX9+GZ9+HB9+HD9+HF9+HH9 -> 0 | HK9: =SUM(HI9:HJ9) -> 0 | IB9: =HL9+HN9+HP9+HR9+HT9+HV9+HX9+HZ9 -> 0 | IC9: =HM9+HO9+HQ9+HS9+HU9+HW9+HY9+IA9 -> 0 | ID9: =SUM(IB9:IC9) -> 0 | IU9: =IE9+IG9+II9+IK9+IM9+IO9+IQ9+IS9 -> 0 | IV9: =IF9+IH9+IJ9+IL9+IN9+IP9+IR9+IT9 -> 0 | IW9: =SUM(IU9:IV9) -> 0 | JN9: =IX9+IZ9+JB9+JD9+JF9+JH9+JJ9+JL9 -> 0 | JO9: =IY9+JA9+JC9+JE9+JG9+JI9+JK9+JM9 -> 0 | JP9: =SUM(JN9:JO9) -> 0 | KG9: =JQ9+JS9+JU9+JW9+JY9+KA9+KC9+KE9 -> 0 | KH9: =JR9+JT9+JV9+JX9+JZ9+KB9+KD9+KF9 -> 0 | KI9: =SUM(KG9:KH9) -> 0 | KZ9: =KJ9+KL9+KN9+KP9+KR9+KT9+KV9+KX9 -> 0 | LA9: =KK9+KM9+KO9+KQ9+KS9+KU9+KW9+KY9 -> 0 | LB9: =SUM(KZ9:LA9) -> 0 | LS9: =LC9+LE9+LG9+LI9+LK9+LM9+LO9+LQ9 -> 0 | LT9: =LD9+LF9+LH9+LJ9+LL9+LN9+LP9+LR9 -> 0 | LU9: =SUM(LS9:LT9) -> 0 | ML9: =LV9+LX9+LZ9+MB9+MD9+MF9+MH9+MJ9 -> 0 | MM9: =LW9+LY9+MA9+MC9+ME9+MG9+MI9+MK9 -> 0 | MN9: =SUM(ML9:MM9) -> 0 | MO9: =K9+AD9+AW9+BP9+CI9+DB9+DU9+EN9+FG9+FZ9+GS9+HL9+IE9+IX9+JQ9+KJ9+LC9+LV9 -> 0 | MP9: =L9+AE9+AX9+BQ9+CJ9+DC9+DV9+EO9+FH9+GA9+GT9+HM9+IF9+IY9+JR9+KK9+LD9+LW9 -> 0 | MQ9: =M9+AF9+AY9+BR9+CK9+DD9+DW9+EP9+FI9+GB9+GU9+HN9+IG9+IZ9+JS9+KL9+LE9+LX9 -> 0 | MR9: =N9+AG9+AZ9+BS9+CL9+DE9+DX9+EQ9+FJ9+GC9+GV9+HO9+IH9+JA9+JT9+KM9+LF9+LY9 -> 0 | MS9: =O9+AH9+BA9+BT9+CM9+DF9+DY9+ER9+FK9+GD9+GW9+HP9+II9+JB9+JU9+KN9+LG9+LZ9 -> 0 | MT9: =P9+AI9+BB9+BU9+CN9+DG9+DZ9+ES9+FL9+GE9+GX9+HQ9+IJ9+JC9+JV9+KO9+LH9+MA9 -> 0 | MU9: =Q9+AJ9+BC9+BV9+CO9+DH9+EA9+ET9+FM9+GF9+GY9+HR9+IK9+JD9+JW9+KP9+LI9+MB9 -> 0 | MV9: =R9+AK9+BD9+BW9+CP9+DI9+EB9+EU9+FN9+GG9+GZ9+HS9+IL9+JE9+JX9+KQ9+LJ9+MC9 -> 0 | ... NG9: =AC9+AV9+BO9+CH9+DA9+DT9+EM9+FF9+FY9+GR9+HK9+ID9+IW9+JP9+KI9+LB9+LU9+MN9 -> 0 | NY9: =NI9+NK9+NM9+NO9+NQ9+NS9+NU9+NW9 -> 0 | NZ9: =NJ9+NL9+NN9+NP9+NR9+NT9+NV9+NX9 -> 0 | OA9: =SUM(NY9:NZ9) -> 0
A10: Region XI | B10: Mati City | C10: DAVAO ORIENTAL | D10: CITY OF MATI (Capital) | E10: 129376 | F10: Belsonda ES | G10: DepED Managed | H10: Public | I10: Kinder & Grade 1-6 | J10: School with no Annexes | AA10: =K10+M10+O10+Q10+S10+U10+W10+Y10 -> 0 | AB10: =L10+N10+P10+R10+T10+V10+X10+Z10 -> 0 | AC10: =SUM(AA10:AB10) -> 0 | AT10: =AD10+AF10+AH10+AJ10+AL10+AN10+AP10+AR10 -> 0 | AU10: =AE10+AG10+AI10+AK10+AM10+AO10+AQ10+AS10 -> 0 | AV10: =SUM(AT10:AU10) -> 0 | BM10: =AW10+AY10+BA10+BC10+BE10+BG10+BI10+BK10 -> 0 | BN10: =AX10+AZ10+BB10+BD10+BF10+BH10+BJ10+BL10 -> 0 | BO10: =SUM(BM10:BN10) -> 0 | CF10: =BP10+BR10+BT10+BV10+BX10+BZ10+CB10+CD10 -> 0 | CG10: =BQ10+BS10+BU10+BW10+BY10+CA10+CC10+CE10 -> 0 | CH10: =SUM(CF10:CG10) -> 0 | CY10: =CI10+CK10+CM10+CO10+CQ10+CS10+CU10+CW10 -> 0 | CZ10: =CJ10+CL10+CN10+CP10+CR10+CT10+CV10+CX10 -> 0 | DA10: =SUM(CY10:CZ10) -> 0 | DR10: =DB10+DD10+DF10+DH10+DJ10+DL10+DN10+DP10 -> 0 | DS10: =DC10+DE10+DG10+DI10+DK10+DM10+DO10+DQ10 -> 0 | DT10: =SUM(DR10:DS10) -> 0 | EK10: =DU10+DW10+DY10+EA10+EC10+EE10+EG10+EI10 -> 0 | EL10: =DV10+DX10+DZ10+EB10+ED10+EF10+EH10+EJ10 -> 0 | EM10: =SUM(EK10:EL10) -> 0 | FD10: =EN10+EP10+ER10+ET10+EV10+EX10+EZ10+FB10 -> 0 | FE10: =EO10+EQ10+ES10+EU10+EW10+EY10+FA10+FC10 -> 0 | FF10: =SUM(FD10:FE10) -> 0 | FW10: =FG10+FI10+FK10+FM10+FO10+FQ10+FS10+FU10 -> 0 | FX10: =FH10+FJ10+FL10+FN10+FP10+FR10+FT10+FV10 -> 0 | FY10: =SUM(FW10:FX10) -> 0 | GP10: =FZ10+GB10+GD10+GF10+GH10+GJ10+GL10+GN10 -> 0 | GQ10: =GA10+GC10+GE10+GG10+GI10+GK10+GM10+GO10 -> 0 | GR10: =SUM(GP10:GQ10) -> 0 | HI10: =GS10+GU10+GW10+GY10+HA10+HC10+HE10+HG10 -> 0 | HJ10: =GT10+GV10+GX10+GZ10+HB10+HD10+HF10+HH10 -> 0 | HK10: =SUM(HI10:HJ10) -> 0 | IB10: =HL10+HN10+HP10+HR10+HT10+HV10+HX10+HZ10 -> 0 | IC10: =HM10+HO10+HQ10+HS10+HU10+HW10+HY10+IA10 -> 0 | ID10: =SUM(IB10:IC10) -> 0 | IU10: =IE10+IG10+II10+IK10+IM10+IO10+IQ10+IS10 -> 0 | IV10: =IF10+IH10+IJ10+IL10+IN10+IP10+IR10+IT10 -> 0 | IW10: =SUM(IU10:IV10) -> 0 | JN10: =IX10+IZ10+JB10+JD10+JF10+JH10+JJ10+JL10 -> 0 | JO10: =IY10+JA10+JC10+JE10+JG10+JI10+JK10+JM10 -> 0 | JP10: =SUM(JN10:JO10) -> 0 | KG10: =JQ10+JS10+JU10+JW10+JY10+KA10+KC10+KE10 -> 0 | KH10: =JR10+JT10+JV10+JX10+JZ10+KB10+KD10+KF10 -> 0 | KI10: =SUM(KG10:KH10) -> 0 | KZ10: =KJ10+KL10+KN10+KP10+KR10+KT10+KV10+KX10 -> 0 | LA10: =KK10+KM10+KO10+KQ10+KS10+KU10+KW10+KY10 -> 0 | LB10: =SUM(KZ10:LA10) -> 0 | LS10: =LC10+LE10+LG10+LI10+LK10+LM10+LO10+LQ10 -> 0 | LT10: =LD10+LF10+LH10+LJ10+LL10+LN10+LP10+LR10 -> 0 | LU10: =SUM(LS10:LT10) -> 0 | ML10: =LV10+LX10+LZ10+MB10+MD10+MF10+MH10+MJ10 -> 0 | MM10: =LW10+LY10+MA10+MC10+ME10+MG10+MI10+MK10 -> 0 | MN10: =SUM(ML10:MM10) -> 0 | MO10: =K10+AD10+AW10+BP10+CI10+DB10+DU10+EN10+FG10+FZ10+GS10+HL10+IE10+IX10+JQ10+KJ10+LC10+LV10 -> 0 | MP10: =L10+AE10+AX10+BQ10+CJ10+DC10+DV10+EO10+FH10+GA10+GT10+HM10+IF10+IY10+JR10+KK10+LD10+LW10 -> 0 | MQ10: =M10+AF10+AY10+BR10+CK10+DD10+DW10+EP10+FI10+GB10+GU10+HN10+IG10+IZ10+JS10+KL10+LE10+LX10 -> 0 | MR10: =N10+AG10+AZ10+BS10+CL10+DE10+DX10+EQ10+FJ10+GC10+GV10+HO10+IH10+JA10+JT10+KM10+LF10+LY10 -> 0 | MS10: =O10+AH10+BA10+BT10+CM10+DF10+DY10+ER10+FK10+GD10+GW10+HP10+II10+JB10+JU10+KN10+LG10+LZ10 -> 0 | MT10: =P10+AI10+BB10+BU10+CN10+DG10+DZ10+ES10+FL10+GE10+GX10+HQ10+IJ10+JC10+JV10+KO10+LH10+MA10 -> 0 | MU10: =Q10+AJ10+BC10+BV10+CO10+DH10+EA10+ET10+FM10+GF10+GY10+HR10+IK10+JD10+JW10+KP10+LI10+MB10 -> 0 | MV10: =R10+AK10+BD10+BW10+CP10+DI10+EB10+EU10+FN10+GG10+GZ10+HS10+IL10+JE10+JX10+KQ10+LJ10+MC10 -> 0 | ... NG10: =AC10+AV10+BO10+CH10+DA10+DT10+EM10+FF10+FY10+GR10+HK10+ID10+IW10+JP10+KI10+LB10+LU10+MN10 -> 0 | NY10: =NI10+NK10+NM10+NO10+NQ10+NS10+NU10+NW10 -> 0 | NZ10: =NJ10+NL10+NN10+NP10+NR10+NT10+NV10+NX10 -> 0 | OA10: =SUM(NY10:NZ10) -> 0
A11: Region XI | B11: Mati City | C11: DAVAO ORIENTAL | D11: CITY OF MATI (Capital) | E11: 129377 | F11: Bagong Lipunan Improvement Site and Services Elementary School | G11: DepED Managed | H11: Public | I11: Kinder & Grade 1-6 | J11: School with no Annexes | K11: 0 | L11: 0 | M11: 0 | N11: 0 | O11: 0 | P11: 0 | Q11: 0 | R11: 0 | S11: 0 | T11: 0 | U11: 0 | V11: 0 | W11: 0 | X11: 0 | Y11: 0 | Z11: 0 | AA11: =K11+M11+O11+Q11+S11+U11+W11+Y11 -> 0 | AB11: =L11+N11+P11+R11+T11+V11+X11+Z11 -> 0 | AC11: =SUM(AA11:AB11) -> 0 | AD11: 0 | AE11: 0 | AF11: 0 | AG11: 0 | AH11: 0 | AI11: 0 | AJ11: 0 | AK11: 0 | AL11: 0 | AM11: 0 | AN11: 0 | AO11: 0 | AP11: 0 | AQ11: 0 | AR11: 0 | AS11: 0 | AT11: =AD11+AF11+AH11+AJ11+AL11+AN11+AP11+AR11 -> 0 | AU11: =AE11+AG11+AI11+AK11+AM11+AO11+AQ11+AS11 -> 0 | AV11: =SUM(AT11:AU11) -> 0 | AW11: 0 | AX11: 0 | AY11: 0 | AZ11: 0 | BA11: 0 | BB11: 0 | BC11: 0 | BD11: 0 | BE11: 0 | BF11: 0 | BG11: 0 | BH11: 0 | BI11: 0 | BJ11: 0 | BK11: 0 | BL11: 0 | BM11: =AW11+AY11+BA11+BC11+BE11+BG11+BI11+BK11 -> 0 | BN11: =AX11+AZ11+BB11+BD11+BF11+BH11+BJ11+BL11 -> 0 | BO11: =SUM(BM11:BN11) -> 0 | BP11: 0 | BQ11: 0 | BR11: 0 | BS11: 0 | BT11: 0 | BU11: 0 | BV11: 0 | BW11: 0 | BX11: 0 | BY11: 0 | BZ11: 0 | CA11: 0 | CB11: 0 | CC11: 2 | CD11: 0 | CE11: 0 | CF11: =BP11+BR11+BT11+BV11+BX11+BZ11+CB11+CD11 -> 0 | CG11: =BQ11+BS11+BU11+BW11+BY11+CA11+CC11+CE11 -> 2 | CH11: =SUM(CF11:CG11) -> 2 | CI11: 0 | CJ11: 0 | CK11: 0 | CL11: 0 | CM11: 0 | CN11: 0 | CO11: 0 | CP11: 0 | CQ11: 0 | CR11: 0 | CS11: 0 | CT11: 0 | CU11: 0 | CV11: 0 | CW11: 0 | CX11: 0 | CY11: =CI11+CK11+CM11+CO11+CQ11+CS11+CU11+CW11 -> 0 | CZ11: =CJ11+CL11+CN11+CP11+CR11+CT11+CV11+CX11 -> 0 | DA11: =SUM(CY11:CZ11) -> 0 | DB11: 0 | DC11: 0 | DD11: 0 | DE11: 0 | DF11: 0 | DG11: 0 | DH11: 0 | DI11: 0 | DJ11: 0 | DK11: 0 | DL11: 0 | DM11: 0 | DN11: 0 | DO11: 0 | DP11: 0 | DQ11: 0 | DR11: =DB11+DD11+DF11+DH11+DJ11+DL11+DN11+DP11 -> 0 | DS11: =DC11+DE11+DG11+DI11+DK11+DM11+DO11+DQ11 -> 0 | DT11: =SUM(DR11:DS11) -> 0 | DU11: 0 | DV11: 0 | DW11: 0 | DX11: 0 | DY11: 0 | DZ11: 0 | EA11: 0 | EB11: 0 | EC11: 0 | ED11: 0 | EE11: 0 | EF11: 0 | EG11: 0 | EH11: 0 | EI11: 0 | EJ11: 0 | EK11: =DU11+DW11+DY11+EA11+EC11+EE11+EG11+EI11 -> 0 | EL11: =DV11+DX11+DZ11+EB11+ED11+EF11+EH11+EJ11 -> 0 | EM11: =SUM(EK11:EL11) -> 0 | EN11: 0 | EO11: 0 | EP11: 0 | EQ11: 0 | ER11: 0 | ES11: 0 | ET11: 0 | EU11: 0 | EV11: 0 | EW11: 0 | EX11: 0 | EY11: 0 | EZ11: 0 | FA11: 0 | FB11: 0 | FC11: 0 | FD11: =EN11+EP11+ER11+ET11+EV11+EX11+EZ11+FB11 -> 0 | FE11: =EO11+EQ11+ES11+EU11+EW11+EY11+FA11+FC11 -> 0 | FF11: =SUM(FD11:FE11) -> 0 | FG11: 2 | FH11: 0 | FI11: 0 | FJ11: 0 | FK11: 1 | FL11: 0 | FM11: 0 | FN11: 0 | FO11: 0 | FP11: 0 | FQ11: 0 | FR11: 0 | FS11: 0 | FT11: 0 | FU11: 0 | FV11: 0 | FW11: =FG11+FI11+FK11+FM11+FO11+FQ11+FS11+FU11 -> 3 | FX11: =FH11+FJ11+FL11+FN11+FP11+FR11+FT11+FV11 -> 0 | FY11: =SUM(FW11:FX11) -> 3 | FZ11: 0 | GA11: 0 | GB11: 0 | GC11: 0 | GD11: 0 | GE11: 0 | GF11: 0 | GG11: 0 | GH11: 0 | GI11: 0 | GJ11: 0 | GK11: 0 | GL11: 0 | GM11: 0 | GN11: 0 | GO11: 0 | GP11: =FZ11+GB11+GD11+GF11+GH11+GJ11+GL11+GN11 -> 0 | GQ11: =GA11+GC11+GE11+GG11+GI11+GK11+GM11+GO11 -> 0 | GR11: =SUM(GP11:GQ11) -> 0 | GS11: 0 | GT11: 0 | GU11: 0 | GV11: 0 | GW11: 0 | GX11: 0 | GY11: 0 | GZ11: 0 | HA11: 0 | HB11: 0 | HC11: 0 | HD11: 0 | HE11: 0 | HF11: 0 | HG11: 0 | HH11: 0 | HI11: =GS11+GU11+GW11+GY11+HA11+HC11+HE11+HG11 -> 0 | HJ11: =GT11+GV11+GX11+GZ11+HB11+HD11+HF11+HH11 -> 0 | HK11: =SUM(HI11:HJ11) -> 0 | HL11: 0 | HM11: 0 | HN11: 0 | HO11: 0 | HP11: 0 | HQ11: 0 | HR11: 0 | HS11: 0 | HT11: 0 | HU11: 0 | HV11: 0 | HW11: 0 | HX11: 0 | HY11: 0 | HZ11: 0 | IA11: 0 | IB11: =HL11+HN11+HP11+HR11+HT11+HV11+HX11+HZ11 -> 0 | IC11: =HM11+HO11+HQ11+HS11+HU11+HW11+HY11+IA11 -> 0 | ID11: =SUM(IB11:IC11) -> 0 | IE11: 0 | IF11: 0 | IG11: 0 | IH11: 0 | II11: 0 | IJ11: 0 | IK11: 0 | IL11: 0 | IM11: 0 | IN11: 0 | IO11: 0 | IP11: 0 | IQ11: 0 | IR11: 0 | IS11: 0 | IT11: 0 | IU11: =IE11+IG11+II11+IK11+IM11+IO11+IQ11+IS11 -> 0 | IV11: =IF11+IH11+IJ11+IL11+IN11+IP11+IR11+IT11 -> 0 | IW11: =SUM(IU11:IV11) -> 0 | IX11: 0 | IY11: 0 | IZ11: 0 | JA11: 0 | JB11: 0 | JC11: 0 | JD11: 0 | JE11: 0 | JF11: 0 | JG11: 0 | JH11: 0 | JI11: 0 | JJ11: 0 | JK11: 0 | JL11: 0 | JM11: 0 | JN11: =IX11+IZ11+JB11+JD11+JF11+JH11+JJ11+JL11 -> 0 | JO11: =IY11+JA11+JC11+JE11+JG11+JI11+JK11+JM11 -> 0 | JP11: =SUM(JN11:JO11) -> 0 | JQ11: 0 | JR11: 0 | JS11: 0 | JT11: 0 | JU11: 0 | JV11: 0 | JW11: 0 | JX11: 0 | JY11: 0 | JZ11: 0 | KA11: 0 | KB11: 0 | KC11: 0 | KD11: 0 | KE11: 0 | KF11: 0 | KG11: =JQ11+JS11+JU11+JW11+JY11+KA11+KC11+KE11 -> 0 | KH11: =JR11+JT11+JV11+JX11+JZ11+KB11+KD11+KF11 -> 0 | KI11: =SUM(KG11:KH11) -> 0 | KJ11: 0 | KK11: 0 | KL11: 0 | KM11: 0 | KN11: 0 | KO11: 0 | KP11: 0 | KQ11: 0 | KR11: 0 | KS11: 0 | KT11: 0 | KU11: 0 | KV11: 0 | KW11: 0 | KX11: 0 | KY11: 0 | KZ11: =KJ11+KL11+KN11+KP11+KR11+KT11+KV11+KX11 -> 0 | LA11: =KK11+KM11+KO11+KQ11+KS11+KU11+KW11+KY11 -> 0 | LB11: =SUM(KZ11:LA11) -> 0 | LC11: 0 | LD11: 0 | LE11: 0 | LF11: 0 | LG11: 0 | LH11: 0 | LI11: 0 | LJ11: 0 | LK11: 0 | LL11: 0 | LM11: 0 | LN11: 0 | LO11: 0 | LP11: 0 | LQ11: 0 | LR11: 0 | LS11: =LC11+LE11+LG11+LI11+LK11+LM11+LO11+LQ11 -> 0 | LT11: =LD11+LF11+LH11+LJ11+LL11+LN11+LP11+LR11 -> 0 | LU11: =SUM(LS11:LT11) -> 0 | LV11: 0 | LW11: 0 | LX11: 0 | LY11: 0 | LZ11: 0 | MA11: 0 | MB11: 0 | MC11: 0 | MD11: 0 | ME11: 0 | MF11: 0 | MG11: 0 | MH11: 0 | MI11: 0 | MJ11: 0 | MK11: 0 | ML11: =LV11+LX11+LZ11+MB11+MD11+MF11+MH11+MJ11 -> 0 | MM11: =LW11+LY11+MA11+MC11+ME11+MG11+MI11+MK11 -> 0 | MN11: =SUM(ML11:MM11) -> 0 | MO11: =K11+AD11+AW11+BP11+CI11+DB11+DU11+EN11+FG11+FZ11+GS11+HL11+IE11+IX11+JQ11+KJ11+LC11+LV11 -> 2 | MP11: =L11+AE11+AX11+BQ11+CJ11+DC11+DV11+EO11+FH11+GA11+GT11+HM11+IF11+IY11+JR11+KK11+LD11+LW11 -> 0 | MQ11: =M11+AF11+AY11+BR11+CK11+DD11+DW11+EP11+FI11+GB11+GU11+HN11+IG11+IZ11+JS11+KL11+LE11+LX11 -> 0 | MR11: =N11+AG11+AZ11+BS11+CL11+DE11+DX11+EQ11+FJ11+GC11+GV11+HO11+IH11+JA11+JT11+KM11+LF11+LY11 -> 0 | MS11: =O11+AH11+BA11+BT11+CM11+DF11+DY11+ER11+FK11+GD11+GW11+HP11+II11+JB11+JU11+KN11+LG11+LZ11 -> 1 | MT11: =P11+AI11+BB11+BU11+CN11+DG11+DZ11+ES11+FL11+GE11+GX11+HQ11+IJ11+JC11+JV11+KO11+LH11+MA11 -> 0 | MU11: =Q11+AJ11+BC11+BV11+CO11+DH11+EA11+ET11+FM11+GF11+GY11+HR11+IK11+JD11+JW11+KP11+LI11+MB11 -> 0 | MV11: =R11+AK11+BD11+BW11+CP11+DI11+EB11+EU11+FN11+GG11+GZ11+HS11+IL11+JE11+JX11+KQ11+LJ11+MC11 -> 0 | ... NG11: =AC11+AV11+BO11+CH11+DA11+DT11+EM11+FF11+FY11+GR11+HK11+ID11+IW11+JP11+KI11+LB11+LU11+MN11 -> 5 | NI11: 0 | NJ11: 0 | NK11: 0 | NL11: 0 | NM11: 0 | NN11: 0 | NO11: 0 | NP11: 0 | NQ11: 0 | NR11: 0 | NS11: 0 | NT11: 0 | NU11: 0 | NV11: 0 | NW11: 0 | NX11: 0 | NY11: =NI11+NK11+NM11+NO11+NQ11+NS11+NU11+NW11 -> 0 | NZ11: =NJ11+NL11+NN11+NP11+NR11+NT11+NV11+NX11 -> 0 | OA11: =SUM(NY11:NZ11) -> 0
A12: Region XI | B12: Mati City | C12: DAVAO ORIENTAL | D12: CITY OF MATI (Capital) | E12: 129380 | F12: Rabat-Rocamora Mati CES I | G12: DepED Managed | H12: Public | I12: Kinder & Grade 1-6 | J12: School with no Annexes | K12: 0 | L12: 0 | M12: 0 | N12: 0 | O12: 0 | P12: 0 | Q12: 0 | R12: 0 | S12: 0 | T12: 0 | U12: 0 | V12: 0 | W12: 0 | X12: 0 | Y12: 0 | Z12: 0 | AA12: =K12+M12+O12+Q12+S12+U12+W12+Y12 -> 0 | AB12: =L12+N12+P12+R12+T12+V12+X12+Z12 -> 0 | AC12: =SUM(AA12:AB12) -> 0 | AD12: 0 | AE12: 0 | AF12: 0 | AG12: 0 | AH12: 0 | AI12: 0 | AJ12: 0 | AK12: 0 | AL12: 0 | AM12: 0 | AN12: 0 | AO12: 0 | AP12: 0 | AQ12: 0 | AR12: 0 | AS12: 0 | AT12: =AD12+AF12+AH12+AJ12+AL12+AN12+AP12+AR12 -> 0 | AU12: =AE12+AG12+AI12+AK12+AM12+AO12+AQ12+AS12 -> 0 | AV12: =SUM(AT12:AU12) -> 0 | AW12: 1 | AX12: 1 | AY12: 1 | AZ12: 0 | BA12: 0 | BB12: 0 | BC12: 0 | BD12: 0 | BE12: 0 | BF12: 0 | BG12: 0 | BH12: 0 | BI12: 0 | BJ12: 0 | BK12: 0 | BL12: 0 | BM12: =AW12+AY12+BA12+BC12+BE12+BG12+BI12+BK12 -> 2 | BN12: =AX12+AZ12+BB12+BD12+BF12+BH12+BJ12+BL12 -> 1 | BO12: =SUM(BM12:BN12) -> 3 | BP12: 2 | BQ12: 1 | BR12: 2 | BS12: 1 | BT12: 0 | BU12: 0 | BV12: 0 | BW12: 0 | BX12: 1 | BY12: 0 | BZ12: 1 | CA12: 0 | CB12: 1 | CC12: 2 | CD12: 0 | CE12: 0 | CF12: =BP12+BR12+BT12+BV12+BX12+BZ12+CB12+CD12 -> 7 | CG12: =BQ12+BS12+BU12+BW12+BY12+CA12+CC12+CE12 -> 4 | CH12: =SUM(CF12:CG12) -> 11 | CI12: 0 | CJ12: 0 | CK12: 0 | CL12: 0 | CM12: 0 | CN12: 0 | CO12: 0 | CP12: 0 | CQ12: 0 | CR12: 0 | CS12: 0 | CT12: 0 | CU12: 0 | CV12: 0 | CW12: 0 | CX12: 0 | CY12: =CI12+CK12+CM12+CO12+CQ12+CS12+CU12+CW12 -> 0 | CZ12: =CJ12+CL12+CN12+CP12+CR12+CT12+CV12+CX12 -> 0 | DA12: =SUM(CY12:CZ12) -> 0 | DB12: 0 | DC12: 0 | DD12: 0 | DE12: 0 | DF12: 0 | DG12: 0 | DH12: 0 | DI12: 0 | DJ12: 0 | DK12: 0 | DL12: 0 | DM12: 0 | DN12: 0 | DO12: 0 | DP12: 0 | DQ12: 0 | DR12: =DB12+DD12+DF12+DH12+DJ12+DL12+DN12+DP12 -> 0 | DS12: =DC12+DE12+DG12+DI12+DK12+DM12+DO12+DQ12 -> 0 | DT12: =SUM(DR12:DS12) -> 0 | DU12: 0 | DV12: 0 | DW12: 0 | DX12: 0 | DY12: 0 | DZ12: 0 | EA12: 0 | EB12: 0 | EC12: 0 | ED12: 0 | EE12: 0 | EF12: 0 | EG12: 0 | EH12: 0 | EI12: 0 | EJ12: 0 | EK12: =DU12+DW12+DY12+EA12+EC12+EE12+EG12+EI12 -> 0 | EL12: =DV12+DX12+DZ12+EB12+ED12+EF12+EH12+EJ12 -> 0 | EM12: =SUM(EK12:EL12) -> 0 | EN12: 1 | EO12: 0 | EP12: 0 | EQ12: 0 | ER12: 0 | ES12: 0 | ET12: 0 | EU12: 0 | EV12: 0 | EW12: 0 | EX12: 1 | EY12: 0 | EZ12: 0 | FA12: 0 | FB12: 0 | FC12: 0 | FD12: =EN12+EP12+ER12+ET12+EV12+EX12+EZ12+FB12 -> 2 | FE12: =EO12+EQ12+ES12+EU12+EW12+EY12+FA12+FC12 -> 0 | FF12: =SUM(FD12:FE12) -> 2 | FG12: 1 | FH12: 1 | FI12: 2 | FJ12: 2 | FK12: 0 | FL12: 0 | FM12: 0 | FN12: 2 | FO12: 0 | FP12: 0 | FQ12: 0 | FR12: 0 | FS12: 2 | FT12: 1 | FU12: 0 | FV12: 0 | FW12: =FG12+FI12+FK12+FM12+FO12+FQ12+FS12+FU12 -> 5 | FX12: =FH12+FJ12+FL12+FN12+FP12+FR12+FT12+FV12 -> 6 | FY12: =SUM(FW12:FX12) -> 11 | FZ12: 0 | GA12: 0 | GB12: 0 | GC12: 0 | GD12: 0 | GE12: 0 | GF12: 0 | GG12: 0 | GH12: 0 | GI12: 0 | GJ12: 0 | GK12: 0 | GL12: 0 | GM12: 0 | GN12: 0 | GO12: 0 | GP12: =FZ12+GB12+GD12+GF12+GH12+GJ12+GL12+GN12 -> 0 | GQ12: =GA12+GC12+GE12+GG12+GI12+GK12+GM12+GO12 -> 0 | GR12: =SUM(GP12:GQ12) -> 0 | GS12: 0 | GT12: 0 | GU12: 0 | GV12: 0 | GW12: 0 | GX12: 0 | GY12: 0 | GZ12: 0 | HA12: 0 | HB12: 0 | HC12: 0 | HD12: 0 | HE12: 0 | HF12: 0 | HG12: 0 | HH12: 0 | HI12: =GS12+GU12+GW12+GY12+HA12+HC12+HE12+HG12 -> 0 | HJ12: =GT12+GV12+GX12+GZ12+HB12+HD12+HF12+HH12 -> 0 | HK12: =SUM(HI12:HJ12) -> 0 | HL12: 0 | HM12: 0 | HN12: 0 | HO12: 0 | HP12: 0 | HQ12: 0 | HR12: 0 | HS12: 0 | HT12: 0 | HU12: 0 | HV12: 0 | HW12: 0 | HX12: 0 | HY12: 0 | HZ12: 0 | IA12: 0 | IB12: =HL12+HN12+HP12+HR12+HT12+HV12+HX12+HZ12 -> 0 | IC12: =HM12+HO12+HQ12+HS12+HU12+HW12+HY12+IA12 -> 0 | ID12: =SUM(IB12:IC12) -> 0 | IE12: 0 | IF12: 0 | IG12: 0 | IH12: 0 | II12: 0 | IJ12: 0 | IK12: 0 | IL12: 0 | IM12: 0 | IN12: 0 | IO12: 0 | IP12: 0 | IQ12: 0 | IR12: 0 | IS12: 0 | IT12: 0 | IU12: =IE12+IG12+II12+IK12+IM12+IO12+IQ12+IS12 -> 0 | IV12: =IF12+IH12+IJ12+IL12+IN12+IP12+IR12+IT12 -> 0 | IW12: =SUM(IU12:IV12) -> 0 | IX12: 0 | IY12: 0 | IZ12: 0 | JA12: 0 | JB12: 0 | JC12: 0 | JD12: 0 | JE12: 0 | JF12: 0 | JG12: 0 | JH12: 0 | JI12: 0 | JJ12: 0 | JK12: 0 | JL12: 0 | JM12: 0 | JN12: =IX12+IZ12+JB12+JD12+JF12+JH12+JJ12+JL12 -> 0 | JO12: =IY12+JA12+JC12+JE12+JG12+JI12+JK12+JM12 -> 0 | JP12: =SUM(JN12:JO12) -> 0 | JQ12: 0 | JR12: 0 | JS12: 0 | JT12: 0 | JU12: 0 | JV12: 0 | JW12: 0 | JX12: 0 | JY12: 0 | JZ12: 0 | KA12: 0 | KB12: 0 | KC12: 0 | KD12: 0 | KE12: 0 | KF12: 0 | KG12: =JQ12+JS12+JU12+JW12+JY12+KA12+KC12+KE12 -> 0 | KH12: =JR12+JT12+JV12+JX12+JZ12+KB12+KD12+KF12 -> 0 | KI12: =SUM(KG12:KH12) -> 0 | KJ12: 0 | KK12: 0 | KL12: 0 | KM12: 0 | KN12: 0 | KO12: 0 | KP12: 0 | KQ12: 0 | KR12: 0 | KS12: 0 | KT12: 0 | KU12: 0 | KV12: 0 | KW12: 0 | KX12: 0 | KY12: 0 | KZ12: =KJ12+KL12+KN12+KP12+KR12+KT12+KV12+KX12 -> 0 | LA12: =KK12+KM12+KO12+KQ12+KS12+KU12+KW12+KY12 -> 0 | LB12: =SUM(KZ12:LA12) -> 0 | LC12: 0 | LD12: 0 | LE12: 0 | LF12: 0 | LG12: 0 | LH12: 0 | LI12: 0 | LJ12: 0 | LK12: 0 | LL12: 0 | LM12: 0 | LN12: 0 | LO12: 0 | LP12: 0 | LQ12: 0 | LR12: 0 | LS12: =LC12+LE12+LG12+LI12+LK12+LM12+LO12+LQ12 -> 0 | LT12: =LD12+LF12+LH12+LJ12+LL12+LN12+LP12+LR12 -> 0 | LU12: =SUM(LS12:LT12) -> 0 | LV12: 0 | LW12: 0 | LX12: 0 | LY12: 0 | LZ12: 0 | MA12: 0 | MB12: 0 | MC12: 0 | MD12: 0 | ME12: 0 | MF12: 0 | MG12: 0 | MH12: 0 | MI12: 0 | MJ12: 0 | MK12: 0 | ML12: =LV12+LX12+LZ12+MB12+MD12+MF12+MH12+MJ12 -> 0 | MM12: =LW12+LY12+MA12+MC12+ME12+MG12+MI12+MK12 -> 0 | MN12: =SUM(ML12:MM12) -> 0 | MO12: =K12+AD12+AW12+BP12+CI12+DB12+DU12+EN12+FG12+FZ12+GS12+HL12+IE12+IX12+JQ12+KJ12+LC12+LV12 -> 5 | MP12: =L12+AE12+AX12+BQ12+CJ12+DC12+DV12+EO12+FH12+GA12+GT12+HM12+IF12+IY12+JR12+KK12+LD12+LW12 -> 3 | MQ12: =M12+AF12+AY12+BR12+CK12+DD12+DW12+EP12+FI12+GB12+GU12+HN12+IG12+IZ12+JS12+KL12+LE12+LX12 -> 5 | MR12: =N12+AG12+AZ12+BS12+CL12+DE12+DX12+EQ12+FJ12+GC12+GV12+HO12+IH12+JA12+JT12+KM12+LF12+LY12 -> 3 | MS12: =O12+AH12+BA12+BT12+CM12+DF12+DY12+ER12+FK12+GD12+GW12+HP12+II12+JB12+JU12+KN12+LG12+LZ12 -> 0 | MT12: =P12+AI12+BB12+BU12+CN12+DG12+DZ12+ES12+FL12+GE12+GX12+HQ12+IJ12+JC12+JV12+KO12+LH12+MA12 -> 0 | MU12: =Q12+AJ12+BC12+BV12+CO12+DH12+EA12+ET12+FM12+GF12+GY12+HR12+IK12+JD12+JW12+KP12+LI12+MB12 -> 0 | MV12: =R12+AK12+BD12+BW12+CP12+DI12+EB12+EU12+FN12+GG12+GZ12+HS12+IL12+JE12+JX12+KQ12+LJ12+MC12 -> 2 | ... NG12: =AC12+AV12+BO12+CH12+DA12+DT12+EM12+FF12+FY12+GR12+HK12+ID12+IW12+JP12+KI12+LB12+LU12+MN12 -> 27 | NI12: 0 | NJ12: 0 | NK12: 0 | NL12: 0 | NM12: 0 | NN12: 0 | NO12: 0 | NP12: 0 | NQ12: 0 | NR12: 0 | NS12: 0 | NT12: 0 | NU12: 0 | NV12: 0 | NW12: 0 | NX12: 0 | NY12: =NI12+NK12+NM12+NO12+NQ12+NS12+NU12+NW12 -> 0 | NZ12: =NJ12+NL12+NN12+NP12+NR12+NT12+NV12+NX12 -> 0 | OA12: =SUM(NY12:NZ12) -> 0
A13: Region XI | B13: Mati City | C13: DAVAO ORIENTAL | D13: CITY OF MATI (Capital) | E13: 129381 | F13: Rabat-Rocamora Mati CES II | G13: DepED Managed | H13: Public | I13: Kinder & Grade 1-6 | J13: School with no Annexes | K13: 0 | L13: 0 | M13: 0 | N13: 0 | O13: 0 | P13: 0 | Q13: 0 | R13: 0 | S13: 0 | T13: 0 | U13: 0 | V13: 0 | W13: 0 | X13: 0 | Y13: 0 | Z13: 0 | AA13: =K13+M13+O13+Q13+S13+U13+W13+Y13 -> 0 | AB13: =L13+N13+P13+R13+T13+V13+X13+Z13 -> 0 | AC13: =SUM(AA13:AB13) -> 0 | AD13: 0 | AE13: 0 | AF13: 0 | AG13: 0 | AH13: 0 | AI13: 0 | AJ13: 0 | AK13: 0 | AL13: 0 | AM13: 0 | AN13: 0 | AO13: 0 | AP13: 0 | AQ13: 0 | AR13: 0 | AS13: 0 | AT13: =AD13+AF13+AH13+AJ13+AL13+AN13+AP13+AR13 -> 0 | AU13: =AE13+AG13+AI13+AK13+AM13+AO13+AQ13+AS13 -> 0 | AV13: =SUM(AT13:AU13) -> 0 | AW13: 0 | AX13: 0 | AY13: 0 | AZ13: 0 | BA13: 0 | BB13: 0 | BC13: 0 | BD13: 0 | BE13: 0 | BF13: 0 | BG13: 0 | BH13: 0 | BI13: 0 | BJ13: 0 | BK13: 0 | BL13: 0 | BM13: =AW13+AY13+BA13+BC13+BE13+BG13+BI13+BK13 -> 0 | BN13: =AX13+AZ13+BB13+BD13+BF13+BH13+BJ13+BL13 -> 0 | BO13: =SUM(BM13:BN13) -> 0 | BP13: 3 | BQ13: 3 | BR13: 0 | BS13: 0 | BT13: 0 | BU13: 0 | BV13: 0 | BW13: 0 | BX13: 0 | BY13: 0 | BZ13: 0 | CA13: 0 | CB13: 0 | CC13: 0 | CD13: 0 | CE13: 0 | CF13: =BP13+BR13+BT13+BV13+BX13+BZ13+CB13+CD13 -> 3 | CG13: =BQ13+BS13+BU13+BW13+BY13+CA13+CC13+CE13 -> 3 | CH13: =SUM(CF13:CG13) -> 6 | CI13: 0 | CJ13: 0 | CK13: 0 | CL13: 0 | CM13: 0 | CN13: 0 | CO13: 0 | CP13: 0 | CQ13: 0 | CR13: 0 | CS13: 0 | CT13: 0 | CU13: 0 | CV13: 0 | CW13: 0 | CX13: 0 | CY13: =CI13+CK13+CM13+CO13+CQ13+CS13+CU13+CW13 -> 0 | CZ13: =CJ13+CL13+CN13+CP13+CR13+CT13+CV13+CX13 -> 0 | DA13: =SUM(CY13:CZ13) -> 0 | DB13: 0 | DC13: 0 | DD13: 0 | DE13: 0 | DF13: 0 | DG13: 0 | DH13: 0 | DI13: 0 | DJ13: 0 | DK13: 0 | DL13: 0 | DM13: 0 | DN13: 0 | DO13: 0 | DP13: 0 | DQ13: 0 | DR13: =DB13+DD13+DF13+DH13+DJ13+DL13+DN13+DP13 -> 0 | DS13: =DC13+DE13+DG13+DI13+DK13+DM13+DO13+DQ13 -> 0 | DT13: =SUM(DR13:DS13) -> 0 | DU13: 0 | DV13: 0 | DW13: 0 | DX13: 0 | DY13: 0 | DZ13: 0 | EA13: 0 | EB13: 0 | EC13: 0 | ED13: 0 | EE13: 0 | EF13: 0 | EG13: 0 | EH13: 0 | EI13: 0 | EJ13: 0 | EK13: =DU13+DW13+DY13+EA13+EC13+EE13+EG13+EI13 -> 0 | EL13: =DV13+DX13+DZ13+EB13+ED13+EF13+EH13+EJ13 -> 0 | EM13: =SUM(EK13:EL13) -> 0 | EN13: 0 | EO13: 0 | EP13: 0 | EQ13: 0 | ER13: 0 | ES13: 0 | ET13: 0 | EU13: 0 | EV13: 0 | EW13: 0 | EX13: 0 | EY13: 0 | EZ13: 0 | FA13: 0 | FB13: 0 | FC13: 0 | FD13: =EN13+EP13+ER13+ET13+EV13+EX13+EZ13+FB13 -> 0 | FE13: =EO13+EQ13+ES13+EU13+EW13+EY13+FA13+FC13 -> 0 | FF13: =SUM(FD13:FE13) -> 0 | FG13: 2 | FH13: 0 | FI13: 0 | FJ13: 0 | FK13: 0 | FL13: 0 | FM13: 0 | FN13: 0 | FO13: 0 | FP13: 0 | FQ13: 0 | FR13: 0 | FS13: 0 | FT13: 0 | FU13: 0 | FV13: 0 | FW13: =FG13+FI13+FK13+FM13+FO13+FQ13+FS13+FU13 -> 2 | FX13: =FH13+FJ13+FL13+FN13+FP13+FR13+FT13+FV13 -> 0 | FY13: =SUM(FW13:FX13) -> 2 | FZ13: 0 | GA13: 0 | GB13: 0 | GC13: 0 | GD13: 0 | GE13: 0 | GF13: 0 | GG13: 0 | GH13: 0 | GI13: 0 | GJ13: 0 | GK13: 0 | GL13: 0 | GM13: 0 | GN13: 0 | GO13: 0 | GP13: =FZ13+GB13+GD13+GF13+GH13+GJ13+GL13+GN13 -> 0 | GQ13: =GA13+GC13+GE13+GG13+GI13+GK13+GM13+GO13 -> 0 | GR13: =SUM(GP13:GQ13) -> 0 | GS13: 0 | GT13: 0 | GU13: 0 | GV13: 0 | GW13: 0 | GX13: 0 | GY13: 0 | GZ13: 0 | HA13: 0 | HB13: 0 | HC13: 0 | HD13: 0 | HE13: 0 | HF13: 0 | HG13: 0 | HH13: 0 | HI13: =GS13+GU13+GW13+GY13+HA13+HC13+HE13+HG13 -> 0 | HJ13: =GT13+GV13+GX13+GZ13+HB13+HD13+HF13+HH13 -> 0 | HK13: =SUM(HI13:HJ13) -> 0 | HL13: 0 | HM13: 0 | HN13: 0 | HO13: 0 | HP13: 0 | HQ13: 0 | HR13: 0 | HS13: 0 | HT13: 0 | HU13: 0 | HV13: 0 | HW13: 0 | HX13: 0 | HY13: 0 | HZ13: 0 | IA13: 0 | IB13: =HL13+HN13+HP13+HR13+HT13+HV13+HX13+HZ13 -> 0 | IC13: =HM13+HO13+HQ13+HS13+HU13+HW13+HY13+IA13 -> 0 | ID13: =SUM(IB13:IC13) -> 0 | IE13: 0 | IF13: 0 | IG13: 0 | IH13: 0 | II13: 0 | IJ13: 0 | IK13: 0 | IL13: 0 | IM13: 0 | IN13: 0 | IO13: 0 | IP13: 0 | IQ13: 0 | IR13: 0 | IS13: 0 | IT13: 0 | IU13: =IE13+IG13+II13+IK13+IM13+IO13+IQ13+IS13 -> 0 | IV13: =IF13+IH13+IJ13+IL13+IN13+IP13+IR13+IT13 -> 0 | IW13: =SUM(IU13:IV13) -> 0 | IX13: 0 | IY13: 0 | IZ13: 0 | JA13: 0 | JB13: 0 | JC13: 0 | JD13: 0 | JE13: 0 | JF13: 0 | JG13: 0 | JH13: 0 | JI13: 0 | JJ13: 0 | JK13: 0 | JL13: 0 | JM13: 0 | JN13: =IX13+IZ13+JB13+JD13+JF13+JH13+JJ13+JL13 -> 0 | JO13: =IY13+JA13+JC13+JE13+JG13+JI13+JK13+JM13 -> 0 | JP13: =SUM(JN13:JO13) -> 0 | JQ13: 0 | JR13: 0 | JS13: 0 | JT13: 0 | JU13: 0 | JV13: 0 | JW13: 0 | JX13: 0 | JY13: 0 | JZ13: 0 | KA13: 0 | KB13: 0 | KC13: 0 | KD13: 0 | KE13: 0 | KF13: 0 | KG13: =JQ13+JS13+JU13+JW13+JY13+KA13+KC13+KE13 -> 0 | KH13: =JR13+JT13+JV13+JX13+JZ13+KB13+KD13+KF13 -> 0 | KI13: =SUM(KG13:KH13) -> 0 | KJ13: 0 | KK13: 0 | KL13: 0 | KM13: 0 | KN13: 0 | KO13: 0 | KP13: 0 | KQ13: 0 | KR13: 0 | KS13: 0 | KT13: 0 | KU13: 0 | KV13: 0 | KW13: 0 | KX13: 0 | KY13: 0 | KZ13: =KJ13+KL13+KN13+KP13+KR13+KT13+KV13+KX13 -> 0 | LA13: =KK13+KM13+KO13+KQ13+KS13+KU13+KW13+KY13 -> 0 | LB13: =SUM(KZ13:LA13) -> 0 | LC13: 0 | LD13: 0 | LE13: 0 | LF13: 0 | LG13: 0 | LH13: 0 | LI13: 0 | LJ13: 0 | LK13: 0 | LL13: 0 | LM13: 0 | LN13: 0 | LO13: 0 | LP13: 0 | LQ13: 0 | LR13: 0 | LS13: =LC13+LE13+LG13+LI13+LK13+LM13+LO13+LQ13 -> 0 | LT13: =LD13+LF13+LH13+LJ13+LL13+LN13+LP13+LR13 -> 0 | LU13: =SUM(LS13:LT13) -> 0 | LV13: 0 | LW13: 0 | LX13: 0 | LY13: 0 | LZ13: 0 | MA13: 0 | MB13: 0 | MC13: 0 | MD13: 0 | ME13: 0 | MF13: 0 | MG13: 0 | MH13: 0 | MI13: 0 | MJ13: 0 | MK13: 0 | ML13: =LV13+LX13+LZ13+MB13+MD13+MF13+MH13+MJ13 -> 0 | MM13: =LW13+LY13+MA13+MC13+ME13+MG13+MI13+MK13 -> 0 | MN13: =SUM(ML13:MM13) -> 0 | MO13: =K13+AD13+AW13+BP13+CI13+DB13+DU13+EN13+FG13+FZ13+GS13+HL13+IE13+IX13+JQ13+KJ13+LC13+LV13 -> 5 | MP13: =L13+AE13+AX13+BQ13+CJ13+DC13+DV13+EO13+FH13+GA13+GT13+HM13+IF13+IY13+JR13+KK13+LD13+LW13 -> 3 | MQ13: =M13+AF13+AY13+BR13+CK13+DD13+DW13+EP13+FI13+GB13+GU13+HN13+IG13+IZ13+JS13+KL13+LE13+LX13 -> 0 | MR13: =N13+AG13+AZ13+BS13+CL13+DE13+DX13+EQ13+FJ13+GC13+GV13+HO13+IH13+JA13+JT13+KM13+LF13+LY13 -> 0 | MS13: =O13+AH13+BA13+BT13+CM13+DF13+DY13+ER13+FK13+GD13+GW13+HP13+II13+JB13+JU13+KN13+LG13+LZ13 -> 0 | MT13: =P13+AI13+BB13+BU13+CN13+DG13+DZ13+ES13+FL13+GE13+GX13+HQ13+IJ13+JC13+JV13+KO13+LH13+MA13 -> 0 | MU13: =Q13+AJ13+BC13+BV13+CO13+DH13+EA13+ET13+FM13+GF13+GY13+HR13+IK13+JD13+JW13+KP13+LI13+MB13 -> 0 | MV13: =R13+AK13+BD13+BW13+CP13+DI13+EB13+EU13+FN13+GG13+GZ13+HS13+IL13+JE13+JX13+KQ13+LJ13+MC13 -> 0 | ... NG13: =AC13+AV13+BO13+CH13+DA13+DT13+EM13+FF13+FY13+GR13+HK13+ID13+IW13+JP13+KI13+LB13+LU13+MN13 -> 8 | NI13: 1 | NJ13: 1 | NK13: 0 | NL13: 0 | NM13: 0 | NN13: 0 | NO13: 0 | NP13: 0 | NQ13: 0 | NR13: 0 | NS13: 0 | NT13: 0 | NU13: 0 | NV13: 0 | NW13: 0 | NX13: 0 | NY13: =NI13+NK13+NM13+NO13+NQ13+NS13+NU13+NW13 -> 1 | NZ13: =NJ13+NL13+NN13+NP13+NR13+NT13+NV13+NX13 -> 1 | OA13: =SUM(NY13:NZ13) -> 2
A14: Region XI | B14: Mati City | C14: DAVAO ORIENTAL | D14: CITY OF MATI (Capital) | E14: 129382 | F14: Mayor Luisito G. Rabat MS | G14: DepED Managed | H14: Public | I14: Kinder & Grade 1-6 | J14: School with no Annexes | K14: 0 | L14: 0 | M14: 0 | N14: 0 | O14: 0 | P14: 0 | Q14: 0 | R14: 0 | S14: 0 | T14: 0 | U14: 0 | V14: 0 | W14: 0 | X14: 0 | Y14: 0 | Z14: 0 | AA14: =K14+M14+O14+Q14+S14+U14+W14+Y14 -> 0 | AB14: =L14+N14+P14+R14+T14+V14+X14+Z14 -> 0 | AC14: =SUM(AA14:AB14) -> 0 | AD14: 0 | AE14: 0 | AF14: 0 | AG14: 0 | AH14: 0 | AI14: 0 | AJ14: 0 | AK14: 0 | AL14: 0 | AM14: 0 | AN14: 0 | AO14: 0 | AP14: 0 | AQ14: 0 | AR14: 0 | AS14: 0 | AT14: =AD14+AF14+AH14+AJ14+AL14+AN14+AP14+AR14 -> 0 | AU14: =AE14+AG14+AI14+AK14+AM14+AO14+AQ14+AS14 -> 0 | AV14: =SUM(AT14:AU14) -> 0 | AW14: 3 | AX14: 0 | AY14: 0 | AZ14: 0 | BA14: 0 | BB14: 1 | BC14: 0 | BD14: 0 | BE14: 0 | BF14: 0 | BG14: 0 | BH14: 0 | BI14: 0 | BJ14: 0 | BK14: 0 | BL14: 0 | BM14: =AW14+AY14+BA14+BC14+BE14+BG14+BI14+BK14 -> 3 | BN14: =AX14+AZ14+BB14+BD14+BF14+BH14+BJ14+BL14 -> 1 | BO14: =SUM(BM14:BN14) -> 4 | BP14: 0 | BQ14: 0 | BR14: 0 | BS14: 0 | BT14: 1 | BU14: 0 | BV14: 1 | BW14: 0 | BX14: 0 | BY14: 1 | BZ14: 0 | CA14: 0 | CB14: 0 | CC14: 0 | CD14: 0 | CE14: 0 | CF14: =BP14+BR14+BT14+BV14+BX14+BZ14+CB14+CD14 -> 2 | CG14: =BQ14+BS14+BU14+BW14+BY14+CA14+CC14+CE14 -> 1 | CH14: =SUM(CF14:CG14) -> 3 | CI14: 0 | CJ14: 1 | CK14: 0 | CL14: 0 | CM14: 0 | CN14: 0 | CO14: 0 | CP14: 0 | CQ14: 0 | CR14: 0 | CS14: 0 | CT14: 0 | CU14: 0 | CV14: 0 | CW14: 0 | CX14: 0 | CY14: =CI14+CK14+CM14+CO14+CQ14+CS14+CU14+CW14 -> 0 | CZ14: =CJ14+CL14+CN14+CP14+CR14+CT14+CV14+CX14 -> 1 | DA14: =SUM(CY14:CZ14) -> 1 | DB14: 0 | DC14: 0 | DD14: 0 | DE14: 0 | DF14: 1 | DG14: 0 | DH14: 0 | DI14: 0 | DJ14: 0 | DK14: 0 | DL14: 0 | DM14: 0 | DN14: 0 | DO14: 0 | DP14: 0 | DQ14: 0 | DR14: =DB14+DD14+DF14+DH14+DJ14+DL14+DN14+DP14 -> 1 | DS14: =DC14+DE14+DG14+DI14+DK14+DM14+DO14+DQ14 -> 0 | DT14: =SUM(DR14:DS14) -> 1 | DU14: 0 | DV14: 0 | DW14: 0 | DX14: 0 | DY14: 0 | DZ14: 0 | EA14: 0 | EB14: 0 | EC14: 0 | ED14: 0 | EE14: 0 | EF14: 0 | EG14: 0 | EH14: 0 | EI14: 0 | EJ14: 0 | EK14: =DU14+DW14+DY14+EA14+EC14+EE14+EG14+EI14 -> 0 | EL14: =DV14+DX14+DZ14+EB14+ED14+EF14+EH14+EJ14 -> 0 | EM14: =SUM(EK14:EL14) -> 0 | EN14: 0 | EO14: 0 | EP14: 0 | EQ14: 0 | ER14: 0 | ES14: 0 | ET14: 0 | EU14: 0 | EV14: 0 | EW14: 0 | EX14: 0 | EY14: 0 | EZ14: 0 | FA14: 0 | FB14: 0 | FC14: 0 | FD14: =EN14+EP14+ER14+ET14+EV14+EX14+EZ14+FB14 -> 0 | FE14: =EO14+EQ14+ES14+EU14+EW14+EY14+FA14+FC14 -> 0 | FF14: =SUM(FD14:FE14) -> 0 | FG14: 5 | FH14: 0 | FI14: 0 | FJ14: 0 | FK14: 1 | FL14: 1 | FM14: 1 | FN14: 0 | FO14: 0 | FP14: 0 | FQ14: 0 | FR14: 0 | FS14: 1 | FT14: 0 | FU14: 0 | FV14: 0 | FW14: =FG14+FI14+FK14+FM14+FO14+FQ14+FS14+FU14 -> 8 | FX14: =FH14+FJ14+FL14+FN14+FP14+FR14+FT14+FV14 -> 1 | FY14: =SUM(FW14:FX14) -> 9 | FZ14: 0 | GA14: 0 | GB14: 0 | GC14: 0 | GD14: 0 | GE14: 0 | GF14: 0 | GG14: 0 | GH14: 0 | GI14: 0 | GJ14: 0 | GK14: 0 | GL14: 0 | GM14: 0 | GN14: 0 | GO14: 0 | GP14: =FZ14+GB14+GD14+GF14+GH14+GJ14+GL14+GN14 -> 0 | GQ14: =GA14+GC14+GE14+GG14+GI14+GK14+GM14+GO14 -> 0 | GR14: =SUM(GP14:GQ14) -> 0 | GS14: 0 | GT14: 0 | GU14: 0 | GV14: 0 | GW14: 0 | GX14: 0 | GY14: 0 | GZ14: 0 | HA14: 0 | HB14: 0 | HC14: 0 | HD14: 0 | HE14: 0 | HF14: 0 | HG14: 0 | HH14: 0 | HI14: =GS14+GU14+GW14+GY14+HA14+HC14+HE14+HG14 -> 0 | HJ14: =GT14+GV14+GX14+GZ14+HB14+HD14+HF14+HH14 -> 0 | HK14: =SUM(HI14:HJ14) -> 0 | HL14: 0 | HM14: 0 | HN14: 0 | HO14: 0 | HP14: 0 | HQ14: 0 | HR14: 0 | HS14: 0 | HT14: 0 | HU14: 0 | HV14: 0 | HW14: 0 | HX14: 0 | HY14: 0 | HZ14: 0 | IA14: 0 | IB14: =HL14+HN14+HP14+HR14+HT14+HV14+HX14+HZ14 -> 0 | IC14: =HM14+HO14+HQ14+HS14+HU14+HW14+HY14+IA14 -> 0 | ID14: =SUM(IB14:IC14) -> 0 | IE14: 0 | IF14: 0 | IG14: 0 | IH14: 0 | II14: 0 | IJ14: 0 | IK14: 0 | IL14: 0 | IM14: 0 | IN14: 0 | IO14: 0 | IP14: 0 | IQ14: 0 | IR14: 0 | IS14: 0 | IT14: 0 | IU14: =IE14+IG14+II14+IK14+IM14+IO14+IQ14+IS14 -> 0 | IV14: =IF14+IH14+IJ14+IL14+IN14+IP14+IR14+IT14 -> 0 | IW14: =SUM(IU14:IV14) -> 0 | IX14: 2 | IY14: 0 | IZ14: 0 | JA14: 0 | JB14: 0 | JC14: 0 | JD14: 0 | JE14: 0 | JF14: 0 | JG14: 0 | JH14: 0 | JI14: 0 | JJ14: 0 | JK14: 0 | JL14: 0 | JM14: 0 | JN14: =IX14+IZ14+JB14+JD14+JF14+JH14+JJ14+JL14 -> 2 | JO14: =IY14+JA14+JC14+JE14+JG14+JI14+JK14+JM14 -> 0 | JP14: =SUM(JN14:JO14) -> 2 | JQ14: 0 | JR14: 0 | JS14: 0 | JT14: 0 | JU14: 0 | JV14: 0 | JW14: 0 | JX14: 0 | JY14: 0 | JZ14: 0 | KA14: 0 | KB14: 0 | KC14: 0 | KD14: 0 | KE14: 0 | KF14: 0 | KG14: =JQ14+JS14+JU14+JW14+JY14+KA14+KC14+KE14 -> 0 | KH14: =JR14+JT14+JV14+JX14+JZ14+KB14+KD14+KF14 -> 0 | KI14: =SUM(KG14:KH14) -> 0 | KJ14: 0 | KK14: 0 | KL14: 0 | KM14: 0 | KN14: 0 | KO14: 0 | KP14: 0 | KQ14: 0 | KR14: 0 | KS14: 0 | KT14: 0 | KU14: 0 | KV14: 0 | KW14: 0 | KX14: 0 | KY14: 0 | KZ14: =KJ14+KL14+KN14+KP14+KR14+KT14+KV14+KX14 -> 0 | LA14: =KK14+KM14+KO14+KQ14+KS14+KU14+KW14+KY14 -> 0 | LB14: =SUM(KZ14:LA14) -> 0 | LC14: 0 | LD14: 0 | LE14: 0 | LF14: 0 | LG14: 0 | LH14: 0 | LI14: 0 | LJ14: 0 | LK14: 0 | LL14: 0 | LM14: 0 | LN14: 0 | LO14: 0 | LP14: 0 | LQ14: 0 | LR14: 0 | LS14: =LC14+LE14+LG14+LI14+LK14+LM14+LO14+LQ14 -> 0 | LT14: =LD14+LF14+LH14+LJ14+LL14+LN14+LP14+LR14 -> 0 | LU14: =SUM(LS14:LT14) -> 0 | LV14: 0 | LW14: 0 | LX14: 0 | LY14: 0 | LZ14: 0 | MA14: 0 | MB14: 0 | MC14: 0 | MD14: 0 | ME14: 0 | MF14: 0 | MG14: 0 | MH14: 0 | MI14: 0 | MJ14: 0 | MK14: 0 | ML14: =LV14+LX14+LZ14+MB14+MD14+MF14+MH14+MJ14 -> 0 | MM14: =LW14+LY14+MA14+MC14+ME14+MG14+MI14+MK14 -> 0 | MN14: =SUM(ML14:MM14) -> 0 | MO14: =K14+AD14+AW14+BP14+CI14+DB14+DU14+EN14+FG14+FZ14+GS14+HL14+IE14+IX14+JQ14+KJ14+LC14+LV14 -> 10 | MP14: =L14+AE14+AX14+BQ14+CJ14+DC14+DV14+EO14+FH14+GA14+GT14+HM14+IF14+IY14+JR14+KK14+LD14+LW14 -> 1 | MQ14: =M14+AF14+AY14+BR14+CK14+DD14+DW14+EP14+FI14+GB14+GU14+HN14+IG14+IZ14+JS14+KL14+LE14+LX14 -> 0 | MR14: =N14+AG14+AZ14+BS14+CL14+DE14+DX14+EQ14+FJ14+GC14+GV14+HO14+IH14+JA14+JT14+KM14+LF14+LY14 -> 0 | MS14: =O14+AH14+BA14+BT14+CM14+DF14+DY14+ER14+FK14+GD14+GW14+HP14+II14+JB14+JU14+KN14+LG14+LZ14 -> 3 | MT14: =P14+AI14+BB14+BU14+CN14+DG14+DZ14+ES14+FL14+GE14+GX14+HQ14+IJ14+JC14+JV14+KO14+LH14+MA14 -> 2 | MU14: =Q14+AJ14+BC14+BV14+CO14+DH14+EA14+ET14+FM14+GF14+GY14+HR14+IK14+JD14+JW14+KP14+LI14+MB14 -> 2 | MV14: =R14+AK14+BD14+BW14+CP14+DI14+EB14+EU14+FN14+GG14+GZ14+HS14+IL14+JE14+JX14+KQ14+LJ14+MC14 -> 0 | ... NG14: =AC14+AV14+BO14+CH14+DA14+DT14+EM14+FF14+FY14+GR14+HK14+ID14+IW14+JP14+KI14+LB14+LU14+MN14 -> 20 | NI14: 0 | NJ14: 0 | NK14: 0 | NL14: 0 | NM14: 0 | NN14: 0 | NO14: 0 | NP14: 0 | NQ14: 0 | NR14: 0 | NS14: 0 | NT14: 0 | NU14: 0 | NV14: 0 | NW14: 0 | NX14: 0 | NY14: =NI14+NK14+NM14+NO14+NQ14+NS14+NU14+NW14 -> 0 | NZ14: =NJ14+NL14+NN14+NP14+NR14+NT14+NV14+NX14 -> 0 | OA14: =SUM(NY14:NZ14) -> 0
