Workbook
Name __xlnm.Print_Area_4: #REF!
Name AgeProfileWorks: #REF!
Name AgeProfileWorks: #REF!
Name AgeProfileWorks: #REF!
Name AgeProfileWorks: #REF!
Name AgeProfileWorks: #REF!
Name AgeProfileWorks: #REF!
Name AgeProfileWorks: #REF!
Name AgeProfileWorks: #REF!
Name AgeProfileWorks: #REF!
Name cmd_shifting: #REF!
Name cmd_shifting: #REF!
Name cmd_shifting: #REF!
Name cmd_shifting: #REF!
Name cmd_shifting: #REF!
Name cmd_shifting: #REF!
Name cmd_shifting: #REF!
Name cmd_shifting: #REF!
Name cmd_shifting: #REF!
Name PRINT_AREA_MI: #REF!
Name PRINT_AREA_MI: #REF!
Name PRINT_AREA_MI: #REF!
Name PRINT_AREA_MI: #REF!
Name PRINT_AREA_MI: #REF!
Name PRINT_AREA_MI: #REF!
Name PRINT_AREA_MI: #REF!
Name PRINT_AREA_MI: #REF!
Name PRINT_AREA_MI: #REF!
Name PRINT_AREA_MI: #REF!
Name PRINT_AREA_MI: #REF!
Name PRINT_AREA_MI: #REF!
Name PRINT_AREA_MI: #REF!
Name PRINT_AREA_MI: #REF!
Name PRINT_AREA_MI: #REF!
Name PRINT_AREA_MI: #REF!
Name PRINT_AREA_MI: #REF!
Name PRINT_AREA_MI: #REF!
Name PRINT_AREA_MI: #REF!
Name PRINT_AREA_MI: #REF!
Name PRINT_AREA_MI: #REF!
Name PRINT_AREA_MI: #REF!
Name PRINT_AREA_MI: #REF!
Name PRINT_AREA_MI: #REF!
Name PRINT_AREA_MI: #REF!

Sheet GER-NER KINDER
A1: DEPARTMENT OF EDUCATION
A2: GROSS AND NET ENROLMENT RATE IN KINDERGARTEN
A3: (Based on Learners' School Address)
A4: SY 2023-2024
A6: Region/Division | C6: Total Enrollment (All Ages) | F6: Total Enrollment (Age 5) | I6: Population | J6: Gross Enrollment Rate (GER) | M6: Net Enrollment Rate (NER) | P6: Gender Parity Index (GER) | S6: Gender Parity Index (NER)
C7: Total | D7: Public | E7: Private | F7: Total | G7: Public | H7: Private | I7: (Age 5) | J7: Both | K7: Public | L7: Private | M7: Both | N7: Public | O7: Private | P7: Both | Q7: Public | R7: Private | S7: Both | T7: Public | U7: Private
A8: REGION XI - DAVAO REGION
A10: Davao City | B10: Total (MF) | C10: 34825 | D10: 30107 | E10: 4718 | F10: 27566 | G10: 23527 | H10: 4039 | I10: 35303 | J10: 0.98646007 | K10: 0.85281704 | L10: 0.13364303 | M10: 0.78084016 | N10: 0.66643061 | O10: 0.11440954 | P10: 1.0079003 | Q10: 1.0116282 | R10: 0.98442319 | S10: 1.0850407 | T10: 1.0946974 | U10: 1.0304637
B11: Male (M) | C11: 17894 | D11: 15442 | E11: 2452 | F11: 13656 | G11: 11603 | H11: 2053 | I11: 18209 | J11: 0.98270086 | K11: 0.84804218 | L11: 0.13465869 | M11: 0.74995881 | N11: 0.63721237 | O11: 0.11274644
B12: Female (F) | C12: 16931 | D12: 14665 | E12: 2266 | F12: 13910 | G12: 11924 | H12: 1986 | I12: 17094 | J12: 0.99046449 | K12: 0.85790336 | L12: 0.13256113 | M12: 0.81373581 | N12: 0.6975547 | O12: 0.11618112
A13: Davao de Oro (Compostela Valley) | B13: Total (MF) | C13: 14722 | D13: 14025 | E13: 697 | F13: 12701 | G13: 12053 | H13: 648 | I13: 16531 | J13: 0.89056923 | K13: 0.84840603 | L13: 0.042163209 | M13: 0.76831408 | N13: 0.729115 | O13: 0.039199081 | P13: 1.0005279 | Q13: 1.0004281 | R13: 1.0025374 | S13: 1.0495843 | T13: 1.0513804 | U13: 1.0167137
B14: Male (M) | C14: 7738 | D14: 7372 | E14: 366 | F14: 6524 | G14: 6186 | H14: 338 | I14: 8691 | J14: 0.89034634 | K14: 0.84823381 | L14: 0.04211253 | M14: 0.7506616 | N14: 0.7117708 | O14: 0.038890807
B15: Female (F) | C15: 6984 | D15: 6653 | E15: 331 | F15: 6177 | G15: 5867 | H15: 310 | I15: 7840 | J15: 0.89081633 | K15: 0.84859694 | L15: 0.042219388 | M15: 0.78788265 | N15: 0.74834184 | O15: 0.039540816
A16: Davao del Norte | B16: Total (MF) | C16: 10241 | D16: 9377 | E16: 864 | F16: 8692 | G16: 7901 | H16: 791 | I16: 10911 | J16: 0.93859408 | K16: 0.85940794 | L16: 0.079186142 | M16: 0.79662726 | N16: 0.72413161 | O16: 0.072495647 | P16: 1.0248842 | Q16: 1.0243004 | R16: 1.031241 | S16: 1.0667454 | T16: 1.0661801 | U16: 1.0724087
B17: Male (M) | C17: 5243 | D17: 4802 | E17: 441 | F17: 4363 | G17: 3967 | H17: 396 | I17: 5653 | J17: 0.92747214 | K17: 0.84946046 | L17: 0.078011675 | M17: 0.77180258 | N17: 0.70175128 | O17: 0.0700513
B18: Female (F) | C18: 4998 | D18: 4575 | E18: 423 | F18: 4329 | G18: 3934 | H18: 395 | I18: 5258 | J18: 0.95055154 | K18: 0.8701027 | L18: 0.08044884 | M18: 0.82331685 | N18: 0.74819323 | O18: 0.075123621
A19: Davao del Sur | B19: Total (MF) | C19: 9022 | D19: 8578 | E19: 444 | F19: 7609 | G19: 7217 | H19: 392 | I19: 10031 | J19: 0.89941182 | K19: 0.85514904 | L19: 0.044262785 | M19: 0.7585485 | N19: 0.71946964 | O19: 0.039078856 | P19: 0.98870803 | Q19: 0.99144266 | R19: 0.93725572 | S19: 1.0461943 | T19: 1.0488806 | U19: 0.99791952
B20: Male (M) | C20: 4716 | D20: 4478 | E20: 238 | F20: 3870 | G20: 3666 | H20: 204 | I20: 5215 | J20: 0.90431448 | K20: 0.85867689 | L20: 0.045637584 | M20: 0.74209012 | N20: 0.7029722 | O20: 0.039117929
B21: Female (F) | C21: 4306 | D21: 4100 | E21: 206 | F21: 3739 | G21: 3551 | H21: 188 | I21: 4816 | J21: 0.89410299 | K21: 0.8513289 | L21: 0.042774086 | M21: 0.77637043 | N21: 0.73733389 | O21: 0.039036545
A22: Davao Occidental | B22: Total (MF) | C22: 7020 | D22: 6864 | E22: 156 | F22: 4696 | G22: 4582 | H22: 114 | I22: 7546 | J22: 0.9302942 | K22: 0.90962099 | L22: 0.020673204 | M22: 0.62231646 | N22: 0.60720912 | O22: 0.015107342 | P22: 0.9918823 | Q22: 0.99658429 | R22: 0.8044975 | S22: 1.0482331 | T22: 1.0529972 | U22: 0.87319274
B23: Male (M) | C23: 3595 | D23: 3507 | E23: 88 | F23: 2340 | G23: 2278 | H23: 62 | I23: 3849 | J23: 0.93400883 | K23: 0.91114575 | L23: 0.022863081 | M23: 0.60795012 | N23: 0.59184204 | O23: 0.01610808
B24: Female (F) | C24: 3425 | D24: 3357 | E24: 68 | F24: 2356 | G24: 2304 | H24: 52 | I24: 3697 | J24: 0.92642683 | K24: 0.90803354 | L24: 0.018393292 | M24: 0.63727346 | N24: 0.62320801 | O24: 0.014065458
A25: Davao Oriental | B25: Total (MF) | C25: 8984 | D25: 8817 | E25: 167 | F25: 7486 | G25: 7337 | H25: 149 | I25: 9287 | J25: 0.96737375 | K25: 0.94939162 | L25: 0.017982126 | M25: 0.80607301 | N25: 0.79002907 | O25: 0.016043932 | P25: 0.98505259 | Q25: 0.97903287 | R25: 1.3627283 | S25: 1.043688 | T25: 1.0368719 | U25: 1.4446485
B26: Male (M) | C26: 4653 | D26: 4580 | E26: 73 | F26: 3769 | G26: 3706 | H26: 63 | I26: 4775 | J26: 0.97445026 | K26: 0.9591623 | L26: 0.015287958 | M26: 0.78931937 | N26: 0.77612565 | O26: 0.013193717
B27: Female (F) | C27: 4331 | D27: 4237 | E27: 94 | F27: 3717 | G27: 3631 | H27: 86 | I27: 4512 | J27: 0.95988475 | K27: 0.93905142 | L27: 0.020833333 | M27: 0.82380319 | N27: 0.80474291 | O27: 0.019060284
A28: Digos City | B28: Total (MF) | C28: 3987 | D28: 3424 | E28: 563 | F28: 3434 | G28: 2906 | H28: 528 | I28: 3711 | J28: 1.0743735 | K28: 0.92266236 | L28: 0.15171113 | M28: 0.92535705 | N28: 0.78307734 | O28: 0.14227971 | P28: 0.95534758 | Q28: 0.94629741 | R28: 1.0122028 | S28: 1.0235252 | T28: 1.0253726 | U28: 1.0134162
B29: Male (M) | C29: 2090 | D29: 1803 | E29: 287 | F29: 1741 | G29: 1472 | H29: 269 | I29: 1903 | J29: 1.0982659 | K29: 0.94745139 | L29: 0.1508145 | M29: 0.91487126 | N29: 0.7735155 | O29: 0.14135575
B30: Female (F) | C30: 1897 | D30: 1621 | E30: 276 | F30: 1693 | G30: 1434 | H30: 259 | I30: 1808 | J30: 1.0492257 | K30: 0.8965708 | L30: 0.15265487 | M30: 0.93639381 | N30: 0.79314159 | O30: 0.14325221
A31: Island Garden City of Samal | B31: Total (MF) | C31: 2273 | D31: 2158 | E31: 115 | F31: 1969 | G31: 1863 | H31: 106 | I31: 2394 | J31: 0.94945698 | K31: 0.90142022 | L31: 0.048036759 | M31: 0.82247285 | N31: 0.77819549 | O31: 0.04427736 | P31: 1.0162967 | Q31: 1.0045865 | R31: 1.2633149 | S31: 1.0854291 | T31: 1.0787718 | U31: 1.2095222
B32: Male (M) | C32: 1171 | D32: 1118 | E32: 53 | F32: 982 | G32: 932 | H32: 50 | I32: 1243 | J32: 0.94207562 | K32: 0.89943685 | L32: 0.042638777 | M32: 0.79002414 | N32: 0.74979887 | O32: 0.040225261
B33: Female (F) | C33: 1102 | D33: 1040 | E33: 62 | F33: 987 | G33: 931 | H33: 56 | I33: 1151 | J33: 0.95742832 | K33: 0.90356212 | L33: 0.053866203 | M33: 0.8575152 | N33: 0.80886186 | O33: 0.048653345
A34: Mati City | B34: Total (MF) | C34: 3400 | D34: 3112 | E34: 288 | F34: 2791 | G34: 2525 | H34: 266 | I34: 3198 | J34: 1.0631645 | K34: 0.97310819 | L34: 0.090056285 | M34: 0.87273296 | N34: 0.78955597 | O34: 0.083176986 | P34: 0.98818257 | Q34: 0.99584426 | R34: 0.90889641 | S34: 1.0599995 | T34: 1.077007 | U34: 0.9110947
B35: Male (M) | C35: 1759 | D35: 1604 | E35: 155 | F35: 1395 | G35: 1252 | H35: 143 | I35: 1645 | J35: 1.0693009 | K35: 0.97507599 | L35: 0.094224924 | M35: 0.84802432 | N35: 0.76109422 | O35: 0.086930091
B36: Female (F) | C36: 1641 | D36: 1508 | E36: 133 | F36: 1396 | G36: 1273 | H36: 123 | I36: 1553 | J36: 1.0566645 | K36: 0.97102382 | L36: 0.085640695 | M36: 0.89890534 | N36: 0.8197038 | O36: 0.079201545
A37: Panabo City | B37: Total (MF) | C37: 4161 | D37: 3661 | E37: 500 | F37: 3685 | G37: 3237 | H37: 448 | I37: 4358 | J37: 0.95479578 | K37: 0.84006425 | L37: 0.11473153 | M37: 0.84557136 | N37: 0.74277191 | O37: 0.10279945 | P37: 1.0053216 | Q37: 1.0310195 | R37: 0.83479819 | S37: 1.0618939 | T37: 1.0924273 | U37: 0.86460144
B38: Male (M) | C38: 2138 | D38: 1858 | E38: 280 | F38: 1843 | G38: 1596 | H38: 247 | I38: 2245 | J38: 0.95233853 | K38: 0.82761693 | L38: 0.1247216 | M38: 0.82093541 | N38: 0.71091314 | O38: 0.11002227
B39: Female (F) | C39: 2023 | D39: 1803 | E39: 220 | F39: 1842 | G39: 1641 | H39: 201 | I39: 2113 | J39: 0.95740653 | K39: 0.85328916 | L39: 0.10411737 | M39: 0.87174633 | N39: 0.77662092 | O39: 0.095125414
A40: Tagum City | B40: Total (MF) | C40: 5650 | D40: 4736 | E40: 914 | F40: 4931 | G40: 4100 | H40: 831 | I40: 5834 | J40: 0.96846075 | K40: 0.81179294 | L40: 0.15666781 | M40: 0.84521769 | N40: 0.70277683 | O40: 0.14244086 | P40: 0.93337938 | Q40: 0.9312522 | R40: 0.94447524 | S40: 0.99325725 | T40: 1.0011666 | U40: 0.95511064
B41: Male (M) | C41: 2990 | D41: 2509 | E41: 481 | F41: 2533 | G41: 2098 | H41: 435 | I41: 2987 | J41: 1.0010044 | K41: 0.83997322 | L41: 0.16103113 | M41: 0.84800803 | N41: 0.70237697 | O41: 0.14563107
B42: Female (F) | C42: 2660 | D42: 2227 | E42: 433 | F42: 2398 | G42: 2002 | H42: 396 | I42: 2847 | J42: 0.93431682 | K42: 0.78222691 | L42: 0.15208992 | M42: 0.84229013 | N42: 0.70319635 | O42: 0.13909378
...

Sheet GER-NER G1toG6wLSENs
A1: DEPARTMENT OF EDUCATION
A2: GROSS AND NET ENROLMENT RATE IN ELEMENTARY (GRADE 1 TO GRADE 6)
A3: (Based on Learners' School Address)
A4: SY 2023-2024
A6: Region/Division | C6: Total Enrollment (All Ages) | F6: Total Enrollment (Ages 6-11) | I6: Population | J6: Gross Enrollment Rate (GER) | M6: Net Enrollment Rate (NER) | P6: Gender Parity Index (GER) | S6: Gender Parity Index (NER)
C7: Total | D7: Public | E7: Private | F7: Total | G7: Public | H7: Private | I7: (Ages 6-11) | J7: Both | K7: Public | L7: Private | M7: Both | N7: Public | O7: Private | P7: Both | Q7: Public | R7: Private | S7: Both | T7: Public | U7: Private
A8: REGION XI - DAVAO REGION
A10: Davao City | B10: Total (MF) | C10: 222340 | D10: 198245 | E10: 24095 | F10: 198977 | G10: 176285 | H10: 22692 | I10: 216865 | J10: 1.0252461 | K10: 0.91414013 | L10: 0.11110599 | M10: 0.91751551 | N10: 0.81287898 | O10: 0.10463653 | P10: 1.0017691 | Q10: 1.0000523 | R10: 1.0160029 | S10: 1.0307176 | T10: 1.0304072 | U10: 1.0331319
B11: Male (M) | C11: 115077 | D11: 102691 | E11: 12386 | F11: 101569 | G11: 89999 | H11: 11570 | I11: 112339 | J11: 1.0243727 | K11: 0.91411709 | L11: 0.11025557 | M11: 0.90412947 | N11: 0.80113763 | O11: 0.10299184
B12: Female (F) | C12: 107263 | D12: 95554 | E12: 11709 | F12: 97408 | G12: 86286 | H12: 11122 | I12: 104526 | J12: 1.0261849 | K12: 0.9141649 | L12: 0.11201998 | M12: 0.93190211 | N12: 0.82549796 | O12: 0.10640415
A13: Davao de Oro (Compostela Valley) | B13: Total (MF) | C13: 100230 | D13: 97465 | E13: 2765 | F13: 91317 | G13: 88703 | H13: 2614 | I13: 104770 | J13: 0.95666698 | K13: 0.93027584 | L13: 0.026391143 | M13: 0.87159492 | N13: 0.84664503 | O13: 0.02494989 | P13: 0.98594723 | Q13: 0.98746262 | R13: 0.93392088 | S13: 1.0114601 | T13: 1.013681 | U13: 0.93880522
B14: Male (M) | C14: 52150 | D14: 50674 | E14: 1476 | F14: 46930 | G14: 45538 | H14: 1392 | I14: 54142 | J14: 0.96320786 | K14: 0.93594622 | L14: 0.027261645 | M14: 0.86679472 | N14: 0.84108456 | O14: 0.02571017
B15: Female (F) | C15: 48080 | D15: 46791 | E15: 1289 | F15: 44387 | G15: 43165 | H15: 1222 | I15: 50628 | J15: 0.94967212 | K15: 0.9242119 | L15: 0.02546022 | M15: 0.87672829 | N15: 0.85259145 | O15: 0.024136841
A16: Davao del Norte | B16: Total (MF) | C16: 64953 | D16: 63265 | E16: 1688 | F16: 59231 | G16: 57595 | H16: 1636 | I16: 67771 | J16: 0.95841879 | K16: 0.93351138 | L16: 0.024907409 | M16: 0.8739874 | N16: 0.84984728 | O16: 0.024140119 | P16: 0.9833751 | Q16: 0.98605633 | R16: 0.88771834 | S16: 1.0052829 | T16: 1.0087096 | U16: 0.89148857
B17: Male (M) | C17: 33669 | D17: 32751 | E17: 918 | F17: 30377 | G17: 29489 | H17: 888 | I17: 34846 | J17: 0.96622281 | K17: 0.93987832 | L17: 0.026344487 | M17: 0.87174999 | N17: 0.84626643 | O17: 0.025483556
B18: Female (F) | C18: 31284 | D18: 30514 | E18: 770 | F18: 28854 | G18: 28106 | H18: 748 | I18: 32925 | J18: 0.95015945 | K18: 0.92677297 | L18: 0.023386484 | M18: 0.87635535 | N18: 0.85363705 | O18: 0.022718299
A19: Davao del Sur | B19: Total (MF) | C19: 60891 | D19: 59832 | E19: 1059 | F19: 55856 | G19: 54882 | H19: 974 | I19: 63754 | J19: 0.95509301 | K19: 0.93848229 | L19: 0.016610722 | M19: 0.87611758 | N19: 0.8608401 | O19: 0.015277473 | P19: 0.99322162 | Q19: 0.99279697 | R19: 1.0175005 | S19: 1.0161194 | T19: 1.0162123 | U19: 1.0109
B20: Male (M) | C20: 31589 | D20: 31046 | E20: 543 | F20: 28659 | G20: 28158 | H20: 501 | I20: 32966 | J20: 0.95822969 | K20: 0.94175818 | L20: 0.016471516 | M20: 0.86935024 | N20: 0.85415276 | O20: 0.015197476
B21: Female (F) | C21: 29302 | D21: 28786 | E21: 516 | F21: 27197 | G21: 26724 | H21: 473 | I21: 30788 | J21: 0.95173444 | K21: 0.93497467 | L21: 0.016759777 | M21: 0.88336365 | N21: 0.86800052 | O21: 0.015363128
A22: Davao Occidental | B22: Total (MF) | C22: 42242 | D22: 41917 | E22: 325 | F22: 36049 | G22: 35742 | H22: 307 | I22: 47682 | J22: 0.88591083 | K22: 0.87909484 | L22: 0.0068159893 | M22: 0.75602953 | N22: 0.74959104 | O22: 0.0064384883 | P22: 0.98518498 | Q22: 0.98735405 | R22: 0.73960063 | S22: 1.024135 | T22: 1.0266888 | U22: 0.76451708
B23: Male (M) | C23: 21702 | D23: 21512 | E23: 190 | F23: 18171 | G23: 17994 | H23: 177 | I23: 24319 | J23: 0.89238867 | K23: 0.88457585 | L23: 0.0078128213 | M23: 0.74719355 | N23: 0.73991529 | O23: 0.0072782598
B24: Female (F) | C24: 20540 | D24: 20405 | E24: 135 | F24: 17878 | G24: 17748 | H24: 130 | I24: 23363 | J24: 0.87916792 | K24: 0.87338955 | L24: 0.0057783675 | M24: 0.76522707 | N24: 0.75966271 | O24: 0.0055643539
A25: Davao Oriental | B25: Total (MF) | C25: 61164 | D25: 60184 | E25: 980 | F25: 54207 | G25: 53285 | H25: 922 | I25: 60934 | J25: 1.0037746 | K25: 0.9876916 | L25: 0.016082975 | M25: 0.88960186 | N25: 0.87447074 | O25: 0.015131125 | P25: 0.97034728 | Q25: 0.97095291 | R25: 0.93383414 | S25: 1.0093908 | T25: 1.0099772 | U25: 0.97605843
B26: Male (M) | C26: 31932 | D26: 31411 | E26: 521 | F26: 27766 | G26: 27286 | H26: 480 | I26: 31354 | J26: 1.0184346 | K26: 1.0018179 | L26: 0.0166167 | M26: 0.88556484 | N26: 0.87025579 | O26: 0.015309051
B27: Female (F) | C27: 29232 | D27: 28773 | E27: 459 | F27: 26441 | G27: 25999 | H27: 442 | I27: 29580 | J27: 0.98823529 | K27: 0.97271805 | L27: 0.015517241 | M27: 0.893881 | N27: 0.87893847 | O27: 0.014942529
A28: Digos City | B28: Total (MF) | C28: 24269 | D28: 22576 | E28: 1693 | F28: 22176 | G28: 20572 | H28: 1604 | I28: 23053 | J28: 1.052748 | K28: 0.97930855 | L28: 0.073439466 | M28: 0.96195723 | N28: 0.89237843 | O28: 0.069578797 | P28: 0.99973621 | Q28: 1.0038688 | R28: 0.946145 | S28: 1.0246391 | T28: 1.0301581 | U28: 0.95631667
B29: Male (M) | C29: 12683 | D29: 11775 | E29: 908 | F29: 11453 | G29: 10597 | H29: 856 | I29: 12046 | J29: 1.0528806 | K29: 0.97750291 | L29: 0.075377719 | M29: 0.95077204 | N29: 0.87971111 | O29: 0.071060933
B30: Female (F) | C30: 11586 | D30: 10801 | E30: 785 | F30: 10723 | G30: 9975 | H30: 748 | I30: 11007 | J30: 1.0526029 | K30: 0.98128464 | L30: 0.071318252 | M30: 0.97419824 | N30: 0.90624148 | O30: 0.067956755
A31: Island Garden City of Samal | B31: Total (MF) | C31: 15376 | D31: 14982 | E31: 394 | F31: 14094 | G31: 13722 | H31: 372 | I31: 14965 | J31: 1.0274641 | K31: 1.001136 | L31: 0.026328099 | M31: 0.94179753 | N31: 0.91693953 | O31: 0.024858002 | P31: 0.97493012 | Q31: 0.98507773 | R31: 0.65191189 | S31: 1.0044763 | T31: 1.0156593 | U31: 0.66219824
B32: Male (M) | C32: 8011 | D32: 7767 | E32: 244 | F32: 7238 | G32: 7009 | H32: 229 | I32: 7702 | J32: 1.0401194 | K32: 1.0084394 | L32: 0.031680083 | M32: 0.93975591 | N32: 0.91002337 | O32: 0.029732537
B33: Female (F) | C33: 7365 | D33: 7215 | E33: 150 | F33: 6856 | G33: 6713 | H33: 143 | I33: 7263 | J33: 1.0140438 | K33: 0.99339116 | L33: 0.020652623 | M33: 0.94396255 | N33: 0.92427372 | O33: 0.019688834
A34: Mati City | B34: Total (MF) | C34: 21488 | D34: 20119 | E34: 1369 | F34: 19067 | G34: 17762 | H34: 1305 | I34: 20058 | J34: 1.0712932 | K34: 1.0030412 | L34: 0.068252069 | M34: 0.95059328 | N34: 0.88553196 | O34: 0.065061322 | P34: 0.96752056 | Q34: 0.96716397 | R34: 0.9727757 | S34: 1.0059259 | T34: 1.0066426 | U34: 0.9962202
B35: Male (M) | C35: 11189 | D35: 10478 | E35: 711 | F35: 9743 | G35: 9073 | H35: 670 | I35: 10279 | J35: 1.08853 | K35: 1.0193599 | L35: 0.069170153 | M35: 0.94785485 | N35: 0.88267341 | O35: 0.065181438
B36: Female (F) | C36: 10299 | D36: 9641 | E36: 658 | F36: 9324 | G36: 8689 | H36: 635 | I36: 9779 | J36: 1.0531752 | K36: 0.98588813 | L36: 0.067287044 | M36: 0.95347173 | N36: 0.88853666 | O36: 0.064935065
A37: Panabo City | B37: Total (MF) | C37: 27441 | D37: 25216 | E37: 2225 | F37: 25380 | G37: 23249 | H37: 2131 | I37: 26553 | J37: 1.0334425 | K37: 0.94964787 | L37: 0.083794675 | M37: 0.9558242 | N37: 0.87556962 | O37: 0.080254585 | P37: 1.0000911 | Q37: 1.0042144 | R37: 0.95448796 | S37: 1.0157066 | T37: 1.0205258 | U37: 0.96454545
B38: Male (M) | C38: 14110 | D38: 12940 | E38: 1170 | F38: 12952 | G38: 11837 | H38: 1115 | I38: 13654 | J38: 1.0333968 | K38: 0.94770763 | L38: 0.085689175 | M38: 0.94858649 | N38: 0.86692544 | O38: 0.081661052
B39: Female (F) | C39: 13331 | D39: 12276 | E39: 1055 | F39: 12428 | G39: 11412 | H39: 1016 | I39: 12899 | J39: 1.033491 | K39: 0.95170168 | L39: 0.081789286 | M39: 0.96348554 | N39: 0.88471975 | O39: 0.078765796
A40: Tagum City | B40: Total (MF) | C40: 35612 | D40: 32502 | E40: 3110 | F40: 32729 | G40: 29750 | H40: 2979 | I40: 36222 | J40: 0.98315941 | K40: 0.89729998 | L40: 0.085859422 | M40: 0.90356689 | N40: 0.82132406 | O40: 0.082242836 | P40: 0.9882427 | Q40: 0.98641793 | R40: 1.00751 | S40: 1.0127415 | T40: 1.0117709 | U40: 1.0224847
B41: Male (M) | C41: 18390 | D41: 16799 | E41: 1591 | F41: 16701 | G41: 15188 | H41: 1513 | I41: 18598 | J41: 0.988816 | K41: 0.90326917 | L41: 0.085546833 | M41: 0.89799978 | N41: 0.81664695 | O41: 0.081352834
B42: Female (F) | C42: 17222 | D42: 15703 | E42: 1519 | F42: 16028 | G42: 14562 | H42: 1466 | I42: 17624 | J42: 0.9771902 | K42: 0.89100091 | L42: 0.086189287 | M42: 0.90944167 | N42: 0.82625965 | O42: 0.083182025
...

Sheet GER-NER KtoG6wLSENs
A1: DEPARTMENT OF EDUCATION
A2: GROSS AND NET ENROLMENT RATE IN ELEMENTARY (KINDERGARTEN TO GRADE 6)
A3: (Based on Learners' School Address)
A4: SY 2023-2024
A6: Region/Division | C6: Total Enrollment (All Ages) | F6: Total Enrollment (Ages 5-11) | I6: Population | J6: Gross Enrollment Rate (GER) | M6: Net Enrollment Rate (NER) | P6: Gender Parity Index (GER) | S6: Gender Parity Index (NER)
C7: Total | D7: Public | E7: Private | F7: Total | G7: Public | H7: Private | I7: (Ages 5-11) | J7: Both | K7: Public | L7: Private | M7: Both | N7: Public | O7: Private | P7: Both | Q7: Public | R7: Private | S7: Both | T7: Public | U7: Private
A8: REGION XI - DAVAO REGION
A10: Davao City | B10: Total (MF) | C10: 260259 | D10: 231446 | E10: 28813 | F10: 234098 | G10: 206685 | H10: 27413 | I10: 252168 | J10: 1.0320858 | K10: 0.91782462 | L10: 0.11426113 | M10: 0.92834142 | N10: 0.81963215 | O10: 0.10870927 | P10: 0.99769014 | Q10: 0.99604778 | R10: 1.0109779 | S10: 1.0261615 | T10: 1.0263614 | U10: 1.0246559
B11: Male (M) | C11: 134887 | D11: 120049 | E11: 14838 | F11: 119683 | G11: 105658 | H11: 14025 | I11: 130548 | J11: 1.0332368 | K11: 0.91957747 | L11: 0.11365934 | M11: 0.91677391 | N11: 0.80934216 | O11: 0.10743175
B12: Female (F) | C12: 125372 | D12: 111397 | E12: 13975 | F12: 114415 | G12: 101027 | H12: 13388 | I12: 121620 | J12: 1.0308502 | K12: 0.9159431 | L12: 0.11490709 | M12: 0.9407581 | N12: 0.83067752 | O12: 0.11008058
A13: Davao de Oro (Compostela Valley) | B13: Total (MF) | C13: 117419 | D13: 113957 | E13: 3462 | F13: 106068 | G13: 102756 | H13: 3312 | I13: 121301 | J13: 0.96799697 | K13: 0.93945639 | L13: 0.028540573 | M13: 0.87441983 | N13: 0.84711585 | O13: 0.027303979 | P13: 0.98174772 | Q13: 0.98288073 | R13: 0.94513739 | S13: 1.0096137 | T13: 1.0115952 | U13: 0.94995209
B14: Male (M) | C14: 61362 | D14: 59520 | E14: 1842 | F14: 54689 | G14: 52931 | H14: 1758 | I14: 62833 | J14: 0.97658874 | K14: 0.94727293 | L14: 0.029315805 | M14: 0.87038658 | N14: 0.84240765 | O14: 0.027978928
B15: Female (F) | C15: 56057 | D15: 54437 | E15: 1620 | F15: 51379 | G15: 49825 | H15: 1554 | I15: 58468 | J15: 0.95876377 | K15: 0.9310563 | L15: 0.027707464 | M15: 0.87875419 | N15: 0.85217555 | O15: 0.026578641
A16: Davao del Norte | B16: Total (MF) | C16: 78125 | D16: 75573 | E16: 2552 | F16: 69440 | G16: 66938 | H16: 2502 | I16: 78682 | J16: 0.99292087 | K16: 0.96048652 | L16: 0.032434356 | M16: 0.88253984 | N16: 0.85074096 | O16: 0.031798887 | P16: 0.98500826 | Q16: 0.98687974 | R16: 0.93109767 | S16: 1.0079278 | T16: 1.0107108 | U16: 0.93615397
B17: Male (M) | C17: 40507 | D17: 39148 | E17: 1359 | F17: 35605 | G17: 34276 | H17: 1329 | I17: 40499 | J17: 1.0001975 | K17: 0.96664115 | L17: 0.033556384 | M17: 0.87915751 | N17: 0.84634188 | O17: 0.032815625
B18: Female (F) | C18: 37618 | D18: 36425 | E18: 1193 | F18: 33835 | G18: 32662 | H18: 1173 | I18: 38183 | J18: 0.98520284 | K18: 0.95395857 | L18: 0.031244271 | M18: 0.88612733 | N18: 0.85540686 | O18: 0.030720478
A19: Davao del Sur | B19: Total (MF) | C19: 70955 | D19: 69452 | E19: 1503 | F19: 64896 | G19: 63478 | H19: 1418 | I19: 73785 | J19: 0.96164532 | K19: 0.94127533 | L19: 0.020369994 | M19: 0.87952836 | N19: 0.86031036 | O19: 0.019217998 | P19: 0.98529344 | Q19: 0.98516239 | R19: 0.99136748 | S19: 1.0126833 | T19: 1.013303 | U19: 0.98531216
B20: Male (M) | C20: 36979 | D20: 36198 | E20: 781 | F20: 33377 | G20: 32638 | H20: 739 | I20: 38181 | J20: 0.96851837 | K20: 0.94806317 | L20: 0.0204552 | M20: 0.87417826 | N20: 0.85482308 | O20: 0.019355177
B21: Female (F) | C21: 33976 | D21: 33254 | E21: 722 | F21: 31519 | G21: 30840 | H21: 679 | I21: 35604 | J21: 0.9542748 | K21: 0.93399618 | L21: 0.02027862 | M21: 0.8852657 | N21: 0.86619481 | O21: 0.019070891
A22: Davao Occidental | B22: Total (MF) | C22: 50777 | D22: 50296 | E22: 481 | F22: 42874 | G22: 42418 | H22: 456 | I22: 55228 | J22: 0.91940682 | K22: 0.91069747 | L22: 0.0087093503 | M22: 0.77630912 | N22: 0.76805244 | O22: 0.0082566814 | P22: 0.99542772 | Q22: 0.9979753 | R22: 0.76011528 | S22: 1.0172314 | T22: 1.0199571 | U22: 0.79176205
B23: Male (M) | C23: 25956 | D23: 25678 | E23: 278 | F23: 21684 | G23: 21425 | H23: 259 | I23: 28168 | J23: 0.92147117 | K23: 0.91160182 | L23: 0.0098693553 | M23: 0.76980971 | N23: 0.76061488 | O23: 0.009194831
B24: Female (F) | C24: 24821 | D24: 24618 | E24: 203 | F24: 21190 | G24: 20993 | H24: 197 | I24: 27060 | J24: 0.91725795 | K24: 0.9097561 | L24: 0.0075018477 | M24: 0.78307465 | N24: 0.77579453 | O24: 0.0072801183
A25: Davao Oriental | B25: Total (MF) | C25: 71747 | D25: 70600 | E25: 1147 | F25: 63197 | G25: 62109 | H25: 1088 | I25: 70221 | J25: 1.0217314 | K25: 1.0053972 | L25: 0.016334145 | M25: 0.89997294 | N25: 0.884479 | O25: 0.015493941 | P25: 0.95775965 | Q25: 0.95729777 | R25: 0.98660235 | S25: 1.0057886 | T25: 1.005386 | U25: 1.0290327
B26: Male (M) | C26: 37687 | D26: 37093 | E26: 594 | F26: 32424 | G26: 31872 | H26: 552 | I26: 36129 | J26: 1.0431233 | K26: 1.0266822 | L26: 0.016441086 | M26: 0.8974508 | N26: 0.88217222 | O26: 0.015278585
B27: Female (F) | C27: 34060 | D27: 33507 | E27: 553 | F27: 30773 | G27: 30237 | H27: 536 | I27: 34092 | J27: 0.99906136 | K27: 0.98284055 | L27: 0.016220814 | M27: 0.90264578 | N27: 0.88692362 | O27: 0.015722164
A28: Digos City | B28: Total (MF) | C28: 28658 | D28: 26402 | E28: 2256 | F28: 26170 | G28: 24003 | H28: 2167 | I28: 26764 | J28: 1.0707667 | K28: 0.98647437 | L28: 0.084292333 | M28: 0.97780601 | N28: 0.89683904 | O28: 0.080966971 | P28: 0.98557563 | Q28: 0.98722785 | R28: 0.96643343 | S28: 1.0136267 | T28: 1.0171697 | U28: 0.97516519
B29: Male (M) | C29: 15040 | D29: 13845 | E29: 1195 | F29: 13551 | G29: 12408 | H29: 1143 | I29: 13949 | J29: 1.0782135 | K29: 0.99254427 | L29: 0.085669224 | M29: 0.97146749 | N29: 0.88952613 | O29: 0.081941358
B30: Female (F) | C30: 13618 | D30: 12557 | E30: 1061 | F30: 12619 | G30: 11595 | H30: 1024 | I30: 12815 | J30: 1.0626609 | K30: 0.97986734 | L30: 0.082793601 | M30: 0.98470542 | N30: 0.90479906 | O30: 0.07990636
A31: Island Garden City of Samal | B31: Total (MF) | C31: 17928 | D31: 17419 | E31: 509 | F31: 16368 | G31: 15883 | H31: 485 | I31: 17359 | J31: 1.0327784 | K31: 1.0034564 | L31: 0.029321966 | M31: 0.94291146 | N31: 0.91497206 | O31: 0.027939397 | P31: 0.96816235 | Q31: 0.9750042 | R31: 0.75885229 | S31: 1.0059717 | T31: 1.0143222 | U31: 0.76528776
B32: Male (M) | C32: 9383 | D32: 9086 | E32: 297 | F32: 8410 | G32: 8128 | H32: 282 | I32: 8945 | J32: 1.0489659 | K32: 1.015763 | L32: 0.033202907 | M32: 0.94019005 | N32: 0.90866406 | O32: 0.031525992
B33: Female (F) | C33: 8545 | D33: 8333 | E33: 212 | F33: 7958 | G33: 7755 | H33: 203 | I33: 8414 | J33: 1.0155693 | K33: 0.99037319 | L33: 0.025196102 | M33: 0.94580461 | N33: 0.92167816 | O33: 0.024126456
A34: Mati City | B34: Total (MF) | C34: 25476 | D34: 23819 | E34: 1657 | F34: 22466 | G34: 20873 | H34: 1593 | I34: 23256 | J34: 1.0954592 | K34: 1.0242088 | L34: 0.07125043 | M34: 0.96603027 | N34: 0.89753182 | O34: 0.068498452 | P34: 0.95396294 | Q34: 0.9534675 | R34: 0.96111199 | S34: 1.0024875 | T34: 1.00426 | U34: 0.97954112
B35: Male (M) | C35: 13362 | D35: 12496 | E35: 866 | F35: 11505 | G35: 10680 | H35: 825 | I35: 11924 | J35: 1.1205971 | K35: 1.0479705 | L35: 0.072626635 | M35: 0.96486078 | N35: 0.89567259 | O35: 0.069188192
B36: Female (F) | C36: 12114 | D36: 11323 | E36: 791 | F36: 10961 | G36: 10193 | H36: 768 | I36: 11332 | J36: 1.0690081 | K36: 0.99920579 | L36: 0.06980233 | M36: 0.96726085 | N36: 0.89948818 | O36: 0.067772679
A37: Panabo City | B37: Total (MF) | C37: 32391 | D37: 29666 | E37: 2725 | F37: 29573 | G37: 26941 | H37: 2632 | I37: 30911 | J37: 1.0478794 | K37: 0.95972308 | L37: 0.08815632 | M37: 0.95671444 | N37: 0.87156676 | O37: 0.085147682 | P37: 0.99055585 | Q37: 0.99617966 | R37: 0.93126533 | S37: 1.0134624 | T37: 1.0210217 | U37: 0.93913223
B38: Male (M) | C38: 16737 | D38: 15287 | E38: 1450 | F38: 15112 | G38: 13717 | H38: 1395 | I38: 15899 | J38: 1.0527077 | K38: 0.96150701 | L38: 0.091200704 | M38: 0.95050003 | N38: 0.86275866 | O38: 0.087741367
B39: Female (F) | C39: 15654 | D39: 14379 | E39: 1275 | F39: 14461 | G39: 13224 | H39: 1237 | I39: 15012 | J39: 1.0427658 | K39: 0.95783373 | L39: 0.084932054 | M39: 0.96329603 | N39: 0.88089528 | O39: 0.082400746
A40: Tagum City | B40: Total (MF) | C40: 41637 | D40: 37613 | E40: 4024 | F40: 38440 | G40: 34546 | H40: 3894 | I40: 42056 | J40: 0.99003709 | K40: 0.89435515 | L40: 0.095681948 | M40: 0.9140194 | N40: 0.82142857 | O40: 0.092590831 | P40: 0.97370651 | Q40: 0.97162707 | R40: 0.99335174 | S40: 0.99834656 | T40: 0.99763156 | U40: 1.0047117
B41: Male (M) | C41: 21647 | D41: 19575 | E41: 2072 | F41: 19745 | G41: 17751 | H41: 1994 | I41: 21585 | J41: 1.0028724 | K41: 0.90687978 | L41: 0.095992587 | M41: 0.91475562 | N41: 0.82237665 | O41: 0.092378967
B42: Female (F) | C42: 19990 | D42: 18038 | E42: 1952 | F42: 18695 | G42: 16795 | H42: 1900 | I42: 20471 | J42: 0.97650335 | K42: 0.88114894 | L42: 0.095354404 | M42: 0.91324312 | N42: 0.8204289 | O42: 0.092814225
...

Sheet GER-NER G7toG10wLSENs
A1: DEPARTMENT OF EDUCATION
A2: GROSS AND NET ENROLMENT RATE IN JUNIOR HIGH SCHOOL
A3: (Based on Learners' School Address)
A4: SY 2023-2024
A6: Region/Division | C6: Total Enrollment (All Ages) | F6: Total Enrollment (Ages 12-15) | I6: Population | J6: Gross Enrollment Rate (GER) | M6: Net Enrollment Rate (NER) | P6: Gender Parity Index (GER) | S6: Gender Parity Index (NER)
C7: Total | D7: Public | E7: Private | F7: Total | G7: Public | H7: Private | I7: (Ages 12-15) | J7: Both | K7: Public | L7: Private | M7: Both | N7: Public | O7: Private | P7: Both | Q7: Public | R7: Private | S7: Both | T7: Public | U7: Private
A8: REGION XI - DAVAO REGION
A10: Davao City | B10: Total (MF) | C10: 133656 | D10: 112797 | E10: 20859 | F10: 118018 | G10: 99351 | H10: 18667 | I10: 139829 | J10: 0.95585322 | K10: 0.80667816 | L10: 0.14917506 | M10: 0.84401662 | N10: 0.71051785 | O10: 0.13349877 | P10: 1.0349973 | Q10: 1.0274732 | R10: 1.0766487 | S10: 1.0948724 | T10: 1.0920774 | U10: 1.1098722
B11: Male (M) | C11: 67246 | D11: 56957 | E11: 10289 | F11: 57719 | G11: 48653 | H11: 9066 | I11: 71554 | J11: 0.93979372 | K11: 0.79600022 | L11: 0.1437935 | M11: 0.80664952 | N11: 0.67994801 | O11: 0.12670151
B12: Female (F) | C12: 66410 | D12: 55840 | E12: 10570 | F12: 60299 | G12: 50698 | H12: 9601 | I12: 68275 | J12: 0.972684 | K12: 0.81786891 | L12: 0.15481509 | M12: 0.88317832 | N12: 0.74255584 | O12: 0.14062248
A13: Davao de Oro (Compostela Valley) | B13: Total (MF) | C13: 56858 | D13: 54550 | E13: 2308 | F13: 52642 | G13: 50432 | H13: 2210 | I13: 68277 | J13: 0.83275481 | K13: 0.79895133 | L13: 0.033803477 | M13: 0.77100634 | N13: 0.73863819 | O13: 0.032368147 | P13: 1.0519115 | Q13: 1.0581281 | R13: 0.91480887 | S13: 1.1059921 | T13: 1.1146932 | U13: 0.92459446
B14: Male (M) | C14: 28864 | D14: 27612 | E14: 1252 | F14: 26064 | G14: 24871 | H14: 1193 | I14: 35524 | J14: 0.81252111 | K14: 0.77727733 | L14: 0.035243779 | M14: 0.73370116 | N14: 0.70011823 | O14: 0.03358293
B15: Female (F) | C15: 27994 | D15: 26938 | E15: 1056 | F15: 26578 | G15: 25561 | H15: 1017 | I15: 32753 | J15: 0.85470033 | K15: 0.82245901 | L15: 0.032241321 | M15: 0.81146765 | N15: 0.78041706 | O15: 0.031050591
A16: Davao del Norte | B16: Total (MF) | C16: 35300 | D16: 32829 | E16: 2471 | F16: 32826 | G16: 30542 | H16: 2284 | I16: 42390 | J16: 0.83274357 | K16: 0.77445152 | L16: 0.05829205 | M16: 0.77438075 | N16: 0.72050012 | O16: 0.053880632 | P16: 1.0340449 | Q16: 1.0440527 | R16: 0.90953581 | S16: 1.0884152 | T16: 1.0993743 | U16: 0.95182491
B17: Male (M) | C17: 17971 | D17: 16634 | E17: 1337 | F17: 16291 | G17: 15081 | H17: 1210 | I17: 21935 | J17: 0.81928425 | K17: 0.75833143 | L17: 0.060952815 | M17: 0.74269432 | N17: 0.68753134 | O17: 0.055162982
B18: Female (F) | C18: 17329 | D18: 16195 | E18: 1134 | F18: 16535 | G18: 15461 | H18: 1074 | I18: 20455 | J18: 0.84717673 | K18: 0.79173796 | L18: 0.055438768 | M18: 0.80835981 | N18: 0.75585431 | O18: 0.0525055
A19: Davao del Sur | B19: Total (MF) | C19: 33633 | D19: 27966 | E19: 5667 | F19: 31371 | G19: 25959 | H19: 5412 | I19: 40910 | J19: 0.82212173 | K19: 0.68359814 | L19: 0.13852359 | M19: 0.76682963 | N19: 0.63453923 | O19: 0.13229039 | P19: 1.0996733 | Q19: 1.1032766 | R19: 1.082064 | S19: 1.1512826 | T19: 1.1622052 | U19: 1.1003376
B20: Male (M) | C20: 16660 | D20: 13830 | E20: 2830 | F20: 15180 | G20: 12500 | H20: 2680 | I20: 21236 | J20: 0.78451686 | K20: 0.65125259 | L20: 0.13326427 | M20: 0.71482388 | N20: 0.58862309 | O20: 0.12620079
B21: Female (F) | C21: 16973 | D21: 14136 | E21: 2837 | F21: 16191 | G21: 13459 | H21: 2732 | I21: 19674 | J21: 0.86271221 | K21: 0.71851174 | L21: 0.14420047 | M21: 0.82296432 | N21: 0.68410084 | O21: 0.13886347
A22: Davao Occidental | B22: Total (MF) | C22: 21223 | D22: 20280 | E22: 943 | F22: 18550 | G22: 17675 | H22: 875 | I22: 30735 | J22: 0.6905157 | K22: 0.65983407 | L22: 0.030681633 | M22: 0.60354645 | N22: 0.57507727 | O22: 0.028469172 | P22: 1.1684378 | Q22: 1.1746504 | R22: 1.042754 | S22: 1.2434704 | T22: 1.252156 | U22: 1.0810626
B23: Male (M) | C23: 10042 | D23: 9569 | E23: 473 | F23: 8490 | G23: 8059 | H23: 431 | I23: 15738 | J23: 0.63807345 | K23: 0.60801881 | L23: 0.030054645 | M23: 0.53945864 | N23: 0.51207269 | O23: 0.027385945
B24: Female (F) | C24: 11181 | D24: 10711 | E24: 470 | F24: 10060 | G24: 9616 | H24: 444 | I24: 14997 | J24: 0.74554911 | K24: 0.71420951 | L24: 0.031339601 | M24: 0.67080083 | N24: 0.64119491 | O24: 0.029605921
A25: Davao Oriental | B25: Total (MF) | C25: 32886 | D25: 30538 | E25: 2348 | F25: 29474 | G25: 27237 | H25: 2237 | I25: 38883 | J25: 0.84576807 | K25: 0.78538179 | L25: 0.060386287 | M25: 0.75801764 | N25: 0.70048607 | O25: 0.057531569 | P25: 1.0547311 | Q25: 1.0549773 | R25: 1.0515339 | S25: 1.1274218 | T25: 1.1314285 | U25: 1.0797979
B26: Male (M) | C26: 16320 | D26: 15153 | E26: 1167 | F26: 14136 | G26: 13039 | H26: 1097 | I26: 19814 | J26: 0.82366004 | K26: 0.76476229 | L26: 0.058897749 | M26: 0.71343494 | N26: 0.65807005 | O26: 0.055364894
B27: Female (F) | C27: 16566 | D27: 15385 | E27: 1181 | F27: 15338 | G27: 14198 | H27: 1140 | I27: 19069 | J27: 0.86873984 | K27: 0.80680686 | L27: 0.06193298 | M27: 0.80434213 | N27: 0.74455923 | O27: 0.059782894
A28: Digos City | B28: Total (MF) | C28: 15216 | D28: 13401 | E28: 1815 | F28: 13850 | G28: 12160 | H28: 1690 | I28: 14947 | J28: 1.0179969 | K28: 0.89656787 | L28: 0.12142905 | M28: 0.92660735 | N28: 0.81354118 | O28: 0.11306617 | P28: 1.0569237 | Q28: 1.0670402 | R28: 0.98512296 | S28: 1.1205516 | T28: 1.1379599 | U28: 1.0030304
B29: Male (M) | C29: 7571 | D29: 6636 | E29: 935 | F29: 6689 | G29: 5826 | H29: 863 | I29: 7644 | J29: 0.99045003 | K29: 0.86813187 | L29: 0.12231816 | M29: 0.87506541 | N29: 0.76216641 | O29: 0.11289901
B30: Female (F) | C30: 7645 | D30: 6765 | E30: 880 | F30: 7161 | G30: 6334 | H30: 827 | I30: 7303 | J30: 1.0468301 | K30: 0.92633164 | L30: 0.12049843 | M30: 0.98055594 | N30: 0.8673148 | O30: 0.11324113
A31: Island Garden City of Samal | B31: Total (MF) | C31: 8801 | D31: 8186 | E31: 615 | F31: 8225 | G31: 7627 | H31: 598 | I31: 9393 | J31: 0.93697434 | K31: 0.87150005 | L31: 0.065474289 | M31: 0.87565208 | N31: 0.81198765 | O31: 0.063664431 | P31: 1.1253468 | Q31: 1.1197237 | R31: 1.2029993 | S31: 1.1895675 | T31: 1.1854831 | U31: 1.24297
B32: Male (M) | C32: 4354 | D32: 4060 | E32: 294 | F32: 3955 | G32: 3674 | H32: 281 | I32: 4924 | J32: 0.88424045 | K32: 0.8245329 | L32: 0.059707555 | M32: 0.80320877 | N32: 0.74614135 | O32: 0.057067425
B33: Female (F) | C33: 4447 | D33: 4126 | E33: 321 | F33: 4270 | G33: 3953 | H33: 317 | I33: 4469 | J33: 0.9950772 | K33: 0.92324905 | L33: 0.071828149 | M33: 0.95547102 | N33: 0.88453793 | O33: 0.070933095
A34: Mati City | B34: Total (MF) | C34: 12198 | D34: 11190 | E34: 1008 | F34: 10737 | G34: 9841 | H34: 896 | I34: 12928 | J34: 0.94353342 | K34: 0.86556312 | L34: 0.077970297 | M34: 0.8305229 | N34: 0.76121597 | O34: 0.069306931 | P34: 1.0988491 | Q34: 1.1077253 | R34: 1.0049955 | S34: 1.208025 | T34: 1.220675 | U34: 1.0778125
B35: Male (M) | C35: 5972 | D35: 5456 | E35: 516 | F35: 5003 | G35: 4560 | H35: 443 | I35: 6634 | J35: 0.90021103 | K35: 0.82242991 | L35: 0.077781128 | M35: 0.75414531 | N35: 0.6873681 | O35: 0.066777208
B36: Female (F) | C36: 6226 | D36: 5734 | E36: 492 | F36: 5734 | G36: 5281 | H36: 453 | I36: 6294 | J36: 0.98919606 | K36: 0.91102637 | L36: 0.078169685 | M36: 0.91102637 | N36: 0.83905307 | O36: 0.071973308
A37: Panabo City | B37: Total (MF) | C37: 16474 | D37: 13696 | E37: 2778 | F37: 15346 | G37: 12724 | H37: 2622 | I37: 17102 | J37: 0.96327915 | K37: 0.80084201 | L37: 0.16243714 | M37: 0.89732195 | N37: 0.74400655 | O37: 0.1533154 | P37: 1.0461963 | Q37: 1.0374422 | R37: 1.090446 | S37: 1.0903089 | T37: 1.0871576 | U37: 1.1057337
B38: Male (M) | C38: 8289 | D38: 6920 | E38: 1369 | F38: 7563 | G38: 6280 | H38: 1283 | I38: 8798 | J38: 0.94214594 | K38: 0.7865424 | L38: 0.15560355 | M38: 0.85962719 | N38: 0.71379859 | O38: 0.1458286
B39: Female (F) | C39: 8185 | D39: 6776 | E39: 1409 | F39: 7783 | G39: 6444 | H39: 1339 | I39: 8304 | J39: 0.98566956 | K39: 0.81599229 | L39: 0.16967726 | M39: 0.93725915 | N39: 0.77601156 | O39: 0.16124759
A40: Tagum City | B40: Total (MF) | C40: 22868 | D40: 19770 | E40: 3098 | F40: 21076 | G40: 18279 | H40: 2797 | I40: 23221 | J40: 0.98479824 | K40: 0.85138452 | L40: 0.13341372 | M40: 0.90762672 | N40: 0.7871754 | O40: 0.12045132 | P40: 1.0241262 | Q40: 1.016099 | R40: 1.0768679 | S40: 1.0696775 | T40: 1.0610498 | U40: 1.1278564
B41: Male (M) | C41: 11507 | D41: 9987 | E41: 1520 | F41: 10376 | G41: 9036 | H41: 1340 | I41: 11823 | J41: 0.97327244 | K41: 0.84470946 | L41: 0.12856297 | M41: 0.87761144 | N41: 0.76427303 | O41: 0.11333841
B42: Female (F) | C42: 11361 | D42: 9783 | E42: 1578 | F42: 10700 | G42: 9243 | H42: 1457 | I42: 11398 | J42: 0.99675382 | K42: 0.85830848 | L42: 0.13844534 | M42: 0.93876119 | N42: 0.81093174 | O42: 0.12782944
...

Sheet GER-NER G11toG12
A1: DEPARTMENT OF EDUCATION
A2: GROSS AND NET ENROLMENT RATE IN SENIOR HIGH SCHOOL
A3: (Based on Learners' School Address)
A4: SY 2023-2024
A6: Region/Division | C6: Total Enrollment (All Ages) | F6: Total Enrollment (Ages 16-17) | I6: Population | J6: Gross Enrollment Rate (GER) | M6: Net Enrollment Rate (NER) | P6: Gender Parity Index (GER) | S6: Gender Parity Index (NER)
C7: Total | D7: Public | E7: Private | F7: Total | G7: Public | H7: Private | I7: (Ages 16- 17) | J7: Both | K7: Public | L7: Private | M7: Both | N7: Public | O7: Private | P7: Both | Q7: Public | R7: Private | S7: Both | T7: Public | U7: Private
A8: REGION XI - DAVAO REGION
A10: Davao City | B10: Total (MF) | C10: 77378 | D10: 39893 | E10: 37485 | F10: 51457 | G10: 24974 | H10: 26483 | I10: 65281 | J10: 1.1853066 | K10: 0.61109664 | L10: 0.57420995 | M10: 0.78823854 | N10: 0.38256154 | O10: 0.405677 | P10: 1.0743576 | Q10: 0.97597127 | R10: 1.1902079 | S10: 1.2255608 | T10: 1.1336246 | U10: 1.3196903
B11: Male (M) | C11: 38004 | D11: 20551 | E11: 17453 | F11: 23584 | G11: 11931 | H11: 11653 | I11: 33233 | J11: 1.1435621 | K11: 0.61839136 | L11: 0.52517076 | M11: 0.70965606 | N11: 0.35901062 | O11: 0.35064544
B12: Female (F) | C12: 39374 | D12: 19342 | E12: 20032 | F12: 27873 | G12: 13043 | H12: 14830 | I12: 32048 | J12: 1.2285946 | K12: 0.6035322 | L12: 0.62506241 | M12: 0.86972666 | N12: 0.40698328 | O12: 0.46274338
A13: Davao de Oro (Compostela Valley) | B13: Total (MF) | C13: 30122 | D13: 25046 | E13: 5076 | F13: 20778 | G13: 17272 | H13: 3506 | I13: 33075 | J13: 0.91071807 | K13: 0.75724868 | L13: 0.15346939 | M13: 0.62820862 | N13: 0.52220711 | O13: 0.10600151 | P13: 1.0726224 | Q13: 1.0662512 | R13: 1.1046203 | S13: 1.2153713 | T13: 1.1988028 | U13: 1.300637
B14: Male (M) | C14: 15134 | D14: 12621 | E14: 2513 | F14: 9791 | G14: 8198 | H14: 1593 | I14: 17197 | J14: 0.88003722 | K14: 0.73390708 | L14: 0.14613014 | M14: 0.56934349 | N14: 0.47671105 | O14: 0.092632436
B15: Female (F) | C15: 14988 | D15: 12425 | E15: 2563 | F15: 10987 | G15: 9074 | H15: 1913 | I15: 15878 | J15: 0.9439476 | K15: 0.78252929 | L15: 0.16141831 | M15: 0.69196372 | N15: 0.57148255 | O15: 0.12048117
A16: Davao del Norte | B16: Total (MF) | C16: 19013 | D16: 17437 | E16: 1576 | F16: 13014 | G16: 11900 | H16: 1114 | I16: 19292 | J16: 0.98553805 | K16: 0.90384615 | L16: 0.081691893 | M16: 0.67458014 | N16: 0.61683599 | O16: 0.057744143 | P16: 1.0068345 | Q16: 1.0126167 | R16: 0.94496268 | S16: 1.1499729 | T16: 1.157891 | U16: 1.0688092
B17: Male (M) | C17: 9688 | D17: 8860 | E17: 828 | F17: 6199 | G17: 5648 | H17: 551 | I17: 9863 | J17: 0.98225692 | K17: 0.8983068 | L17: 0.083950117 | M17: 0.6285106 | N17: 0.57264524 | O17: 0.055865355
B18: Female (F) | C18: 9325 | D18: 8577 | E18: 748 | F18: 6815 | G18: 6252 | H18: 563 | I18: 9429 | J18: 0.9889702 | K18: 0.90964047 | L18: 0.079329727 | M18: 0.72277018 | N18: 0.66306077 | O18: 0.059709407
A19: Davao del Sur | B19: Total (MF) | C19: 15996 | D19: 12184 | E19: 3812 | F19: 11573 | G19: 8559 | H19: 3014 | I19: 18535 | J19: 0.86301592 | K19: 0.65735096 | L19: 0.20566496 | M19: 0.6243863 | N19: 0.46177502 | O19: 0.16261128 | P19: 1.0725912 | Q19: 1.0727724 | R19: 1.0720124 | S19: 1.2315472 | T19: 1.2424098 | U19: 1.2012457
B20: Male (M) | C20: 8042 | D20: 6125 | E20: 1917 | F20: 5419 | G20: 3989 | H20: 1430 | I20: 9643 | J20: 0.83397283 | K20: 0.63517578 | L20: 0.19879705 | M20: 0.56196205 | N20: 0.41366795 | O20: 0.1482941
B21: Female (F) | C21: 7954 | D21: 6059 | E21: 1895 | F21: 6154 | G21: 4570 | H21: 1584 | I21: 8892 | J21: 0.89451192 | K21: 0.68139901 | L21: 0.21311291 | M21: 0.69208277 | N21: 0.51394512 | O21: 0.17813765
A22: Davao Occidental | B22: Total (MF) | C22: 9838 | D22: 9225 | E22: 613 | F22: 5872 | G22: 5468 | H22: 404 | I22: 12996 | J22: 0.75700215 | K22: 0.7098338 | L22: 0.047168359 | M22: 0.45183133 | N22: 0.42074484 | O22: 0.031086488 | P22: 1.218963 | Q22: 1.2375231 | R22: 0.97217762 | S22: 1.3423322 | T22: 1.3518753 | U22: 1.2202722
B23: Male (M) | C23: 4532 | D23: 4215 | E23: 317 | F23: 2565 | G23: 2379 | H23: 186 | I23: 6629 | J23: 0.68366269 | K23: 0.63584251 | L23: 0.047820184 | M23: 0.38693619 | N23: 0.35887766 | O23: 0.028058531
B24: Female (F) | C24: 5306 | D24: 5010 | E24: 296 | F24: 3307 | G24: 3089 | H24: 218 | I24: 6367 | J24: 0.83335951 | K24: 0.7868698 | L24: 0.046489713 | M24: 0.51939689 | N24: 0.48515785 | O24: 0.034239045
A25: Davao Oriental | B25: Total (MF) | C25: 15913 | D25: 13016 | E25: 2897 | F25: 10324 | G25: 8483 | H25: 1841 | I25: 17851 | J25: 0.89143465 | K25: 0.72914683 | L25: 0.16228783 | M25: 0.57834295 | N25: 0.47521147 | O25: 0.10313148 | P25: 1.106191 | Q25: 1.0905956 | R25: 1.1791557 | S25: 1.3076083 | T25: 1.3070981 | U25: 1.3099616
B26: Male (M) | C26: 7757 | D26: 6391 | E26: 1366 | F26: 4603 | G26: 3783 | H26: 820 | I26: 9152 | J26: 0.8475743 | K26: 0.69831731 | L26: 0.14925699 | M26: 0.50295017 | N26: 0.41335227 | O26: 0.089597902
B27: Female (F) | C27: 8156 | D27: 6625 | E27: 1531 | F27: 5721 | G27: 4700 | H27: 1021 | I27: 8699 | J27: 0.93757903 | K27: 0.76158179 | L27: 0.17599724 | M27: 0.6576618 | N27: 0.54029199 | O27: 0.11736981
A28: Digos City | B28: Total (MF) | C28: 10924 | D28: 2783 | E28: 8141 | F28: 6912 | G28: 1713 | H28: 5199 | I28: 7057 | J28: 1.5479666 | K28: 0.39436021 | L28: 1.1536063 | M28: 0.97945303 | N28: 0.24273771 | O28: 0.73671532 | P28: 1.1145616 | Q28: 0.87964681 | R28: 1.2088183 | S28: 1.3213985 | T28: 1.0258575 | U28: 1.4384607
B29: Male (M) | C29: 5207 | D29: 1491 | E29: 3716 | F29: 3003 | G29: 852 | H29: 2151 | I29: 3555 | J29: 1.4646976 | K29: 0.41940928 | L29: 1.0452883 | M29: 0.84472574 | N29: 0.23966245 | O29: 0.60506329
B30: Female (F) | C30: 5717 | D30: 1292 | E30: 4425 | F30: 3909 | G30: 861 | H30: 3048 | I30: 3502 | J30: 1.6324957 | K30: 0.36893204 | L30: 1.2635637 | M30: 1.1162193 | N30: 0.24585951 | O30: 0.87035979
A31: Island Garden City of Samal | B31: Total (MF) | C31: 4707 | D31: 4266 | E31: 441 | F31: 3225 | G31: 2869 | H31: 356 | I31: 4469 | J31: 1.0532558 | K31: 0.95457597 | L31: 0.098679794 | M31: 0.72163795 | N31: 0.64197807 | O31: 0.079659879 | P31: 1.0902201 | Q31: 1.08253 | R31: 1.1674372 | S31: 1.3031353 | T31: 1.3122581 | U31: 1.2320095
B32: Male (M) | C32: 2418 | D32: 2199 | E32: 219 | F32: 1513 | G32: 1341 | H32: 172 | I32: 2392 | J32: 1.0108696 | K32: 0.91931438 | L32: 0.091555184 | M32: 0.63252508 | N32: 0.56061873 | O32: 0.071906355
B33: Female (F) | C33: 2289 | D33: 2067 | E33: 222 | F33: 1712 | G33: 1528 | H33: 184 | I33: 2077 | J33: 1.1020703 | K33: 0.99518536 | L33: 0.10688493 | M33: 0.82426577 | N33: 0.73567646 | O33: 0.088589312
A34: Mati City | B34: Total (MF) | C34: 6827 | D34: 5140 | E34: 1687 | F34: 4261 | G34: 3142 | H34: 1119 | I34: 6417 | J34: 1.0638928 | K34: 0.80099735 | L34: 0.26289543 | M34: 0.66401745 | N34: 0.4896369 | O34: 0.17438055 | P34: 1.0754189 | Q34: 1.0750974 | R34: 1.076399 | S34: 1.3122623 | T34: 1.3423226 | U34: 1.2318051
B35: Male (M) | C35: 3324 | D35: 2503 | E35: 821 | F35: 1864 | G35: 1357 | H35: 507 | I35: 3241 | J35: 1.0256094 | K35: 0.7722925 | L35: 0.25331688 | M35: 0.57513113 | N35: 0.41869793 | O35: 0.1564332
B36: Female (F) | C36: 3503 | D36: 2637 | E36: 866 | F36: 2397 | G36: 1785 | H36: 612 | I36: 3176 | J36: 1.1029597 | K36: 0.83028967 | L36: 0.27267003 | M36: 0.75472292 | N36: 0.56202771 | O36: 0.19269521
A37: Panabo City | B37: Total (MF) | C37: 9858 | D37: 6678 | E37: 3180 | F37: 7047 | G37: 4559 | H37: 2488 | I37: 8169 | J37: 1.2067573 | K37: 0.81748072 | L37: 0.38927653 | M37: 0.86265149 | N37: 0.55808544 | O37: 0.30456604 | P37: 1.068894 | Q37: 0.98329572 | R37: 1.2744853 | S37: 1.2030628 | T37: 1.1112701 | U37: 1.3932849
B38: Male (M) | C38: 4868 | D38: 3437 | E38: 1431 | F38: 3272 | G38: 2207 | H38: 1065 | I38: 4170 | J38: 1.1673861 | K38: 0.82422062 | L38: 0.34316547 | M38: 0.78465228 | N38: 0.52925659 | O38: 0.25539568
B39: Female (F) | C39: 4990 | D39: 3241 | E39: 1749 | F39: 3775 | G39: 2352 | H39: 1423 | I39: 3999 | J39: 1.247812 | K39: 0.81045261 | L39: 0.43735934 | M39: 0.943986 | N39: 0.58814704 | O39: 0.35583896
A40: Tagum City | B40: Total (MF) | C40: 14173 | D40: 6745 | E40: 7428 | F40: 10172 | G40: 4603 | H40: 5569 | I40: 11294 | J40: 1.2549141 | K40: 0.59721976 | L40: 0.65769435 | M40: 0.90065522 | N40: 0.40756154 | O40: 0.49309368 | P40: 1.0580611 | Q40: 0.87902538 | R40: 1.2527166 | S40: 1.1916122 | T40: 0.98123988 | U40: 1.4021644
B41: Male (M) | C41: 6938 | D41: 3614 | E41: 3324 | F41: 4678 | G41: 2340 | H41: 2338 | I41: 5688 | J41: 1.2197609 | K41: 0.63537271 | L41: 0.58438819 | M41: 0.82243319 | N41: 0.41139241 | O41: 0.41104079
B42: Female (F) | C42: 7235 | D42: 3131 | E42: 4104 | F42: 5494 | G42: 2263 | H42: 3231 | I42: 5606 | J42: 1.2905815 | K42: 0.55850874 | L42: 0.73207278 | M42: 0.98002141 | N42: 0.40367463 | O42: 0.57634677
...

Sheet GER-NER G7toG12wLSENs
A1: DEPARTMENT OF EDUCATION
A2: GROSS AND NET ENROLMENT RATE IN JUNIOR HIGH SCHOOL TO SENIOR HIGH SCHOOL
A3: (Based on Learners' School Address)
A4: SY 2023-2024
A6: Region/Division | C6: Total Enrollment (All Ages) | F6: Total Enrollment (Ages 12-17) | I6: Population | J6: Gross Enrollment Rate (GER) | M6: Net Enrollment Rate (NER) | P6: Gender Parity Index (GER) | S6: Gender Parity Index (NER)
C7: Total | D7: Public | E7: Private | F7: Total | G7: Public | H7: Private | I7: (Ages 12-17) | J7: Both | K7: Public | L7: Private | M7: Both | N7: Public | O7: Private | P7: Both | Q7: Public | R7: Private | S7: Both | T7: Public | U7: Private
A8: REGION XI - DAVAO REGION
A10: Davao City | B10: Total (MF) | C10: 218663 | D10: 160319 | E10: 58344 | F10: 184625 | G10: 137258 | H10: 47367 | I10: 205110 | J10: 1.0660767 | K10: 0.78162449 | L10: 0.28445225 | M10: 0.90012676 | N10: 0.66919214 | O10: 0.23093462 | P10: 1.0425015 | Q10: 1.0052577 | R10: 1.1521763 | S10: 1.0941796 | T10: 1.05502 | U10: 1.2163754
B11: Male (M) | C11: 109436 | D11: 81694 | E11: 27742 | F11: 90168 | G11: 68285 | H11: 21883 | I11: 104787 | J11: 1.0443662 | K11: 0.77961961 | L11: 0.26474658 | M11: 0.86048842 | N11: 0.65165526 | O11: 0.20883316
B12: Female (F) | C12: 109227 | D12: 78625 | E12: 30602 | F12: 94457 | G12: 68973 | H12: 25484 | I12: 100323 | J12: 1.0887533 | K12: 0.78371859 | L12: 0.30503474 | M12: 0.94152886 | N12: 0.68750934 | O12: 0.25401952
A13: Davao de Oro (Compostela Valley) | B13: Total (MF) | C13: 93687 | D13: 86303 | E13: 7384 | F13: 78463 | G13: 72609 | H13: 5854 | I13: 101352 | J13: 0.92437248 | K13: 0.85151748 | L13: 0.072855 | M13: 0.77416331 | N13: 0.71640422 | O13: 0.057759097 | P13: 1.04736 | Q13: 1.0478145 | R13: 1.0420632 | S13: 1.096358 | T13: 1.0927672 | U13: 1.1419013
B14: Male (M) | C14: 47651 | D14: 43886 | E14: 3765 | F14: 39011 | G14: 36160 | H14: 2851 | I14: 52721 | J14: 0.90383339 | K14: 0.83241972 | L14: 0.071413668 | M14: 0.73995182 | N14: 0.6858747 | O14: 0.054077123
B15: Female (F) | C15: 46036 | D15: 42417 | E15: 3619 | F15: 39452 | G15: 36449 | H15: 3003 | I15: 48631 | J15: 0.94663898 | K15: 0.87222142 | L15: 0.074417553 | M15: 0.81125208 | N15: 0.74950135 | O15: 0.061750735
A16: Davao del Norte | B16: Total (MF) | C16: 58675 | D16: 54628 | E16: 4047 | F16: 48902 | G16: 45346 | H16: 3556 | I16: 61682 | J16: 0.95124996 | K16: 0.88563925 | L16: 0.065610713 | M16: 0.79280827 | N16: 0.73515774 | O16: 0.05765053 | P16: 1.0113794 | Q16: 1.0180813 | R16: 0.92495967 | S16: 1.0616135 | T16: 1.0684683 | U16: 0.97791319
B17: Male (M) | C17: 30082 | D17: 27917 | E17: 2165 | F17: 24479 | G17: 22626 | H17: 1853 | I17: 31798 | J17: 0.94603434 | K17: 0.8779483 | L17: 0.068086043 | M17: 0.76982829 | N17: 0.71155419 | O17: 0.058274105
B18: Female (F) | C18: 28593 | D18: 26711 | E18: 1882 | F18: 24423 | G18: 22720 | H18: 1703 | I18: 29884 | J18: 0.95679963 | K18: 0.89382278 | L18: 0.062976844 | M18: 0.81726007 | N18: 0.76027306 | O18: 0.056987016
A19: Davao del Sur | B19: Total (MF) | C19: 52809 | D19: 43330 | E19: 9479 | F19: 45882 | G19: 37207 | H19: 8675 | I19: 59445 | J19: 0.8883674 | K19: 0.72890908 | L19: 0.15945832 | M19: 0.77183952 | N19: 0.6259063 | O19: 0.14593322 | P19: 1.0611349 | Q19: 1.0575762 | R19: 1.0775546 | S19: 1.1231485 | T19: 1.12333 | U19: 1.1223703
B20: Male (M) | C20: 26649 | D20: 21902 | E20: 4747 | F20: 22502 | G20: 18246 | H20: 4256 | I20: 30879 | J20: 0.8630137 | K20: 0.70928463 | L20: 0.15372907 | M20: 0.72871531 | N20: 0.59088701 | O20: 0.1378283
B21: Female (F) | C21: 26160 | D21: 21428 | E21: 4732 | F21: 23380 | G21: 18961 | H21: 4419 | I21: 28566 | J21: 0.915774 | K21: 0.75012252 | L21: 0.16565147 | M21: 0.81845551 | N21: 0.66376111 | O21: 0.15469439
A22: Davao Occidental | B22: Total (MF) | C22: 32985 | D22: 31429 | E22: 1556 | F22: 27135 | G22: 25795 | H22: 1340 | I22: 43731 | J22: 0.75427043 | K22: 0.71868926 | L22: 0.035581167 | M22: 0.62049804 | N22: 0.58985617 | O22: 0.030641879 | P22: 1.1965122 | Q22: 1.206324 | R22: 1.0151421 | S22: 1.2150901 | T22: 1.2218939 | U22: 1.0916349
B23: Male (M) | C23: 15393 | D23: 14603 | E23: 790 | F23: 12559 | G23: 11903 | H23: 656 | I23: 22367 | J23: 0.68820137 | K23: 0.65288148 | L23: 0.035319891 | M23: 0.56149685 | N23: 0.53216793 | O23: 0.029328922
B24: Female (F) | C24: 17592 | D24: 16826 | E24: 766 | F24: 14576 | G24: 13892 | H24: 684 | I24: 21364 | J24: 0.8234413 | K24: 0.78758659 | L24: 0.035854709 | M24: 0.68226924 | N24: 0.65025276 | O24: 0.032016476
A25: Davao Oriental | B25: Total (MF) | C25: 52842 | D25: 47597 | E25: 5245 | F25: 43559 | G25: 39349 | H25: 4210 | I25: 56734 | J25: 0.93139916 | K25: 0.83895019 | L25: 0.092448972 | M25: 0.76777594 | N25: 0.69356999 | O25: 0.074205944 | P25: 1.0287144 | Q25: 1.0194393 | R25: 1.1168592 | S25: 1.1119637 | T25: 1.1070214 | U25: 1.1592805
B26: Male (M) | C26: 26605 | D26: 24072 | E26: 2533 | F26: 21084 | G26: 19090 | H26: 1994 | I26: 28966 | J26: 0.91849064 | K26: 0.83104329 | L26: 0.087447352 | M26: 0.72788787 | N26: 0.65904854 | O26: 0.068839329
B27: Female (F) | C27: 26237 | D27: 23525 | E27: 2712 | F27: 22475 | G27: 20259 | H27: 2216 | I27: 27768 | J27: 0.94486459 | K27: 0.84719821 | L27: 0.097666379 | M27: 0.8093849 | N27: 0.72958081 | O27: 0.079804091
A28: Digos City | B28: Total (MF) | C28: 27561 | D28: 17605 | E28: 9956 | F28: 22331 | G28: 15270 | H28: 7061 | I28: 22004 | J28: 1.252545 | K28: 0.8000818 | L28: 0.45246319 | M28: 1.0148609 | N28: 0.69396473 | O28: 0.3208962 | P28: 1.0538325 | Q28: 0.98760188 | R28: 1.182207 | S28: 1.1296834 | T28: 1.0493043 | U28: 1.3266211
B29: Male (M) | C29: 13666 | D29: 9015 | E29: 4651 | F29: 10685 | G29: 7588 | H29: 3097 | I29: 11199 | J29: 1.2202875 | K29: 0.80498259 | L29: 0.41530494 | M29: 0.95410304 | N29: 0.6775605 | O29: 0.27654255
B30: Female (F) | C30: 13895 | D30: 8590 | E30: 5305 | F30: 11646 | G30: 7682 | H30: 3964 | I30: 10805 | J30: 1.2859787 | K30: 0.79500231 | L30: 0.4909764 | M30: 1.0778343 | N30: 0.71096714 | O30: 0.36686719
A31: Island Garden City of Samal | B31: Total (MF) | C31: 14631 | D31: 13575 | E31: 1056 | F31: 12190 | G31: 11221 | H31: 969 | I31: 13862 | J31: 1.0554754 | K31: 0.97929592 | L31: 0.076179483 | M31: 0.87938248 | N31: 0.80947915 | O31: 0.069903333 | P31: 1.0831826 | Q31: 1.0757806 | R31: 1.1829875 | S31: 1.1690273 | T31: 1.1646122 | U31: 1.2214262
B32: Male (M) | C32: 7430 | D32: 6917 | E32: 513 | F32: 5958 | G32: 5495 | H32: 463 | I32: 7316 | J32: 1.0155823 | K32: 0.945462 | L32: 0.070120284 | M32: 0.81437944 | N32: 0.75109349 | O32: 0.063285949
B33: Female (F) | C33: 7201 | D33: 6658 | E33: 543 | F33: 6232 | G33: 5726 | H33: 506 | I33: 6546 | J33: 1.1000611 | K33: 1.0171097 | L33: 0.082951421 | M33: 0.95203178 | N33: 0.87473266 | O33: 0.077299114
A34: Mati City | B34: Total (MF) | C34: 20532 | D34: 17837 | E34: 2695 | F34: 16601 | G34: 14469 | H34: 2132 | I34: 19345 | J34: 1.0613595 | K34: 0.92204704 | L34: 0.13931248 | M34: 0.85815456 | N34: 0.74794521 | O34: 0.11020936 | P34: 1.0616254 | Q34: 1.0620006 | R34: 1.0591452 | S34: 1.1523854 | T34: 1.1543777 | U34: 1.138959
B35: Male (M) | C35: 10174 | D35: 8837 | E35: 1337 | F35: 7886 | G35: 6867 | H35: 1019 | I35: 9875 | J35: 1.0302785 | K35: 0.89488608 | L35: 0.13539241 | M35: 0.79858228 | N35: 0.69539241 | O35: 0.10318987
B36: Female (F) | C36: 10358 | D36: 9000 | E36: 1358 | F36: 8715 | G36: 7602 | H36: 1113 | I36: 9470 | J36: 1.0937698 | K36: 0.95036959 | L36: 0.14340021 | M36: 0.92027455 | N36: 0.80274551 | O36: 0.11752904
A37: Panabo City | B37: Total (MF) | C37: 28997 | D37: 23039 | E37: 5958 | F37: 23922 | G37: 18627 | H37: 5295 | I37: 25271 | J37: 1.1474417 | K37: 0.91167742 | L37: 0.23576431 | M37: 0.94661865 | N37: 0.73708994 | O37: 0.20952871 | P37: 1.0339616 | Q37: 0.99733357 | R37: 1.1888199 | S37: 1.0877156 | T37: 1.0503237 | U37: 1.2305182
B38: Male (M) | C38: 14638 | D38: 11838 | E38: 2800 | F38: 11773 | G38: 9330 | H38: 2443 | I38: 12968 | J38: 1.1287785 | K38: 0.91286243 | L38: 0.2159161 | M38: 0.90785009 | N38: 0.71946329 | O38: 0.1883868
B39: Female (F) | C39: 14359 | D39: 11201 | E39: 3158 | F39: 12149 | G39: 9297 | H39: 2852 | I39: 12303 | J39: 1.1671137 | K39: 0.91042835 | L39: 0.25668536 | M39: 0.98748273 | N39: 0.75566935 | O39: 0.23181338
A40: Tagum City | B40: Total (MF) | C40: 38344 | D40: 27818 | E40: 10526 | F40: 33191 | G40: 24520 | H40: 8671 | I40: 34515 | J40: 1.1109373 | K40: 0.80596842 | L40: 0.30496885 | M40: 0.96163987 | N40: 0.71041576 | O40: 0.25122411 | P40: 1.0261704 | Q40: 0.96485246 | R40: 1.2079722 | S40: 1.078928 | T40: 1.0116663 | U40: 1.2955843
B41: Male (M) | C41: 19206 | D41: 14362 | E41: 4844 | F41: 16209 | G41: 12369 | H41: 3840 | I41: 17511 | J41: 1.0967963 | K41: 0.82017018 | L41: 0.27662612 | M41: 0.92564674 | N41: 0.706356 | O41: 0.21929073
B42: Female (F) | C42: 19138 | D42: 13456 | E42: 5682 | F42: 16982 | G42: 12151 | H42: 4831 | I42: 17004 | J42: 1.1254999 | K42: 0.79134321 | L42: 0.33415667 | M42: 0.99870619 | N42: 0.71459657 | O42: 0.28410962
...

Sheet AIR-NIR Kinder
A1: DEPARTMENT OF EDUCATION
A2: APPARENT (GROSS) AND NET INTAKE RATE IN KINDERGARTEN EDUCATION
A3: (Based on Learners' School Address)
A4: SY 2023-2024
A6: Region/Division | C6: New Entrants to Kinder (All Ages) | F6: New Entrants to Kinder (Age 5) | I6: Population | J6: Apparent Intake Rate (AIR) | M6: Net Intake Rate (NIR) | P6: Gender Parity Index (AIR) | S6: Gender Parity Index (NIR)
C7: Total | D7: Public | E7: Private | F7: Total | G7: Public | H7: Private | I7: (Age 5) | J7: Both | K7: Public | L7: Private | M7: Both | N7: Public | O7: Private | P7: Both | Q7: Public | R7: Private | S7: Both | T7: Public | U7: Private
A8: REGION XI - DAVAO REGION
A10: Davao City | B10: Total (MF) | C10: 34178 | D10: 29520 | E10: 4658 | F10: 27565 | G10: 23526 | H10: 4039 | I10: 35303 | J10: 0.96813302 | K10: 0.83618956 | L10: 0.13194346 | M10: 0.78081183 | N10: 0.66640229 | O10: 0.11440954 | P10: 1.0162628 | Q10: 1.0211258 | R10: 0.98596301 | S10: 1.0851201 | T10: 1.0947917 | U10: 1.0304637
B11: Male (M) | C11: 17491 | D11: 15072 | E11: 2419 | F11: 13655 | G11: 11602 | H11: 2053 | I11: 18209 | J11: 0.96056895 | K11: 0.82772255 | L11: 0.13284639 | M11: 0.74990389 | N11: 0.63715745 | O11: 0.11274644
B12: Female (F) | C12: 16687 | D12: 14448 | E12: 2239 | F12: 13910 | G12: 11924 | H12: 1986 | I12: 17094 | J12: 0.97619048 | K12: 0.84520885 | L12: 0.13098163 | M12: 0.81373581 | N12: 0.6975547 | O12: 0.11618112
A13: Davao de Oro (Compostela Valley) | B13: Total (MF) | C13: 14346 | D13: 13653 | E13: 693 | F13: 12700 | G13: 12052 | H13: 648 | I13: 16531 | J13: 0.86782409 | K13: 0.82590285 | L13: 0.041921239 | M13: 0.76825358 | N13: 0.7290545 | O13: 0.039199081 | P13: 1.0118807 | Q13: 1.0126843 | R13: 0.99617277 | S13: 1.0494144 | T13: 1.0512012 | U13: 1.0167137
B14: Male (M) | C14: 7500 | D14: 7135 | E14: 365 | F14: 6524 | G14: 6186 | H14: 338 | I14: 8691 | J14: 0.86296168 | K14: 0.82096422 | L14: 0.041997469 | M14: 0.7506616 | N14: 0.7117708 | O14: 0.038890807
B15: Female (F) | C15: 6846 | D15: 6518 | E15: 328 | F15: 6176 | G15: 5866 | H15: 310 | I15: 7840 | J15: 0.87321429 | K15: 0.83137755 | L15: 0.041836735 | M15: 0.7877551 | N15: 0.74821429 | O15: 0.039540816
A16: Davao del Norte | B16: Total (MF) | C16: 10142 | D16: 9287 | E16: 855 | F16: 8692 | G16: 7901 | H16: 791 | I16: 10911 | J16: 0.92952067 | K16: 0.85115938 | L16: 0.078361287 | M16: 0.79662726 | N16: 0.72413161 | O16: 0.072495647 | P16: 1.0298771 | Q16: 1.0286844 | R16: 1.0429195 | S16: 1.0667454 | T16: 1.0661801 | U16: 1.0724087
B17: Male (M) | C17: 5180 | D17: 4746 | E17: 434 | F17: 4363 | G17: 3967 | H17: 396 | I17: 5653 | J17: 0.91632761 | K17: 0.83955422 | L17: 0.076773395 | M17: 0.77180258 | N17: 0.70175128 | O17: 0.0700513
B18: Female (F) | C18: 4962 | D18: 4541 | E18: 421 | F18: 4329 | G18: 3934 | H18: 395 | I18: 5258 | J18: 0.94370483 | K18: 0.86363636 | L18: 0.080068467 | M18: 0.82331685 | N18: 0.74819323 | O18: 0.075123621
A19: Davao del Sur | B19: Total (MF) | C19: 8891 | D19: 8455 | E19: 436 | F19: 7607 | G19: 7215 | H19: 392 | I19: 10031 | J19: 0.88635231 | K19: 0.84288705 | L19: 0.043465258 | M19: 0.75834912 | N19: 0.71927026 | O19: 0.039078856 | P19: 0.99296164 | Q19: 0.99605373 | R19: 0.93476694 | S19: 1.0461848 | T19: 1.0488713 | U19: 0.99791952
B20: Male (M) | C20: 4638 | D20: 4404 | E20: 234 | F20: 3869 | G20: 3665 | H20: 204 | I20: 5215 | J20: 0.88935762 | K20: 0.84448706 | L20: 0.044870566 | M20: 0.74189837 | N20: 0.70278044 | O20: 0.039117929
B21: Female (F) | C21: 4253 | D21: 4051 | E21: 202 | F21: 3738 | G21: 3550 | H21: 188 | I21: 4816 | J21: 0.88309801 | K21: 0.84115449 | L21: 0.041943522 | M21: 0.77616279 | N21: 0.73712625 | O21: 0.039036545
A22: Davao Occidental | B22: Total (MF) | C22: 6882 | D22: 6728 | E22: 154 | F22: 4696 | G22: 4582 | H22: 114 | I22: 7546 | J22: 0.91200636 | K22: 0.8915982 | L22: 0.020408163 | M22: 0.62231646 | N22: 0.60720912 | O22: 0.015107342 | P22: 1.0001817 | Q22: 1.0058224 | R22: 0.78083581 | S22: 1.0482331 | T22: 1.0529972 | U22: 0.87319274
B23: Male (M) | C23: 3510 | D23: 3422 | E23: 88 | F23: 2340 | G23: 2278 | H23: 62 | I23: 3849 | J23: 0.91192518 | K23: 0.88906209 | L23: 0.022863081 | M23: 0.60795012 | N23: 0.59184204 | O23: 0.01610808
B24: Female (F) | C24: 3372 | D24: 3306 | E24: 66 | F24: 2356 | G24: 2304 | H24: 52 | I24: 3697 | J24: 0.91209088 | K24: 0.89423857 | L24: 0.017852313 | M24: 0.63727346 | N24: 0.62320801 | O24: 0.014065458
